Workbook

Sheet Annex A
A1: I. CHECK SỔ SÁCH VỚI DANH MỤC KIỂM KÊ
B3: TÀI SẢN | C3: Anex | D3: Theo sổ sách (23.3.2026) | F3: Theo Annex A | H3: Chênh lệch
D4: Số lượng | E4: Giá trị | F4: Số lượng | G4: Giá trị | H4: Số lượng | I4: Giá trị
B5: Tồn kho phim SX (Tk 15666) | C5: A | D5: =COUNTA('TK 15666. Phim SX'!$B$6:$B$13) | E5: 36977023489 | G5: =E5
B6: Tồn kho CT Phim (Tk 15661) | C6: A | D6: =COUNTA('TK 15661.Bản quyền phim '!$B$6:$B$497)+2 | E6: 55564486653 | F6: =COUNTIF('TK 15661.Bản quyền phim '!$AH$6:$AH$497,"OK")+2 | G6: =E6 | H6: =D6-F6 | I6: =SUMIF('TK 15661.Bản quyền phim '!$AH$6:$AH$497, 0, 'TK 15661.Bản quyền phim '!$X$6:$X$497) | J6: Cần kiểm kê bổ sung
B7: Bản quyền phim VOD | C7: A | E7: 0 | F7: =H20 | G7: 0 | H7: Đã ghi nhận thẳng vào P&L, không còn số dư trên BCĐKT
B8: Phim Barter | C8: A | E8: 0 | F8: =I20 | G8: 0
B9: Show tự sản xuất | C9: A | E9: 0 | F9: =J20 | G9: 0
A11: II. CHECK DANH MỤC KIỂM KÊ VỚI SỔ SÁCH
E12: Trong sổ sách | I12: Ngoài sổ sách
B13: Danh sách kiểm kê License | C13: Unit | D13: Number | E13: TK 15661 | F13: TK 242. Bản quyền phim hợp tác | G13: TK 15666. Bản quyền phim tự SX | H13: 242. Bản quyền phim VOD | I13: Phim Barter | J13: Show tự sản xuất | K13: Check | L13: VSTV's note
B14: KK1. Movies | C14: Titles | D14: =COUNTA('KK1. Movies'!A7:A343) | E14: =COUNTIF('KK1. Movies'!$AM$7:$AM$343,1) | F14: =COUNTIF('242.BQ Phim hợp tác'!$R:$R,1) | K14: =SUM(E14:J14)=D14 | L14: Gồm 331 phim trong sheet 15661 và 6 phim trong sheet 242 bản quyền Phim hợp tác
B15: KK2. Series | C15: Titles | D15: =COUNTA('KK2. Series'!A7:A174) | E15: =COUNTIF('KK2. Series'!$AR$7:$AR$174,1) | G15: =COUNTIF('KK2. Series'!$AQ$7:$AQ$174,1) | H15: =COUNTIF('KK2. Series'!$AP$7:$AP$174,1) | I15: =COUNTIF('KK2. Series'!$AS$7:$AS$174,1) | K15: =SUM(E15:J15)=D15 | L15: Gồm 331 phim trong sheet 15661 và 7 phim trong sheet 15666 Bản quyền phim tự SX
B16: KK3. Kids | C16: Titles | D16: =COUNTA('KK3. Kids'!$A$7:$A$57) | E16: =COUNTIF('KK3. Kids'!$AI$7:$AI$57,1) | K16: =SUM(E16:J16)=D16 | L16: Thực tế tăng 2 so với Annex A vì lỗi STT ở sheet Kids
B17: KK4. Show | C17: Titles | D17: =COUNTA('KK4. Show'!A7:A15) | J17: =COUNTIF('KK4. Show'!$O$6:$O$15,1) | K17: =SUM(E17:J17)=D17 | L17: Đây là các show K+ thuê bên thứ 3 hoặc tự sản xuất, không theo dõi tồn kho, đã tính vào chi phí khi phát sóng shows
B18: KK5. Doc | C18: Titles | D18: =COUNTA('KK5. Doc'!B7:B23) | E18: =COUNTIF('KK5. Doc'!$Y$7:$Y$23,1) | G18: =COUNTIF('KK5. Doc'!$Z$7:$Z$23,1) | I18: =COUNTIF('KK5. Doc'!$AA$7:$AA$23,1) | K18: =SUM(E18:J18)=D18 | L18: gồm 14 Docs free của Kênh DW + 3 Docs
B19: KK6. Bổ sung | C19: Titles | D19: =COUNTA('KK6. Bổ sung'!$A$7:$A$44) | E19: =COUNTIF('TK 15661.Bản quyền phim '!$AH$5:$AH$1048576,0) | K19: =SUM(E19:J19)=D19
B20: Total | D20: =SUM(D14:D19) | E20: =SUM(E14:E19) | F20: =SUM(F14:F19) | G20: =SUM(G14:G19) | H20: =SUM(H14:H19) | I20: =SUM(I14:I19) | J20: =SUM(J14:J19)

Sheet CodeRanMovies
A1: Clip Code | B1: Title EN | C1: Genres | D1: Rating | E1: Year | F1: Start Time | G1: End Time | H1: Data ID | I1: Stream URL | J1: Play Result | K1: Status
A2: MOV_DRA730 | B2: Shining for One Thing | C2: Movies | D2: 2 | E2: 2023 | F2: 2024-12-11T00:00:00+07:00 | H2: 99db7204-f12d-442e-be59-e8596a148abd | I2: https://censorship.kplus.vn/MediaAssets/Asset/6d095282-3fce-ef11-8593-0c42a12723cb/StreamPreview | J2: YES | K2: Success
A3: MOV_ACT_23__2691047 | B3: Rogue | C3: Movies | D3: 3 | E3: 2020 | F3: 2023-02-23T00:00:00+07:00 | H3: f2258306-4dcb-4197-a268-7896a7f70e45 | I3: https://censorship.kplus.vn/MediaAssets/Asset/c38272f7-e9ef-ee11-9144-f40270bf9ea7/StreamPreview | J3: YES | K3: Success
A4: MOV_ACT_22__2687284 | B4: Escape Plan 2: Hades | C4: Movies | D4: 4 | E4: 2018 | F4: 2022-12-22T00:00:00+07:00 | H4: f25fcdb0-2c40-4079-8fdd-3692aef3e45d | I4: https://censorship.kplus.vn/MediaAssets/Asset/239b2c3e-ceed-ee11-9144-f40270bf9ea7/StreamPreview | J4: YES | K4: Success
A5: MOV_ACT_23__2693370 | B5: Riam: Fighting Angel | C5: Movies | D5: 3 | E5: 2020 | F5: 2023-03-23T00:00:00+07:00 | H5: 8f92b6e0-a6ed-4c4f-b921-36b2f2694452 | I5: https://censorship.kplus.vn/MediaAssets/Asset/5a613a78-79f0-ee11-9144-f40270bf9ea7/StreamPreview | J5: YES | K5: Success
A6: MOV_ANI_23__2697127 | B6: Happy family | C6: Movies | D6: 5 | E6: 2017 | F6: 2023-05-12T00:00:00+07:00 | H6: dfc52e23-1a10-4573-9e16-6a589266ea2c | I6: https://censorship.kplus.vn/MediaAssets/Asset/c8311c8f-6ff0-ee11-9144-f40270bf9ea7/StreamPreview | J6: YES | K6: Success
A7: MOV_DRA739 | B7: Memoirs of a Geisha | C7: Movies | D7: 3 | E7: 2005 | F7: 2024-12-28T00:00:00+07:00 | H7: a65b5116-7df4-49d5-ad87-c2a0ac2f9ef3 | I7: https://censorship.kplus.vn/MediaAssets/Asset/49e59ea8-d5e9-ef11-8593-0c42a12723cb/StreamPreview | J7: YES | K7: Success
A8: MOV_DRA_23__2695077 | B8: The Courier | C8: Movies | D8: 3 | E8: 2021 | F8: 2023-04-20T00:00:00+07:00 | H8: 390f2015-66be-4d5d-bd86-5a292b9e17f9 | I8: https://censorship.kplus.vn/MediaAssets/Asset/fbac9cea-8ff3-ee11-9144-f40270bf9ea7/StreamPreview | J8: YES | K8: Success
A9: MOV_ACT_22__2686885 | B9: Hitman's Wife's Bodyguard | C9: Movies | D9: 4 | E9: 2021 | F9: 2022-12-16T00:00:00+07:00 | H9: ff3ed7b0-ee55-4648-83bb-4a44f4c0e853 | I9: https://censorship.kplus.vn/MediaAssets/Asset/e3f612f7-d2ed-ee11-9144-f40270bf9ea7/StreamPreview | J9: YES | K9: Success
A10: MOV_HOR_24__2713435 | B10: Guimoon: The lightless door | C10: Movies | D10: 4 | E10: 2021 | F10: 2024-02-28T00:00:00+07:00 | H10: 848b5a96-9f0e-4f95-ab59-a5ccb66fa8b2 | I10: https://censorship.kplus.vn/MediaAssets/Asset/0e72dc39-2077-ef11-8593-0c42a12723cb/StreamPreview | J10: YES | K10: Success
A11: MOV_DRA_23__2696593 | B11: Greta | C11: Movies | D11: 3 | E11: 2018 | F11: 2023-05-05T00:00:00+07:00 | H11: d8c4c337-36ec-40eb-9bb5-a0696eb79df5 | I11: https://censorship.kplus.vn/MediaAssets/Asset/6e78c7e1-54f0-ee11-9144-f40270bf9ea7/StreamPreview | J11: YES | K11: Success
A12: MOV_FAN_22__2686869 | B12: HOUSE WITH A CLOCK IN ITS WALLS | C12: Movies | D12: 5 | E12: 2018 | F12: 2022-12-15T00:00:00+07:00 | H12: 1be7d597-9d3f-4099-a11c-2aecd70ca673 | I12: https://censorship.kplus.vn/MediaAssets/Asset/d1884a75-d3f4-ee11-9144-f40270bf9ea7/StreamPreview | J12: YES | K12: Success
A13: MOV_CRI_21__2648182 | B13: MOZU | C13: Movies | D13: 3 | E13: 2015 | F13: 2021-04-13T00:00:00+07:00 | H13: bebd0816-a009-4c32-8999-c855c0c8140f | I13: https://censorship.kplus.vn/MediaAssets/Asset/318eb5ad-58ea-ee11-9144-f40270bf9ea7/StreamPreview | J13: YES | K13: Success
... A63: MOV_DRA_24__2712649 | B63: Phantom Thread | C63: Movies | D63: 3 | E63: 2017 | F63: 2024-02-16T00:00:00+07:00 | H63: 11bc91f4-93af-4874-a792-255ca791e5cb | I63: https://censorship.kplus.vn/MediaAssets/Asset/19783d90-0bf8-ee11-9144-f40270bf9ea7/StreamPreview | J63: YES | K63: Success
A64: MOV_ACT608 | B64: Elysium | C64: Movies | D64: 3 | F64: 2025-02-26T00:00:00+07:00 | H64: ecd81622-b53c-4a29-a8d5-a9929542c4e4 | I64: https://censorship.kplus.vn/MediaAssets/Asset/76172eb6-a90b-f011-8593-0c42a12723cb/StreamPreview | J64: YES | K64: Success
A65: MOV_HOR_22__2686491 | B65: Countdown (US) | C65: Movies | D65: 4 | E65: 2019 | F65: 2022-12-08T00:00:00+07:00 | H65: e89dcc78-bd41-48a5-a443-11ed62874399 | I65: https://censorship.kplus.vn/MediaAssets/Asset/7ca6779f-d0ed-ee11-9144-f40270bf9ea7/StreamPreview | J65: YES | K65: Success
A66: MOV_DRA_23__2698013 | B66: The Woman Who Ran | C66: Movies | D66: 2 | E66: 2020 | F66: 2023-05-24T00:00:00+07:00 | H66: 5fa4df1f-2b28-4402-96dc-eb65e637ebf0 | I66: https://censorship.kplus.vn/MediaAssets/Asset/089e84fb-4af0-ee11-9144-f40270bf9ea7/StreamPreview | J66: YES | K66: Success
A67: MOV_ADV_22__2686513 | B67: Arctic | C67: Movies | D67: 2 | E67: 2018 | F67: 2022-12-08T00:00:00+07:00 | H67: 0bb30b57-9133-40d7-800a-319415635db2 | I67: https://censorship.kplus.vn/MediaAssets/Asset/060fe2bf-cbed-ee11-9144-f40270bf9ea7/StreamPreview | J67: YES | K67: Success
A68: MOV_ACT_24__2713785 | B68: The bravest | C68: Movies | D68: 2 | E68: 2019 | F68: 2024-03-05T00:00:00+07:00 | H68: c71c93a1-6d09-4288-a386-98bc7c9d8cb4 | I68: https://censorship.kplus.vn/MediaAssets/Asset/abc5582b-3df8-ee11-9144-f40270bf9ea7/StreamPreview | J68: YES | K68: Success
A69: MOV_ACT588 | B69: Ride Along 2 | C69: Movies | D69: 3 | E69: 2016 | F69: 2024-07-17T00:00:00+07:00 | H69: d10d2da7-1b5d-4056-996d-32589caa938d | I69: https://censorship.kplus.vn/MediaAssets/Asset/e63c2091-9788-ef11-8593-0c42a12723cb/StreamPreview | J69: YES | K69: Success
A70: MOV_COM_22__2686870 | B70: Love again | C70: Movies | D70: 3 | E70: 2019 | F70: 2022-12-15T00:00:00+07:00 | H70: 1678f8ff-bd0b-4e92-8d00-dc310f15e4f9 | I70: https://censorship.kplus.vn/MediaAssets/Asset/ee2e91b2-cced-ee11-9144-f40270bf9ea7/StreamPreview | J70: YES | K70: Success
A71: MOV_COM290 | B71: The Royal Bride | C71: Movies | D71: 3 | E71: 2020 | F71: 2024-12-11T00:00:00+07:00 | H71: f070a445-e563-427e-a25d-f36acc0302ef | I71: https://censorship.kplus.vn/MediaAssets/Asset/cd5e0583-71bf-ef11-8593-0c42a12723cb/StreamPreview | J71: YES | K71: Success
A72: MOV_COM_23__2697133 | B72: More than family | C72: Movies | D72: 3 | E72: 2020 | F72: 2023-05-12T00:00:00+07:00 | H72: ff87254e-a32c-4fad-a344-f1cf8e6efca2 | I72: https://censorship.kplus.vn/MediaAssets/Asset/edf5e806-6ef0-ee11-9144-f40270bf9ea7/StreamPreview | J72: YES | K72: Success
A73: MOV_ACT610 | B73: Good job | C73: Movies | D73: 3 | E73: 2023 | F73: 2025-03-19T00:00:00+07:00 | H73: cec9ab68-c716-4c5f-aefe-59d90b65cccb | I73: https://censorship.kplus.vn/MediaAssets/Asset/ffaff898-c415-f011-8593-0c42a12723cb/StreamPreview | J73: YES | K73: Success
A74: MOV_ACT_24__2714420 | B74: The Age of Blood | C74: Movies | D74: 3 | E74: 2017 | F74: 2024-03-15T00:00:00+07:00 | H74: 9c66f642-f344-4e09-a4ea-39d3a909aca3 | I74: https://censorship.kplus.vn/MediaAssets/Asset/a5bbd01c-4f01-ef11-9144-f40270bf9ea7/StreamPreview | J74: YES | K74: Success
A75: MOV_BIO_24__2713783 | B75: A Beautiful Day in the Neighborhood | C75: Movies | D75: 2 | E75: 2019 | F75: 2024-03-05T00:00:00+07:00 | H75: edb0cf65-3881-4096-8b68-5dd8459e3a8a | I75: https://censorship.kplus.vn/MediaAssets/Asset/1f66ab66-ef0d-ef11-9144-f40270bf9ea7/StreamPreview | J75: YES | K75: Success
A76: MOV_ACT576 | B76: Hanna | C76: Movies | D76: 3 | E76: 2011 | F76: 2024-06-19T00:00:00+07:00 | H76: 25430911-4471-4510-82ca-aae7360731fb | I76: https://censorship.kplus.vn/MediaAssets/Asset/640403e3-6c58-ef11-914a-f40270bf9ea7/StreamPreview | J76: YES | K76: Success
... A92: MOV_ACT593 | B92: Twilight of the Warriors: Walled In | C92: Movies | D92: 4 | E92: 2024 | F92: 2024-12-11T00:00:00+07:00 | H92: 2711eb79-2611-464e-9a98-179a5c6afd9b | I92: https://censorship.kplus.vn/MediaAssets/Asset/2fece511-5fb6-f011-8593-0c42a12723cb/StreamPreview | J92: YES | K92: Success
A93: MOV_FAN_LNVM__15__2467819 | B93: THE LOST DRAGON | C93: Movies | D93: 2 | F93: 2017-09-09T00:00:00+07:00 | H93: 2ef968d7-5467-4bfe-bd28-8614b5d174ee | I93: https://censorship.kplus.vn/MediaAssets/Asset/9e1b17fc-d37c-ef11-8593-0c42a12723cb/StreamPreview | J93: YES | K93: Success
A94: MOV_ACT_23__2695915 | B94: AVA (Eve) | C94: Movies | D94: 3 | E94: 2020 | F94: 2023-04-27T00:00:00+07:00 | H94: 9ab6bef3-c5a6-4dd1-81e8-f4adfe487714 | I94: https://censorship.kplus.vn/MediaAssets/Asset/79cf8027-70f0-ee11-9144-f40270bf9ea7/StreamPreview | J94: YES | K94: Success
A95: MOV_COM_23__2697132 | B95: Seven Sundays | C95: Movies | D95: 2 | E95: 2017 | F95: 2023-05-12T00:00:00+07:00 | H95: 138cc898-277f-4a2b-8320-ffa2f47fc165 | I95: https://censorship.kplus.vn/MediaAssets/Asset/71d37d0f-57f0-ee11-9144-f40270bf9ea7/StreamPreview | J95: YES | K95: Success
A96: MOV_ACT_24__2711608 | B96: Hypnotic | C96: Movies | D96: 4 | E96: 2023 | F96: 2024-01-24T00:00:00+07:00 | H96: de6d52f6-3d28-4941-88e4-c000b2a2ae43 | I96: https://censorship.kplus.vn/MediaAssets/Asset/3bbc123b-1e43-ef11-9145-f40270bf9ea7/StreamPreview | J96: YES | K96: Success
A97: MOV_COM_22__2686514 | B97: Bye Bye Morons | C97: Movies | D97: 2 | E97: 2020 | F97: 2022-12-08T00:00:00+07:00 | H97: 10246818-6f63-4b6f-ba52-a5b7eb094a23 | I97: https://censorship.kplus.vn/MediaAssets/Asset/47077827-d1ed-ee11-9144-f40270bf9ea7/StreamPreview | J97: YES | K97: Success
A98: MOV_DRA741 | B98: Blood Moon Party | C98: Movies | D98: 4 | E98: 2020 | F98: 2025-01-01T00:00:00+07:00 | H98: 9fd13652-1fd2-4cbe-b076-38da98160612 | I98: https://censorship.kplus.vn/MediaAssets/Asset/fe8e37f4-4ac7-ef11-8593-0c42a12723cb/StreamPreview | J98: YES | K98: Success
A99: MOV_THR168 | B99: Watcher | C99: Movies | D99: 3 | E99: 2022 | F99: 2025-04-09T00:00:00+07:00 | H99: 1532c171-aba4-47bf-a7f4-af637fb54a76 | I99: https://censorship.kplus.vn/MediaAssets/Asset/d6e9ed2a-b021-f011-8593-0c42a12723cb/StreamPreview | J99: YES | K99: Success
A100: MOV_ANI87 | B100: SONIC THE HEDGEHOG 2 | C100: Movies | D100: 1 | E100: 2022 | F100: 2025-04-29T00:00:00+07:00 | H100: 6967569f-89fb-45b6-98f9-d4d1394574bd | I100: https://censorship.kplus.vn/MediaAssets/Asset/78c141b2-d036-f011-8593-0c42a12723cb/StreamPreview | J100: YES | K100: Success
A101: MOV_BIO_24__2715624 | B101: Get on up | C101: Movies | D101: 3 | E101: 2014 | F101: 2024-04-02T00:00:00+07:00 | H101: 93f7a5c2-5625-4ce5-926e-0aff01acff52 | I101: https://censorship.kplus.vn/MediaAssets/Asset/92a688d2-3a13-ef11-9144-f40270bf9ea7/StreamPreview | J101: YES | K101: Success
A102: MOV_ACT_24__2710435 | B102: The King's Daughter | C102: Movies | D102: 2 | E102: 2022 | F102: 2024-01-09T00:00:00+07:00 | H102: 838c3d6e-3ec6-4621-9b24-35916537001a | I102: https://censorship.kplus.vn/MediaAssets/Asset/3759c88d-2ef8-ee11-9144-f40270bf9ea7/StreamPreview | J102: YES | K102: Success
A103: MOV_FAN27 | B103: The Journey Of Flower | C103: Movies | D103: 2 | E103: 2024 | F103: 2025-04-02T00:00:00+07:00 | H103: b46e5f46-e328-4434-82af-6ae09321466d | I103: https://censorship.kplus.vn/MediaAssets/Asset/74287a46-f21f-f011-8593-0c42a12723cb/StreamPreview | J103: YES | K103: Success
A104: MOV_COM_21__2662692 | B104: Mother Gamer | C104: Movies | D104: 3 | E104: 2020 | F104: 2021-12-07T00:00:00+07:00 | H104: 753ce577-a1b1-40d1-b20b-67ab1f802870 | I104: https://censorship.kplus.vn/MediaAssets/Asset/b99881be-ede9-ee11-9144-f40270bf9ea7/StreamPreview | J104: YES | K104: Success
...

Sheet KK1. Movies
A1: CÔNG TY: | C1: Công ty TNHH Truyền hình số vệ tinh Việt Nam | AO1: Cộng Hòa Xã Hội Chủ Nghĩa Việt Nam
AO2: Độc Lập - Tự Do - Hạnh Phúc
A3: BÁO CÁO KIỂM KÊ BẢN QUYỀN MOVIES
A4: Thời điểm:….......giờ, ngày…....tháng.........năm 2026
AD5: Lưu trữ | AI5: Ref File Kế toán | AN5: Check | AO5: SỐ LIỆU KIỂM KÊ | AR5: Giải trình chênh lệch | AS5: Đề xuất Phương án xử lý
A6: STT | B6: Content Rating | C6: Clip Code | D6: ENGLISH Title | E6: VIET Title | F6: Main Genre | G6: Provider | H6: Contract number | I6: Year of Production | J6: Origin | K6: Duration (minute) | L6: From (DTH) | M6: To (DTH) | N6: VSTV's 1st airing date | O6: Channel | P6: Exclusive (month) | Q6: Sub-license | R6: OTT rights | S6: Catch-up | T6: SVOD | U6: FVOD | V6: AVOD | W6: TVOD | X6: Internet Streaming | Y6: Internet Downloading | Z6: From (VOD) | AA6: To (VOD) | AB6: Runs No. | AC6: Broadcasted runs | AD6: HD Censorship | AE6: LTO | AF6: Drive ( ổ cứng) | AG6: Note | AI6: Tên trên file Kế toán | AJ6: details kế toán | AK6: Giá trị còn lại (15661) | AL6: Check ref "TK 242.BQ Phim hợp tác" | AM6: Check ref "TK 15661. Bản quyền phim" | AO6: Số lượng | AP6: From (VOD) | AQ6: To (VOD) | AR6: Giải trình chênh lệch | AS6: Đề xuất Phương án xử lý | AT6: Kết quả tìm
A7: =_xlfn.AGGREGATE(3,3,$D$7:D7) | B7: 13+ | C7: MOV_DRA730 | D7: SHINING FOR ONE THING | E7: Ngôi Sao Lấp Lánh | F7: Thriller, Mystery, Romance, Fantasy | G7: Skyline Media | H7: 36/2025/HDBQ/VSTV-SM | I7: 2023 | J7: China | K7: 107 | L7: 45674 | M7: 47169 | N7: 45674 | P7: 12 | Q7: No | R7: Yes | S7: Yes | T7: Yes | U7: Yes | V7: Yes | W7: Yes | X7: Yes | Y7: No | Z7: 45674 | AA7: 47169 | AB7: 24 | AC7: 3 | AD7: Yes | AE7: Yes | AG7: Phim còn hạn từ 2026 | AI7: SHINING FOR ONE THING | AJ7: =SUMIF('TK 15661.Bản quyền phim '!F:F,'KK1. Movies'!D7,'TK 15661.Bản quyền phim '!X:X) | AK7: =SUMIF('TK 15661.Bản quyền phim '!F:F,'KK1. Movies'!AI7,'TK 15661.Bản quyền phim '!X:X) | AL7: =COUNTIF('242.BQ Phim hợp tác'!$C:$C,'KK1. Movies'!AI7) | AM7: =COUNTIF('TK 15661.Bản quyền phim '!F:F,'KK1. Movies'!AI7) | AN7: =AL7+AM7 | AT7: =IFERROR(VLOOKUP(C7, CodeRanMovies!$A:$K, 11, 0), "Not found")
A8: =_xlfn.AGGREGATE(3,3,$D$7:D8) | B8: 16+ | C8: MOV_ACT_23__2691047 | D8: ROGUE | E8: Biệt đội săn mồi | F8: Action, Adventure | G8: Roses Media | H8: 140/2022/HDBQ/VSTV-RM | I8: 2020 | J8: US | K8: 105 | L8: 45077 | M8: 46172 | N8: 45077 | O8: K+CINE | P8: Exclusive All Pay TV Rights for first 12 months. Non exclusive All VOD during LP | Q8: No | R8: Yes | S8: No | T8: Yes | U8: Yes | V8: Yes | W8: Yes | X8: Yes | Y8: No | Z8: 45077 | AA8: 46172 | AB8: 24 | AC8: 14 | AD8: Yes | AE8: Yes | AG8: Phim còn hạn từ 2026 | AI8: ROGUE HEROS | AJ8: =SUMIF('TK 15661.Bản quyền phim '!F:F,'KK1. Movies'!D8,'TK 15661.Bản quyền phim '!X:X) | AK8: =SUMIF('TK 15661.Bản quyền phim '!F:F,'KK1. Movies'!AI8,'TK 15661.Bản quyền phim '!X:X) | AL8: =COUNTIF('242.BQ Phim hợp tác'!$C:$C,'KK1. Movies'!AI8) | AM8: =COUNTIF('TK 15661.Bản quyền phim '!F:F,'KK1. Movies'!AI8) | AN8: =AL8+AM8 | AT8: =IFERROR(VLOOKUP(C8, CodeRanMovies!$A:$K, 11, 0), "Not found")
A9: =_xlfn.AGGREGATE(3,3,$D$7:D9) | B9: 16+ | C9: MOV_ACT_22__2687284 | D9: Escape Plan 2: Hades | E9: Kế hoạch đào tẩu 2: Địa ngục | F9: Crime, Thriller | G9: Roses Media | H9: 140/2022/HDBQ/VSTV-RM | I9: 2018 | J9: US | K9: 96 | L9: 44967 | M9: 46062 | N9: 44967 | O9: K+CINE | P9: Exclusive All Pay TV Rights for first 12 months. Non exclusive All VOD during LP | Q9: No | R9: Yes | S9: No | T9: Yes | U9: Yes | V9: Yes | W9: Yes | X9: Yes | Y9: no | Z9: 44967 | AA9: 46062 | AB9: 24 | AC9: 22 | AD9: Yes | AE9: Yes | AG9: Phim còn hạn từ 2026 | AI9: Escape Plan 2: Hades | AJ9: =SUMIF('TK 15661.Bản quyền phim '!F:F,'KK1. Movies'!D9,'TK 15661.Bản quyền phim '!X:X) | AK9: =SUMIF('TK 15661.Bản quyền phim '!F:F,'KK1. Movies'!AI9,'TK 15661.Bản quyền phim '!X:X) | AL9: =COUNTIF('242.BQ Phim hợp tác'!$C:$C,'KK1. Movies'!AI9) | AM9: =COUNTIF('TK 15661.Bản quyền phim '!F:F,'KK1. Movies'!AI9) | AN9: =AL9+AM9 | AT9: =IFERROR(VLOOKUP(C9, CodeRanMovies!$A:$K, 11, 0), "Not found")
A10: =_xlfn.AGGREGATE(3,3,$D$7:D10) | B10: 16+ | C10: MOV_ACT_23__2693370 | D10: Riam: Fighting Angel | E10: Riam: Nữ quái nổi loạn | F10: Comedy | G10: Roses Media | H10: 140/2022/HDBQ/VSTV-RM | I10: 2020 | J10: Thailand | K10: 108 | L10: 45064 | M10: 46159 | N10: 45064 | O10: K+CINE | P10: Exclusive All Pay TV Rights for first 12 months. Non exclusive All VOD during LP | Q10: No | R10: Yes | S10: No | T10: Yes | U10: Yes | V10: Yes | W10: Yes | X10: Yes | Y10: No | Z10: 45064 | AA10: 46159 | AB10: 24 | AC10: 16 | AD10: Yes | AE10: Yes | AG10: Phim còn hạn từ 2026 | AI10: Riam: Fighting Angel | AJ10: =SUMIF('TK 15661.Bản quyền phim '!F:F,'KK1. Movies'!D10,'TK 15661.Bản quyền phim '!X:X) | AK10: =SUMIF('TK 15661.Bản quyền phim '!F:F,'KK1. Movies'!AI10,'TK 15661.Bản quyền phim '!X:X) | AL10: =COUNTIF('242.BQ Phim hợp tác'!$C:$C,'KK1. Movies'!AI10) | AM10: =COUNTIF('TK 15661.Bản quyền phim '!F:F,'KK1. Movies'!AI10) | AN10: =AL10+AM10 | AT10: =IFERROR(VLOOKUP(C10, CodeRanMovies!$A:$K, 11, 0), "Not found")
A11: =_xlfn.AGGREGATE(3,3,$D$7:D11) | B11: P | C11: MOV_ANI_23__2697127 | D11: Happy Family | E11: Gia đình là tất cả | F11: Comedy | G11: Roses Media | H11: 140/2022/HDBQ/VSTV-RM | I11: 2017 | J11: Germany | K11: 96 | L11: 45227 | M11: 46322 | N11: 45227 | O11: K+KIDS | Q11: No | R11: Yes | S11: No | T11: Yes | U11: Yes | V11: Yes | W11: Yes | X11: Yes | Y11: No | Z11: 45227 | AA11: 46322 | AB11: 24 | AC11: 16 | AD11: Yes | AE11: Yes | AG11: Phim còn hạn từ 2026 | AI11: Happy Family | AJ11: =SUMIF('TK 15661.Bản quyền phim '!F:F,'KK1. Movies'!D11,'TK 15661.Bản quyền phim '!X:X) | AK11: =SUMIF('TK 15661.Bản quyền phim '!F:F,'KK1. Movies'!AI11,'TK 15661.Bản quyền phim '!X:X) | AL11: =COUNTIF('242.BQ Phim hợp tác'!$C:$C,'KK1. Movies'!AI11) | AM11: =COUNTIF('TK 15661.Bản quyền phim '!F:F,'KK1. Movies'!AI11) | AN11: =AL11+AM11 | AT11: =IFERROR(VLOOKUP(C11, CodeRanMovies!$A:$K, 11, 0), "Not found")
A12: =_xlfn.AGGREGATE(3,3,$D$7:D12) | B12: 16+ | C12: MOV_DRA739 | D12: MEMOIRS OF A GEISHA | E12: Hồi ức của một Geisha | F12: Drama | G12: SONY | H12: Sony/K+Vietnam PayBasic SVOD Package Agmt D3A FE (Feb-5-24) | I12: 2005 | J12: U.S.A.[excluding Territories & Possessions] | K12: 145 | L12: 45701 | M12: 46430 | Q12: No | R12: Yes | S12: Yes | T12: Yes | U12: No | V12: No | W12: No | X12: Yes | Y12: No | Z12: 45701 | AA12: 46246 | AB12: 7 | AC12: 1 | AD12: Yes | AE12: Yes | AG12: Phim còn hạn từ 2026 | AI12: MEMOIRS OF A GEISHA | AJ12: =SUMIF('TK 15661.Bản quyền phim '!F:F,'KK1. Movies'!D12,'TK 15661.Bản quyền phim '!X:X) | AK12: =SUMIF('TK 15661.Bản quyền phim '!F:F,'KK1. Movies'!AI12,'TK 15661.Bản quyền phim '!X:X) | AL12: =COUNTIF('242.BQ Phim hợp tác'!$C:$C,'KK1. Movies'!AI12) | AM12: =COUNTIF('TK 15661.Bản quyền phim '!F:F,'KK1. Movies'!AI12) | AN12: =AL12+AM12 | AT12: =IFERROR(VLOOKUP(C12, CodeRanMovies!$A:$K, 11, 0), "Not found")
A13: =_xlfn.AGGREGATE(3,3,$D$7:D13) | B13: 16+ | C13: MOV_DRA_23__2695077 | D13: Ironbark/ The Courier | E13: Người đưa tin | F13: Crime, Thriller | G13: Roses Media | H13: 140/2022/HDBQ/VSTV-RM | I13: 2021 | J13: US | K13: 112 | L13: 45191 | M13: 46286 | N13: 45191 | O13: K+CINE | P13: Exclusive All Pay TV Rights for first 12 months. Non exclusive All VOD during LP | Q13: No | R13: Yes | S13: No | T13: Yes | U13: Yes | V13: Yes | W13: Yes | X13: Yes | Y13: Yes | Z13: 45191 | AA13: 46286 | AB13: 24 | AC13: 12 | AD13: Yes | AE13: Yes | AG13: Phim còn hạn từ 2026 | AI13: Ironbark/The Courier | AJ13: =SUMIF('TK 15661.Bản quyền phim '!F:F,'KK1. Movies'!D13,'TK 15661.Bản quyền phim '!X:X) | AK13: =SUMIF('TK 15661.Bản quyền phim '!F:F,'KK1. Movies'!AI13,'TK 15661.Bản quyền phim '!X:X) | AL13: =COUNTIF('242.BQ Phim hợp tác'!$C:$C,'KK1. Movies'!AI13) | AM13: =COUNTIF('TK 15661.Bản quyền phim '!F:F,'KK1. Movies'!AI13) | AN13: =AL13+AM13 | AT13: =IFERROR(VLOOKUP(C13, CodeRanMovies!$A:$K, 11, 0), "Not found")
A14: =_xlfn.AGGREGATE(3,3,$D$7:D14) | B14: 16+ | C14: MOV_ACT_22__2686885 | D14: Hitman's Wife's Bodyguard | E14: Vệ sĩ sát thủ 2: Nhà có nóc | F14: Action, Adventure | G14: Roses Media | H14: 140/2022/HDBQ/VSTV-RM | I14: 2021 | J14: US | K14: 89 | L14: 44951 | M14: 46046 | N14: 44951 | O14: K+CINE | P14: Exclusive All Pay TV Rights for first 12 months. Non exclusive All VOD during LP | Q14: No | R14: Yes | S14: Yes | T14: Yes | U14: Yes | V14: Yes | W14: Yes | X14: Yes | Y14: no | Z14: 44951 | AA14: 46046 | AB14: 24 | AC14: 13 | AD14: Yes | AE14: Yes | AG14: Phim còn hạn từ 2026 | AI14: Hitman's Wife's Bodyguard | AJ14: =SUMIF('TK 15661.Bản quyền phim '!F:F,'KK1. Movies'!D14,'TK 15661.Bản quyền phim '!X:X) | AK14: =SUMIF('TK 15661.Bản quyền phim '!F:F,'KK1. Movies'!AI14,'TK 15661.Bản quyền phim '!X:X) | AL14: =COUNTIF('242.BQ Phim hợp tác'!$C:$C,'KK1. Movies'!AI14) | AM14: =COUNTIF('TK 15661.Bản quyền phim '!F:F,'KK1. Movies'!AI14) | AN14: =AL14+AM14 | AT14: =IFERROR(VLOOKUP(C14, CodeRanMovies!$A:$K, 11, 0), "Not found")
A15: =_xlfn.AGGREGATE(3,3,$D$7:D15) | B15: 16+ | C15: MOV_HOR_24__2713435 | D15: GUIMOON: THE LIGHTLESS DOOR | E15: CỔNG ĐỊA NGỤC | F15: Horror | G15: CJ HK | H15: 180/2024/HDBQ/VSTV-CJHK | I15: 2021 | J15: Korea | K15: 85 | L15: 45566 | M15: 46660 | N15: 45568 | O15: K+ACTION | P15: 12 | Q15: No | R15: Yes | S15: Yes | T15: Yes | U15: Yes | V15: Yes | W15: Yes | X15: No | Y15: Yes | Z15: 45566 | AA15: 46660 | AB15: Unlimited | AC15: 11 | AD15: Yes | AE15: Yes | AG15: Phim còn hạn từ 2026 | AI15: GUIMOON: THE LIGHTLESS DOOR (CỔNG ĐỊA NGỤC) | AJ15: =SUMIF('TK 15661.Bản quyền phim '!F:F,'KK1. Movies'!D15,'TK 15661.Bản quyền phim '!X:X) | AK15: =SUMIF('TK 15661.Bản quyền phim '!F:F,'KK1. Movies'!AI15,'TK 15661.Bản quyền phim '!X:X) | AL15: =COUNTIF('242.BQ Phim hợp tác'!$C:$C,'KK1. Movies'!AI15) | AM15: =COUNTIF('TK 15661.Bản quyền phim '!F:F,'KK1. Movies'!AI15) | AN15: =AL15+AM15 | AT15: =IFERROR(VLOOKUP(C15, CodeRanMovies!$A:$K, 11, 0), "Not found")
A16: =_xlfn.AGGREGATE(3,3,$D$7:D16) | B16: 16+ | C16: MOV_DRA_23__2696593 | D16: Greta | E16: Góa phụ Greta | F16: Crime, Thriller | G16: Roses Media | H16: 140/2022/HDBQ/VSTV-RM | I16: 2018 | J16: US | K16: 98 | L16: 45217 | M16: 46312 | N16: 45217 | O16: K+CINE | P16: Exclusive All Pay TV Rights for first 12 months. Non exclusive All VOD during LP | Q16: No | R16: Yes | S16: No | T16: Yes | U16: Yes | V16: Yes | W16: Yes | X16: Yes | Y16: No | Z16: 45217 | AA16: 46312 | AB16: 24 | AC16: 18 | AD16: Yes | AE16: Yes | AG16: Phim còn hạn từ 2026 | AH16: MOV_DRA_23__2696593 | AI16: Greta | AJ16: =SUMIF('TK 15661.Bản quyền phim '!F:F,'KK1. Movies'!D16,'TK 15661.Bản quyền phim '!X:X) | AK16: =SUMIF('TK 15661.Bản quyền phim '!F:F,'KK1. Movies'!AI16,'TK 15661.Bản quyền phim '!X:X) | AL16: =COUNTIF('242.BQ Phim hợp tác'!$C:$C,'KK1. Movies'!AI16) | AM16: =COUNTIF('TK 15661.Bản quyền phim '!F:F,'KK1. Movies'!AI16) | AN16: =AL16+AM16 | AT16: =IFERROR(VLOOKUP(C16, CodeRanMovies!$A:$K, 11, 0), "Not found")
A17: =_xlfn.AGGREGATE(3,3,$D$7:D17) | B17: K | C17: MOV_FAN_22__2686869 | D17: HOUSE WITH A CLOCK IN ITS WALLS | E17: Ngôi nhà có chiếc đồng hồ ma thuật | F17: Comedy | G17: CJ HK | H17: 135/2022/HDBQ/VSTV-CJHK | I17: 2018 | J17: US | K17: 105 | L17: 44952 | M17: 46047 | N17: 44952 | O17: K+CINE | P17: 12 | Q17: No | R17: Yes | S17: Yes | T17: Yes | U17: Yes | V17: Yes | W17: Yes | X17: No | Y17: Yes | Z17: 44952 | AA17: 46047 | AB17: unlimited | AC17: 22 | AD17: Yes | AE17: Yes | AG17: Phim còn hạn từ 2026 | AH17: MOV_FAN_22__2686869 | AI17: HOUSE WITH A CLOCK IN ITS WALLS (Ngôi nhà có chiếc đồng hồ ma thuật) | AJ17: =SUMIF('TK 15661.Bản quyền phim '!F:F,'KK1. Movies'!D17,'TK 15661.Bản quyền phim '!X:X) | AK17: =SUMIF('TK 15661.Bản quyền phim '!F:F,'KK1. Movies'!AI17,'TK 15661.Bản quyền phim '!X:X) | AL17: =COUNTIF('242.BQ Phim hợp tác'!$C:$C,'KK1. Movies'!AI17) | AM17: =COUNTIF('TK 15661.Bản quyền phim '!F:F,'KK1. Movies'!AI17) | AN17: =AL17+AM17 | AT17: =IFERROR(VLOOKUP(C17, CodeRanMovies!$A:$K, 11, 0), "Not found")
A18: =_xlfn.AGGREGATE(3,3,$D$7:D18) | B18: 16+ | C18: MOV_DRA730 | D18: HUNT, THE | E18: Cuộc săn lùng | F18: action | G18: NBC Universal | H18: 5049540-2/161434-3 | I18: 2019 | J18: US | K18: 90 | L18: 45414 | M18: 46143 | N18: 45442 | O18: K+ACTION | P18: Non exclusive | Q18: No | R18: Yes | S18: Yes | T18: Yes | U18: No | V18: No | W18: No | X18: No | Y18: Yes | Z18: 45414 | AA18: 46143 | AB18: 6 | AC18: 4 | AD18: Yes | AE18: Yes | AG18: Phim còn hạn từ 2026 | AI18: HUNT, THE | AJ18: =SUMIF('TK 15661.Bản quyền phim '!F:F,'KK1. Movies'!D18,'TK 15661.Bản quyền phim '!X:X) | AK18: =SUMIF('TK 15661.Bản quyền phim '!F:F,'KK1. Movies'!AI18,'TK 15661.Bản quyền phim '!X:X) | AL18: =COUNTIF('242.BQ Phim hợp tác'!$C:$C,'KK1. Movies'!AI18) | AM18: =COUNTIF('TK 15661.Bản quyền phim '!F:F,'KK1. Movies'!AI18) | AN18: =AL18+AM18 | AT18: =IFERROR(VLOOKUP(C18, CodeRanMovies!$A:$K, 11, 0), "Not found")
A19: =_xlfn.AGGREGATE(3,3,$D$7:D19) | B19: 16+ | C19: MOV_CRI_21__2648182 | D19: MOZU | E19: Sát thủ Mozu | F19: Crime, Thriller | G19: TBS | H19: 202104013 | I19: 2015 | J19: Japan | K19: 116 | L19: 44284 | M19: 46109 | N19: 44349 | O19: K+CINE | Q19: No | R19: Yes | S19: Yes | T19: Yes | U19: Yes | V19: Yes | W19: Yes | X19: Yes | Y19: Yes | Z19: 44284 | AA19: 46109 | AB19: 50 | AC19: 34 | AD19: Yes | AE19: Yes | AG19: Phim còn hạn từ 2026 | AH19: MOV_CRI_21__2648182 | AI19: MOZU | AJ19: =SUMIF('TK 15661.Bản quyền phim '!F:F,'KK1. Movies'!D19,'TK 15661.Bản quyền phim '!X:X) | AK19: =SUMIF('TK 15661.Bản quyền phim '!F:F,'KK1. Movies'!AI19,'TK 15661.Bản quyền phim '!X:X) | AL19: =COUNTIF('242.BQ Phim hợp tác'!$C:$C,'KK1. Movies'!AI19) | AM19: =COUNTIF('TK 15661.Bản quyền phim '!F:F,'KK1. Movies'!AI19) | AN19: =AL19+AM19 | AT19: =IFERROR(VLOOKUP(C19, CodeRanMovies!$A:$K, 11, 0), "Not found")
A20: =_xlfn.AGGREGATE(3,3,$D$7:D20) | B20: 16+ | C20: MOV_ACT556 | D20: Caught In Time | E20: Trừ Gian Diệt Ác | F20: action | G20: Hỏa Thổ | H20: 25A/2024/HDBQ/VSTV-Hoa tho | I20: 2020 | J20: China | K20: 95 | L20: 45443 | M20: 46537 | N20: 45443 | O20: K+CINE | Q20: No | R20: Yes | S20: Yes | T20: Yes | U20: No | V20: Yes | W20: Yes | X20: No | Y20: No | Z20: 45443 | AA20: 46537 | AB20: Unlimited run | AC20: 14 | AD20: Yes | AE20: Yes | AG20: Phim còn hạn từ 2026 | AH20: MOV_ACT556 | AI20: Caught In Time (Trừ Gian Diệt Ác) | AJ20: =SUMIF('TK 15661.Bản quyền phim '!F:F,'KK1. Movies'!D20,'TK 15661.Bản quyền phim '!X:X) | AK20: =SUMIF('TK 15661.Bản quyền phim '!F:F,'KK1. Movies'!AI20,'TK 15661.Bản quyền phim '!X:X) | AL20: =COUNTIF('242.BQ Phim hợp tác'!$C:$C,'KK1. Movies'!AI20) | AM20: =COUNTIF('TK 15661.Bản quyền phim '!F:F,'KK1. Movies'!AI20) | AN20: =AL20+AM20 | AT20: =IFERROR(VLOOKUP(C20, CodeRanMovies!$A:$K, 11, 0), "Not found")
A21: =_xlfn.AGGREGATE(3,3,$D$7:D21) | B21: 16+ | C21: MOV_HOR_24__2713878 | D21: CONTORTED | E21: NHÀ KHO CHẾT CHÓC | F21: Horror | G21: CJ HK | H21: 180/2024/HDBQ/VSTV-CJHK | I21: 2022 | J21: Korea | K21: 90 | L21: 45566 | M21: 46660 | N21: 45589 | O21: K+ACTION | P21: 12 | Q21: No | R21: Yes | S21: Yes | T21: Yes | U21: Yes | V21: Yes | W21: Yes | X21: No | Y21: No | Z21: 45566 | AA21: 46660 | AB21: Unlimited | AC21: 11 | AD21: Yes | AE21: Yes | AG21: Phim còn hạn từ 2026 | AH21: MOV_HOR_24__2713878 | AI21: CONTORTED (NHÀ KHO CHẾT CHÓC) | AJ21: =SUMIF('TK 15661.Bản quyền phim '!F:F,'KK1. Movies'!D21,'TK 15661.Bản quyền phim '!X:X) | AK21: =SUMIF('TK 15661.Bản quyền phim '!F:F,'KK1. Movies'!AI21,'TK 15661.Bản quyền phim '!X:X) | AL21: =COUNTIF('242.BQ Phim hợp tác'!$C:$C,'KK1. Movies'!AI21) | AM21: =COUNTIF('TK 15661.Bản quyền phim '!F:F,'KK1. Movies'!AI21) | AN21: =AL21+AM21 | AT21: =IFERROR(VLOOKUP(C21, CodeRanMovies!$A:$K, 11, 0), "Not found")
A22: =_xlfn.AGGREGATE(3,3,$D$7:D22) | B22: 16+ | C22: MOV_SCI20 | D22: LONG DISTANCE | E22: Tín hiệu vũ trụ | F22: Others | G22: CJ HK | H22: 15/2025/HDBQ/VSTV-CJHK | I22: 2024 | J22: US | K22: 91 | L22: 45722 | M22: 46817 | P22: 12 | Q22: No | R22: Yes | S22: Yes | T22: Yes | U22: Yes | V22: Yes | W22: Yes | X22: Yes | Y22: Yes | Z22: 45722 | AA22: 46817 | AB22: Unlimited | AC22: 8 | AD22: Yes | AE22: Yes | AG22: Phim còn hạn từ 2026 | AI22: LONG DISTANCE | AJ22: =SUMIF('TK 15661.Bản quyền phim '!F:F,'KK1. Movies'!D22,'TK 15661.Bản quyền phim '!X:X) | AK22: =SUMIF('TK 15661.Bản quyền phim '!F:F,'KK1. Movies'!AI22,'TK 15661.Bản quyền phim '!X:X) | AL22: =COUNTIF('242.BQ Phim hợp tác'!$C:$C,'KK1. Movies'!AI22) | AM22: =COUNTIF('TK 15661.Bản quyền phim '!F:F,'KK1. Movies'!AI22) | AN22: =AL22+AM22 | AT22: =IFERROR(VLOOKUP(C22, CodeRanMovies!$A:$K, 11, 0), "Not found")
A23: =_xlfn.AGGREGATE(3,3,$D$7:D23) | B23: 16+ | C23: MOV_CRI_22__2686505 | D23: The Night Clerk | E23: Người trực đêm | F23: Crime, Thriller | G23: Skyline Media | H23: 66/2023/HDBQ/VSTV-SM | I23: 2020 | J23: US | K23: 90 | L23: 44937 | M23: 46032 | N23: 44937 | O23: K+CINE | P23: Exclusive All TV Rights the first 12 months of LP Non-exclusive with All Catch-up TV Rights; All VOD Rights during LP | Q23: No | R23: Yes | S23: Yes | T23: Yes | U23: Yes | V23: Yes | W23: Yes | X23: Yes | Y23: Yes | Z23: 44937 | AA23: 46032 | AB23: 24 | AC23: 21 | AD23: Yes | AE23: Yes | AG23: Phim còn hạn từ 2026 | AI23: The Night Clerk | AJ23: =SUMIF('TK 15661.Bản quyền phim '!F:F,'KK1. Movies'!D23,'TK 15661.Bản quyền phim '!X:X) | AK23: =SUMIF('TK 15661.Bản quyền phim '!F:F,'KK1. Movies'!AI23,'TK 15661.Bản quyền phim '!X:X) | AL23: =COUNTIF('242.BQ Phim hợp tác'!$C:$C,'KK1. Movies'!AI23) | AM23: =COUNTIF('TK 15661.Bản quyền phim '!F:F,'KK1. Movies'!AI23) | AN23: =AL23+AM23 | AT23: =IFERROR(VLOOKUP(C23, CodeRanMovies!$A:$K, 11, 0), "Not found")
A24: =_xlfn.AGGREGATE(3,3,$D$7:D24) | B24: 13+ | C24: MOV_ACT_24__2710733 | D24: Journey to China: The Mystery of the Dragon Seal | E24: Long ẩn cơ mật | F24: Action, Adventure | G24: Rose media | H24: 5/2022/HDBQ/VSTV-RM | I24: 2019 | J24: China | K24: 120 | L24: 45338 | M24: 46433 | N24: 45338 | O24: K+CINE | Q24: No | R24: Yes | S24: Yes | T24: Yes | U24: Yes | V24: Yes | W24: Yes | X24: Yes | Y24: No | Z24: 45338 | AA24: 46433 | AB24: 24 | AC24: 18 | AD24: Yes | AE24: Yes | AG24: Phim còn hạn từ 2026 | AI24: Journey to China: The Mystery of the Dragon Seal | AJ24: =SUMIF('TK 15661.Bản quyền phim '!F:F,'KK1. Movies'!D24,'TK 15661.Bản quyền phim '!X:X) | AK24: =SUMIF('TK 15661.Bản quyền phim '!F:F,'KK1. Movies'!AI24,'TK 15661.Bản quyền phim '!X:X) | AL24: =COUNTIF('242.BQ Phim hợp tác'!$C:$C,'KK1. Movies'!AI24) | AM24: =COUNTIF('TK 15661.Bản quyền phim '!F:F,'KK1. Movies'!AI24) | AN24: =AL24+AM24 | AT24: =IFERROR(VLOOKUP(C24, CodeRanMovies!$A:$K, 11, 0), "Not found")
A25: =_xlfn.AGGREGATE(3,3,$D$7:D25) | B25: 16+ | C25: MOV_ACT_22__2686478 | D25: Gringo | E25: Nhọ gặp hên | F25: Action, Adventure | G25: Pro Partner | H25: 56/2023/HDBQ/VSTV-Pro Partner | I25: 2018 | J25: US | K25: 111 | L25: 44930 | M25: 46025 | N25: 44930 | O25: K+CINE | P25: Exclusive All TV Rights the first 9 months of LP Non-exclusive with All Catch-up TV Rights; All VOD Rights during LP | Q25: No | R25: Yes | S25: Yes | T25: Yes | U25: Yes | V25: Yes | W25: Yes | X25: Yes | Y25: Yes | Z25: 44930 | AA25: 46025 | AB25: unlimited | AC25: 27 | AD25: Yes | AE25: Yes | AG25: Phim còn hạn từ 2026 | AI25: Gringo | AJ25: =SUMIF('TK 15661.Bản quyền phim '!F:F,'KK1. Movies'!D25,'TK 15661.Bản quyền phim '!X:X) | AK25: =SUMIF('TK 15661.Bản quyền phim '!F:F,'KK1. Movies'!AI25,'TK 15661.Bản quyền phim '!X:X) | AL25: =COUNTIF('242.BQ Phim hợp tác'!$C:$C,'KK1. Movies'!AI25) | AM25: =COUNTIF('TK 15661.Bản quyền phim '!F:F,'KK1. Movies'!AI25) | AN25: =AL25+AM25 | AT25: =IFERROR(VLOOKUP(C25, CodeRanMovies!$A:$K, 11, 0), "Not found")
A26: =_xlfn.AGGREGATE(3,3,$D$7:D26) | B26: 16+ | C26: MOV_CRI_23__2694717 | D26: THE GIRL ON THE TRAIN | E26: Cô gái trên tàu | F26: Crime, Thriller | G26: CJ HK | H26: 135/2022/HDBQ/VSTV-CJHK | I26: 2016 | J26: US | K26: 112 | L26: 45275 | M26: 46370 | N26: 45275 | O26: K+CINE | P26: 12 | Q26: No | R26: Yes | S26: Yes | T26: Yes | U26: Yes | V26: Yes | W26: Yes | X26: No | Y26: Yes | Z26: 45275 | AA26: 46370 | AB26: unlimited | AC26: 23 | AD26: Yes | AE26: Yes | AG26: Phim còn hạn từ 2026 | AI26: THE GIRL ON THE TRAIN (Cô gái trên tàu) | AJ26: =SUMIF('TK 15661.Bản quyền phim '!F:F,'KK1. Movies'!D26,'TK 15661.Bản quyền phim '!X:X) | AK26: =SUMIF('TK 15661.Bản quyền phim '!F:F,'KK1. Movies'!AI26,'TK 15661.Bản quyền phim '!X:X) | AL26: =COUNTIF('242.BQ Phim hợp tác'!$C:$C,'KK1. Movies'!AI26) | AM26: =COUNTIF('TK 15661.Bản quyền phim '!F:F,'KK1. Movies'!AI26) | AN26: =AL26+AM26 | AT26: =IFERROR(VLOOKUP(C26, CodeRanMovies!$A:$K, 11, 0), "Not found")
A27: =_xlfn.AGGREGATE(3,3,$D$7:D27) | B27: 16+ | C27: MOV_ACT_23__2691050 | D27: Triple Threat | E27: Bộ ba vệ sĩ | F27: Crime, Thriller | G27: Roses Media | H27: 140/2022/HDBQ/VSTV-RM | I27: 2019 | J27: US, Thailand, China, France | K27: 96 | L27: 45161 | M27: 46256 | N27: 45161 | O27: K+CINE | P27: Exclusive All Pay TV Rights for first 12 months. Non exclusive All VOD during LP | Q27: No | R27: Yes | S27: No | T27: Yes | U27: Yes | V27: Yes | W27: Yes | X27: Yes | Y27: No | Z27: 45161 | AA27: 46256 | AB27: 24 | AC27: 15 | AD27: Yes | AE27: Yes | AG27: Phim còn hạn từ 2026 | AI27: Triple Threat | AJ27: =SUMIF('TK 15661.Bản quyền phim '!F:F,'KK1. Movies'!D27,'TK 15661.Bản quyền phim '!X:X) | AK27: =SUMIF('TK 15661.Bản quyền phim '!F:F,'KK1. Movies'!AI27,'TK 15661.Bản quyền phim '!X:X) | AL27: =COUNTIF('242.BQ Phim hợp tác'!$C:$C,'KK1. Movies'!AI27) | AM27: =COUNTIF('TK 15661.Bản quyền phim '!F:F,'KK1. Movies'!AI27) | AN27: =AL27+AM27 | AT27: =IFERROR(VLOOKUP(C27, CodeRanMovies!$A:$K, 11, 0), "Not found")
A28: =_xlfn.AGGREGATE(3,3,$D$7:D28) | B28: 16+ | C28: MOV_THR_24__2712729 | D28: RECALLED | E28: TRIỆU HỒI | F28: Horror | G28: CJ HK | H28: 180/2024/HDBQ/VSTV-CJHK | I28: 2021 | J28: Korea | K28: 99 | L28: 45358 | M28: 46452 | N28: 45358 | O28: K+ACTION | P28: 12 | Q28: No | R28: Yes | S28: Yes | T28: Yes | U28: Yes | V28: Yes | W28: Yes | X28: No | Y28: Yes | Z28: 45358 | AA28: 46452 | AB28: Unlimited | AC28: 18 | AD28: Yes | AE28: Yes | AG28: Phim còn hạn từ 2026 | AI28: RECALLED (TRIỆU HỒI) | AJ28: =SUMIF('TK 15661.Bản quyền phim '!F:F,'KK1. Movies'!D28,'TK 15661.Bản quyền phim '!X:X) | AK28: =SUMIF('TK 15661.Bản quyền phim '!F:F,'KK1. Movies'!AI28,'TK 15661.Bản quyền phim '!X:X) | AL28: =COUNTIF('242.BQ Phim hợp tác'!$C:$C,'KK1. Movies'!AI28) | AM28: =COUNTIF('TK 15661.Bản quyền phim '!F:F,'KK1. Movies'!AI28) | AN28: =AL28+AM28 | AT28: =IFERROR(VLOOKUP(C28, CodeRanMovies!$A:$K, 11, 0), "Not found")
A29: =_xlfn.AGGREGATE(3,3,$D$7:D29) | B29: 13+ | C29: MOV_ADV_23__2694718 | D29: A DOG'S PURPOSE | E29: Mục đích sống của một chú chó | F29: Drama | G29: CJ HK | H29: 135/2022/HDBQ/VSTV-CJHK | I29: 2016 | J29: US | K29: 100 | L29: 45281 | M29: 46376 | N29: 45281 | O29: K+CINE | P29: 12 | Q29: No | R29: Yes | S29: Yes | T29: Yes | U29: Yes | V29: Yes | W29: Yes | X29: No | Y29: Yes | Z29: 45281 | AA29: 46376 | AB29: unlimited | AC29: 16 | AD29: Yes | AE29: Yes | AG29: Phim còn hạn từ 2026 | AI29: A DOG'S PURPOSE (Mục đích sống của một chú chó) | AJ29: =SUMIF('TK 15661.Bản quyền phim '!F:F,'KK1. Movies'!D29,'TK 15661.Bản quyền phim '!X:X) | AK29: =SUMIF('TK 15661.Bản quyền phim '!F:F,'KK1. Movies'!AI29,'TK 15661.Bản quyền phim '!X:X) | AL29: =COUNTIF('242.BQ Phim hợp tác'!$C:$C,'KK1. Movies'!AI29) | AM29: =COUNTIF('TK 15661.Bản quyền phim '!F:F,'KK1. Movies'!AI29) | AN29: =AL29+AM29 | AT29: =IFERROR(VLOOKUP(C29, CodeRanMovies!$A:$K, 11, 0), "Not found")
A30: =_xlfn.AGGREGATE(3,3,$D$7:D30) | B30: 13+ | C30: MOV_MUS7 | D30: BURLESQUE | E30: Vũ nữ | F30: Drama | G30: SONY PICTURES | H30: Sony/K+Vietnam PayBasic SVOD Package Agmt D2D per JK (19-01-2024) | I30: 2010 | J30: US | K30: 118 | L30: 45505 | M30: 46234 | N30: 45602 | O30: K+CINE | Q30: No | R30: Yes | S30: Yes | T30: Yes | U30: No | V30: No | W30: No | X30: No | Y30: No | Z30: 45505 | AA30: 46234 | AB30: 7 | AC30: 2 | AD30: Yes | AE30: Yes | AG30: Phim còn hạn từ 2026 | AI30: BURLESQUE | AJ30: =SUMIF('TK 15661.Bản quyền phim '!F:F,'KK1. Movies'!D30,'TK 15661.Bản quyền phim '!X:X) | AK30: =SUMIF('TK 15661.Bản quyền phim '!F:F,'KK1. Movies'!AI30,'TK 15661.Bản quyền phim '!X:X) | AL30: =COUNTIF('242.BQ Phim hợp tác'!$C:$C,'KK1. Movies'!AI30) | AM30: =COUNTIF('TK 15661.Bản quyền phim '!F:F,'KK1. Movies'!AI30) | AN30: =AL30+AM30 | AT30: =IFERROR(VLOOKUP(C30, CodeRanMovies!$A:$K, 11, 0), "Not found")
A31: =_xlfn.AGGREGATE(3,3,$D$7:D31) | B31: 13+ | C31: MOV_ACT_23__2695079 | D31: My Spy | E31: Điệp viên tí hon | F31: Comedy | G31: Roses Media | H31: 140/2022/HDBQ/VSTV-RM | I31: 2020 | J31: US | K31: 99 | L31: 45197 | M31: 46292 | N31: 45197 | O31: K+CINE | P31: Exclusive All Pay TV Rights for first 12 months. Non exclusive All VOD during LP | Q31: No | R31: Yes | S31: No | T31: Yes | U31: Yes | V31: Yes | W31: Yes | X31: Yes | Y31: No | Z31: 45197 | AA31: 46292 | AB31: 24 | AC31: 14 | AD31: Yes | AE31: Yes | AG31: Phim còn hạn từ 2026 | AI31: My Spy | AJ31: =SUMIF('TK 15661.Bản quyền phim '!F:F,'KK1. Movies'!D31,'TK 15661.Bản quyền phim '!X:X) | AK31: =SUMIF('TK 15661.Bản quyền phim '!F:F,'KK1. Movies'!AI31,'TK 15661.Bản quyền phim '!X:X) | AL31: =COUNTIF('242.BQ Phim hợp tác'!$C:$C,'KK1. Movies'!AI31) | AM31: =COUNTIF('TK 15661.Bản quyền phim '!F:F,'KK1. Movies'!AI31) | AN31: =AL31+AM31 | AT31: =IFERROR(VLOOKUP(C31, CodeRanMovies!$A:$K, 11, 0), "Not found")
A32: =_xlfn.AGGREGATE(3,3,$D$7:D32) | B32: 16+ | C32: MOV_CRI107 | D32: EMILY THE CRIMINAL | E32: Tội phạm Emily | F32: action | G32: NBC Universal | H32: 5049540-2/161434-3 | I32: 2022 | J32: US | K32: 96 | L32: 45554 | M32: 46283 | N32: 45554 | O32: K+ACTION | Q32: No | R32: Yes | S32: Yes | T32: Yes | U32: No | V32: No | W32: No | X32: No | Y32: Yes | Z32: 45554 | AA32: 46283 | AB32: 6 | AC32: 3 | AD32: Yes | AE32: Yes | AG32: Phim còn hạn từ 2026 | AI32: EMILY THE CRIMINAL | AJ32: =SUMIF('TK 15661.Bản quyền phim '!F:F,'KK1. Movies'!D32,'TK 15661.Bản quyền phim '!X:X) | AK32: =SUMIF('TK 15661.Bản quyền phim '!F:F,'KK1. Movies'!AI32,'TK 15661.Bản quyền phim '!X:X) | AL32: =COUNTIF('242.BQ Phim hợp tác'!$C:$C,'KK1. Movies'!AI32) | AM32: =COUNTIF('TK 15661.Bản quyền phim '!F:F,'KK1. Movies'!AI32) | AN32: =AL32+AM32 | AT32: =IFERROR(VLOOKUP(C32, CodeRanMovies!$A:$K, 11, 0), "Not found")
A33: =_xlfn.AGGREGATE(3,3,$D$7:D33) | B33: 16+ | C33: MOV_COM_24__2710443 | D33: A LONG WAY DOWN | E33: Còn lâu mới chết | F33: Drama | G33: Skyline Media | H33: 28/2024/HDBQ/VSTV-SM | I33: 2014 | J33: UK | K33: 96 | L33: 45385 | M33: 46479 | N33: 45506 | O33: K+CINE | P33: 12 | Q33: No | R33: Yes | S33: Yes | T33: Yes | U33: Yes | V33: Yes | W33: Yes | X33: Yes | Y33: No | Z33: 45385 | AA33: 46479 | AB33: 24 | AC33: 14 | AD33: Yes | AE33: Yes | AG33: Phim còn hạn từ 2026 | AI33: A LONG WAY DOWN | AJ33: =SUMIF('TK 15661.Bản quyền phim '!F:F,'KK1. Movies'!D33,'TK 15661.Bản quyền phim '!X:X) | AK33: =SUMIF('TK 15661.Bản quyền phim '!F:F,'KK1. Movies'!AI33,'TK 15661.Bản quyền phim '!X:X) | AL33: =COUNTIF('242.BQ Phim hợp tác'!$C:$C,'KK1. Movies'!AI33) | AM33: =COUNTIF('TK 15661.Bản quyền phim '!F:F,'KK1. Movies'!AI33) | AN33: =AL33+AM33 | AT33: =IFERROR(VLOOKUP(C33, CodeRanMovies!$A:$K, 11, 0), "Not found")
A34: =_xlfn.AGGREGATE(3,3,$D$7:D34) | B34: 16+ | C34: MOV_HOR68 | D34: WITCH, THE | E34: Phù thủy | F34: Horror | G34: NBC Universal | H34: 5049540-2/161434-3 | I34: 2016 | J34: US | K34: 90 | L34: 45596 | M34: 46325 | N34: 45596 | O34: K+ACTION | Q34: No | R34: Yes | S34: Yes | T34: Yes | U34: No | V34: No | W34: No | X34: No | Y34: Yes | Z34: 45596 | AA34: 46325 | AB34: 6 | AC34: 2 | AD34: Yes | AE34: Yes | AG34: Phim còn hạn từ 2026 | AI34: WITCH, THE | AJ34: =SUMIF('TK 15661.Bản quyền phim '!F:F,'KK1. Movies'!D34,'TK 15661.Bản quyền phim '!X:X) | AK34: =SUMIF('TK 15661.Bản quyền phim '!F:F,'KK1. Movies'!AI34,'TK 15661.Bản quyền phim '!X:X) | AL34: =COUNTIF('242.BQ Phim hợp tác'!$C:$C,'KK1. Movies'!AI34) | AM34: =COUNTIF('TK 15661.Bản quyền phim '!F:F,'KK1. Movies'!AI34) | AN34: =AL34+AM34 | AT34: =IFERROR(VLOOKUP(C34, CodeRanMovies!$A:$K, 11, 0), "Not found")
A35: =_xlfn.AGGREGATE(3,3,$D$7:D35) | B35: 16+ | C35: MOV_ACT584 | D35: AMBULANCE (2022) | E35: Xe cấp cứu | F35: action | G35: NBC Universal | H35: 5049540-2/161434-3 | I35: 2022 | J35: US | K35: 136 | L35: 45513 | M35: 46242 | N35: 45513 | O35: K+CINE | P35: 12 | Q35: No | R35: Yes | S35: Yes | T35: Yes | U35: No | V35: No | W35: No | X35: No | Y35: Yes | Z35: 45513 | AA35: 46242 | AB35: 6 | AC35: 3 | AD35: Yes | AE35: Yes | AG35: Phim còn hạn từ 2026 | AI35: AMBULANCE (2022) | AJ35: =SUMIF('TK 15661.Bản quyền phim '!F:F,'KK1. Movies'!D35,'TK 15661.Bản quyền phim '!X:X) | AK35: =SUMIF('TK 15661.Bản quyền phim '!F:F,'KK1. Movies'!AI35,'TK 15661.Bản quyền phim '!X:X) | AL35: =COUNTIF('242.BQ Phim hợp tác'!$C:$C,'KK1. Movies'!AI35) | AM35: =COUNTIF('TK 15661.Bản quyền phim '!F:F,'KK1. Movies'!AI35) | AN35: =AL35+AM35 | AT35: =IFERROR(VLOOKUP(C35, CodeRanMovies!$A:$K, 11, 0), "Not found")
A36: =_xlfn.AGGREGATE(3,3,$D$7:D36) | B36: 16+ | C36: MOV_COM_22__2686480 | D36: Best Friend | E36: Láng giềng gần | F36: Drama | G36: Pro Partner | H36: 56/2023/HDBQ/VSTV-Pro Partner | I36: 2020 | J36: Korea | K36: 130 | L36: 44938 | M36: 46033 | N36: 44938 | O36: K+CINE | P36: Exclusive All TV Rights the first 9 months of LP Non-exclusive with All Catch-up TV Rights; All VOD Rights during LP | Q36: No | R36: Yes | S36: Yes | T36: Yes | U36: Yes | V36: Yes | W36: Yes | X36: Yes | Y36: Yes | Z36: 44938 | AA36: 46033 | AB36: unlimited | AC36: 26 | AD36: Yes | AE36: Yes | AG36: Phim còn hạn từ 2026 | AI36: Best Friend | AJ36: =SUMIF('TK 15661.Bản quyền phim '!F:F,'KK1. Movies'!D36,'TK 15661.Bản quyền phim '!X:X) | AK36: =SUMIF('TK 15661.Bản quyền phim '!F:F,'KK1. Movies'!AI36,'TK 15661.Bản quyền phim '!X:X) | AL36: =COUNTIF('242.BQ Phim hợp tác'!$C:$C,'KK1. Movies'!AI36) | AM36: =COUNTIF('TK 15661.Bản quyền phim '!F:F,'KK1. Movies'!AI36) | AN36: =AL36+AM36 | AT36: =IFERROR(VLOOKUP(C36, CodeRanMovies!$A:$K, 11, 0), "Not found")
A37: =_xlfn.AGGREGATE(3,3,$D$7:D37) | B37: P | C37: MOV_ANI_23__2709986 | D37: AROUND THE WORLD IN 80 DAYS | E37: KHỈ CON LON TON THẾ GIỚI | F37: Comedy | G37: CJ HK | H37: 180/2024/HDBQ/VSTV-CJHK | I37: 2021 | J37: France | K37: 82 | L37: 45304 | M37: 46399 | N37: 45304 | O37: K+KIDS | P37: 12 | Q37: No | R37: Yes | S37: Yes | T37: Yes | U37: Yes | V37: Yes | W37: Yes | X37: No | Y37: Yes | Z37: 45304 | AA37: 46399 | AB37: Unlimited | AC37: 31 | AD37: Yes | AE37: Yes | AG37: Phim còn hạn từ 2026 | AI37: AROUND THE WORLD IN 80 DAYS (KHỈ CON LON TON THẾ GIỚI) | AJ37: =SUMIF('TK 15661.Bản quyền phim '!F:F,'KK1. Movies'!D37,'TK 15661.Bản quyền phim '!X:X) | AK37: =SUMIF('TK 15661.Bản quyền phim '!F:F,'KK1. Movies'!AI37,'TK 15661.Bản quyền phim '!X:X) | AL37: =COUNTIF('242.BQ Phim hợp tác'!$C:$C,'KK1. Movies'!AI37) | AM37: =COUNTIF('TK 15661.Bản quyền phim '!F:F,'KK1. Movies'!AI37) | AN37: =AL37+AM37 | AT37: =IFERROR(VLOOKUP(C37, CodeRanMovies!$A:$K, 11, 0), "Not found")
A38: =_xlfn.AGGREGATE(3,3,$D$7:D38) | B38: 16+ | C38: MOV_DRA_23__2696805 | D38: The Last Princess | E38: Công chúa cuối cùng | F38: Drama | G38: King Content | H38: 52/2023/HDBQ/VSTV-KC | I38: 2016 | J38: Korea | K38: 127 | L38: 45147 | M38: 46242 | N38: 45226 | O38: K+CINE | P38: Exclusive All PayTV rights and Non-Exclusive VOD rights | Q38: Yes | R38: Yes | S38: No | T38: Yes | U38: Yes | V38: Yes | W38: Yes | X38: Yes | Y38: No | Z38: 45147 | AA38: 46242 | AB38: unlimited | AC38: 15 | AD38: Yes | AE38: Yes | AG38: Phim còn hạn từ 2026 | AI38: Last princess | AJ38: =SUMIF('TK 15661.Bản quyền phim '!F:F,'KK1. Movies'!D38,'TK 15661.Bản quyền phim '!X:X) | AK38: =SUMIF('TK 15661.Bản quyền phim '!F:F,'KK1. Movies'!AI38,'TK 15661.Bản quyền phim '!X:X) | AL38: =COUNTIF('242.BQ Phim hợp tác'!$C:$C,'KK1. Movies'!AI38) | AM38: =COUNTIF('TK 15661.Bản quyền phim '!F:F,'KK1. Movies'!AI38) | AN38: =AL38+AM38 | AT38: =IFERROR(VLOOKUP(C38, CodeRanMovies!$A:$K, 11, 0), "Not found")
A39: =_xlfn.AGGREGATE(3,3,$D$7:D39) | B39: P | C39: MOV_ANI_23__2698580 | D39: Space dogs: Tropical adventure | E39: Biệt đội phi hành cún | F39: Comedy | G39: Roses Media | H39: 82/2023/HDBQ/VSTV-Roses Media | I39: 2020 | J39: Russia | K39: 80 | L39: 45206 | M39: 46301 | N39: 45206 | O39: K+KIDS | P39: Exclusive All Pay TV Rights for first 12 months. Non exclusive All VOD during LP | Q39: No | R39: Yes | S39: Yes | T39: Yes | U39: Yes | V39: Yes | W39: Yes | X39: Yes | Y39: No | Z39: 45206 | AA39: 46301 | AB39: 24 | AC39: 16 | AD39: Yes | AE39: Yes | AG39: Phim còn hạn từ 2026 | AI39: Space Dogs: Return to Earth | AJ39: =SUMIF('TK 15661.Bản quyền phim '!F:F,'KK1. Movies'!D39,'TK 15661.Bản quyền phim '!X:X) | AK39: =SUMIF('TK 15661.Bản quyền phim '!F:F,'KK1. Movies'!AI39,'TK 15661.Bản quyền phim '!X:X) | AL39: =COUNTIF('242.BQ Phim hợp tác'!$C:$C,'KK1. Movies'!AI39) | AM39: =COUNTIF('TK 15661.Bản quyền phim '!F:F,'KK1. Movies'!AI39) | AN39: =AL39+AM39 | AT39: =IFERROR(VLOOKUP(C39, CodeRanMovies!$A:$K, 11, 0), "Not found")
A40: =_xlfn.AGGREGATE(3,3,$D$7:D40) | B40: 16+ | C40: MOV_ACT_23__2693252 | D40: The Ice Road | E40: Con đường băng | F40: Action, Adventure | G40: Roses Media | H40: 140/2022/HDBQ/VSTV-RM | I40: 2021 | J40: US | K40: 103 | L40: 45133 | M40: 46228 | N40: 45133 | O40: K+CINE | P40: Exclusive All Pay TV Rights for first 12 months. Non exclusive All VOD during LP | Q40: No | R40: Yes | S40: No | T40: Yes | U40: Yes | V40: Yes | W40: Yes | X40: Yes | Y40: No | Z40: 45133 | AA40: 46228 | AB40: 24 | AC40: 15 | AD40: Yes | AE40: Yes | AG40: Phim còn hạn từ 2026 | AI40: The Ice Road | AJ40: =SUMIF('TK 15661.Bản quyền phim '!F:F,'KK1. Movies'!D40,'TK 15661.Bản quyền phim '!X:X) | AK40: =SUMIF('TK 15661.Bản quyền phim '!F:F,'KK1. Movies'!AI40,'TK 15661.Bản quyền phim '!X:X) | AL40: =COUNTIF('242.BQ Phim hợp tác'!$C:$C,'KK1. Movies'!AI40) | AM40: =COUNTIF('TK 15661.Bản quyền phim '!F:F,'KK1. Movies'!AI40) | AN40: =AL40+AM40 | AT40: =IFERROR(VLOOKUP(C40, CodeRanMovies!$A:$K, 11, 0), "Not found")
...

Sheet KK6. Bổ sung
A1: CÔNG TY: | B1: Công ty TNHH Truyền hình số vệ tinh Việt Nam | T1: Cộng Hòa Xã Hội Chủ Nghĩa Việt Nam
T2: Độc Lập - Tự Do - Hạnh Phúc
Q4: =COUNTIF(Q7:Q44,1) | R4: =COUNTIF(R7:R44,1)
N5: Ref File Kế toán | S5: Check | T5: SỐ LIỆU KIỂM KÊ | W5: Giải trình chênh lệch | X5: Đề xuất Phương án xử lý
A6: Inventory code | B6: Contract currency | C6: Contractor code | D6: Contractor name | E6: Program name | F6: Nature Programme | G6: No of EPS (Initially) | H6: Starting Date of right | I6: Ending date of right | J6: From (DTH) | K6: To (DTH) | L6: Note | N6: Tên trên file Kế toán | O6: details kế toán | P6: Giá trị còn lại (15661) | Q6: Check ref "TK 242.BQ Phim hợp tác" | R6: Check ref "TK 15661. Bản quyền phim" | T6: Số lượng | U6: From (VOD) | V6: To (VOD) | Y6: Kết quả kiểm tra VOD
A7: K+1MOV021273 | B7: VND | C7: S0001502 | D7: Công ty TNHH Đối tác Chuyên nghiệp | E7: THE BREAKUP GURU | F7: Movies International | G7: 1 | H7: 5 | I7: 5 | J7: 44519 | K7: 46160 | L7: Phim còn hạn từ 2026 | N7: SHINING FOR ONE THING | O7: =SUMIF('TK 15661.Bản quyền phim '!F:F,'KK6. Bổ sung'!D7,'TK 15661.Bản quyền phim '!X:X) | P7: =SUMIF('TK 15661.Bản quyền phim '!F:F,'KK6. Bổ sung'!N7,'TK 15661.Bản quyền phim '!X:X) | R7: =COUNTIF('TK 15661.Bản quyền phim '!F:F,'KK6. Bổ sung'!N7) | S7: =Q7+R7 | Y7: ✗ Not Found
A8: K+1MOV021274 | B8: VND | C8: S0001502 | D8: Công ty TNHH Đối tác Chuyên nghiệp | E8: FALL IN LOVE LIKE A STAR | F8: Movies International | G8: 1 | H8: 5 | I8: 5 | J8: 44491 | K8: 46133 | L8: Phim còn hạn từ 2026 | N8: ROGUE HEROS | O8: =SUMIF('TK 15661.Bản quyền phim '!F:F,'KK6. Bổ sung'!D8,'TK 15661.Bản quyền phim '!X:X) | P8: =SUMIF('TK 15661.Bản quyền phim '!F:F,'KK6. Bổ sung'!N8,'TK 15661.Bản quyền phim '!X:X) | R8: =COUNTIF('TK 15661.Bản quyền phim '!F:F,'KK6. Bổ sung'!N8) | S8: =Q8+R8 | Y8: ✗ Not Found
A9: K+1MOV021275 | B9: VND | C9: S0001502 | D9: Công ty TNHH Đối tác Chuyên nghiệp | E9: NE ZHA | F9: Movies International | G9: 1 | H9: 5 | I9: 5 | J9: 44533 | K9: 46175 | L9: Phim còn hạn từ 2026 | N9: Escape Plan 2: Hades | O9: =SUMIF('TK 15661.Bản quyền phim '!F:F,'KK6. Bổ sung'!D9,'TK 15661.Bản quyền phim '!X:X) | P9: =SUMIF('TK 15661.Bản quyền phim '!F:F,'KK6. Bổ sung'!N9,'TK 15661.Bản quyền phim '!X:X) | R9: =COUNTIF('TK 15661.Bản quyền phim '!F:F,'KK6. Bổ sung'!N9) | S9: =Q9+R9 | Y9: ✗ Not Found
A10: K+1MOV021276 | B10: VND | C10: S0001502 | D10: Công ty TNHH Đối tác Chuyên nghiệp | E10: SOUL SNATCHER | F10: Movies International | G10: 1 | H10: 5 | I10: 5 | J10: 44517 | K10: 46158 | L10: Phim còn hạn từ 2026 | N10: Riam: Fighting Angel | O10: =SUMIF('TK 15661.Bản quyền phim '!F:F,'KK6. Bổ sung'!D10,'TK 15661.Bản quyền phim '!X:X) | P10: =SUMIF('TK 15661.Bản quyền phim '!F:F,'KK6. Bổ sung'!N10,'TK 15661.Bản quyền phim '!X:X) | R10: =COUNTIF('TK 15661.Bản quyền phim '!F:F,'KK6. Bổ sung'!N10) | S10: =Q10+R10 | Y10: ✗ Not Found
A11: K+1MOV021279 | B11: VND | C11: S0001502 | D11: Công ty TNHH Đối tác Chuyên nghiệp | E11: RAT DISASTER | F11: Movies International | G11: 1 | H11: 5 | I11: 5 | J11: 44538 | K11: 46180 | L11: Phim còn hạn từ 2026 | N11: Happy Family | O11: =SUMIF('TK 15661.Bản quyền phim '!F:F,'KK6. Bổ sung'!D11,'TK 15661.Bản quyền phim '!X:X) | P11: =SUMIF('TK 15661.Bản quyền phim '!F:F,'KK6. Bổ sung'!N11,'TK 15661.Bản quyền phim '!X:X) | R11: =COUNTIF('TK 15661.Bản quyền phim '!F:F,'KK6. Bổ sung'!N11) | S11: =Q11+R11 | Y11: ✗ Not Found
A12: K+1MOV021282 | B12: VND | C12: S0001502 | D12: Công ty TNHH Đối tác Chuyên nghiệp | E12: FEARLESS KUNGFU KING | F12: Movies International | G12: 1 | H12: 5 | I12: 5 | J12: 44531 | K12: 46356 | L12: Phim còn hạn từ 2026 | N12: MEMOIRS OF A GEISHA | O12: =SUMIF('TK 15661.Bản quyền phim '!F:F,'KK6. Bổ sung'!D12,'TK 15661.Bản quyền phim '!X:X) | P12: =SUMIF('TK 15661.Bản quyền phim '!F:F,'KK6. Bổ sung'!N12,'TK 15661.Bản quyền phim '!X:X) | R12: =COUNTIF('TK 15661.Bản quyền phim '!F:F,'KK6. Bổ sung'!N12) | S12: =Q12+R12 | Y12: ✗ Not Found
A13: K+1MOV021283 | B13: VND | C13: S0001502 | D13: Công ty TNHH Đối tác Chuyên nghiệp | E13: MATCHLESS MULAN | F13: Movies International | G13: 1 | H13: 5 | I13: 5 | J13: 44489 | K13: 46131 | L13: Phim còn hạn từ 2026 | N13: Ironbark/The Courier | O13: =SUMIF('TK 15661.Bản quyền phim '!F:F,'KK6. Bổ sung'!D13,'TK 15661.Bản quyền phim '!X:X) | P13: =SUMIF('TK 15661.Bản quyền phim '!F:F,'KK6. Bổ sung'!N13,'TK 15661.Bản quyền phim '!X:X) | R13: =COUNTIF('TK 15661.Bản quyền phim '!F:F,'KK6. Bổ sung'!N13) | S13: =Q13+R13 | Y13: ✗ Not Found
A14: K+1MOV021284 | B14: VND | C14: S0001502 | D14: Công ty TNHH Đối tác Chuyên nghiệp | E14: LOVE IN BLOOD | F14: Movies International | G14: 1 | H14: 5 | I14: 5 | J14: 44461 | K14: 46102 | L14: Phim còn hạn từ 2026 | N14: Hitman's Wife's Bodyguard | O14: =SUMIF('TK 15661.Bản quyền phim '!F:F,'KK6. Bổ sung'!D14,'TK 15661.Bản quyền phim '!X:X) | P14: =SUMIF('TK 15661.Bản quyền phim '!F:F,'KK6. Bổ sung'!N14,'TK 15661.Bản quyền phim '!X:X) | R14: =COUNTIF('TK 15661.Bản quyền phim '!F:F,'KK6. Bổ sung'!N14) | S14: =Q14+R14 | Y14: ✗ Not Found
A15: K+1MOV021285 | B15: VND | C15: S0001502 | D15: Công ty TNHH Đối tác Chuyên nghiệp | E15: GOD OF WAR | F15: Movies International | G15: 1 | H15: 5 | I15: 5 | J15: 44475 | K15: 46117 | L15: Phim còn hạn từ 2026 | N15: GUIMOON: THE LIGHTLESS DOOR (CỔNG ĐỊA NGỤC) | O15: =SUMIF('TK 15661.Bản quyền phim '!F:F,'KK6. Bổ sung'!D15,'TK 15661.Bản quyền phim '!X:X) | P15: =SUMIF('TK 15661.Bản quyền phim '!F:F,'KK6. Bổ sung'!N15,'TK 15661.Bản quyền phim '!X:X) | R15: =COUNTIF('TK 15661.Bản quyền phim '!F:F,'KK6. Bổ sung'!N15) | S15: =Q15+R15 | Y15: ✗ Not Found
A16: K+1MOV021287 | B16: VND | C16: S0001502 | D16: Công ty TNHH Đối tác Chuyên nghiệp | E16: THE RISE OF HERO | F16: Movies International | G16: 1 | H16: 5 | I16: 5 | J16: 44559 | K16: 46201 | L16: Phim còn hạn từ 2026 | M16: MOV_DRA_23__2696593 | N16: Greta | O16: =SUMIF('TK 15661.Bản quyền phim '!F:F,'KK6. Bổ sung'!D16,'TK 15661.Bản quyền phim '!X:X) | P16: =SUMIF('TK 15661.Bản quyền phim '!F:F,'KK6. Bổ sung'!N16,'TK 15661.Bản quyền phim '!X:X) | R16: =COUNTIF('TK 15661.Bản quyền phim '!F:F,'KK6. Bổ sung'!N16) | S16: =Q16+R16 | Y16: ✗ Not Found
A17: K+1MOV021288 | B17: VND | C17: S0001502 | D17: Công ty TNHH Đối tác Chuyên nghiệp | E17: SWORDSMAN | F17: Movies International | G17: 1 | H17: 5 | I17: 5 | J17: 44503 | K17: 46144 | L17: Phim còn hạn từ 2026 | M17: MOV_FAN_22__2686869 | N17: HOUSE WITH A CLOCK IN ITS WALLS (Ngôi nhà có chiếc đồng hồ ma thuật) | O17: =SUMIF('TK 15661.Bản quyền phim '!F:F,'KK6. Bổ sung'!D17,'TK 15661.Bản quyền phim '!X:X) | P17: =SUMIF('TK 15661.Bản quyền phim '!F:F,'KK6. Bổ sung'!N17,'TK 15661.Bản quyền phim '!X:X) | R17: =COUNTIF('TK 15661.Bản quyền phim '!F:F,'KK6. Bổ sung'!N17) | S17: =Q17+R17 | Y17: ✗ Not Found
A18: K+2SER022116 | B18: USD | C18: S0002262 | D18: IQIYI INTERNATIONAL SINGAPORE PTE. LTD. | E18: Ideal City | F18: Series Asian | G18: 40 | H18: 4 | I18: 160 | J18: 44642 | K18: 46102 | L18: Phim còn hạn từ 2026 | N18: HUNT, THE | O18: =SUMIF('TK 15661.Bản quyền phim '!F:F,'KK6. Bổ sung'!D18,'TK 15661.Bản quyền phim '!X:X) | P18: =SUMIF('TK 15661.Bản quyền phim '!F:F,'KK6. Bổ sung'!N18,'TK 15661.Bản quyền phim '!X:X) | R18: =COUNTIF('TK 15661.Bản quyền phim '!F:F,'KK6. Bổ sung'!N18) | S18: =Q18+R18 | Y18: ✓ Found
A19: K+1MOV023009 | B19: VND | C19: S0001804 | D19: CÔNG TY TNHH TRUYỀN THÔNG ROSES | E19: ROGUE | F19: Movies International | G19: 1 | H19: 3 | I19: 3 | J19: 45077 | K19: 46172 | L19: Phim còn hạn từ 2026 | M19: MOV_CRI_21__2648182 | N19: MOZU | O19: =SUMIF('TK 15661.Bản quyền phim '!F:F,'KK6. Bổ sung'!D19,'TK 15661.Bản quyền phim '!X:X) | P19: =SUMIF('TK 15661.Bản quyền phim '!F:F,'KK6. Bổ sung'!N19,'TK 15661.Bản quyền phim '!X:X) | R19: =COUNTIF('TK 15661.Bản quyền phim '!F:F,'KK6. Bổ sung'!N19) | S19: =Q19+R19 | Y19: ✗ Not Found
A20: K+5KID023239 | B20: USD | C20: S0002484 | D20: GULLANE (THOMAS) LIMITED | E20: Thomas & Friends Series 25 Special – Race for the Sodor Cup | F20: KIDS | G20: 1 | H20: 3 | I20: 3 | J20: 45200 | K20: 46295 | L20: Phim còn hạn từ 2026 | M20: MOV_HOR_24__2713878 | N20: CONTORTED (NHÀ KHO CHẾT CHÓC) | O20: =SUMIF('TK 15661.Bản quyền phim '!F:F,'KK6. Bổ sung'!D20,'TK 15661.Bản quyền phim '!X:X) | P20: =SUMIF('TK 15661.Bản quyền phim '!F:F,'KK6. Bổ sung'!N20,'TK 15661.Bản quyền phim '!X:X) | R20: =COUNTIF('TK 15661.Bản quyền phim '!F:F,'KK6. Bổ sung'!N20) | S20: =Q20+R20 | Y20: ✗ Not Found
A21: K+1MOV024126 | B21: VND | C21: S0002365 | D21: CÔNG TY CỔ PHẦN TRUYỀN THÔNG HỎA THỔ | E21: The Hot-Blooded (Tử Chiến) | F21: Movies International | G21: 1 | H21: 3 | I21: 3 | J21: 45435 | K21: 46529 | L21: Phim còn hạn từ 2026 | N21: The Night Clerk | O21: =SUMIF('TK 15661.Bản quyền phim '!F:F,'KK6. Bổ sung'!D21,'TK 15661.Bản quyền phim '!X:X) | P21: =SUMIF('TK 15661.Bản quyền phim '!F:F,'KK6. Bổ sung'!N21,'TK 15661.Bản quyền phim '!X:X) | R21: =COUNTIF('TK 15661.Bản quyền phim '!F:F,'KK6. Bổ sung'!N21) | S21: =Q21+R21 | Y21: ✗ Not Found
A22: K+1MOV024132 | B22: VND | C22: S0002365 | D22: CÔNG TY CỔ PHẦN TRUYỀN THÔNG HỎA THỔ | E22: Z Storm (Đội Chống Tham Nhũng) | F22: Movies International | G22: 1 | H22: 3 | I22: 3 | J22: 45506 | K22: 46600 | L22: Phim còn hạn từ 2026 | N22: Journey to China: The Mystery of the Dragon Seal | O22: =SUMIF('TK 15661.Bản quyền phim '!F:F,'KK6. Bổ sung'!D22,'TK 15661.Bản quyền phim '!X:X) | P22: =SUMIF('TK 15661.Bản quyền phim '!F:F,'KK6. Bổ sung'!N22,'TK 15661.Bản quyền phim '!X:X) | R22: =COUNTIF('TK 15661.Bản quyền phim '!F:F,'KK6. Bổ sung'!N22) | S22: =Q22+R22 | Y22: ✗ Not Found
A23: K+1MOV024133 | B23: VND | C23: S0002365 | D23: CÔNG TY CỔ PHẦN TRUYỀN THÔNG HỎA THỔ | E23: Raging Fire (Cuồng Phong Nộ Hỏa) | F23: Movies International | G23: 1 | H23: 3 | I23: 3 | J23: 45520 | K23: 46614 | L23: Phim còn hạn từ 2026 | N23: Gringo | O23: =SUMIF('TK 15661.Bản quyền phim '!F:F,'KK6. Bổ sung'!D23,'TK 15661.Bản quyền phim '!X:X) | P23: =SUMIF('TK 15661.Bản quyền phim '!F:F,'KK6. Bổ sung'!N23,'TK 15661.Bản quyền phim '!X:X) | R23: =COUNTIF('TK 15661.Bản quyền phim '!F:F,'KK6. Bổ sung'!N23) | S23: =Q23+R23 | Y23: ✗ Not Found
A24: K+1MOV024134 | B24: VND | C24: S0002365 | D24: CÔNG TY CỔ PHẦN TRUYỀN THÔNG HỎA THỔ | E24: Ip Man 3 (Diệp Vấn 3) | F24: Movies International | G24: 1 | H24: 3 | I24: 3 | J24: 45548 | K24: 46642 | L24: Phim còn hạn từ 2026 | N24: THE GIRL ON THE TRAIN (Cô gái trên tàu) | O24: =SUMIF('TK 15661.Bản quyền phim '!F:F,'KK6. Bổ sung'!D24,'TK 15661.Bản quyền phim '!X:X) | P24: =SUMIF('TK 15661.Bản quyền phim '!F:F,'KK6. Bổ sung'!N24,'TK 15661.Bản quyền phim '!X:X) | R24: =COUNTIF('TK 15661.Bản quyền phim '!F:F,'KK6. Bổ sung'!N24) | S24: =Q24+R24 | Y24: ✗ Not Found
A25: K+1MOV024135 | B25: USD | C25: S0002438 | D25: Paramount Pictures International Limited | E25: CRAWL | F25: Movies International | G25: 1 | H25: 2 | I25: 2 | J25: 45609 | K25: 46154 | L25: Phim còn hạn từ 2026 | N25: Triple Threat | O25: =SUMIF('TK 15661.Bản quyền phim '!F:F,'KK6. Bổ sung'!D25,'TK 15661.Bản quyền phim '!X:X) | P25: =SUMIF('TK 15661.Bản quyền phim '!F:F,'KK6. Bổ sung'!N25,'TK 15661.Bản quyền phim '!X:X) | R25: =COUNTIF('TK 15661.Bản quyền phim '!F:F,'KK6. Bổ sung'!N25) | S25: =Q25+R25 | Y25: ✗ Not Found
