Workbook
Name base_year: 'Assumptions'!$B$6
Name start_month: 'Assumptions'!$B$7
Name projection_years: 'Assumptions'!$B$8
Name TAM_enterprises: 'Assumptions'!$B$12
Name SAM_enterprises: 'Assumptions'!$B$13
Name ecom_market_base: 'Assumptions'!$B$14
Name ecom_growth_rate: 'Assumptions'!$B$15
Name adoption_max: 'Assumptions'!$B$19
Name adoption_midpoint: 'Assumptions'!$B$20
Name adoption_steepness: 'Assumptions'!$B$21
Name pilot_count: 'Assumptions'!$B$22
Name churn_rate: 'Assumptions'!$B$23
Name cert_fee_yr1: 'Assumptions'!$B$27
Name cert_fee_escalation: 'Assumptions'!$B$28
Name tx_take_rate: 'Assumptions'!$B$29
Name platform_market_share: 'Assumptions'!$B$30
Name daas_price: 'Assumptions'!$B$31
Name ad_cpm: 'Assumptions'!$B$32
Name ad_impressions_base: 'Assumptions'!$B$33
Name training_fee: 'Assumptions'!$B$34
Name audit_fee: 'Assumptions'!$B$35
Name training_pct: 'Assumptions'!$B$36
Name capex_maintenance_pct: 'Assumptions'!$B$40
Name opex_marketing: 'Assumptions'!$B$41
Name marketing_growth: 'Assumptions'!$B$42
Name opex_cloud_base: 'Assumptions'!$B$43
Name cloud_per_1M_vcr: 'Assumptions'!$B$44
Name vcr_per_enterprise: 'Assumptions'!$B$45
Name opex_external: 'Assumptions'!$B$46
Name opex_legal: 'Assumptions'!$B$47
Name opex_branding: 'Assumptions'!$B$48
Name opex_security: 'Assumptions'!$B$49
Name opex_pilot_eval: 'Assumptions'!$B$50
Name payment_proc_pct: 'Assumptions'!$B$51
Name salary_mgmt: 'Assumptions'!$B$55
Name salary_dev: 'Assumptions'!$B$56
Name salary_bizops: 'Assumptions'!$B$57
Name salary_data: 'Assumptions'!$B$58
Name salary_escalation: 'Assumptions'!$B$59
Name bhxh_rate: 'Assumptions'!$B$60
Name recruit_cost_pct: 'Assumptions'!$B$61
Name cit_rate: 'Assumptions'!$B$65
Name discount_rate: 'Assumptions'!$B$66
Name depreciation_years: 'Assumptions'!$B$67
Name ar_days: 'Assumptions'!$B$68
Name ap_days: 'Assumptions'!$B$69
Name stage2_gate: 'Assumptions'!$B$70
Name capex_cloud_setup: 'Initial Investment'!$B$5
Name capex_backend: 'Initial Investment'!$B$6
Name capex_frontend: 'Initial Investment'!$B$7
Name capex_data_platform: 'Initial Investment'!$B$8
Name capex_security_setup: 'Initial Investment'!$B$9
Name capex_ux_design: 'Initial Investment'!$B$10
Name capex_integration: 'Initial Investment'!$B$11
Name capex_devops: 'Initial Investment'!$B$12
Name capex_testing: 'Initial Investment'!$B$13
Name capex_contingency: 'Initial Investment'!$B$14
Name capex_total: 'Initial Investment'!$B$16
Name opex_support_per_ent: 'Assumptions'!$B$52
Name opex_partner_mgmt: 'Assumptions'!$B$53

Sheet Guide
A1: VISIT VIETNAM — FINANCIAL MODEL v3 — GUIDE
A2: Version: 3.0 | Date: 2026-03-21 | Fixed assumptions, added Scenarios + Budget sheets
A4: SHEET DIRECTORY
A5: Sheet | B5: Purpose | C5: Key notes
A6: Guide | B6: This sheet. Explains all sheets, formulas, and how to use the model. | C6: Read first
A7: Assumptions | B7: ALL input parameters (yellow cells). Every formula references this sheet via named ranges. | C7: Edit ONLY yellow cells to change the model
A8: Initial Investment | B8: CAPEX breakdown: 10 line items from original data. Depreciation schedule. | C8: capex_total named range used everywhere
A9: HR Plan | B9: Headcount by dept (4 depts) × 42 time periods. Salary cost with escalation & BHXH. | C9: Yellow cells = editable headcount per period
A10: Market Sizing | B10: TAM/SAM, S-curve adoption formula, VCR projections. Year fractions calculated from base_year. | C10: No hardcoded years — all derived from Assumptions
A11: Revenue Schedule | B11: 6 revenue streams: 3 Stage 1 (cert, training, audit) + 3 Stage 2 (tx, DaaS, ads). Stage 2 gated. | C11: Stage 2 activates when enterprises ≥ stage2_gate
A12: Cost Schedule | B12: CAPEX (from Initial Investment) + OPEX (8 categories). HR from HR Plan sheet. | C12: References HR Plan and Initial Investment
A13: P&L | B13: Income statement: Revenue→COGS→GP→OPEX→EBITDA→D&A→EBIT→CIT 20%→Net Income + margins. | C13: CIT 20% applied (was 0% in old model)
A14: Cash Flow | B14: Operating CF + Investing CF → FCF + Cumulative. Working capital modeled (AR days). | C14: Working capital changes reduce reported cash
A15: DCF & Returns | B15: Annual FCF summary, NPV, IRR, ROI. Uses discount_rate from Assumptions. | C15: Single consistent NPV formula (old model had 2 conflicting)
A16: Sensitivity | B16: Impact tables: enterprise×fee, market share×take rate. Scenario comparison. | C16: Change Assumptions to run scenarios
... A19: Budget 2026 | B19: Monthly budget Jan-Dec 2026. Revenue + CAPEX + OPEX detail. Approval-ready. | C19: HR scaling, enterprise growth via S-curve
A21: NAMED RANGES
A22: Name | B22: Description | C22: Used in formulas as
A23: base_year | B23: Project start year | C23: =base_year (in year fraction calculation)
A24: start_month | B24: Start month (7=July) | C24: =start_month (in year fraction calculation)
A25: adoption_max | B25: S-curve ceiling | C25: =adoption_max/(1+EXP(...))
A26: adoption_midpoint | B26: S-curve inflection year | C26: in S-curve formula
A27: cert_fee_yr1 | B27: Annual cert fee per enterprise | C27: =net_ent * cert_fee_yr1 * (1+escalation)^years
A28: tx_take_rate | B28: Transaction commission % | C28: =ecom_market * platform_market_share * tx_take_rate
A29: platform_market_share | B29: % of e-tourism GMV | C29: in transaction fee formula
A30: stage2_gate | B30: Min enterprises for Stage 2 | C30: =IF(net_ent >= stage2_gate, ..., 0)
A31: capex_total | B31: Total initial CAPEX | C31: =capex_total/depreciation_years (for D&A)
A32: cit_rate | B32: Corporate income tax rate | C32: =IF(EBIT>0, -EBIT*cit_rate, 0)
A33: discount_rate | B33: WACC for NPV | C33: =NPV(discount_rate, ...)
A34: salary_escalation | B34: Annual raise % | C34: =headcount*salary*(1+salary_escalation)^years
A35: bhxh_rate | B35: Social insurance overhead | C35: =salary_cost*(1+bhxh_rate)
A37: CELL CONVENTIONS
A38: 🟡 Yellow background + blue font | B38: INPUT — editable placeholder. Change these values.
A39: 🟢 Green background | B39: TOTAL / SUBTOTAL — formula, do not edit
A40: 🔵 Blue header | B40: COLUMN/SECTION HEADER — label only
A41: ⬜ White background | B41: FORMULA — calculated from inputs, do not edit
A43: KEY FORMULA PATTERNS
A44: S-curve adoption | B44: =MAX(pilot_count, adoption_max/(1+EXP(-adoption_steepness*(year_frac-adoption_midpoint))))
A45: Year fraction | B45: =base_year + (start_month - 1 + period_index) / 12 — NO hardcoded values
A46: Certification revenue | B46: =net_enterprises * cert_fee_yr1 * (1+cert_fee_escalation)^years / period_divisor
...

Sheet Assumptions
A1: VISIT VIETNAM — FINANCIAL MODEL v2 — ASSUMPTIONS
A2: Version 2.0 | All yellow cells = editable inputs | Named ranges used in all formulas
A4: TIMING
A5: Parameter | B5: Value | C5: Unit | D5: Notes
A6: Base year (project start) | B6: 2025 | C6: Year | D6: H2 of this year
A7: Start month | B7: 7 | C7: Month | D7: July = 7
A8: Projection years | B8: 6 | C8: Years | D8: 2025-2030
A10: MARKET DATA
A11: Parameter | B11: Value | C11: Unit | D11: Notes
A12: Total tourism enterprises in Vietnam | B12: 40000 | D12: GSO/VNAT
A13: Digitally active / certifiable | B13: 15000 | D13: Industry reports
A14: E-commerce tourism market (base year) | B14: 82500 | C14: Bn VND | D14: e-Conomy SEA
A15: E-tourism YoY growth | B15: 0.08 | C15: % | D15: Historical
A17: ADOPTION S-CURVE
A18: Parameter | B18: Value | C18: Unit | D18: Notes
A19: Maximum enterprises (ceiling) | B19: 1200 | D19: S-curve asymptote
A20: Midpoint year (fastest growth) | B20: 2028 | C20: Year | D20: Inflection point
A21: Steepness factor | B21: 0.9 | D21: Higher=steeper
A22: Starting enterprises (pilot) | B22: 15 | D22: Known partners
A23: Annual non-renewal rate | B23: 0.2 | C23: % | D23: Certification churn
A25: PRICING
A26: Parameter | B26: Value | C26: Unit | D26: Notes
A27: Certification fee/enterprise/yr | B27: 25 | C27: M VND | D27: Annual subscription
A28: Cert fee annual increase | B28: 0.05 | C28: % | D28: Price escalation
A29: Transaction fee (% of GMV) | B29: 0.02 | C29: % | D29: Platform commission
A30: % e-tourism GMV via VV | B30: 0.005 | C30: % | D30: Realistic target
A31: DaaS price per million VCR | B31: 30 | C31: M VND | D31: Data subscription
A32: Advertising CPM | B32: 150 | C32: K VND | D32: B2B benchmark
A33: Monthly ad impressions (K) | B33: 500 | C33: K | D33: Base; scales with enterprises
A34: Training fee per engagement | B34: 15 | C34: M VND | D34: NEW stream
A35: Audit fee per certification | B35: 10 | C35: M VND | D35: NEW stream
A36: % enterprises buying training | B36: 0.3 | C36: % | D36: Estimated
A38: COST PARAMETERS
A39: Parameter | B39: Value | C39: Unit | D39: Notes
A40: Annual maintenance (% CAPEX) | B40: 0.18 | C40: % | D40: Industry 15-20%
A41: Marketing (annual base) | B41: 7000 | C41: M VND | D41: From original data
A42: Marketing annual growth | B42: 0.15 | C42: % | D42: Scales with ambition
A43: Cloud base (annual) | B43: 3250 | C43: M VND | D43: From original data
A44: Cloud cost per M VCR | B44: 8 | C44: M VND | D44: Variable scaling
A45: VCR per enterprise per month | B45: 10000 | C45: records | D45: Est. traffic
...

Sheet Initial Investment
A1: INITIAL INVESTMENT — CAPEX BREAKDOWN (M VND)
A2: Source: 20250718_HHDLQG_Financial Projection 5 Years.xlsx
A4: CAPEX Item | B4: Amount (M VND) | C4: Timing | D4: Notes
A5: Cloud infrastructure setup | B5: 800 | C5: H2 2025 | D5: AWS/GCP initial setup
A6: Backend development | B6: 1200 | C6: H2 2025 | D6: API, database, core logic
A7: Frontend + mobile development | B7: 900 | C7: H2 2025 | D7: Web + mobile app
A8: Data platform & analytics | B8: 600 | C8: H2 2025 | D8: Data pipeline, analytics engine
A9: Security infrastructure | B9: 250 | C9: H2 2025 | D9: Initial pentest, encryption, auth
A10: UX/UI design | B10: 350 | C10: H2 2025 | D10: Design system, prototypes
A11: 3rd-party integrations | B11: 400 | C11: H2 2025 | D11: Payment gateways, OTA APIs
A12: DevOps & CI/CD setup | B12: 280 | C12: H2 2025 | D12: Deployment pipeline, monitoring
A13: QA & testing infrastructure | B13: 200 | C13: H2 2025 | D13: Automated testing, load testing
A14: CAPEX contingency (10%) | B14: 300 | C14: H2 2025 | D14: Buffer for overruns
A16: TOTAL INITIAL CAPEX | B16: =SUM(B5:B14)
A18: DEPRECIATION SCHEDULE (M VND)
A19: Year | B19: Annual D&A | C19: Accum D&A | D19: Net Book Value
A20: 2025 | B20: =capex_total/depreciation_years | C20: =B20 | D20: =capex_total-C20
A21: 2026 | B21: =capex_total/depreciation_years | C21: =C20+B21 | D21: =capex_total-C21
A22: 2027 | B22: =capex_total/depreciation_years | C22: =C21+B22 | D22: =capex_total-C22
A23: 2028 | B23: =capex_total/depreciation_years | C23: =C22+B23 | D23: =capex_total-C23
A24: 2029 | B24: =capex_total/depreciation_years | C24: =C23+B24 | D24: =capex_total-C24
A25: 2030 | B25: =0 | C25: =C24+B25 | D25: =capex_total-C25

Sheet HR Plan
A1: HR PLAN — HEADCOUNT & COST
A3: Department / Role | B3: Unit | C3: Jul 2025 | D3: Aug 2025 | E3: Sep 2025 | F3: Oct 2025 | G3: Nov 2025 | H3: Dec 2025 | I3: Jan 2026 | J3: Feb 2026 | K3: Mar 2026 | L3: Apr 2026 | M3: May 2026 | N3: Jun 2026 | O3: Jul 2026 | P3: Aug 2026 | Q3: Sep 2026 | R3: Oct 2026 | S3: Nov 2026 | T3: Dec 2026 | U3: Jan 2027 | V3: Feb 2027 | W3: Mar 2027 | X3: Apr 2027 | Y3: May 2027 | Z3: Jun 2027 | AA3: Jul 2027 | AB3: Aug 2027 | AC3: Sep 2027 | AD3: Oct 2027 | AE3: Nov 2027 | AF3: Dec 2027 | AG3: Q1 2028 | AH3: Q2 2028 | AI3: Q3 2028 | AJ3: Q4 2028 | AK3: Q1 2029 | AL3: Q2 2029 | AM3: Q3 2029 | AN3: Q4 2029 | AO3: Q1 2030 | AP3: Q2 2030 | AQ3: Q3 2030 | AR3: Q4 2030
A4: HEADCOUNT
A5: Management | B5: people | C5: 2 | D5: 2 | E5: 2 | F5: 2 | G5: 2 | H5: 2 | I5: 2 | J5: 2 | K5: 2 | L5: 2 | M5: 2 | N5: 2 | O5: 2 | P5: 2 | Q5: 2 | R5: 2 | S5: 2 | T5: 2 | U5: 3 | V5: 3 | W5: 3 | X5: 3 | Y5: 3 | Z5: 3 | AA5: 3 | AB5: 3 | AC5: 3 | AD5: 3 | AE5: 3 | AF5: 3 | AG5: 3 | AH5: 3 | AI5: 3 | AJ5: 3 | AK5: 4 | AL5: 4 | AM5: 4 | AN5: 4 | AO5: 4 | AP5: 4 | AQ5: 4 | AR5: 4
A6: Development | B6: people | C6: 12 | D6: 12 | E6: 12 | F6: 12 | G6: 12 | H6: 12 | I6: 12 | J6: 12 | K6: 12 | L6: 12 | M6: 12 | N6: 12 | O6: 12 | P6: 12 | Q6: 12 | R6: 12 | S6: 12 | T6: 12 | U6: 14 | V6: 14 | W6: 14 | X6: 14 | Y6: 14 | Z6: 14 | AA6: 14 | AB6: 14 | AC6: 14 | AD6: 14 | AE6: 14 | AF6: 14 | AG6: 16 | AH6: 16 | AI6: 16 | AJ6: 16 | AK6: 18 | AL6: 18 | AM6: 18 | AN6: 18 | AO6: 20 | AP6: 20 | AQ6: 20 | AR6: 20
A7: Biz Ops | B7: people | C7: 2 | D7: 2 | E7: 2 | F7: 2 | G7: 2 | H7: 2 | I7: 6 | J7: 6 | K7: 6 | L7: 6 | M7: 6 | N7: 6 | O7: 6 | P7: 6 | Q7: 6 | R7: 6 | S7: 6 | T7: 6 | U7: 10 | V7: 10 | W7: 10 | X7: 10 | Y7: 10 | Z7: 10 | AA7: 10 | AB7: 10 | AC7: 10 | AD7: 10 | AE7: 10 | AF7: 10 | AG7: 18 | AH7: 18 | AI7: 18 | AJ7: 18 | AK7: 28 | AL7: 28 | AM7: 28 | AN7: 28 | AO7: 35 | AP7: 35 | AQ7: 35 | AR7: 35
A8: Data & Analytics | B8: people | C8: 0 | D8: 0 | E8: 0 | F8: 0 | G8: 0 | H8: 0 | I8: 2 | J8: 2 | K8: 2 | L8: 2 | M8: 2 | N8: 2 | O8: 2 | P8: 2 | Q8: 2 | R8: 2 | S8: 2 | T8: 2 | U8: 3 | V8: 3 | W8: 3 | X8: 3 | Y8: 3 | Z8: 3 | AA8: 3 | AB8: 3 | AC8: 3 | AD8: 3 | AE8: 3 | AF8: 3 | AG8: 4 | AH8: 4 | AI8: 4 | AJ8: 4 | AK8: 5 | AL8: 5 | AM8: 5 | AN8: 5 | AO8: 6 | AP8: 6 | AQ8: 6 | AR8: 6
A9: TOTAL HEADCOUNT | B9: people | C9: =SUM(C5:C8) | D9: =SUM(D5:D8) | E9: =SUM(E5:E8) | F9: =SUM(F5:F8) | G9: =SUM(G5:G8) | H9: =SUM(H5:H8) | I9: =SUM(I5:I8) | J9: =SUM(J5:J8) | ... AR9: =SUM(AR5:AR8)
A11: NEW HIRES PER PERIOD
A12: New hires | B12: people | C12: =C9 | D12: =MAX(0,D9-C9) | E12: =MAX(0,E9-D9) | F12: =MAX(0,F9-E9) | G12: =MAX(0,G9-F9) | H12: =MAX(0,H9-G9) | I12: =MAX(0,I9-H9) | J12: =MAX(0,J9-I9) | K12: =MAX(0,K9-J9) | ... AR12: =MAX(0,AR9-AQ9)
A14: MONTHLY SALARY COST (M VND)
A15: Management salary cost | B15: M VND | C15: =C5*salary_mgmt*1*(1+salary_escalation)^0*(1+bhxh_rate) | D15: =D5*salary_mgmt*1*(1+salary_escalation)^0*(1+bhxh_rate) | E15: =E5*salary_mgmt*1*(1+salary_escalation)^0*(1+bhxh_rate) | F15: =F5*salary_mgmt*1*(1+salary_escalation)^0*(1+bhxh_rate) | G15: =G5*salary_mgmt*1*(1+salary_escalation)^0*(1+bhxh_rate) | H15: =H5*salary_mgmt*1*(1+salary_escalation)^0*(1+bhxh_rate) | I15: =I5*salary_mgmt*1*(1+salary_escalation)^1*(1+bhxh_rate) | J15: =J5*salary_mgmt*1*(1+salary_escalation)^1*(1+bhxh_rate) | K15: =K5*salary_mgmt*1*(1+salary_escalation)^1*(1+bhxh_rate) | L15: =L5*salary_mgmt*1*(1+salary_escalation)^1*(1+bhxh_rate) | M15: =M5*salary_mgmt*1*(1+salary_escalation)^1*(1+bhxh_rate) | N15: =N5*salary_mgmt*1*(1+salary_escalation)^1*(1+bhxh_rate) | O15: =O5*salary_mgmt*1*(1+salary_escalation)^1*(1+bhxh_rate) | P15: =P5*salary_mgmt*1*(1+salary_escalation)^1*(1+bhxh_rate) | ... T15: =T5*salary_mgmt*1*(1+salary_escalation)^1*(1+bhxh_rate) | U15: =U5*salary_mgmt*1*(1+salary_escalation)^2*(1+bhxh_rate) | V15: =V5*salary_mgmt*1*(1+salary_escalation)^2*(1+bhxh_rate) | W15: =W5*salary_mgmt*1*(1+salary_escalation)^2*(1+bhxh_rate) | X15: =X5*salary_mgmt*1*(1+salary_escalation)^2*(1+bhxh_rate) | Y15: =Y5*salary_mgmt*1*(1+salary_escalation)^2*(1+bhxh_rate) | Z15: =Z5*salary_mgmt*1*(1+salary_escalation)^2*(1+bhxh_rate) | AA15: =AA5*salary_mgmt*1*(1+salary_escalation)^2*(1+bhxh_rate) | AB15: =AB5*salary_mgmt*1*(1+salary_escalation)^2*(1+bhxh_rate) | ... AF15: =AF5*salary_mgmt*1*(1+salary_escalation)^2*(1+bhxh_rate) | AG15: =AG5*salary_mgmt*3*(1+salary_escalation)^3*(1+bhxh_rate) | AH15: =AH5*salary_mgmt*3*(1+salary_escalation)^3*(1+bhxh_rate) | AI15: =AI5*salary_mgmt*3*(1+salary_escalation)^3*(1+bhxh_rate) | AJ15: =AJ5*salary_mgmt*3*(1+salary_escalation)^3*(1+bhxh_rate) | AK15: =AK5*salary_mgmt*3*(1+salary_escalation)^4*(1+bhxh_rate) | AL15: =AL5*salary_mgmt*3*(1+salary_escalation)^4*(1+bhxh_rate) | AM15: =AM5*salary_mgmt*3*(1+salary_escalation)^4*(1+bhxh_rate) | AN15: =AN5*salary_mgmt*3*(1+salary_escalation)^4*(1+bhxh_rate) | AO15: =AO5*salary_mgmt*3*(1+salary_escalation)^5*(1+bhxh_rate) | AP15: =AP5*salary_mgmt*3*(1+salary_escalation)^5*(1+bhxh_rate) | AQ15: =AQ5*salary_mgmt*3*(1+salary_escalation)^5*(1+bhxh_rate) | AR15: =AR5*salary_mgmt*3*(1+salary_escalation)^5*(1+bhxh_rate)
A16: Development salary cost | B16: M VND | C16: =C6*salary_dev*1*(1+salary_escalation)^0*(1+bhxh_rate) | D16: =D6*salary_dev*1*(1+salary_escalation)^0*(1+bhxh_rate) | E16: =E6*salary_dev*1*(1+salary_escalation)^0*(1+bhxh_rate) | F16: =F6*salary_dev*1*(1+salary_escalation)^0*(1+bhxh_rate) | G16: =G6*salary_dev*1*(1+salary_escalation)^0*(1+bhxh_rate) | H16: =H6*salary_dev*1*(1+salary_escalation)^0*(1+bhxh_rate) | I16: =I6*salary_dev*1*(1+salary_escalation)^1*(1+bhxh_rate) | J16: =J6*salary_dev*1*(1+salary_escalation)^1*(1+bhxh_rate) | K16: =K6*salary_dev*1*(1+salary_escalation)^1*(1+bhxh_rate) | L16: =L6*salary_dev*1*(1+salary_escalation)^1*(1+bhxh_rate) | M16: =M6*salary_dev*1*(1+salary_escalation)^1*(1+bhxh_rate) | N16: =N6*salary_dev*1*(1+salary_escalation)^1*(1+bhxh_rate) | O16: =O6*salary_dev*1*(1+salary_escalation)^1*(1+bhxh_rate) | P16: =P6*salary_dev*1*(1+salary_escalation)^1*(1+bhxh_rate) | ... T16: =T6*salary_dev*1*(1+salary_escalation)^1*(1+bhxh_rate) | U16: =U6*salary_dev*1*(1+salary_escalation)^2*(1+bhxh_rate) | V16: =V6*salary_dev*1*(1+salary_escalation)^2*(1+bhxh_rate) | W16: =W6*salary_dev*1*(1+salary_escalation)^2*(1+bhxh_rate) | X16: =X6*salary_dev*1*(1+salary_escalation)^2*(1+bhxh_rate) | Y16: =Y6*salary_dev*1*(1+salary_escalation)^2*(1+bhxh_rate) | Z16: =Z6*salary_dev*1*(1+salary_escalation)^2*(1+bhxh_rate) | AA16: =AA6*salary_dev*1*(1+salary_escalation)^2*(1+bhxh_rate) | AB16: =AB6*salary_dev*1*(1+salary_escalation)^2*(1+bhxh_rate) | ... AF16: =AF6*salary_dev*1*(1+salary_escalation)^2*(1+bhxh_rate) | AG16: =AG6*salary_dev*3*(1+salary_escalation)^3*(1+bhxh_rate) | AH16: =AH6*salary_dev*3*(1+salary_escalation)^3*(1+bhxh_rate) | AI16: =AI6*salary_dev*3*(1+salary_escalation)^3*(1+bhxh_rate) | AJ16: =AJ6*salary_dev*3*(1+salary_escalation)^3*(1+bhxh_rate) | AK16: =AK6*salary_dev*3*(1+salary_escalation)^4*(1+bhxh_rate) | AL16: =AL6*salary_dev*3*(1+salary_escalation)^4*(1+bhxh_rate) | AM16: =AM6*salary_dev*3*(1+salary_escalation)^4*(1+bhxh_rate) | AN16: =AN6*salary_dev*3*(1+salary_escalation)^4*(1+bhxh_rate) | AO16: =AO6*salary_dev*3*(1+salary_escalation)^5*(1+bhxh_rate) | AP16: =AP6*salary_dev*3*(1+salary_escalation)^5*(1+bhxh_rate) | AQ16: =AQ6*salary_dev*3*(1+salary_escalation)^5*(1+bhxh_rate) | AR16: =AR6*salary_dev*3*(1+salary_escalation)^5*(1+bhxh_rate)
A17: Biz Ops salary cost | B17: M VND | C17: =C7*salary_bizops*1*(1+salary_escalation)^0*(1+bhxh_rate) | D17: =D7*salary_bizops*1*(1+salary_escalation)^0*(1+bhxh_rate) | E17: =E7*salary_bizops*1*(1+salary_escalation)^0*(1+bhxh_rate) | F17: =F7*salary_bizops*1*(1+salary_escalation)^0*(1+bhxh_rate) | G17: =G7*salary_bizops*1*(1+salary_escalation)^0*(1+bhxh_rate) | H17: =H7*salary_bizops*1*(1+salary_escalation)^0*(1+bhxh_rate) | I17: =I7*salary_bizops*1*(1+salary_escalation)^1*(1+bhxh_rate) | J17: =J7*salary_bizops*1*(1+salary_escalation)^1*(1+bhxh_rate) | K17: =K7*salary_bizops*1*(1+salary_escalation)^1*(1+bhxh_rate) | L17: =L7*salary_bizops*1*(1+salary_escalation)^1*(1+bhxh_rate) | M17: =M7*salary_bizops*1*(1+salary_escalation)^1*(1+bhxh_rate) | N17: =N7*salary_bizops*1*(1+salary_escalation)^1*(1+bhxh_rate) | O17: =O7*salary_bizops*1*(1+salary_escalation)^1*(1+bhxh_rate) | P17: =P7*salary_bizops*1*(1+salary_escalation)^1*(1+bhxh_rate) | ... T17: =T7*salary_bizops*1*(1+salary_escalation)^1*(1+bhxh_rate) | U17: =U7*salary_bizops*1*(1+salary_escalation)^2*(1+bhxh_rate) | V17: =V7*salary_bizops*1*(1+salary_escalation)^2*(1+bhxh_rate) | W17: =W7*salary_bizops*1*(1+salary_escalation)^2*(1+bhxh_rate) | X17: =X7*salary_bizops*1*(1+salary_escalation)^2*(1+bhxh_rate) | Y17: =Y7*salary_bizops*1*(1+salary_escalation)^2*(1+bhxh_rate) | Z17: =Z7*salary_bizops*1*(1+salary_escalation)^2*(1+bhxh_rate) | AA17: =AA7*salary_bizops*1*(1+salary_escalation)^2*(1+bhxh_rate) | AB17: =AB7*salary_bizops*1*(1+salary_escalation)^2*(1+bhxh_rate) | ... AF17: =AF7*salary_bizops*1*(1+salary_escalation)^2*(1+bhxh_rate) | AG17: =AG7*salary_bizops*3*(1+salary_escalation)^3*(1+bhxh_rate) | AH17: =AH7*salary_bizops*3*(1+salary_escalation)^3*(1+bhxh_rate) | AI17: =AI7*salary_bizops*3*(1+salary_escalation)^3*(1+bhxh_rate) | AJ17: =AJ7*salary_bizops*3*(1+salary_escalation)^3*(1+bhxh_rate) | AK17: =AK7*salary_bizops*3*(1+salary_escalation)^4*(1+bhxh_rate) | AL17: =AL7*salary_bizops*3*(1+salary_escalation)^4*(1+bhxh_rate) | AM17: =AM7*salary_bizops*3*(1+salary_escalation)^4*(1+bhxh_rate) | AN17: =AN7*salary_bizops*3*(1+salary_escalation)^4*(1+bhxh_rate) | AO17: =AO7*salary_bizops*3*(1+salary_escalation)^5*(1+bhxh_rate) | AP17: =AP7*salary_bizops*3*(1+salary_escalation)^5*(1+bhxh_rate) | AQ17: =AQ7*salary_bizops*3*(1+salary_escalation)^5*(1+bhxh_rate) | AR17: =AR7*salary_bizops*3*(1+salary_escalation)^5*(1+bhxh_rate)
A18: Data & Analytics salary cost | B18: M VND | C18: =C8*salary_data*1*(1+salary_escalation)^0*(1+bhxh_rate) | D18: =D8*salary_data*1*(1+salary_escalation)^0*(1+bhxh_rate) | E18: =E8*salary_data*1*(1+salary_escalation)^0*(1+bhxh_rate) | F18: =F8*salary_data*1*(1+salary_escalation)^0*(1+bhxh_rate) | G18: =G8*salary_data*1*(1+salary_escalation)^0*(1+bhxh_rate) | H18: =H8*salary_data*1*(1+salary_escalation)^0*(1+bhxh_rate) | I18: =I8*salary_data*1*(1+salary_escalation)^1*(1+bhxh_rate) | J18: =J8*salary_data*1*(1+salary_escalation)^1*(1+bhxh_rate) | K18: =K8*salary_data*1*(1+salary_escalation)^1*(1+bhxh_rate) | L18: =L8*salary_data*1*(1+salary_escalation)^1*(1+bhxh_rate) | M18: =M8*salary_data*1*(1+salary_escalation)^1*(1+bhxh_rate) | N18: =N8*salary_data*1*(1+salary_escalation)^1*(1+bhxh_rate) | O18: =O8*salary_data*1*(1+salary_escalation)^1*(1+bhxh_rate) | P18: =P8*salary_data*1*(1+salary_escalation)^1*(1+bhxh_rate) | ... T18: =T8*salary_data*1*(1+salary_escalation)^1*(1+bhxh_rate) | U18: =U8*salary_data*1*(1+salary_escalation)^2*(1+bhxh_rate) | V18: =V8*salary_data*1*(1+salary_escalation)^2*(1+bhxh_rate) | W18: =W8*salary_data*1*(1+salary_escalation)^2*(1+bhxh_rate) | X18: =X8*salary_data*1*(1+salary_escalation)^2*(1+bhxh_rate) | Y18: =Y8*salary_data*1*(1+salary_escalation)^2*(1+bhxh_rate) | Z18: =Z8*salary_data*1*(1+salary_escalation)^2*(1+bhxh_rate) | AA18: =AA8*salary_data*1*(1+salary_escalation)^2*(1+bhxh_rate) | AB18: =AB8*salary_data*1*(1+salary_escalation)^2*(1+bhxh_rate) | ... AF18: =AF8*salary_data*1*(1+salary_escalation)^2*(1+bhxh_rate) | AG18: =AG8*salary_data*3*(1+salary_escalation)^3*(1+bhxh_rate) | AH18: =AH8*salary_data*3*(1+salary_escalation)^3*(1+bhxh_rate) | AI18: =AI8*salary_data*3*(1+salary_escalation)^3*(1+bhxh_rate) | AJ18: =AJ8*salary_data*3*(1+salary_escalation)^3*(1+bhxh_rate) | AK18: =AK8*salary_data*3*(1+salary_escalation)^4*(1+bhxh_rate) | AL18: =AL8*salary_data*3*(1+salary_escalation)^4*(1+bhxh_rate) | AM18: =AM8*salary_data*3*(1+salary_escalation)^4*(1+bhxh_rate) | AN18: =AN8*salary_data*3*(1+salary_escalation)^4*(1+bhxh_rate) | AO18: =AO8*salary_data*3*(1+salary_escalation)^5*(1+bhxh_rate) | AP18: =AP8*salary_data*3*(1+salary_escalation)^5*(1+bhxh_rate) | AQ18: =AQ8*salary_data*3*(1+salary_escalation)^5*(1+bhxh_rate) | AR18: =AR8*salary_data*3*(1+salary_escalation)^5*(1+bhxh_rate)
A19: TOTAL SALARY COST | B19: M VND | C19: =SUM(C15:C18) | D19: =SUM(D15:D18) | E19: =SUM(E15:E18) | F19: =SUM(F15:F18) | G19: =SUM(G15:G18) | H19: =SUM(H15:H18) | I19: =SUM(I15:I18) | J19: =SUM(J15:J18) | ... AR19: =SUM(AR15:AR18)
A20: Recruitment cost | B20: M VND | C20: =C12*30*12*recruit_cost_pct | D20: =D12*30*12*recruit_cost_pct | E20: =E12*30*12*recruit_cost_pct | F20: =F12*30*12*recruit_cost_pct | G20: =G12*30*12*recruit_cost_pct | H20: =H12*30*12*recruit_cost_pct | I20: =I12*30*12*recruit_cost_pct | J20: =J12*30*12*recruit_cost_pct | ... AR20: =AR12*30*12*recruit_cost_pct
A21: TOTAL HR COST | B21: M VND | C21: =C19+C20 | D21: =D19+D20 | E21: =E19+E20 | F21: =F19+F20 | G21: =G19+G20 | H21: =H19+H20 | I21: =I19+I20 | J21: =J19+J20 | ... AR21: =AR19+AR20

Sheet Market Sizing
A1: MARKET SIZING & ADOPTION
A2: Period index (0-based) | B2: idx | C2: 0 | D2: 1 | E2: 2 | F2: 3 | G2: 4 | H2: 5 | I2: 6 | J2: 7 | K2: 8 | L2: 9 | M2: 10 | N2: 11 | O2: 12 | P2: 13 | Q2: 14 | R2: 15 | S2: 16 | T2: 17 | U2: 18 | V2: 19 | W2: 20 | X2: 21 | Y2: 22 | Z2: 23 | AA2: 24 | AB2: 25 | AC2: 26 | AD2: 27 | AE2: 28 | AF2: 29 | AG2: 30 | AH2: 31 | AI2: 32 | AJ2: 33 | AK2: 34 | AL2: 35 | AM2: 36 | AN2: 37 | AO2: 38 | AP2: 39 | AQ2: 40 | AR2: 41
A3: Year fraction (from formula) | B3: year | C3: =base_year+(start_month-1+C2)/12 | D3: =base_year+(start_month-1+D2)/12 | E3: =base_year+(start_month-1+E2)/12 | F3: =base_year+(start_month-1+F2)/12 | G3: =base_year+(start_month-1+G2)/12 | H3: =base_year+(start_month-1+H2)/12 | I3: =base_year+(start_month-1+I2)/12 | J3: =base_year+(start_month-1+J2)/12 | ... AF3: =base_year+(start_month-1+AF2)/12 | AG3: =2028+(1-0.5)/12 | AH3: =2028+(4-0.5)/12 | AI3: =2028+(7-0.5)/12 | AJ3: =2028+(10-0.5)/12 | AK3: =2028+(13-0.5)/12 | AL3: =2028+(16-0.5)/12 | AM3: =2028+(19-0.5)/12 | AN3: =2028+(22-0.5)/12 | AO3: =2028+(25-0.5)/12 | AP3: =2028+(28-0.5)/12 | AQ3: =2028+(31-0.5)/12 | AR3: =2028+(34-0.5)/12
A4: Years from base year | B4: years | C4: =C3-base_year | D4: =D3-base_year | E4: =E3-base_year | F4: =F3-base_year | G4: =G3-base_year | H4: =H3-base_year | I4: =I3-base_year | J4: =J3-base_year | ... AR4: =AR3-base_year
A5: Period divisor | B5: div | C5: 12 | D5: 12 | E5: 12 | F5: 12 | G5: 12 | H5: 12 | I5: 12 | J5: 12 | K5: 12 | L5: 12 | M5: 12 | N5: 12 | O5: 12 | P5: 12 | Q5: 12 | R5: 12 | S5: 12 | T5: 12 | U5: 12 | V5: 12 | W5: 12 | X5: 12 | Y5: 12 | Z5: 12 | AA5: 12 | AB5: 12 | AC5: 12 | AD5: 12 | AE5: 12 | AF5: 12 | AG5: 4 | AH5: 4 | AI5: 4 | AJ5: 4 | AK5: 4 | AL5: 4 | AM5: 4 | AN5: 4 | AO5: 4 | AP5: 4 | AQ5: 4 | AR5: 4
A6: Months in period | B6: months | C6: 1 | D6: 1 | E6: 1 | F6: 1 | G6: 1 | H6: 1 | I6: 1 | J6: 1 | K6: 1 | L6: 1 | M6: 1 | N6: 1 | O6: 1 | P6: 1 | Q6: 1 | R6: 1 | S6: 1 | T6: 1 | U6: 1 | V6: 1 | W6: 1 | X6: 1 | Y6: 1 | Z6: 1 | AA6: 1 | AB6: 1 | AC6: 1 | AD6: 1 | AE6: 1 | AF6: 1 | AG6: 3 | AH6: 3 | AI6: 3 | AJ6: 3 | AK6: 3 | AL6: 3 | AM6: 3 | AN6: 3 | AO6: 3 | AP6: 3 | AQ6: 3 | AR6: 3
A8: Item | B8: Unit | C8: Jul 2025 | D8: Aug 2025 | E8: Sep 2025 | F8: Oct 2025 | G8: Nov 2025 | H8: Dec 2025 | I8: Jan 2026 | J8: Feb 2026 | K8: Mar 2026 | L8: Apr 2026 | M8: May 2026 | N8: Jun 2026 | O8: Jul 2026 | P8: Aug 2026 | Q8: Sep 2026 | R8: Oct 2026 | S8: Nov 2026 | T8: Dec 2026 | U8: Jan 2027 | V8: Feb 2027 | W8: Mar 2027 | X8: Apr 2027 | Y8: May 2027 | Z8: Jun 2027 | AA8: Jul 2027 | AB8: Aug 2027 | AC8: Sep 2027 | AD8: Oct 2027 | AE8: Nov 2027 | AF8: Dec 2027 | AG8: Q1 2028 | AH8: Q2 2028 | AI8: Q3 2028 | AJ8: Q4 2028 | AK8: Q1 2029 | AL8: Q2 2029 | AM8: Q3 2029 | AN8: Q4 2029 | AO8: Q1 2030 | AP8: Q2 2030 | AQ8: Q3 2030 | AR8: Q4 2030
A9: E-commerce tourism market | B9: Bn VND | C9: =ecom_market_base*(1+ecom_growth_rate)^FLOOR(C4,1)/C5 | D9: =ecom_market_base*(1+ecom_growth_rate)^FLOOR(D4,1)/D5 | E9: =ecom_market_base*(1+ecom_growth_rate)^FLOOR(E4,1)/E5 | F9: =ecom_market_base*(1+ecom_growth_rate)^FLOOR(F4,1)/F5 | G9: =ecom_market_base*(1+ecom_growth_rate)^FLOOR(G4,1)/G5 | H9: =ecom_market_base*(1+ecom_growth_rate)^FLOOR(H4,1)/H5 | I9: =ecom_market_base*(1+ecom_growth_rate)^FLOOR(I4,1)/I5 | J9: =ecom_market_base*(1+ecom_growth_rate)^FLOOR(J4,1)/J5 | ... AR9: =ecom_market_base*(1+ecom_growth_rate)^FLOOR(AR4,1)/AR5
A11: ENTERPRISE ADOPTION (S-CURVE)
A12: Gross enterprises (S-curve) | B12: count | C12: =MAX(pilot_count,adoption_max/(1+EXP(-adoption_steepness*(C3-adoption_midpoint)))) | D12: =MAX(pilot_count,adoption_max/(1+EXP(-adoption_steepness*(D3-adoption_midpoint)))) | E12: =MAX(pilot_count,adoption_max/(1+EXP(-adoption_steepness*(E3-adoption_midpoint)))) | F12: =MAX(pilot_count,adoption_max/(1+EXP(-adoption_steepness*(F3-adoption_midpoint)))) | G12: =MAX(pilot_count,adoption_max/(1+EXP(-adoption_steepness*(G3-adoption_midpoint)))) | H12: =MAX(pilot_count,adoption_max/(1+EXP(-adoption_steepness*(H3-adoption_midpoint)))) | I12: =MAX(pilot_count,adoption_max/(1+EXP(-adoption_steepness*(I3-adoption_midpoint)))) | J12: =MAX(pilot_count,adoption_max/(1+EXP(-adoption_steepness*(J3-adoption_midpoint)))) | ... AR12: =MAX(pilot_count,adoption_max/(1+EXP(-adoption_steepness*(AR3-adoption_midpoint))))
A13: Churned enterprises | B13: count | C13: =0 | D13: =ROUND(D12*churn_rate/D5,0) | E13: =ROUND(E12*churn_rate/E5,0) | F13: =ROUND(F12*churn_rate/F5,0) | G13: =ROUND(G12*churn_rate/G5,0) | H13: =ROUND(H12*churn_rate/H5,0) | I13: =ROUND(I12*churn_rate/I5,0) | J13: =ROUND(J12*churn_rate/J5,0) | K13: =ROUND(K12*churn_rate/K5,0) | ... AR13: =ROUND(AR12*churn_rate/AR5,0)
A14: Net active enterprises | B14: count | C14: =C12-C13 | D14: =D12-D13 | E14: =E12-E13 | F14: =F12-F13 | G14: =G12-G13 | H14: =H12-H13 | I14: =I12-I13 | J14: =J12-J13 | ... AR14: =AR12-AR13
A15: New enterprises (period) | B15: count | C15: =C14 | D15: =MAX(0,D14-C14) | E15: =MAX(0,E14-D14) | F15: =MAX(0,F14-E14) | G15: =MAX(0,G14-F14) | H15: =MAX(0,H14-G14) | I15: =MAX(0,I14-H14) | J15: =MAX(0,J14-I14) | K15: =MAX(0,K14-J14) | ... AR15: =MAX(0,AR14-AQ14)
A16: VCR (visitor records) | B16: M recs | C16: =C14*vcr_per_enterprise*C6/1000000 | D16: =D14*vcr_per_enterprise*D6/1000000 | E16: =E14*vcr_per_enterprise*E6/1000000 | F16: =F14*vcr_per_enterprise*F6/1000000 | G16: =G14*vcr_per_enterprise*G6/1000000 | H16: =H14*vcr_per_enterprise*H6/1000000 | I16: =I14*vcr_per_enterprise*I6/1000000 | J16: =J14*vcr_per_enterprise*J6/1000000 | ... AR16: =AR14*vcr_per_enterprise*AR6/1000000

Sheet Revenue Schedule
A1: REVENUE SCHEDULE (M VND)
A3: Item | B3: Unit | C3: Jul 2025 | D3: Aug 2025 | E3: Sep 2025 | F3: Oct 2025 | G3: Nov 2025 | H3: Dec 2025 | I3: Jan 2026 | J3: Feb 2026 | K3: Mar 2026 | L3: Apr 2026 | M3: May 2026 | N3: Jun 2026 | O3: Jul 2026 | P3: Aug 2026 | Q3: Sep 2026 | R3: Oct 2026 | S3: Nov 2026 | T3: Dec 2026 | U3: Jan 2027 | V3: Feb 2027 | W3: Mar 2027 | X3: Apr 2027 | Y3: May 2027 | Z3: Jun 2027 | AA3: Jul 2027 | AB3: Aug 2027 | AC3: Sep 2027 | AD3: Oct 2027 | AE3: Nov 2027 | AF3: Dec 2027 | AG3: Q1 2028 | AH3: Q2 2028 | AI3: Q3 2028 | AJ3: Q4 2028 | AK3: Q1 2029 | AL3: Q2 2029 | AM3: Q3 2029 | AN3: Q4 2029 | AO3: Q1 2030 | AP3: Q2 2030 | AQ3: Q3 2030 | AR3: Q4 2030
A4: STAGE 1 REVENUE
A5: Certification fees | B5: M VND | C5: ='Market Sizing'!C14*cert_fee_yr1*(1+cert_fee_escalation)^FLOOR('Market Sizing'!C4,1)/'Market Sizing'!C5 | D5: ='Market Sizing'!D14*cert_fee_yr1*(1+cert_fee_escalation)^FLOOR('Market Sizing'!D4,1)/'Market Sizing'!D5 | E5: ='Market Sizing'!E14*cert_fee_yr1*(1+cert_fee_escalation)^FLOOR('Market Sizing'!E4,1)/'Market Sizing'!E5 | F5: ='Market Sizing'!F14*cert_fee_yr1*(1+cert_fee_escalation)^FLOOR('Market Sizing'!F4,1)/'Market Sizing'!F5 | G5: ='Market Sizing'!G14*cert_fee_yr1*(1+cert_fee_escalation)^FLOOR('Market Sizing'!G4,1)/'Market Sizing'!G5 | H5: ='Market Sizing'!H14*cert_fee_yr1*(1+cert_fee_escalation)^FLOOR('Market Sizing'!H4,1)/'Market Sizing'!H5 | I5: ='Market Sizing'!I14*cert_fee_yr1*(1+cert_fee_escalation)^FLOOR('Market Sizing'!I4,1)/'Market Sizing'!I5 | J5: ='Market Sizing'!J14*cert_fee_yr1*(1+cert_fee_escalation)^FLOOR('Market Sizing'!J4,1)/'Market Sizing'!J5 | ... AR5: ='Market Sizing'!AR14*cert_fee_yr1*(1+cert_fee_escalation)^FLOOR('Market Sizing'!AR4,1)/'Market Sizing'!AR5
A6: Training & consulting | B6: M VND | C6: ='Market Sizing'!C14*training_pct*training_fee/'Market Sizing'!C5 | D6: ='Market Sizing'!D14*training_pct*training_fee/'Market Sizing'!D5 | E6: ='Market Sizing'!E14*training_pct*training_fee/'Market Sizing'!E5 | F6: ='Market Sizing'!F14*training_pct*training_fee/'Market Sizing'!F5 | G6: ='Market Sizing'!G14*training_pct*training_fee/'Market Sizing'!G5 | H6: ='Market Sizing'!H14*training_pct*training_fee/'Market Sizing'!H5 | I6: ='Market Sizing'!I14*training_pct*training_fee/'Market Sizing'!I5 | J6: ='Market Sizing'!J14*training_pct*training_fee/'Market Sizing'!J5 | ... AR6: ='Market Sizing'!AR14*training_pct*training_fee/'Market Sizing'!AR5
A7: Audit fees | B7: M VND | C7: ='Market Sizing'!C14*audit_fee/'Market Sizing'!C5 | D7: ='Market Sizing'!D14*audit_fee/'Market Sizing'!D5 | E7: ='Market Sizing'!E14*audit_fee/'Market Sizing'!E5 | F7: ='Market Sizing'!F14*audit_fee/'Market Sizing'!F5 | G7: ='Market Sizing'!G14*audit_fee/'Market Sizing'!G5 | H7: ='Market Sizing'!H14*audit_fee/'Market Sizing'!H5 | I7: ='Market Sizing'!I14*audit_fee/'Market Sizing'!I5 | J7: ='Market Sizing'!J14*audit_fee/'Market Sizing'!J5 | ... AR7: ='Market Sizing'!AR14*audit_fee/'Market Sizing'!AR5
A8: Subtotal Stage 1 | B8: M VND | C8: =SUM(C5:C7) | D8: =SUM(D5:D7) | E8: =SUM(E5:E7) | F8: =SUM(F5:F7) | G8: =SUM(G5:G7) | H8: =SUM(H5:H7) | I8: =SUM(I5:I7) | J8: =SUM(J5:J7) | ... AR8: =SUM(AR5:AR7)
A10: STAGE 2 REVENUE (gated)
A11: Transaction fees | B11: M VND | C11: =IF('Market Sizing'!C14>=stage2_gate,'Market Sizing'!C9*platform_market_share*tx_take_rate*1000,0) | D11: =IF('Market Sizing'!D14>=stage2_gate,'Market Sizing'!D9*platform_market_share*tx_take_rate*1000,0) | E11: =IF('Market Sizing'!E14>=stage2_gate,'Market Sizing'!E9*platform_market_share*tx_take_rate*1000,0) | F11: =IF('Market Sizing'!F14>=stage2_gate,'Market Sizing'!F9*platform_market_share*tx_take_rate*1000,0) | G11: =IF('Market Sizing'!G14>=stage2_gate,'Market Sizing'!G9*platform_market_share*tx_take_rate*1000,0) | H11: =IF('Market Sizing'!H14>=stage2_gate,'Market Sizing'!H9*platform_market_share*tx_take_rate*1000,0) | I11: =IF('Market Sizing'!I14>=stage2_gate,'Market Sizing'!I9*platform_market_share*tx_take_rate*1000,0) | J11: =IF('Market Sizing'!J14>=stage2_gate,'Market Sizing'!J9*platform_market_share*tx_take_rate*1000,0) | ... AR11: =IF('Market Sizing'!AR14>=stage2_gate,'Market Sizing'!AR9*platform_market_share*tx_take_rate*1000,0)
A12: DaaS | B12: M VND | C12: =IF('Market Sizing'!C14>=stage2_gate,'Market Sizing'!C16*daas_price,0) | D12: =IF('Market Sizing'!D14>=stage2_gate,'Market Sizing'!D16*daas_price,0) | E12: =IF('Market Sizing'!E14>=stage2_gate,'Market Sizing'!E16*daas_price,0) | F12: =IF('Market Sizing'!F14>=stage2_gate,'Market Sizing'!F16*daas_price,0) | G12: =IF('Market Sizing'!G14>=stage2_gate,'Market Sizing'!G16*daas_price,0) | H12: =IF('Market Sizing'!H14>=stage2_gate,'Market Sizing'!H16*daas_price,0) | I12: =IF('Market Sizing'!I14>=stage2_gate,'Market Sizing'!I16*daas_price,0) | J12: =IF('Market Sizing'!J14>=stage2_gate,'Market Sizing'!J16*daas_price,0) | ... AR12: =IF('Market Sizing'!AR14>=stage2_gate,'Market Sizing'!AR16*daas_price,0)
A13: Advertising | B13: M VND | C13: =IF('Market Sizing'!C14>=stage2_gate,ad_impressions_base*'Market Sizing'!C6*'Market Sizing'!C14/1000*ad_cpm/1000,0) | D13: =IF('Market Sizing'!D14>=stage2_gate,ad_impressions_base*'Market Sizing'!D6*'Market Sizing'!D14/1000*ad_cpm/1000,0) | E13: =IF('Market Sizing'!E14>=stage2_gate,ad_impressions_base*'Market Sizing'!E6*'Market Sizing'!E14/1000*ad_cpm/1000,0) | F13: =IF('Market Sizing'!F14>=stage2_gate,ad_impressions_base*'Market Sizing'!F6*'Market Sizing'!F14/1000*ad_cpm/1000,0) | G13: =IF('Market Sizing'!G14>=stage2_gate,ad_impressions_base*'Market Sizing'!G6*'Market Sizing'!G14/1000*ad_cpm/1000,0) | H13: =IF('Market Sizing'!H14>=stage2_gate,ad_impressions_base*'Market Sizing'!H6*'Market Sizing'!H14/1000*ad_cpm/1000,0) | I13: =IF('Market Sizing'!I14>=stage2_gate,ad_impressions_base*'Market Sizing'!I6*'Market Sizing'!I14/1000*ad_cpm/1000,0) | J13: =IF('Market Sizing'!J14>=stage2_gate,ad_impressions_base*'Market Sizing'!J6*'Market Sizing'!J14/1000*ad_cpm/1000,0) | ... AR13: =IF('Market Sizing'!AR14>=stage2_gate,ad_impressions_base*'Market Sizing'!AR6*'Market Sizing'!AR14/1000*ad_cpm/1000,0)
A14: Subtotal Stage 2 | B14: M VND | C14: =SUM(C11:C13) | D14: =SUM(D11:D13) | E14: =SUM(E11:E13) | F14: =SUM(F11:F13) | G14: =SUM(G11:G13) | H14: =SUM(H11:H13) | I14: =SUM(I11:I13) | J14: =SUM(J11:J13) | ... AR14: =SUM(AR11:AR13)
A16: TOTAL REVENUE | B16: M VND | C16: =C8+C14 | D16: =D8+D14 | E16: =E8+E14 | F16: =F8+F14 | G16: =G8+G14 | H16: =H8+H14 | I16: =I8+I14 | J16: =J8+J14 | ... AR16: =AR8+AR14
A18: COGS
A19: Payment processing | B19: M VND | C19: =C11*payment_proc_pct | D19: =D11*payment_proc_pct | E19: =E11*payment_proc_pct | F19: =F11*payment_proc_pct | G19: =G11*payment_proc_pct | H19: =H11*payment_proc_pct | I19: =I11*payment_proc_pct | J19: =J11*payment_proc_pct | ... AR19: =AR11*payment_proc_pct
A20: TOTAL COGS | B20: M VND | C20: =C19 | D20: =D19 | E20: =E19 | F20: =F19 | G20: =G19 | H20: =H19 | I20: =I19 | J20: =J19 | ... AR20: =AR19

Sheet Cost Schedule
A1: COST SCHEDULE (M VND)
A3: Item | B3: Unit | C3: Jul 2025 | D3: Aug 2025 | E3: Sep 2025 | F3: Oct 2025 | G3: Nov 2025 | H3: Dec 2025 | I3: Jan 2026 | J3: Feb 2026 | K3: Mar 2026 | L3: Apr 2026 | M3: May 2026 | N3: Jun 2026 | O3: Jul 2026 | P3: Aug 2026 | Q3: Sep 2026 | R3: Oct 2026 | S3: Nov 2026 | T3: Dec 2026 | U3: Jan 2027 | V3: Feb 2027 | W3: Mar 2027 | X3: Apr 2027 | Y3: May 2027 | Z3: Jun 2027 | AA3: Jul 2027 | AB3: Aug 2027 | AC3: Sep 2027 | AD3: Oct 2027 | AE3: Nov 2027 | AF3: Dec 2027 | AG3: Q1 2028 | AH3: Q2 2028 | AI3: Q3 2028 | AJ3: Q4 2028 | AK3: Q1 2029 | AL3: Q2 2029 | AM3: Q3 2029 | AN3: Q4 2029 | AO3: Q1 2030 | AP3: Q2 2030 | AQ3: Q3 2030 | AR3: Q4 2030
A4: CAPEX
A5: Platform development | B5: M VND | C5: =capex_total/6 | D5: =capex_total/6 | E5: =capex_total/6 | F5: =capex_total/6 | G5: =capex_total/6 | H5: =capex_total/6 | I5: =0 | J5: =0 | K5: =0 | L5: =0 | M5: =0 | N5: =0 | O5: =0 | P5: =0 | ... AR5: =0
A6: Annual maintenance | B6: M VND | C6: =0 | D6: =0 | E6: =0 | F6: =0 | G6: =0 | H6: =0 | I6: =capex_total*capex_maintenance_pct/'Market Sizing'!I5 | J6: =capex_total*capex_maintenance_pct/'Market Sizing'!J5 | K6: =capex_total*capex_maintenance_pct/'Market Sizing'!K5 | L6: =capex_total*capex_maintenance_pct/'Market Sizing'!L5 | M6: =capex_total*capex_maintenance_pct/'Market Sizing'!M5 | N6: =capex_total*capex_maintenance_pct/'Market Sizing'!N5 | O6: =capex_total*capex_maintenance_pct/'Market Sizing'!O5 | P6: =capex_total*capex_maintenance_pct/'Market Sizing'!P5 | ... AR6: =capex_total*capex_maintenance_pct/'Market Sizing'!AR5
A7: TOTAL CAPEX | B7: M VND | C7: =C5+C6 | D7: =D5+D6 | E7: =E5+E6 | F7: =F5+F6 | G7: =G5+G6 | H7: =H5+H6 | I7: =I5+I6 | J7: =J5+J6 | ... AR7: =AR5+AR6
A9: OPEX
A10: Human resources (from HR Plan) | B10: M VND | C10: ='HR Plan'!C21 | D10: ='HR Plan'!D21 | E10: ='HR Plan'!E21 | F10: ='HR Plan'!F21 | G10: ='HR Plan'!G21 | H10: ='HR Plan'!H21 | I10: ='HR Plan'!I21 | J10: ='HR Plan'!J21 | ... AR10: ='HR Plan'!AR21
A11: Marketing & communications | B11: M VND | C11: =opex_marketing*(1+marketing_growth)^FLOOR('Market Sizing'!C4,1)/'Market Sizing'!C5 | D11: =opex_marketing*(1+marketing_growth)^FLOOR('Market Sizing'!D4,1)/'Market Sizing'!D5 | E11: =opex_marketing*(1+marketing_growth)^FLOOR('Market Sizing'!E4,1)/'Market Sizing'!E5 | F11: =opex_marketing*(1+marketing_growth)^FLOOR('Market Sizing'!F4,1)/'Market Sizing'!F5 | G11: =opex_marketing*(1+marketing_growth)^FLOOR('Market Sizing'!G4,1)/'Market Sizing'!G5 | H11: =opex_marketing*(1+marketing_growth)^FLOOR('Market Sizing'!H4,1)/'Market Sizing'!H5 | I11: =opex_marketing*(1+marketing_growth)^FLOOR('Market Sizing'!I4,1)/'Market Sizing'!I5 | J11: =opex_marketing*(1+marketing_growth)^FLOOR('Market Sizing'!J4,1)/'Market Sizing'!J5 | ... AR11: =opex_marketing*(1+marketing_growth)^FLOOR('Market Sizing'!AR4,1)/'Market Sizing'!AR5
A12: Branding & events | B12: M VND | C12: =opex_branding/'Market Sizing'!C5 | D12: =opex_branding/'Market Sizing'!D5 | E12: =opex_branding/'Market Sizing'!E5 | F12: =opex_branding/'Market Sizing'!F5 | G12: =opex_branding/'Market Sizing'!G5 | H12: =opex_branding/'Market Sizing'!H5 | I12: =opex_branding/'Market Sizing'!I5 | J12: =opex_branding/'Market Sizing'!J5 | ... AR12: =opex_branding/'Market Sizing'!AR5
A13: Cloud & infrastructure | B13: M VND | C13: =opex_cloud_base/'Market Sizing'!C5+'Market Sizing'!C16*cloud_per_1M_vcr | D13: =opex_cloud_base/'Market Sizing'!D5+'Market Sizing'!D16*cloud_per_1M_vcr | E13: =opex_cloud_base/'Market Sizing'!E5+'Market Sizing'!E16*cloud_per_1M_vcr | F13: =opex_cloud_base/'Market Sizing'!F5+'Market Sizing'!F16*cloud_per_1M_vcr | G13: =opex_cloud_base/'Market Sizing'!G5+'Market Sizing'!G16*cloud_per_1M_vcr | H13: =opex_cloud_base/'Market Sizing'!H5+'Market Sizing'!H16*cloud_per_1M_vcr | I13: =opex_cloud_base/'Market Sizing'!I5+'Market Sizing'!I16*cloud_per_1M_vcr | J13: =opex_cloud_base/'Market Sizing'!J5+'Market Sizing'!J16*cloud_per_1M_vcr | ... AR13: =opex_cloud_base/'Market Sizing'!AR5+'Market Sizing'!AR16*cloud_per_1M_vcr
A14: Security / pentest | B14: M VND | C14: =opex_security/'Market Sizing'!C5 | D14: =opex_security/'Market Sizing'!D5 | E14: =opex_security/'Market Sizing'!E5 | F14: =opex_security/'Market Sizing'!F5 | G14: =opex_security/'Market Sizing'!G5 | H14: =opex_security/'Market Sizing'!H5 | I14: =opex_security/'Market Sizing'!I5 | J14: =opex_security/'Market Sizing'!J5 | ... AR14: =opex_security/'Market Sizing'!AR5
A15: External affairs | B15: M VND | C15: =opex_external/'Market Sizing'!C5 | D15: =opex_external/'Market Sizing'!D5 | E15: =opex_external/'Market Sizing'!E5 | F15: =opex_external/'Market Sizing'!F5 | G15: =opex_external/'Market Sizing'!G5 | H15: =opex_external/'Market Sizing'!H5 | I15: =opex_external/'Market Sizing'!I5 | J15: =opex_external/'Market Sizing'!J5 | ... AR15: =opex_external/'Market Sizing'!AR5
A16: Legal & compliance | B16: M VND | C16: =opex_legal/'Market Sizing'!C5 | D16: =opex_legal/'Market Sizing'!D5 | E16: =opex_legal/'Market Sizing'!E5 | F16: =opex_legal/'Market Sizing'!F5 | G16: =opex_legal/'Market Sizing'!G5 | H16: =opex_legal/'Market Sizing'!H5 | I16: =opex_legal/'Market Sizing'!I5 | J16: =opex_legal/'Market Sizing'!J5 | ... AR16: =opex_legal/'Market Sizing'!AR5
A17: Pilot evaluation (Y1 only) | B17: M VND | C17: =opex_pilot_eval/'Market Sizing'!C5 | D17: =opex_pilot_eval/'Market Sizing'!D5 | E17: =opex_pilot_eval/'Market Sizing'!E5 | F17: =opex_pilot_eval/'Market Sizing'!F5 | G17: =opex_pilot_eval/'Market Sizing'!G5 | H17: =opex_pilot_eval/'Market Sizing'!H5 | I17: =0 | J17: =0 | K17: =0 | L17: =0 | M17: =0 | N17: =0 | O17: =0 | P17: =0 | ... AR17: =0
A18: TOTAL OPEX | B18: M VND | C18: =SUM(C10:C17) | D18: =SUM(D10:D17) | E18: =SUM(E10:E17) | F18: =SUM(F10:F17) | G18: =SUM(G10:G17) | H18: =SUM(H10:H17) | I18: =SUM(I10:I17) | J18: =SUM(J10:J17) | ... AR18: =SUM(AR10:AR17)
A20: TOTAL COSTS (CAPEX+OPEX) | B20: M VND | C20: =C7+C18 | D20: =D7+D18 | E20: =E7+E18 | F20: =F7+F18 | G20: =G7+G18 | H20: =H7+H18 | I20: =I7+I18 | J20: =J7+J18 | ... AR20: =AR7+AR18

Sheet P&L
A1: PROFIT & LOSS (M VND)
A3: Item | B3: Unit | C3: Jul 2025 | D3: Aug 2025 | E3: Sep 2025 | F3: Oct 2025 | G3: Nov 2025 | H3: Dec 2025 | I3: Jan 2026 | J3: Feb 2026 | K3: Mar 2026 | L3: Apr 2026 | M3: May 2026 | N3: Jun 2026 | O3: Jul 2026 | P3: Aug 2026 | Q3: Sep 2026 | R3: Oct 2026 | S3: Nov 2026 | T3: Dec 2026 | U3: Jan 2027 | V3: Feb 2027 | W3: Mar 2027 | X3: Apr 2027 | Y3: May 2027 | Z3: Jun 2027 | AA3: Jul 2027 | AB3: Aug 2027 | AC3: Sep 2027 | AD3: Oct 2027 | AE3: Nov 2027 | AF3: Dec 2027 | AG3: Q1 2028 | AH3: Q2 2028 | AI3: Q3 2028 | AJ3: Q4 2028 | AK3: Q1 2029 | AL3: Q2 2029 | AM3: Q3 2029 | AN3: Q4 2029 | AO3: Q1 2030 | AP3: Q2 2030 | AQ3: Q3 2030 | AR3: Q4 2030
A4: Revenue | B4: M VND | C4: ='Revenue Schedule'!C16 | D4: ='Revenue Schedule'!D16 | E4: ='Revenue Schedule'!E16 | F4: ='Revenue Schedule'!F16 | G4: ='Revenue Schedule'!G16 | H4: ='Revenue Schedule'!H16 | I4: ='Revenue Schedule'!I16 | J4: ='Revenue Schedule'!J16 | ... AR4: ='Revenue Schedule'!AR16
A5: COGS | B5: M VND | C5: =-'Revenue Schedule'!C20 | D5: =-'Revenue Schedule'!D20 | E5: =-'Revenue Schedule'!E20 | F5: =-'Revenue Schedule'!F20 | G5: =-'Revenue Schedule'!G20 | H5: =-'Revenue Schedule'!H20 | I5: =-'Revenue Schedule'!I20 | J5: =-'Revenue Schedule'!J20 | ... AR5: =-'Revenue Schedule'!AR20
A6: GROSS PROFIT | B6: M VND | C6: =C4+C5 | D6: =D4+D5 | E6: =E4+E5 | F6: =F4+F5 | G6: =G4+G5 | H6: =H4+H5 | I6: =I4+I5 | J6: =J4+J5 | ... AR6: =AR4+AR5
A8: Operating expenses | B8: M VND | C8: =-'Cost Schedule'!C18 | D8: =-'Cost Schedule'!D18 | E8: =-'Cost Schedule'!E18 | F8: =-'Cost Schedule'!F18 | G8: =-'Cost Schedule'!G18 | H8: =-'Cost Schedule'!H18 | I8: =-'Cost Schedule'!I18 | J8: =-'Cost Schedule'!J18 | ... AR8: =-'Cost Schedule'!AR18
A9: EBITDA | B9: M VND | C9: =C6+C8 | D9: =D6+D8 | E9: =E6+E8 | F9: =F6+F8 | G9: =G6+G8 | H9: =H6+H8 | I9: =I6+I8 | J9: =J6+J8 | ... AR9: =AR6+AR8
A10: Depreciation | B10: M VND | C10: =-capex_total/depreciation_years/'Market Sizing'!C5 | D10: =-capex_total/depreciation_years/'Market Sizing'!D5 | E10: =-capex_total/depreciation_years/'Market Sizing'!E5 | F10: =-capex_total/depreciation_years/'Market Sizing'!F5 | G10: =-capex_total/depreciation_years/'Market Sizing'!G5 | H10: =-capex_total/depreciation_years/'Market Sizing'!H5 | I10: =-capex_total/depreciation_years/'Market Sizing'!I5 | J10: =-capex_total/depreciation_years/'Market Sizing'!J5 | ... AN10: =-capex_total/depreciation_years/'Market Sizing'!AN5 | AO10: =0 | AP10: =0 | AQ10: =0 | AR10: =0
A11: EBIT | B11: M VND | C11: =C9+C10 | D11: =D9+D10 | E11: =E9+E10 | F11: =F9+F10 | G11: =G9+G10 | H11: =H9+H10 | I11: =I9+I10 | J11: =J9+J10 | ... AR11: =AR9+AR10
A12: Tax (CIT) | B12: M VND | C12: =IF(C11>0,-C11*cit_rate,0) | D12: =IF(D11>0,-D11*cit_rate,0) | E12: =IF(E11>0,-E11*cit_rate,0) | F12: =IF(F11>0,-F11*cit_rate,0) | G12: =IF(G11>0,-G11*cit_rate,0) | H12: =IF(H11>0,-H11*cit_rate,0) | I12: =IF(I11>0,-I11*cit_rate,0) | J12: =IF(J11>0,-J11*cit_rate,0) | ... AR12: =IF(AR11>0,-AR11*cit_rate,0)
A13: NET INCOME | B13: M VND | C13: =C11+C12 | D13: =D11+D12 | E13: =E11+E12 | F13: =F11+F12 | G13: =G11+G12 | H13: =H11+H12 | I13: =I11+I12 | J13: =J11+J12 | ... AR13: =AR11+AR12
A15: KEY RATIOS
A16: Gross margin | C16: =IF(C4=0,0,C6/C4) | D16: =IF(D4=0,0,D6/D4) | E16: =IF(E4=0,0,E6/E4) | F16: =IF(F4=0,0,F6/F4) | G16: =IF(G4=0,0,G6/G4) | H16: =IF(H4=0,0,H6/H4) | I16: =IF(I4=0,0,I6/I4) | J16: =IF(J4=0,0,J6/J4) | ... AR16: =IF(AR4=0,0,AR6/AR4)
A17: EBITDA margin | C17: =IF(C4=0,0,C9/C4) | D17: =IF(D4=0,0,D9/D4) | E17: =IF(E4=0,0,E9/E4) | F17: =IF(F4=0,0,F9/F4) | G17: =IF(G4=0,0,G9/G4) | H17: =IF(H4=0,0,H9/H4) | I17: =IF(I4=0,0,I9/I4) | J17: =IF(J4=0,0,J9/J4) | ... AR17: =IF(AR4=0,0,AR9/AR4)
A18: Net margin | C18: =IF(C4=0,0,C13/C4) | D18: =IF(D4=0,0,D13/D4) | E18: =IF(E4=0,0,E13/E4) | F18: =IF(F4=0,0,F13/F4) | G18: =IF(G4=0,0,G13/G4) | H18: =IF(H4=0,0,H13/H4) | I18: =IF(I4=0,0,I13/I4) | J18: =IF(J4=0,0,J13/J4) | ... AR18: =IF(AR4=0,0,AR13/AR4)

Sheet Cash Flow
A1: CASH FLOW (M VND)
A3: Item | B3: Unit | C3: Jul 2025 | D3: Aug 2025 | E3: Sep 2025 | F3: Oct 2025 | G3: Nov 2025 | H3: Dec 2025 | I3: Jan 2026 | J3: Feb 2026 | K3: Mar 2026 | L3: Apr 2026 | M3: May 2026 | N3: Jun 2026 | O3: Jul 2026 | P3: Aug 2026 | Q3: Sep 2026 | R3: Oct 2026 | S3: Nov 2026 | T3: Dec 2026 | U3: Jan 2027 | V3: Feb 2027 | W3: Mar 2027 | X3: Apr 2027 | Y3: May 2027 | Z3: Jun 2027 | AA3: Jul 2027 | AB3: Aug 2027 | AC3: Sep 2027 | AD3: Oct 2027 | AE3: Nov 2027 | AF3: Dec 2027 | AG3: Q1 2028 | AH3: Q2 2028 | AI3: Q3 2028 | AJ3: Q4 2028 | AK3: Q1 2029 | AL3: Q2 2029 | AM3: Q3 2029 | AN3: Q4 2029 | AO3: Q1 2030 | AP3: Q2 2030 | AQ3: Q3 2030 | AR3: Q4 2030
A4: Operating Cash Flow
A5: Net income | C5: ='P&L'!C13 | D5: ='P&L'!D13 | E5: ='P&L'!E13 | F5: ='P&L'!F13 | G5: ='P&L'!G13 | H5: ='P&L'!H13 | I5: ='P&L'!I13 | J5: ='P&L'!J13 | ... AR5: ='P&L'!AR13
A6: Add: Depreciation | C6: =-'P&L'!C10 | D6: =-'P&L'!D10 | E6: =-'P&L'!E10 | F6: =-'P&L'!F10 | G6: =-'P&L'!G10 | H6: =-'P&L'!H10 | I6: =-'P&L'!I10 | J6: =-'P&L'!J10 | ... AR6: =-'P&L'!AR10
A7: Chg in working capital | C7: =-'P&L'!C4*ar_days/365 | D7: =-('P&L'!D4-'P&L'!C4)*ar_days/365 | E7: =-('P&L'!E4-'P&L'!D4)*ar_days/365 | F7: =-('P&L'!F4-'P&L'!E4)*ar_days/365 | G7: =-('P&L'!G4-'P&L'!F4)*ar_days/365 | H7: =-('P&L'!H4-'P&L'!G4)*ar_days/365 | I7: =-('P&L'!I4-'P&L'!H4)*ar_days/365 | J7: =-('P&L'!J4-'P&L'!I4)*ar_days/365 | K7: =-('P&L'!K4-'P&L'!J4)*ar_days/365 | ... AR7: =-('P&L'!AR4-'P&L'!AQ4)*ar_days/365
A8: OPERATING CF | C8: =C5+C6+C7 | D8: =D5+D6+D7 | E8: =E5+E6+E7 | F8: =F5+F6+F7 | G8: =G5+G6+G7 | H8: =H5+H6+H7 | I8: =I5+I6+I7 | J8: =J5+J6+J7 | ... AR8: =AR5+AR6+AR7
A10: Investing Cash Flow
A11: Capital expenditure | C11: =-'Cost Schedule'!C7 | D11: =-'Cost Schedule'!D7 | E11: =-'Cost Schedule'!E7 | F11: =-'Cost Schedule'!F7 | G11: =-'Cost Schedule'!G7 | H11: =-'Cost Schedule'!H7 | I11: =-'Cost Schedule'!I7 | J11: =-'Cost Schedule'!J7 | ... AR11: =-'Cost Schedule'!AR7
A12: INVESTING CF | C12: =C11 | D12: =D11 | E12: =E11 | F12: =F11 | G12: =G11 | H12: =H11 | I12: =I11 | J12: =J11 | ... AR12: =AR11
A14: FREE CASH FLOW | C14: =C8+C12 | D14: =D8+D12 | E14: =E8+E12 | F14: =F8+F12 | G14: =G8+G12 | H14: =H8+H12 | I14: =I8+I12 | J14: =J8+J12 | ... AR14: =AR8+AR12
A15: Cumulative CF | C15: =C14 | D15: =C15+D14 | E15: =D15+E14 | F15: =E15+F14 | G15: =F15+G14 | H15: =G15+H14 | I15: =H15+I14 | J15: =I15+J14 | K15: =J15+K14 | ... AR15: =AQ15+AR14

Sheet DCF & Returns
A1: DCF & RETURNS
A3: Annual FCF Summary
A4: Year | B4: FCF (M VND)
A5: H2_2025 | B5: =SUM('Cash Flow'!C14:H14)
A6: Y2026 | B6: =SUM('Cash Flow'!I14:T14)
A7: Y2027 | B7: =SUM('Cash Flow'!U14:AF14)
A8: Y2028 | B8: =SUM('Cash Flow'!AG14:AJ14)
A9: Y2029 | B9: =SUM('Cash Flow'!AK14:AN14)
A10: Y2030 | B10: =SUM('Cash Flow'!AO14:AR14)
A12: Key Metrics
A13: NPV | B13: =NPV(discount_rate,B6:B10)+B5
A14: IRR | B14: =IFERROR(IRR(B5:B10),"N/A")
A15: Total investment | B15: =-MIN(0,'Cash Flow'!C15:'Cash Flow'!AR15)
A16: ROI | B16: =IF(B15=0,0,('Cash Flow'!AR15+B15)/B15)
A17: CIT rate applied | B17: =cit_rate
A18: Discount rate used | B18: =discount_rate

Sheet Scenarios
A1: SCENARIO ANALYSIS
A2: Copy values from a scenario column into Assumptions to run it.
A4: Parameter | B4: WORST | C4: BEAR | D4: BASE (Current) | E4: BULL | F4: BEST
A5: Adoption max | B5: 200 | C5: 600 | D5: =adoption_max | E5: 2000 | F5: 3500
A6: Adoption steepness | B6: 0.5 | C6: 0.7 | D6: =adoption_steepness | E6: 1.2 | F6: 1.5
A7: Churn rate | B7: 0.35 | C7: 0.25 | D7: =churn_rate | E7: 0.15 | F7: 0.1
A8: Platform market share | B8: 0.001 | C8: 0.003 | D8: =platform_market_share | E8: 0.01 | F8: 0.02
A9: Cert fee (M VND) | B9: 15 | C9: 20 | D9: =cert_fee_yr1 | E9: 30 | F9: 40
A10: Cert fee escalation | B10: 0 | C10: 0.03 | D10: =cert_fee_escalation | E10: 0.08 | F10: 0.12
A11: Tx take rate | B11: 0.01 | C11: 0.015 | D11: =tx_take_rate | E11: 0.025 | F11: 0.03
A12: Marketing base (M VND) | B12: 8000 | C12: 7500 | D12: =opex_marketing | E12: 6000 | F12: 5000
A13: Marketing growth | B13: 0.2 | C13: 0.18 | D13: =marketing_growth | E13: 0.12 | F13: 0.08
A14: Discount rate | B14: 0.2 | C14: 0.18 | D14: =discount_rate | E14: 0.12 | F14: 0.1
A15: Pilot count | B15: 5 | C15: 10 | D15: =pilot_count | E15: 20 | F15: 30
A16: Stage 2 gate | B16: 500 | C16: 400 | D16: =stage2_gate | E16: 200 | F16: 150
A19: WHY v2 HAD NPV 238K & IRR 214%
A20: Top 3 drivers of inflated returns in v2:
A21: 1. platform_market_share = 2% → now 0.5%. At 2%, VV captures ~$1.6B GMV. Unrealistic.
A22: 2. adoption_max = 3,000 → now 1,200. 3K = 7.5% market; 1.2K = 3% — achievable.
A23: 3. churn = 15% → now 20%. Higher reflects cert renewal resistance.
A24: Also: WACC 12%→15%, cert fee 30→25M, slower escalation, higher cloud costs.

Sheet Budget 2025
A1: BUDGET 2025 — MONTHLY DETAIL (M VND)
A2: Approval-ready budget. Yellow cells = adjustable items.
A4: Budget Item | B4: Unit | C4: Jul | D4: Aug | E4: Sep | F4: Oct | G4: Nov | H4: Dec | I4: TOTAL
A5: REVENUE
A6: Certification fees | B6: M VND | C6: =pilot_count*cert_fee_yr1/12 | D6: =pilot_count*cert_fee_yr1/12 | E6: =pilot_count*cert_fee_yr1/12 | F6: =pilot_count*cert_fee_yr1/12 | G6: =pilot_count*cert_fee_yr1/12 | H6: =pilot_count*cert_fee_yr1/12 | I6: =SUM(C6:H6)
A7: Training & consulting | B7: M VND | C7: =pilot_count*training_pct*training_fee/12 | D7: =pilot_count*training_pct*training_fee/12 | E7: =pilot_count*training_pct*training_fee/12 | F7: =pilot_count*training_pct*training_fee/12 | G7: =pilot_count*training_pct*training_fee/12 | H7: =pilot_count*training_pct*training_fee/12 | I7: =SUM(C7:H7)
A8: Audit fees | B8: M VND | C8: =pilot_count*audit_fee/12 | D8: =pilot_count*audit_fee/12 | E8: =pilot_count*audit_fee/12 | F8: =pilot_count*audit_fee/12 | G8: =pilot_count*audit_fee/12 | H8: =pilot_count*audit_fee/12 | I8: =SUM(C8:H8)
A9: TOTAL REVENUE | B9: M VND | C9: =SUM(C6:C8) | D9: =SUM(D6:D8) | E9: =SUM(E6:E8) | F9: =SUM(F6:F8) | G9: =SUM(G6:G8) | H9: =SUM(H6:H8) | I9: =SUM(C9:H9)
A11: CAPITAL EXPENDITURE
A12: Cloud infrastructure setup | B12: M VND | C12: =capex_cloud_setup/6 | D12: =capex_cloud_setup/6 | E12: =capex_cloud_setup/6 | F12: =capex_cloud_setup/6 | G12: =capex_cloud_setup/6 | H12: =capex_cloud_setup/6 | I12: =SUM(C12:H12)
A13: Backend development | B13: M VND | C13: =capex_backend/6 | D13: =capex_backend/6 | E13: =capex_backend/6 | F13: =capex_backend/6 | G13: =capex_backend/6 | H13: =capex_backend/6 | I13: =SUM(C13:H13)
A14: Frontend + mobile | B14: M VND | C14: =capex_frontend/6 | D14: =capex_frontend/6 | E14: =capex_frontend/6 | F14: =capex_frontend/6 | G14: =capex_frontend/6 | H14: =capex_frontend/6 | I14: =SUM(C14:H14)
A15: Data platform | B15: M VND | C15: =capex_data_platform/6 | D15: =capex_data_platform/6 | E15: =capex_data_platform/6 | F15: =capex_data_platform/6 | G15: =capex_data_platform/6 | H15: =capex_data_platform/6 | I15: =SUM(C15:H15)
A16: Security infrastructure | B16: M VND | C16: =capex_security_setup/6 | D16: =capex_security_setup/6 | E16: =capex_security_setup/6 | F16: =capex_security_setup/6 | G16: =capex_security_setup/6 | H16: =capex_security_setup/6 | I16: =SUM(C16:H16)
A17: UX/UI design | B17: M VND | C17: =capex_ux_design/6 | D17: =capex_ux_design/6 | E17: =capex_ux_design/6 | F17: =capex_ux_design/6 | G17: =capex_ux_design/6 | H17: =capex_ux_design/6 | I17: =SUM(C17:H17)
A18: 3rd-party integrations | B18: M VND | C18: =capex_integration/6 | D18: =capex_integration/6 | E18: =capex_integration/6 | F18: =capex_integration/6 | G18: =capex_integration/6 | H18: =capex_integration/6 | I18: =SUM(C18:H18)
A19: DevOps & CI/CD | B19: M VND | C19: =capex_devops/6 | D19: =capex_devops/6 | E19: =capex_devops/6 | F19: =capex_devops/6 | G19: =capex_devops/6 | H19: =capex_devops/6 | I19: =SUM(C19:H19)
A20: QA & testing | B20: M VND | C20: =capex_testing/6 | D20: =capex_testing/6 | E20: =capex_testing/6 | F20: =capex_testing/6 | G20: =capex_testing/6 | H20: =capex_testing/6 | I20: =SUM(C20:H20)
A21: CAPEX contingency | B21: M VND | C21: =capex_contingency/6 | D21: =capex_contingency/6 | E21: =capex_contingency/6 | F21: =capex_contingency/6 | G21: =capex_contingency/6 | H21: =capex_contingency/6 | I21: =SUM(C21:H21)
A22: TOTAL CAPEX | B22: M VND | C22: =SUM(C12:C21) | D22: =SUM(D12:D21) | E22: =SUM(E12:E21) | F22: =SUM(F12:F21) | G22: =SUM(G12:G21) | H22: =SUM(H12:H21) | I22: =SUM(C22:H22)
A24: OPERATING EXPENDITURE
A25: HR — Management (2 FTE) | B25: M VND | C25: =2*salary_mgmt*(1+salary_escalation)^0*(1+bhxh_rate) | D25: =2*salary_mgmt*(1+salary_escalation)^0*(1+bhxh_rate) | E25: =2*salary_mgmt*(1+salary_escalation)^0*(1+bhxh_rate) | F25: =2*salary_mgmt*(1+salary_escalation)^0*(1+bhxh_rate) | G25: =2*salary_mgmt*(1+salary_escalation)^0*(1+bhxh_rate) | H25: =2*salary_mgmt*(1+salary_escalation)^0*(1+bhxh_rate) | I25: =SUM(C25:H25)
A26: HR — Development (12 FTE) | B26: M VND | C26: =12*salary_dev*(1+salary_escalation)^0*(1+bhxh_rate) | D26: =12*salary_dev*(1+salary_escalation)^0*(1+bhxh_rate) | E26: =12*salary_dev*(1+salary_escalation)^0*(1+bhxh_rate) | F26: =12*salary_dev*(1+salary_escalation)^0*(1+bhxh_rate) | G26: =12*salary_dev*(1+salary_escalation)^0*(1+bhxh_rate) | H26: =12*salary_dev*(1+salary_escalation)^0*(1+bhxh_rate) | I26: =SUM(C26:H26)
A27: HR — Biz Ops (2 FTE) | B27: M VND | C27: =2*salary_bizops*(1+salary_escalation)^0*(1+bhxh_rate) | D27: =2*salary_bizops*(1+salary_escalation)^0*(1+bhxh_rate) | E27: =2*salary_bizops*(1+salary_escalation)^0*(1+bhxh_rate) | F27: =2*salary_bizops*(1+salary_escalation)^0*(1+bhxh_rate) | G27: =2*salary_bizops*(1+salary_escalation)^0*(1+bhxh_rate) | H27: =2*salary_bizops*(1+salary_escalation)^0*(1+bhxh_rate) | I27: =SUM(C27:H27)
A28: HR — Data (0 FTE) | B28: M VND | C28: =0*salary_data*(1+salary_escalation)^0*(1+bhxh_rate) | D28: =0*salary_data*(1+salary_escalation)^0*(1+bhxh_rate) | E28: =0*salary_data*(1+salary_escalation)^0*(1+bhxh_rate) | F28: =0*salary_data*(1+salary_escalation)^0*(1+bhxh_rate) | G28: =0*salary_data*(1+salary_escalation)^0*(1+bhxh_rate) | H28: =0*salary_data*(1+salary_escalation)^0*(1+bhxh_rate) | I28: =SUM(C28:H28)
A29: Recruitment | B29: M VND | C29: =16*30*12*recruit_cost_pct | D29: =0 | E29: =0 | F29: =0 | G29: =0 | H29: =0 | I29: =SUM(C29:H29)
A30: Marketing | B30: M VND | C30: =opex_marketing*(1+marketing_growth)^0/12 | D30: =opex_marketing*(1+marketing_growth)^0/12 | E30: =opex_marketing*(1+marketing_growth)^0/12 | F30: =opex_marketing*(1+marketing_growth)^0/12 | G30: =opex_marketing*(1+marketing_growth)^0/12 | H30: =opex_marketing*(1+marketing_growth)^0/12 | I30: =SUM(C30:H30)
A31: Branding & events | B31: M VND | C31: =opex_branding/12 | D31: =opex_branding/12 | E31: =opex_branding/12 | F31: =opex_branding/12 | G31: =opex_branding/12 | H31: =opex_branding/12 | I31: =SUM(C31:H31)
A32: Cloud & infra | B32: M VND | C32: =opex_cloud_base/12 | D32: =opex_cloud_base/12 | E32: =opex_cloud_base/12 | F32: =opex_cloud_base/12 | G32: =opex_cloud_base/12 | H32: =opex_cloud_base/12 | I32: =SUM(C32:H32)
A33: Security | B33: M VND | C33: =opex_security/12 | D33: =opex_security/12 | E33: =opex_security/12 | F33: =opex_security/12 | G33: =opex_security/12 | H33: =opex_security/12 | I33: =SUM(C33:H33)
A34: External affairs | B34: M VND | C34: =opex_external/12 | D34: =opex_external/12 | E34: =opex_external/12 | F34: =opex_external/12 | G34: =opex_external/12 | H34: =opex_external/12 | I34: =SUM(C34:H34)
A35: Legal & compliance | B35: M VND | C35: =opex_legal/12 | D35: =opex_legal/12 | E35: =opex_legal/12 | F35: =opex_legal/12 | G35: =opex_legal/12 | H35: =opex_legal/12 | I35: =SUM(C35:H35)
A36: Pilot evaluation | B36: M VND | C36: =opex_pilot_eval/6 | D36: =opex_pilot_eval/6 | E36: =opex_pilot_eval/6 | F36: =opex_pilot_eval/6 | G36: =opex_pilot_eval/6 | H36: =opex_pilot_eval/6 | I36: =SUM(C36:H36)
A37: Partner management | B37: M VND | C37: =opex_partner_mgmt/12 | D37: =opex_partner_mgmt/12 | E37: =opex_partner_mgmt/12 | F37: =opex_partner_mgmt/12 | G37: =opex_partner_mgmt/12 | H37: =opex_partner_mgmt/12 | I37: =SUM(C37:H37)
A38: Customer support | B38: M VND | C38: =pilot_count*opex_support_per_ent/12 | D38: =pilot_count*opex_support_per_ent/12 | E38: =pilot_count*opex_support_per_ent/12 | F38: =pilot_count*opex_support_per_ent/12 | G38: =pilot_count*opex_support_per_ent/12 | H38: =pilot_count*opex_support_per_ent/12 | I38: =SUM(C38:H38)
A39: OPEX Subtotal | B39: M VND | C39: =SUM(C25:C38) | D39: =SUM(D25:D38) | E39: =SUM(E25:E38) | F39: =SUM(F25:F38) | G39: =SUM(G25:G38) | H39: =SUM(H25:H38) | I39: =SUM(C39:H39)
A40: Contingency (% of OPEX) | B40: M VND | C40: =C39*opex_contingency_pct | D40: =D39*opex_contingency_pct | E40: =E39*opex_contingency_pct | F40: =F39*opex_contingency_pct | G40: =G39*opex_contingency_pct | H40: =H39*opex_contingency_pct | I40: =SUM(C40:H40)
A41: TOTAL OPEX (incl. contingency) | B41: M VND | C41: =C39+C40 | D41: =D39+D40 | E41: =E39+E40 | F41: =F39+F40 | G41: =G39+G40 | H41: =H39+H40 | I41: =SUM(C41:H41)
A43: BUDGET SUMMARY
A44: Total Revenue | B44: M VND | C44: =C9 | D44: =D9 | E44: =E9 | F44: =F9 | G44: =G9 | H44: =H9 | I44: =SUM(C44:H44)
...

Sheet Budget 2026
A1: BUDGET 2026 — MONTHLY DETAIL (M VND)
A2: Approval-ready budget. Yellow cells = adjustable items.
A4: Budget Item | B4: Unit | C4: Jan | D4: Feb | E4: Mar | F4: Apr | G4: May | H4: Jun | I4: Jul | J4: Aug | K4: Sep | L4: Oct | M4: Nov | N4: Dec | O4: TOTAL
A5: REVENUE
