Workbook

Sheet Dashboard
A1: VISIT VIETNAM — FINANCIAL MODEL DASHBOARD
A3: KEY METRICS
A4: NPV | C4: IRR | E4: CIT Rate | G4: Discount Rate
A5: ='DCF & Returns'!B13 -> 241386.37 | C5: ='DCF & Returns'!B14 -> 2.2298519 | E5: =Assumptions!$B$60 -> 0.2 | G5: =Assumptions!$B$61 -> 0.12
A6: M VND | E6: Applied | G6: WACC
A8: ANNUAL SUMMARY (M VND)
A9: Metric | B9: H2 2025 | C9: 2026 | D9: 2027 | E9: 2028 | F9: 2029 | G9: 2030
A10: Revenue | B10: =SUM('P&L'!C4:H4) -> 4014.7647 | C10: =SUM('P&L'!I4:T4) -> 48731.32 | D10: =SUM('P&L'!U4:AF4) -> 96476.21 | E10: =SUM('P&L'!AG4:AJ4) -> 151312.28 | F10: =SUM('P&L'!AK4:AN4) -> 198198.58 | G10: =SUM('P&L'!AO4:AR4) -> 228166.09
A11: COGS | B11: =SUM('P&L'!C5:H5) -> 0 | C11: =SUM('P&L'!I5:T5) -> -668.25 | D11: =SUM('P&L'!U5:AF5) -> -962.28 | E11: =SUM('P&L'!AG5:AJ5) -> -1039.2624 | F11: =SUM('P&L'!AK5:AN5) -> -1122.4034 | G11: =SUM('P&L'!AO5:AR5) -> -1212.1957
A12: Gross Profit | B12: =SUM('P&L'!C6:H6) -> 4014.7647 | C12: =SUM('P&L'!I6:T6) -> 48063.07 | D12: =SUM('P&L'!U6:AF6) -> 95513.93 | E12: =SUM('P&L'!AG6:AJ6) -> 150273.02 | F12: =SUM('P&L'!AK6:AN6) -> 197076.18 | G12: =SUM('P&L'!AO6:AR6) -> 226953.89
A13: OPEX | B13: =SUM('P&L'!C8:H8) -> -11975.332 | C13: =SUM('P&L'!I8:T8) -> -26007.656 | D13: =SUM('P&L'!U8:AF8) -> -32470.569 | E13: =SUM('P&L'!AG8:AJ8) -> -41899.766 | F13: =SUM('P&L'!AK8:AN8) -> -54632.907 | G13: =SUM('P&L'!AO8:AR8) -> -65957.884
A14: EBITDA | B14: =SUM('P&L'!C9:H9) -> -7960.567 | C14: =SUM('P&L'!I9:T9) -> 22055.414 | D14: =SUM('P&L'!U9:AF9) -> 63043.361 | E14: =SUM('P&L'!AG9:AJ9) -> 108373.26 | F14: =SUM('P&L'!AK9:AN9) -> 142443.27 | G14: =SUM('P&L'!AO9:AR9) -> 160996.01
A15: Tax (CIT 20%) | B15: =SUM('P&L'!C12:H12) -> 0 | C15: =SUM('P&L'!I12:T12) -> -4978.6302 | D15: =SUM('P&L'!U12:AF12) -> -12397.472 | E15: =SUM('P&L'!AG12:AJ12) -> -21463.451 | F15: =SUM('P&L'!AK12:AN12) -> -28277.454 | G15: =SUM('P&L'!AO12:AR12) -> -32199.202
A16: Net Income | B16: =SUM('P&L'!C13:H13) -> -8488.567 | C16: =SUM('P&L'!I13:T13) -> 16020.784 | D16: =SUM('P&L'!U13:AF13) -> 49589.889 | E16: =SUM('P&L'!AG13:AJ13) -> 85853.805 | F16: =SUM('P&L'!AK13:AN13) -> 113109.81 | G16: =SUM('P&L'!AO13:AR13) -> 128796.81
A17: Free Cash Flow | B17: =SUM('Cash Flow'!C14:H14) -> -13343.279 | C17: =SUM('Cash Flow'!I14:T14) -> 15512.11 | D17: =SUM('Cash Flow'!U14:AF14) -> 49201.635 | E17: =SUM('Cash Flow'!AG14:AJ14) -> 81985.998 | F17: =SUM('Cash Flow'!AK14:AN14) -> 112007.26 | G17: =SUM('Cash Flow'!AO14:AR14) -> 127095.95
A18: Cumulative CF | B18: ='Cash Flow'!H15 -> -13343.279 | C18: ='Cash Flow'!T15 -> 2168.8305 | D18: ='Cash Flow'!AF15 -> 51370.465 | E18: ='Cash Flow'!AJ15 -> 133356.46 | F18: ='Cash Flow'!AN15 -> 245363.73 | G18: ='Cash Flow'!AR15 -> 372459.68
A19: Net enterprises | B19: ='Market Sizing'!H12 -> 224.65868 | C19: ='Market Sizing'!T12 -> 634.69703 | D19: ='Market Sizing'!AF12 -> 1407.3617 | E19: ='Market Sizing'!AJ12 -> 2139.3247 | F19: ='Market Sizing'!AN12 -> 2611.9516 | G19: ='Market Sizing'!AR12 -> 2798.6934

Sheet Assumptions
A1: VISIT VIETNAM — FINANCIAL MODEL ASSUMPTIONS
A2: All yellow cells are editable placeholders. Change values to update the entire model.
A4: MARKET DATA
A5: Parameter | B5: Value | C5: Unit | D5: Notes
A6: Total tourism enterprises in Vietnam | B6: 40000 | D6: GSO/VNAT statistics
A7: Digitally active / certifiable subset | B7: 15000 | D7: Industry reports
A8: E-commerce tourism market (2025) | B8: 82500 | C8: Bn VND | D8: e-Conomy SEA
A9: E-tourism market YoY growth | B9: 0.08 | C9: % | D9: Historical 2020-2025
A10: Existing competitors' combined share | B10: 0.6 | C10: % | D10: Desk research
A12: ADOPTION S-CURVE PARAMETERS
A13: Parameter | B13: Value | C13: Unit | D13: Notes
A14: Maximum enterprises (ceiling) | B14: 3000 | D14: S-curve asymptote
A15: Midpoint year (fastest growth) | B15: 2028 | C15: Year | D15: Inflection point
A16: Steepness factor | B16: 1.2 | D16: Higher = steeper curve
A17: Starting enterprises (H2 2025) | B17: 15 | D17: Pilot partners
A18: Annual non-renewal rate | B18: 0.15 | C18: % | D18: Certification churn
A20: PRICING
A21: Parameter | B21: Value | C21: Unit | D21: Notes
A22: Certification fee per enterprise/yr | B22: 30 | C22: M VND | D22: Annual subscription
A23: Cert fee annual price increase | B23: 0.08 | C23: % | D23: Reduced from old 15%
A24: Transaction fee (% of GMV) | B24: 0.02 | C24: % | D24: Platform commission
A25: % of e-tourism GMV via VV | B25: 0.02 | C25: % | D25: Realistic; was 25%
A26: DaaS price per million VCR | B26: 50 | C26: M VND | D26: Data subscription
A27: Advertising CPM | B27: 150 | C27: K VND | D27: B2B travel benchmark
A28: Monthly ad impressions (K) | B28: 500 | C28: K | D28: Grows with traffic
A29: Training/consulting fee per engagement | B29: 15 | C29: M VND | D29: NEW stream
A30: Per-certification audit fee | B30: 10 | C30: M VND | D30: NEW stream
A31: % enterprises buying training | B31: 0.3 | C31: % | D31: Estimated
A32: Audits per enterprise per year | B32: 1 | D32: Annual cycle
A34: COST PARAMETERS
A35: Parameter | B35: Value | C35: Unit | D35: Notes
A36: Platform development (MVP) | B36: 5280 | C36: M VND | D36: Current Excel data
A37: Annual maintenance (% of CAPEX) | B37: 0.18 | C37: % | D37: Industry std 15-20%
A38: Marketing & communications (annual) | B38: 6000 | C38: M VND | D38: Current data
A39: Cloud & licenses (base annual) | B39: 3250 | C39: M VND | D39: Current data
A40: Cloud cost per million VCR | B40: 5 | C40: M VND | D40: Scales with traffic
A41: External affairs (annual) | B41: 400 | C41: M VND | D41: Current data
A42: Legal & compliance (annual) | B42: 240 | C42: M VND | D42: Current data
A43: Pilot evaluation (Y1 only) | B43: 200 | C43: M VND | D43: One-time
A44: Payment gateway fee (% tx rev) | B44: 0.025 | C44: % | D44: COGS for transactions
...

Sheet Market Sizing
A1: MARKET SIZING & ADOPTION
A3: Metric | B3: Unit | C3: Jul 2025 | D3: Aug 2025 | E3: Sep 2025 | F3: Oct 2025 | G3: Nov 2025 | H3: Dec 2025 | I3: Jan 2026 | J3: Feb 2026 | K3: Mar 2026 | L3: Apr 2026 | M3: May 2026 | N3: Jun 2026 | O3: Jul 2026 | P3: Aug 2026 | Q3: Sep 2026 | R3: Oct 2026 | S3: Nov 2026 | T3: Dec 2026 | U3: Jan 2027 | V3: Feb 2027 | W3: Mar 2027 | X3: Apr 2027 | Y3: May 2027 | Z3: Jun 2027 | AA3: Jul 2027 | AB3: Aug 2027 | AC3: Sep 2027 | AD3: Oct 2027 | AE3: Nov 2027 | AF3: Dec 2027 | AG3: Q1 2028 | AH3: Q2 2028 | AI3: Q3 2028 | AJ3: Q4 2028 | AK3: Q1 2029 | AL3: Q2 2029 | AM3: Q3 2029 | AN3: Q4 2029 | AO3: Q1 2030 | AP3: Q2 2030 | AQ3: Q3 2030 | AR3: Q4 2030
A4: Market Size
A5: TAM (total enterprises) | B5: count | C5: =Assumptions!$B$6 -> 40000 | D5: =Assumptions!$B$6 -> 40000 | E5: =Assumptions!$B$6 -> 40000 | F5: =Assumptions!$B$6 -> 40000 | G5: =Assumptions!$B$6 -> 40000 | H5: =Assumptions!$B$6 -> 40000 | I5: =Assumptions!$B$6 -> 40000 | J5: =Assumptions!$B$6 -> 40000 | ... AR5: =Assumptions!$B$6 -> 40000
A6: SAM (serviceable) | B6: count | C6: =Assumptions!$B$7 -> 15000 | D6: =Assumptions!$B$7 -> 15000 | E6: =Assumptions!$B$7 -> 15000 | F6: =Assumptions!$B$7 -> 15000 | G6: =Assumptions!$B$7 -> 15000 | H6: =Assumptions!$B$7 -> 15000 | I6: =Assumptions!$B$7 -> 15000 | J6: =Assumptions!$B$7 -> 15000 | ... AR6: =Assumptions!$B$7 -> 15000
A7: E-commerce tourism market | B7: Bn VND | C7: =Assumptions!$B$8*(1+Assumptions!$B$9)^0/12 -> 6875 | D7: =Assumptions!$B$8*(1+Assumptions!$B$9)^0/12 -> 6875 | E7: =Assumptions!$B$8*(1+Assumptions!$B$9)^0/12 -> 6875 | F7: =Assumptions!$B$8*(1+Assumptions!$B$9)^0/12 -> 6875 | G7: =Assumptions!$B$8*(1+Assumptions!$B$9)^0/12 -> 6875 | H7: =Assumptions!$B$8*(1+Assumptions!$B$9)^0/12 -> 6875 | I7: =Assumptions!$B$8*(1+Assumptions!$B$9)^1/12 -> 7425 | J7: =Assumptions!$B$8*(1+Assumptions!$B$9)^1/12 -> 7425 | K7: =Assumptions!$B$8*(1+Assumptions!$B$9)^1/12 -> 7425 | L7: =Assumptions!$B$8*(1+Assumptions!$B$9)^1/12 -> 7425 | M7: =Assumptions!$B$8*(1+Assumptions!$B$9)^1/12 -> 7425 | N7: =Assumptions!$B$8*(1+Assumptions!$B$9)^1/12 -> 7425 | O7: =Assumptions!$B$8*(1+Assumptions!$B$9)^1/12 -> 7425 | P7: =Assumptions!$B$8*(1+Assumptions!$B$9)^1/12 -> 7425 | ... T7: =Assumptions!$B$8*(1+Assumptions!$B$9)^1/12 -> 7425 | U7: =Assumptions!$B$8*(1+Assumptions!$B$9)^2/12 -> 8019 | V7: =Assumptions!$B$8*(1+Assumptions!$B$9)^2/12 -> 8019 | W7: =Assumptions!$B$8*(1+Assumptions!$B$9)^2/12 -> 8019 | X7: =Assumptions!$B$8*(1+Assumptions!$B$9)^2/12 -> 8019 | Y7: =Assumptions!$B$8*(1+Assumptions!$B$9)^2/12 -> 8019 | Z7: =Assumptions!$B$8*(1+Assumptions!$B$9)^2/12 -> 8019 | AA7: =Assumptions!$B$8*(1+Assumptions!$B$9)^2/12 -> 8019 | AB7: =Assumptions!$B$8*(1+Assumptions!$B$9)^2/12 -> 8019 | ... AF7: =Assumptions!$B$8*(1+Assumptions!$B$9)^2/12 -> 8019 | AG7: =Assumptions!$B$8*(1+Assumptions!$B$9)^3/4 -> 25981.56 | AH7: =Assumptions!$B$8*(1+Assumptions!$B$9)^3/4 -> 25981.56 | AI7: =Assumptions!$B$8*(1+Assumptions!$B$9)^3/4 -> 25981.56 | AJ7: =Assumptions!$B$8*(1+Assumptions!$B$9)^3/4 -> 25981.56 | AK7: =Assumptions!$B$8*(1+Assumptions!$B$9)^4/4 -> 28060.085 | AL7: =Assumptions!$B$8*(1+Assumptions!$B$9)^4/4 -> 28060.085 | AM7: =Assumptions!$B$8*(1+Assumptions!$B$9)^4/4 -> 28060.085 | AN7: =Assumptions!$B$8*(1+Assumptions!$B$9)^4/4 -> 28060.085 | AO7: =Assumptions!$B$8*(1+Assumptions!$B$9)^5/4 -> 30304.892 | AP7: =Assumptions!$B$8*(1+Assumptions!$B$9)^5/4 -> 30304.892 | AQ7: =Assumptions!$B$8*(1+Assumptions!$B$9)^5/4 -> 30304.892 | AR7: =Assumptions!$B$8*(1+Assumptions!$B$9)^5/4 -> 30304.892
A9: Enterprise Adoption (S-Curve)
A10: Gross enterprises (S-curve) | B10: count | C10: =MAX(Assumptions!$B$17,Assumptions!$B$14/(1+EXP(-Assumptions!$B$16*(2025.5-Assumptions!$B$15)))) -> 142.27762 | D10: =MAX(Assumptions!$B$17,Assumptions!$B$14/(1+EXP(-Assumptions!$B$16*(2025.583-Assumptions!$B$15)))) -> 156.40138 | E10: =MAX(Assumptions!$B$17,Assumptions!$B$14/(1+EXP(-Assumptions!$B$16*(2025.667-Assumptions!$B$15)))) -> 172.03738 | F10: =MAX(Assumptions!$B$17,Assumptions!$B$14/(1+EXP(-Assumptions!$B$16*(2025.75-Assumptions!$B$15)))) -> 188.92007 | G10: =MAX(Assumptions!$B$17,Assumptions!$B$14/(1+EXP(-Assumptions!$B$16*(2025.833-Assumptions!$B$15)))) -> 207.33804 | H10: =MAX(Assumptions!$B$17,Assumptions!$B$14/(1+EXP(-Assumptions!$B$16*(2025.917-Assumptions!$B$15)))) -> 227.65868 | I10: =MAX(Assumptions!$B$17,Assumptions!$B$14/(1+EXP(-Assumptions!$B$16*(2026-Assumptions!$B$15)))) -> 249.51809 | J10: =MAX(Assumptions!$B$17,Assumptions!$B$14/(1+EXP(-Assumptions!$B$16*(2026.083-Assumptions!$B$15)))) -> 273.26952 | K10: =MAX(Assumptions!$B$17,Assumptions!$B$14/(1+EXP(-Assumptions!$B$16*(2026.167-Assumptions!$B$15)))) -> 299.35925 | L10: =MAX(Assumptions!$B$17,Assumptions!$B$14/(1+EXP(-Assumptions!$B$16*(2026.25-Assumptions!$B$15)))) -> 327.29046 | M10: =MAX(Assumptions!$B$17,Assumptions!$B$14/(1+EXP(-Assumptions!$B$16*(2026.333-Assumptions!$B$15)))) -> 357.48279 | N10: =MAX(Assumptions!$B$17,Assumptions!$B$14/(1+EXP(-Assumptions!$B$16*(2026.417-Assumptions!$B$15)))) -> 390.46126 | O10: =MAX(Assumptions!$B$17,Assumptions!$B$14/(1+EXP(-Assumptions!$B$16*(2026.5-Assumptions!$B$15)))) -> 425.55319 | P10: =MAX(Assumptions!$B$17,Assumptions!$B$14/(1+EXP(-Assumptions!$B$16*(2026.583-Assumptions!$B$15)))) -> 463.23909 | Q10: =MAX(Assumptions!$B$17,Assumptions!$B$14/(1+EXP(-Assumptions!$B$16*(2026.667-Assumptions!$B$15)))) -> 504.11258 | R10: =MAX(Assumptions!$B$17,Assumptions!$B$14/(1+EXP(-Assumptions!$B$16*(2026.75-Assumptions!$B$15)))) -> 547.27657 | S10: =MAX(Assumptions!$B$17,Assumptions!$B$14/(1+EXP(-Assumptions!$B$16*(2026.833-Assumptions!$B$15)))) -> 593.25794 | T10: =MAX(Assumptions!$B$17,Assumptions!$B$14/(1+EXP(-Assumptions!$B$16*(2026.917-Assumptions!$B$15)))) -> 642.69703 | U10: =MAX(Assumptions!$B$17,Assumptions!$B$14/(1+EXP(-Assumptions!$B$16*(2027-Assumptions!$B$15)))) -> 694.42565 | V10: =MAX(Assumptions!$B$17,Assumptions!$B$14/(1+EXP(-Assumptions!$B$16*(2027.083-Assumptions!$B$15)))) -> 748.99486 | W10: =MAX(Assumptions!$B$17,Assumptions!$B$14/(1+EXP(-Assumptions!$B$16*(2027.167-Assumptions!$B$15)))) -> 807.06022 | X10: =MAX(Assumptions!$B$17,Assumptions!$B$14/(1+EXP(-Assumptions!$B$16*(2027.25-Assumptions!$B$15)))) -> 867.15149 | Y10: =MAX(Assumptions!$B$17,Assumptions!$B$14/(1+EXP(-Assumptions!$B$16*(2027.333-Assumptions!$B$15)))) -> 929.81988 | Z10: =MAX(Assumptions!$B$17,Assumptions!$B$14/(1+EXP(-Assumptions!$B$16*(2027.417-Assumptions!$B$15)))) -> 995.70276 | AA10: =MAX(Assumptions!$B$17,Assumptions!$B$14/(1+EXP(-Assumptions!$B$16*(2027.5-Assumptions!$B$15)))) -> 1063.0311 | AB10: =MAX(Assumptions!$B$17,Assumptions!$B$14/(1+EXP(-Assumptions!$B$16*(2027.583-Assumptions!$B$15)))) -> 1132.34 | AC10: =MAX(Assumptions!$B$17,Assumptions!$B$14/(1+EXP(-Assumptions!$B$16*(2027.667-Assumptions!$B$15)))) -> 1204.2253 | AD10: =MAX(Assumptions!$B$17,Assumptions!$B$14/(1+EXP(-Assumptions!$B$16*(2027.75-Assumptions!$B$15)))) -> 1276.6724 | AE10: =MAX(Assumptions!$B$17,Assumptions!$B$14/(1+EXP(-Assumptions!$B$16*(2027.833-Assumptions!$B$15)))) -> 1350.201 | AF10: =MAX(Assumptions!$B$17,Assumptions!$B$14/(1+EXP(-Assumptions!$B$16*(2027.917-Assumptions!$B$15)))) -> 1425.3617 | AG10: =MAX(Assumptions!$B$17,Assumptions!$B$14/(1+EXP(-Assumptions!$B$16*(2028.125-Assumptions!$B$15)))) -> 1612.2895 | AH10: =MAX(Assumptions!$B$17,Assumptions!$B$14/(1+EXP(-Assumptions!$B$16*(2028.375-Assumptions!$B$15)))) -> 1831.9177 | AI10: =MAX(Assumptions!$B$17,Assumptions!$B$14/(1+EXP(-Assumptions!$B$16*(2028.625-Assumptions!$B$15)))) -> 2037.5361 | AJ10: =MAX(Assumptions!$B$17,Assumptions!$B$14/(1+EXP(-Assumptions!$B$16*(2028.875-Assumptions!$B$15)))) -> 2222.3247 | AK10: =MAX(Assumptions!$B$17,Assumptions!$B$14/(1+EXP(-Assumptions!$B$16*(2029.125-Assumptions!$B$15)))) -> 2382.3889 | AL10: =MAX(Assumptions!$B$17,Assumptions!$B$14/(1+EXP(-Assumptions!$B$16*(2029.375-Assumptions!$B$15)))) -> 2516.6732 | AM10: =MAX(Assumptions!$B$17,Assumptions!$B$14/(1+EXP(-Assumptions!$B$16*(2029.625-Assumptions!$B$15)))) -> 2626.3399 | AN10: =MAX(Assumptions!$B$17,Assumptions!$B$14/(1+EXP(-Assumptions!$B$16*(2029.875-Assumptions!$B$15)))) -> 2713.9516 | AO10: =MAX(Assumptions!$B$17,Assumptions!$B$14/(1+EXP(-Assumptions!$B$16*(2030.125-Assumptions!$B$15)))) -> 2782.7205 | AP10: =MAX(Assumptions!$B$17,Assumptions!$B$14/(1+EXP(-Assumptions!$B$16*(2030.375-Assumptions!$B$15)))) -> 2835.956 | AQ10: =MAX(Assumptions!$B$17,Assumptions!$B$14/(1+EXP(-Assumptions!$B$16*(2030.625-Assumptions!$B$15)))) -> 2876.7262 | AR10: =MAX(Assumptions!$B$17,Assumptions!$B$14/(1+EXP(-Assumptions!$B$16*(2030.875-Assumptions!$B$15)))) -> 2907.6934
A11: Churned enterprises | B11: count | C11: =0 -> 0 | D11: =ROUND(D10*Assumptions!$B$18/12, 0) -> 2 | E11: =ROUND(E10*Assumptions!$B$18/12, 0) -> 2 | F11: =ROUND(F10*Assumptions!$B$18/12, 0) -> 2 | G11: =ROUND(G10*Assumptions!$B$18/12, 0) -> 3 | H11: =ROUND(H10*Assumptions!$B$18/12, 0) -> 3 | I11: =ROUND(I10*Assumptions!$B$18/12, 0) -> 3 | J11: =ROUND(J10*Assumptions!$B$18/12, 0) -> 3 | K11: =ROUND(K10*Assumptions!$B$18/12, 0) -> 4 | ... AF11: =ROUND(AF10*Assumptions!$B$18/12, 0) -> 18 | AG11: =ROUND(AG10*Assumptions!$B$18/4, 0) -> 60 | AH11: =ROUND(AH10*Assumptions!$B$18/4, 0) -> 69 | AI11: =ROUND(AI10*Assumptions!$B$18/4, 0) -> 76 | AJ11: =ROUND(AJ10*Assumptions!$B$18/4, 0) -> 83 | AK11: =ROUND(AK10*Assumptions!$B$18/4, 0) -> 89 | AL11: =ROUND(AL10*Assumptions!$B$18/4, 0) -> 94 | AM11: =ROUND(AM10*Assumptions!$B$18/4, 0) -> 98 | AN11: =ROUND(AN10*Assumptions!$B$18/4, 0) -> 102 | ... AR11: =ROUND(AR10*Assumptions!$B$18/4, 0) -> 109
A12: Net active enterprises | B12: count | C12: =C10-C11 -> 142.27762 | D12: =D10-D11 -> 154.40138 | E12: =E10-E11 -> 170.03738 | F12: =F10-F11 -> 186.92007 | G12: =G10-G11 -> 204.33804 | H12: =H10-H11 -> 224.65868 | I12: =I10-I11 -> 246.51809 | J12: =J10-J11 -> 270.26952 | ... AR12: =AR10-AR11 -> 2798.6934
A13: New enterprises (period) | B13: count | C13: =C12 -> 142.27762 | D13: =MAX(0,D12-C12) -> 12.12376 | E13: =MAX(0,E12-D12) -> 15.636005 | F13: =MAX(0,F12-E12) -> 16.882683 | G13: =MAX(0,G12-F12) -> 17.417976 | H13: =MAX(0,H12-G12) -> 20.320634 | I13: =MAX(0,I12-H12) -> 21.859411 | J13: =MAX(0,J12-I12) -> 23.751426 | K13: =MAX(0,K12-J12) -> 25.089729 | ... AR13: =MAX(0,AR12-AQ12) -> 29.967257
A14: VCR (visitor records) | B14: M records | C14: =C12*10/1000 -> 1.4227762 | D14: =D12*10/1000 -> 1.5440138 | E14: =E12*10/1000 -> 1.7003738 | F14: =F12*10/1000 -> 1.8692007 | G14: =G12*10/1000 -> 2.0433804 | H14: =H12*10/1000 -> 2.2465868 | I14: =I12*10/1000 -> 2.4651809 | J14: =J12*10/1000 -> 2.7026952 | ... AF14: =AF12*10/1000 -> 14.073617 | AG14: =AG12*10*3/1000 -> 46.568686 | AH14: =AH12*10*3/1000 -> 52.887531 | AI14: =AI12*10*3/1000 -> 58.846083 | AJ14: =AJ12*10*3/1000 -> 64.179741 | AK14: =AK12*10*3/1000 -> 68.801667 | AL14: =AL12*10*3/1000 -> 72.680195 | AM14: =AM12*10*3/1000 -> 75.850198 | AN14: =AN12*10*3/1000 -> 78.358548 | ... AR14: =AR12*10*3/1000 -> 83.960803

Sheet Revenue Schedule
A1: REVENUE SCHEDULE (M VND)
A3: Item | B3: Unit | C3: Jul 2025 | D3: Aug 2025 | E3: Sep 2025 | F3: Oct 2025 | G3: Nov 2025 | H3: Dec 2025 | I3: Jan 2026 | J3: Feb 2026 | K3: Mar 2026 | L3: Apr 2026 | M3: May 2026 | N3: Jun 2026 | O3: Jul 2026 | P3: Aug 2026 | Q3: Sep 2026 | R3: Oct 2026 | S3: Nov 2026 | T3: Dec 2026 | U3: Jan 2027 | V3: Feb 2027 | W3: Mar 2027 | X3: Apr 2027 | Y3: May 2027 | Z3: Jun 2027 | AA3: Jul 2027 | AB3: Aug 2027 | AC3: Sep 2027 | AD3: Oct 2027 | AE3: Nov 2027 | AF3: Dec 2027 | AG3: Q1 2028 | AH3: Q2 2028 | AI3: Q3 2028 | AJ3: Q4 2028 | AK3: Q1 2029 | AL3: Q2 2029 | AM3: Q3 2029 | AN3: Q4 2029 | AO3: Q1 2030 | AP3: Q2 2030 | AQ3: Q3 2030 | AR3: Q4 2030 | AT3: TOTAL
A4: Stage 1 Revenue
A5: Certification fees | B5: M VND | C5: ='Market Sizing'!C12*Assumptions!$B$22*(1+Assumptions!$B$23)^0/12 -> 355.69405 | D5: ='Market Sizing'!D12*Assumptions!$B$22*(1+Assumptions!$B$23)^0/12 -> 386.00345 | E5: ='Market Sizing'!E12*Assumptions!$B$22*(1+Assumptions!$B$23)^0/12 -> 425.09346 | F5: ='Market Sizing'!F12*Assumptions!$B$22*(1+Assumptions!$B$23)^0/12 -> 467.30017 | G5: ='Market Sizing'!G12*Assumptions!$B$22*(1+Assumptions!$B$23)^0/12 -> 510.84511 | H5: ='Market Sizing'!H12*Assumptions!$B$22*(1+Assumptions!$B$23)^0/12 -> 561.6467 | I5: ='Market Sizing'!I12*Assumptions!$B$22*(1+Assumptions!$B$23)^1/12 -> 665.59884 | J5: ='Market Sizing'!J12*Assumptions!$B$22*(1+Assumptions!$B$23)^1/12 -> 729.72769 | K5: ='Market Sizing'!K12*Assumptions!$B$22*(1+Assumptions!$B$23)^1/12 -> 797.46996 | L5: ='Market Sizing'!L12*Assumptions!$B$22*(1+Assumptions!$B$23)^1/12 -> 872.88425 | M5: ='Market Sizing'!M12*Assumptions!$B$22*(1+Assumptions!$B$23)^1/12 -> 954.40354 | N5: ='Market Sizing'!N12*Assumptions!$B$22*(1+Assumptions!$B$23)^1/12 -> 1040.7454 | O5: ='Market Sizing'!O12*Assumptions!$B$22*(1+Assumptions!$B$23)^1/12 -> 1135.4936 | P5: ='Market Sizing'!P12*Assumptions!$B$22*(1+Assumptions!$B$23)^1/12 -> 1234.5455 | ... T5: ='Market Sizing'!T12*Assumptions!$B$22*(1+Assumptions!$B$23)^1/12 -> 1713.682 | U5: ='Market Sizing'!U12*Assumptions!$B$22*(1+Assumptions!$B$23)^2/12 -> 1998.7012 | V5: ='Market Sizing'!V12*Assumptions!$B$22*(1+Assumptions!$B$23)^2/12 -> 2157.825 | W5: ='Market Sizing'!W12*Assumptions!$B$22*(1+Assumptions!$B$23)^2/12 -> 2324.2276 | X5: ='Market Sizing'!X12*Assumptions!$B$22*(1+Assumptions!$B$23)^2/12 -> 2496.5378 | Y5: ='Market Sizing'!Y12*Assumptions!$B$22*(1+Assumptions!$B$23)^2/12 -> 2676.3628 | Z5: ='Market Sizing'!Z12*Assumptions!$B$22*(1+Assumptions!$B$23)^2/12 -> 2868.4772 | AA5: ='Market Sizing'!AA12*Assumptions!$B$22*(1+Assumptions!$B$23)^2/12 -> 3061.8906 | AB5: ='Market Sizing'!AB12*Assumptions!$B$22*(1+Assumptions!$B$23)^2/12 -> 3261.0795 | ... AF5: ='Market Sizing'!AF12*Assumptions!$B$22*(1+Assumptions!$B$23)^2/12 -> 4103.8667 | AG5: ='Market Sizing'!AG12*Assumptions!$B$22*(1+Assumptions!$B$23)^3/4 -> 14665.783 | AH5: ='Market Sizing'!AH12*Assumptions!$B$22*(1+Assumptions!$B$23)^3/4 -> 16655.764 | AI5: ='Market Sizing'!AI12*Assumptions!$B$22*(1+Assumptions!$B$23)^3/4 -> 18532.279 | AJ5: ='Market Sizing'!AJ12*Assumptions!$B$22*(1+Assumptions!$B$23)^3/4 -> 20211.997 | AK5: ='Market Sizing'!AK12*Assumptions!$B$22*(1+Assumptions!$B$23)^4/4 -> 23400.977 | AL5: ='Market Sizing'!AL12*Assumptions!$B$22*(1+Assumptions!$B$23)^4/4 -> 24720.151 | AM5: ='Market Sizing'!AM12*Assumptions!$B$22*(1+Assumptions!$B$23)^4/4 -> 25798.339 | AN5: ='Market Sizing'!AN12*Assumptions!$B$22*(1+Assumptions!$B$23)^4/4 -> 26651.485 | AO5: ='Market Sizing'!AO12*Assumptions!$B$22*(1+Assumptions!$B$23)^5/4 -> 29519.395 | AP5: ='Market Sizing'!AP12*Assumptions!$B$22*(1+Assumptions!$B$23)^5/4 -> 30084.008 | AQ5: ='Market Sizing'!AQ12*Assumptions!$B$22*(1+Assumptions!$B$23)^5/4 -> 30511.253 | AR5: ='Market Sizing'!AR12*Assumptions!$B$22*(1+Assumptions!$B$23)^5/4 -> 30841.491
A6: Training & consulting | B6: M VND | C6: ='Market Sizing'!C12*Assumptions!$B$31*Assumptions!$B$29/12 -> 53.354107 | D6: ='Market Sizing'!D12*Assumptions!$B$31*Assumptions!$B$29/12 -> 57.900517 | E6: ='Market Sizing'!E12*Assumptions!$B$31*Assumptions!$B$29/12 -> 63.764019 | F6: ='Market Sizing'!F12*Assumptions!$B$31*Assumptions!$B$29/12 -> 70.095026 | G6: ='Market Sizing'!G12*Assumptions!$B$31*Assumptions!$B$29/12 -> 76.626767 | H6: ='Market Sizing'!H12*Assumptions!$B$31*Assumptions!$B$29/12 -> 84.247005 | I6: ='Market Sizing'!I12*Assumptions!$B$31*Assumptions!$B$29/12 -> 92.444284 | J6: ='Market Sizing'!J12*Assumptions!$B$31*Assumptions!$B$29/12 -> 101.35107 | ... AF6: ='Market Sizing'!AF12*Assumptions!$B$31*Assumptions!$B$29/12 -> 527.76063 | AG6: ='Market Sizing'!AG12*Assumptions!$B$31*Assumptions!$B$29/4 -> 1746.3257 | AH6: ='Market Sizing'!AH12*Assumptions!$B$31*Assumptions!$B$29/4 -> 1983.2824 | AI6: ='Market Sizing'!AI12*Assumptions!$B$31*Assumptions!$B$29/4 -> 2206.7281 | AJ6: ='Market Sizing'!AJ12*Assumptions!$B$31*Assumptions!$B$29/4 -> 2406.7403 | AK6: ='Market Sizing'!AK12*Assumptions!$B$31*Assumptions!$B$29/4 -> 2580.0625 | AL6: ='Market Sizing'!AL12*Assumptions!$B$31*Assumptions!$B$29/4 -> 2725.5073 | AM6: ='Market Sizing'!AM12*Assumptions!$B$31*Assumptions!$B$29/4 -> 2844.3824 | AN6: ='Market Sizing'!AN12*Assumptions!$B$31*Assumptions!$B$29/4 -> 2938.4456 | ... AR6: ='Market Sizing'!AR12*Assumptions!$B$31*Assumptions!$B$29/4 -> 3148.5301
A7: Audit fees | B7: M VND | C7: ='Market Sizing'!C12*Assumptions!$B$30*Assumptions!$B$32/12 -> 118.56468 | D7: ='Market Sizing'!D12*Assumptions!$B$30*Assumptions!$B$32/12 -> 128.66782 | E7: ='Market Sizing'!E12*Assumptions!$B$30*Assumptions!$B$32/12 -> 141.69782 | F7: ='Market Sizing'!F12*Assumptions!$B$30*Assumptions!$B$32/12 -> 155.76672 | G7: ='Market Sizing'!G12*Assumptions!$B$30*Assumptions!$B$32/12 -> 170.2817 | H7: ='Market Sizing'!H12*Assumptions!$B$30*Assumptions!$B$32/12 -> 187.21557 | I7: ='Market Sizing'!I12*Assumptions!$B$30*Assumptions!$B$32/12 -> 205.43174 | J7: ='Market Sizing'!J12*Assumptions!$B$30*Assumptions!$B$32/12 -> 225.2246 | ... AF7: ='Market Sizing'!AF12*Assumptions!$B$30*Assumptions!$B$32/12 -> 1172.8014 | AG7: ='Market Sizing'!AG12*Assumptions!$B$30*Assumptions!$B$32/4 -> 3880.7238 | AH7: ='Market Sizing'!AH12*Assumptions!$B$30*Assumptions!$B$32/4 -> 4407.2943 | AI7: ='Market Sizing'!AI12*Assumptions!$B$30*Assumptions!$B$32/4 -> 4903.8402 | AJ7: ='Market Sizing'!AJ12*Assumptions!$B$30*Assumptions!$B$32/4 -> 5348.3117 | AK7: ='Market Sizing'!AK12*Assumptions!$B$30*Assumptions!$B$32/4 -> 5733.4722 | AL7: ='Market Sizing'!AL12*Assumptions!$B$30*Assumptions!$B$32/4 -> 6056.6829 | AM7: ='Market Sizing'!AM12*Assumptions!$B$30*Assumptions!$B$32/4 -> 6320.8498 | AN7: ='Market Sizing'!AN12*Assumptions!$B$30*Assumptions!$B$32/4 -> 6529.879 | ... AR7: ='Market Sizing'!AR12*Assumptions!$B$30*Assumptions!$B$32/4 -> 6996.7336
A8: Subtotal Stage 1 | B8: M VND | C8: =SUM(C5:C7) -> 527.61284 | D8: =SUM(D5:D7) -> 572.57178 | E8: =SUM(E5:E7) -> 630.5553 | F8: =SUM(F5:F7) -> 693.16192 | G8: =SUM(G5:G7) -> 757.75358 | H8: =SUM(H5:H7) -> 833.10927 | I8: =SUM(I5:I7) -> 963.47487 | J8: =SUM(J5:J7) -> 1056.3034 | ... AR8: =SUM(AR5:AR7) -> 40986.755
A10: Stage 2 Revenue (gated on enterprise count)
A11: Transaction fees | B11: M VND | C11: =IF('Market Sizing'!C12>=Assumptions!$B$65,'Market Sizing'!C7*Assumptions!$B$25*Assumptions!$B$24*1000,0) -> 0 | D11: =IF('Market Sizing'!D12>=Assumptions!$B$65,'Market Sizing'!D7*Assumptions!$B$25*Assumptions!$B$24*1000,0) -> 0 | E11: =IF('Market Sizing'!E12>=Assumptions!$B$65,'Market Sizing'!E7*Assumptions!$B$25*Assumptions!$B$24*1000,0) -> 0 | F11: =IF('Market Sizing'!F12>=Assumptions!$B$65,'Market Sizing'!F7*Assumptions!$B$25*Assumptions!$B$24*1000,0) -> 0 | G11: =IF('Market Sizing'!G12>=Assumptions!$B$65,'Market Sizing'!G7*Assumptions!$B$25*Assumptions!$B$24*1000,0) -> 0 | H11: =IF('Market Sizing'!H12>=Assumptions!$B$65,'Market Sizing'!H7*Assumptions!$B$25*Assumptions!$B$24*1000,0) -> 0 | I11: =IF('Market Sizing'!I12>=Assumptions!$B$65,'Market Sizing'!I7*Assumptions!$B$25*Assumptions!$B$24*1000,0) -> 0 | J11: =IF('Market Sizing'!J12>=Assumptions!$B$65,'Market Sizing'!J7*Assumptions!$B$25*Assumptions!$B$24*1000,0) -> 0 | ... AR11: =IF('Market Sizing'!AR12>=Assumptions!$B$65,'Market Sizing'!AR7*Assumptions!$B$25*Assumptions!$B$24*1000,0) -> 12121.957
A12: DaaS (data as a service) | B12: M VND | C12: =IF('Market Sizing'!C12>=Assumptions!$B$65,'Market Sizing'!C14*Assumptions!$B$26,0) -> 0 | D12: =IF('Market Sizing'!D12>=Assumptions!$B$65,'Market Sizing'!D14*Assumptions!$B$26,0) -> 0 | E12: =IF('Market Sizing'!E12>=Assumptions!$B$65,'Market Sizing'!E14*Assumptions!$B$26,0) -> 0 | F12: =IF('Market Sizing'!F12>=Assumptions!$B$65,'Market Sizing'!F14*Assumptions!$B$26,0) -> 0 | G12: =IF('Market Sizing'!G12>=Assumptions!$B$65,'Market Sizing'!G14*Assumptions!$B$26,0) -> 0 | H12: =IF('Market Sizing'!H12>=Assumptions!$B$65,'Market Sizing'!H14*Assumptions!$B$26,0) -> 0 | I12: =IF('Market Sizing'!I12>=Assumptions!$B$65,'Market Sizing'!I14*Assumptions!$B$26,0) -> 0 | J12: =IF('Market Sizing'!J12>=Assumptions!$B$65,'Market Sizing'!J14*Assumptions!$B$26,0) -> 0 | ... AR12: =IF('Market Sizing'!AR12>=Assumptions!$B$65,'Market Sizing'!AR14*Assumptions!$B$26,0) -> 4198.0401
A13: Advertising | B13: M VND | C13: =IF('Market Sizing'!C12>=Assumptions!$B$65,Assumptions!$B$28*1*'Market Sizing'!C12/1000*Assumptions!$B$27/1000,0) -> 0 | D13: =IF('Market Sizing'!D12>=Assumptions!$B$65,Assumptions!$B$28*1*'Market Sizing'!D12/1000*Assumptions!$B$27/1000,0) -> 0 | E13: =IF('Market Sizing'!E12>=Assumptions!$B$65,Assumptions!$B$28*1*'Market Sizing'!E12/1000*Assumptions!$B$27/1000,0) -> 0 | F13: =IF('Market Sizing'!F12>=Assumptions!$B$65,Assumptions!$B$28*1*'Market Sizing'!F12/1000*Assumptions!$B$27/1000,0) -> 0 | G13: =IF('Market Sizing'!G12>=Assumptions!$B$65,Assumptions!$B$28*1*'Market Sizing'!G12/1000*Assumptions!$B$27/1000,0) -> 0 | H13: =IF('Market Sizing'!H12>=Assumptions!$B$65,Assumptions!$B$28*1*'Market Sizing'!H12/1000*Assumptions!$B$27/1000,0) -> 0 | I13: =IF('Market Sizing'!I12>=Assumptions!$B$65,Assumptions!$B$28*1*'Market Sizing'!I12/1000*Assumptions!$B$27/1000,0) -> 0 | J13: =IF('Market Sizing'!J12>=Assumptions!$B$65,Assumptions!$B$28*1*'Market Sizing'!J12/1000*Assumptions!$B$27/1000,0) -> 0 | ... AF13: =IF('Market Sizing'!AF12>=Assumptions!$B$65,Assumptions!$B$28*1*'Market Sizing'!AF12/1000*Assumptions!$B$27/1000,0) -> 105.55213 | AG13: =IF('Market Sizing'!AG12>=Assumptions!$B$65,Assumptions!$B$28*3*'Market Sizing'!AG12/1000*Assumptions!$B$27/1000,0) -> 349.26515 | AH13: =IF('Market Sizing'!AH12>=Assumptions!$B$65,Assumptions!$B$28*3*'Market Sizing'!AH12/1000*Assumptions!$B$27/1000,0) -> 396.65648 | AI13: =IF('Market Sizing'!AI12>=Assumptions!$B$65,Assumptions!$B$28*3*'Market Sizing'!AI12/1000*Assumptions!$B$27/1000,0) -> 441.34562 | AJ13: =IF('Market Sizing'!AJ12>=Assumptions!$B$65,Assumptions!$B$28*3*'Market Sizing'!AJ12/1000*Assumptions!$B$27/1000,0) -> 481.34806 | AK13: =IF('Market Sizing'!AK12>=Assumptions!$B$65,Assumptions!$B$28*3*'Market Sizing'!AK12/1000*Assumptions!$B$27/1000,0) -> 516.0125 | AL13: =IF('Market Sizing'!AL12>=Assumptions!$B$65,Assumptions!$B$28*3*'Market Sizing'!AL12/1000*Assumptions!$B$27/1000,0) -> 545.10146 | AM13: =IF('Market Sizing'!AM12>=Assumptions!$B$65,Assumptions!$B$28*3*'Market Sizing'!AM12/1000*Assumptions!$B$27/1000,0) -> 568.87648 | AN13: =IF('Market Sizing'!AN12>=Assumptions!$B$65,Assumptions!$B$28*3*'Market Sizing'!AN12/1000*Assumptions!$B$27/1000,0) -> 587.68911 | ... AR13: =IF('Market Sizing'!AR12>=Assumptions!$B$65,Assumptions!$B$28*3*'Market Sizing'!AR12/1000*Assumptions!$B$27/1000,0) -> 629.70602
A14: Subtotal Stage 2 | B14: M VND | C14: =SUM(C11:C13) -> 0 | D14: =SUM(D11:D13) -> 0 | E14: =SUM(E11:E13) -> 0 | F14: =SUM(F11:F13) -> 0 | G14: =SUM(G11:G13) -> 0 | H14: =SUM(H11:H13) -> 0 | I14: =SUM(I11:I13) -> 0 | J14: =SUM(J11:J13) -> 0 | ... AR14: =SUM(AR11:AR13) -> 16949.703
A16: TOTAL REVENUE | B16: M VND | C16: =C8+C14 -> 527.61284 | D16: =D8+D14 -> 572.57178 | E16: =E8+E14 -> 630.5553 | F16: =F8+F14 -> 693.16192 | G16: =G8+G14 -> 757.75358 | H16: =H8+H14 -> 833.10927 | I16: =I8+I14 -> 963.47487 | J16: =J8+J14 -> 1056.3034 | ... AR16: =AR8+AR14 -> 57936.458
A18: COST OF GOODS SOLD (COGS)
A19: Payment processing fees | B19: M VND | C19: =C11*Assumptions!$B$44 -> 0 | D19: =D11*Assumptions!$B$44 -> 0 | E19: =E11*Assumptions!$B$44 -> 0 | F19: =F11*Assumptions!$B$44 -> 0 | G19: =G11*Assumptions!$B$44 -> 0 | H19: =H11*Assumptions!$B$44 -> 0 | I19: =I11*Assumptions!$B$44 -> 0 | J19: =J11*Assumptions!$B$44 -> 0 | ... AR19: =AR11*Assumptions!$B$44 -> 303.04892
A20: TOTAL COGS | B20: M VND | C20: =C19 -> 0 | D20: =D19 -> 0 | E20: =E19 -> 0 | F20: =F19 -> 0 | G20: =G19 -> 0 | H20: =H19 -> 0 | I20: =I19 -> 0 | J20: =J19 -> 0 | ... AR20: =AR19 -> 303.04892
A22: GROSS PROFIT | B22: M VND | C22: =C16-C20 -> 527.61284 | D22: =D16-D20 -> 572.57178 | E22: =E16-E20 -> 630.5553 | F22: =F16-F20 -> 693.16192 | G22: =G16-G20 -> 757.75358 | H22: =H16-H20 -> 833.10927 | I22: =I16-I20 -> 963.47487 | J22: =J16-J20 -> 1056.3034 | ... AR22: =AR16-AR20 -> 57633.409

Sheet Cost Schedule
A1: COST SCHEDULE (M VND)
A3: Item | B3: Unit | C3: Jul 2025 | D3: Aug 2025 | E3: Sep 2025 | F3: Oct 2025 | G3: Nov 2025 | H3: Dec 2025 | I3: Jan 2026 | J3: Feb 2026 | K3: Mar 2026 | L3: Apr 2026 | M3: May 2026 | N3: Jun 2026 | O3: Jul 2026 | P3: Aug 2026 | Q3: Sep 2026 | R3: Oct 2026 | S3: Nov 2026 | T3: Dec 2026 | U3: Jan 2027 | V3: Feb 2027 | W3: Mar 2027 | X3: Apr 2027 | Y3: May 2027 | Z3: Jun 2027 | AA3: Jul 2027 | AB3: Aug 2027 | AC3: Sep 2027 | AD3: Oct 2027 | AE3: Nov 2027 | AF3: Dec 2027 | AG3: Q1 2028 | AH3: Q2 2028 | AI3: Q3 2028 | AJ3: Q4 2028 | AK3: Q1 2029 | AL3: Q2 2029 | AM3: Q3 2029 | AN3: Q4 2029 | AO3: Q1 2030 | AP3: Q2 2030 | AQ3: Q3 2030 | AR3: Q4 2030 | AT3: TOTAL
A4: CAPITAL EXPENDITURE (CAPEX)
A5: Platform development | B5: M VND | C5: =Assumptions!$B$36/6 -> 880 | D5: =Assumptions!$B$36/6 -> 880 | E5: =Assumptions!$B$36/6 -> 880 | F5: =Assumptions!$B$36/6 -> 880 | G5: =Assumptions!$B$36/6 -> 880 | H5: =Assumptions!$B$36/6 -> 880 | I5: =0 -> 0 | J5: =0 -> 0 | K5: =0 -> 0 | L5: =0 -> 0 | M5: =0 -> 0 | N5: =0 -> 0 | O5: =0 -> 0 | P5: =0 -> 0 | ... AR5: =0 -> 0
A6: Annual maintenance | B6: M VND | C6: =0 -> 0 | D6: =0 -> 0 | E6: =0 -> 0 | F6: =0 -> 0 | G6: =0 -> 0 | H6: =0 -> 0 | I6: =Assumptions!$B$36*Assumptions!$B$37/12 -> 79.2 | J6: =Assumptions!$B$36*Assumptions!$B$37/12 -> 79.2 | K6: =Assumptions!$B$36*Assumptions!$B$37/12 -> 79.2 | L6: =Assumptions!$B$36*Assumptions!$B$37/12 -> 79.2 | M6: =Assumptions!$B$36*Assumptions!$B$37/12 -> 79.2 | N6: =Assumptions!$B$36*Assumptions!$B$37/12 -> 79.2 | O6: =Assumptions!$B$36*Assumptions!$B$37/12 -> 79.2 | P6: =Assumptions!$B$36*Assumptions!$B$37/12 -> 79.2 | ... AF6: =Assumptions!$B$36*Assumptions!$B$37/12 -> 79.2 | AG6: =Assumptions!$B$36*Assumptions!$B$37/4 -> 237.6 | AH6: =Assumptions!$B$36*Assumptions!$B$37/4 -> 237.6 | AI6: =Assumptions!$B$36*Assumptions!$B$37/4 -> 237.6 | AJ6: =Assumptions!$B$36*Assumptions!$B$37/4 -> 237.6 | AK6: =Assumptions!$B$36*Assumptions!$B$37/4 -> 237.6 | AL6: =Assumptions!$B$36*Assumptions!$B$37/4 -> 237.6 | AM6: =Assumptions!$B$36*Assumptions!$B$37/4 -> 237.6 | AN6: =Assumptions!$B$36*Assumptions!$B$37/4 -> 237.6 | ... AR6: =Assumptions!$B$36*Assumptions!$B$37/4 -> 237.6
A7: TOTAL CAPEX | B7: M VND | C7: =C5+C6 -> 880 | D7: =D5+D6 -> 880 | E7: =E5+E6 -> 880 | F7: =F5+F6 -> 880 | G7: =G5+G6 -> 880 | H7: =H5+H6 -> 880 | I7: =I5+I6 -> 79.2 | J7: =J5+J6 -> 79.2 | ... AR7: =AR5+AR6 -> 237.6
A9: OPERATING EXPENDITURE (OPEX)
A10: Human resources (total) | B10: M VND | C10: =16*30*(1+Assumptions!$B$54)^0*(1+Assumptions!$B$55) -> 583.2 | D10: =16*30*(1+Assumptions!$B$54)^0*(1+Assumptions!$B$55) -> 583.2 | E10: =16*30*(1+Assumptions!$B$54)^0*(1+Assumptions!$B$55) -> 583.2 | F10: =16*30*(1+Assumptions!$B$54)^0*(1+Assumptions!$B$55) -> 583.2 | G10: =16*30*(1+Assumptions!$B$54)^0*(1+Assumptions!$B$55) -> 583.2 | H10: =16*30*(1+Assumptions!$B$54)^0*(1+Assumptions!$B$55) -> 583.2 | I10: =22*30*(1+Assumptions!$B$54)^1*(1+Assumptions!$B$55) -> 882.09 | J10: =22*30*(1+Assumptions!$B$54)^1*(1+Assumptions!$B$55) -> 882.09 | K10: =22*30*(1+Assumptions!$B$54)^1*(1+Assumptions!$B$55) -> 882.09 | L10: =22*30*(1+Assumptions!$B$54)^1*(1+Assumptions!$B$55) -> 882.09 | M10: =22*30*(1+Assumptions!$B$54)^1*(1+Assumptions!$B$55) -> 882.09 | N10: =22*30*(1+Assumptions!$B$54)^1*(1+Assumptions!$B$55) -> 882.09 | O10: =22*30*(1+Assumptions!$B$54)^1*(1+Assumptions!$B$55) -> 882.09 | P10: =22*30*(1+Assumptions!$B$54)^1*(1+Assumptions!$B$55) -> 882.09 | ... T10: =22*30*(1+Assumptions!$B$54)^1*(1+Assumptions!$B$55) -> 882.09 | U10: =30*30*(1+Assumptions!$B$54)^2*(1+Assumptions!$B$55) -> 1323.135 | V10: =30*30*(1+Assumptions!$B$54)^2*(1+Assumptions!$B$55) -> 1323.135 | W10: =30*30*(1+Assumptions!$B$54)^2*(1+Assumptions!$B$55) -> 1323.135 | X10: =30*30*(1+Assumptions!$B$54)^2*(1+Assumptions!$B$55) -> 1323.135 | Y10: =30*30*(1+Assumptions!$B$54)^2*(1+Assumptions!$B$55) -> 1323.135 | Z10: =30*30*(1+Assumptions!$B$54)^2*(1+Assumptions!$B$55) -> 1323.135 | AA10: =30*30*(1+Assumptions!$B$54)^2*(1+Assumptions!$B$55) -> 1323.135 | AB10: =30*30*(1+Assumptions!$B$54)^2*(1+Assumptions!$B$55) -> 1323.135 | ... AF10: =30*30*(1+Assumptions!$B$54)^2*(1+Assumptions!$B$55) -> 1323.135 | AG10: =41*30*3*(1+Assumptions!$B$54)^3*(1+Assumptions!$B$55) -> 5967.3389 | AH10: =41*30*3*(1+Assumptions!$B$54)^3*(1+Assumptions!$B$55) -> 5967.3389 | AI10: =41*30*3*(1+Assumptions!$B$54)^3*(1+Assumptions!$B$55) -> 5967.3389 | AJ10: =41*30*3*(1+Assumptions!$B$54)^3*(1+Assumptions!$B$55) -> 5967.3389 | AK10: =55*30*3*(1+Assumptions!$B$54)^4*(1+Assumptions!$B$55) -> 8805.4634 | AL10: =55*30*3*(1+Assumptions!$B$54)^4*(1+Assumptions!$B$55) -> 8805.4634 | AM10: =55*30*3*(1+Assumptions!$B$54)^4*(1+Assumptions!$B$55) -> 8805.4634 | AN10: =55*30*3*(1+Assumptions!$B$54)^4*(1+Assumptions!$B$55) -> 8805.4634 | AO10: =65*30*3*(1+Assumptions!$B$54)^5*(1+Assumptions!$B$55) -> 11447.102 | AP10: =65*30*3*(1+Assumptions!$B$54)^5*(1+Assumptions!$B$55) -> 11447.102 | AQ10: =65*30*3*(1+Assumptions!$B$54)^5*(1+Assumptions!$B$55) -> 11447.102 | AR10: =65*30*3*(1+Assumptions!$B$54)^5*(1+Assumptions!$B$55) -> 11447.102
A11: Recruitment costs | B11: M VND | C11: =16*30*12*Assumptions!$B$56 -> 1152 | D11: =0 -> 0 | E11: =0 -> 0 | F11: =0 -> 0 | G11: =0 -> 0 | H11: =0 -> 0 | I11: =6*30*12*Assumptions!$B$56 -> 432 | J11: =0 -> 0 | K11: =0 -> 0 | L11: =0 -> 0 | M11: =0 -> 0 | N11: =0 -> 0 | O11: =0 -> 0 | P11: =0 -> 0 | Q11: =0 -> 0 | ... W11: =0 -> 0 | X11: =8*30*12*Assumptions!$B$56 -> 576 | Y11: =0 -> 0 | Z11: =0 -> 0 | AA11: =0 -> 0 | AB11: =0 -> 0 | AC11: =0 -> 0 | AD11: =0 -> 0 | AE11: =0 -> 0 | AF11: =0 -> 0 | AG11: =11*30*12*Assumptions!$B$56 -> 792 | AH11: =0 -> 0 | AI11: =0 -> 0 | AJ11: =0 -> 0 | AK11: =14*30*12*Assumptions!$B$56 -> 1008 | AL11: =0 -> 0 | AM11: =0 -> 0 | AN11: =0 -> 0 | AO11: =10*30*12*Assumptions!$B$56 -> 720 | AP11: =0 -> 0 | AQ11: =0 -> 0 | AR11: =0 -> 0
A12: Marketing & communications | B12: M VND | C12: =Assumptions!$B$38*(1+0.1)^0/12 -> 500 | D12: =Assumptions!$B$38*(1+0.1)^0/12 -> 500 | E12: =Assumptions!$B$38*(1+0.1)^0/12 -> 500 | F12: =Assumptions!$B$38*(1+0.1)^0/12 -> 500 | G12: =Assumptions!$B$38*(1+0.1)^0/12 -> 500 | H12: =Assumptions!$B$38*(1+0.1)^0/12 -> 500 | I12: =Assumptions!$B$38*(1+0.1)^1/12 -> 550 | J12: =Assumptions!$B$38*(1+0.1)^1/12 -> 550 | K12: =Assumptions!$B$38*(1+0.1)^1/12 -> 550 | L12: =Assumptions!$B$38*(1+0.1)^1/12 -> 550 | M12: =Assumptions!$B$38*(1+0.1)^1/12 -> 550 | N12: =Assumptions!$B$38*(1+0.1)^1/12 -> 550 | O12: =Assumptions!$B$38*(1+0.1)^1/12 -> 550 | P12: =Assumptions!$B$38*(1+0.1)^1/12 -> 550 | ... T12: =Assumptions!$B$38*(1+0.1)^1/12 -> 550 | U12: =Assumptions!$B$38*(1+0.1)^2/12 -> 605 | V12: =Assumptions!$B$38*(1+0.1)^2/12 -> 605 | W12: =Assumptions!$B$38*(1+0.1)^2/12 -> 605 | X12: =Assumptions!$B$38*(1+0.1)^2/12 -> 605 | Y12: =Assumptions!$B$38*(1+0.1)^2/12 -> 605 | Z12: =Assumptions!$B$38*(1+0.1)^2/12 -> 605 | AA12: =Assumptions!$B$38*(1+0.1)^2/12 -> 605 | AB12: =Assumptions!$B$38*(1+0.1)^2/12 -> 605 | ... AF12: =Assumptions!$B$38*(1+0.1)^2/12 -> 605 | AG12: =Assumptions!$B$38*(1+0.1)^3/4 -> 1996.5 | AH12: =Assumptions!$B$38*(1+0.1)^3/4 -> 1996.5 | AI12: =Assumptions!$B$38*(1+0.1)^3/4 -> 1996.5 | AJ12: =Assumptions!$B$38*(1+0.1)^3/4 -> 1996.5 | AK12: =Assumptions!$B$38*(1+0.1)^4/4 -> 2196.15 | AL12: =Assumptions!$B$38*(1+0.1)^4/4 -> 2196.15 | AM12: =Assumptions!$B$38*(1+0.1)^4/4 -> 2196.15 | AN12: =Assumptions!$B$38*(1+0.1)^4/4 -> 2196.15 | AO12: =Assumptions!$B$38*(1+0.1)^5/4 -> 2415.765 | AP12: =Assumptions!$B$38*(1+0.1)^5/4 -> 2415.765 | AQ12: =Assumptions!$B$38*(1+0.1)^5/4 -> 2415.765 | AR12: =Assumptions!$B$38*(1+0.1)^5/4 -> 2415.765
A13: Branding & events | B13: M VND | C13: =Assumptions!$B$45/12 -> 333.33333 | D13: =Assumptions!$B$45/12 -> 333.33333 | E13: =Assumptions!$B$45/12 -> 333.33333 | F13: =Assumptions!$B$45/12 -> 333.33333 | G13: =Assumptions!$B$45/12 -> 333.33333 | H13: =Assumptions!$B$45/12 -> 333.33333 | I13: =Assumptions!$B$45/12 -> 333.33333 | J13: =Assumptions!$B$45/12 -> 333.33333 | ... AF13: =Assumptions!$B$45/12 -> 333.33333 | AG13: =Assumptions!$B$45/4 -> 1000 | AH13: =Assumptions!$B$45/4 -> 1000 | AI13: =Assumptions!$B$45/4 -> 1000 | AJ13: =Assumptions!$B$45/4 -> 1000 | AK13: =Assumptions!$B$45/4 -> 1000 | AL13: =Assumptions!$B$45/4 -> 1000 | AM13: =Assumptions!$B$45/4 -> 1000 | AN13: =Assumptions!$B$45/4 -> 1000 | ... AR13: =Assumptions!$B$45/4 -> 1000
A14: Cloud & infrastructure | B14: M VND | C14: =Assumptions!$B$39/12+'Market Sizing'!C14*Assumptions!$B$40 -> 277.94721 | D14: =Assumptions!$B$39/12+'Market Sizing'!D14*Assumptions!$B$40 -> 278.5534 | E14: =Assumptions!$B$39/12+'Market Sizing'!E14*Assumptions!$B$40 -> 279.3352 | F14: =Assumptions!$B$39/12+'Market Sizing'!F14*Assumptions!$B$40 -> 280.17934 | G14: =Assumptions!$B$39/12+'Market Sizing'!G14*Assumptions!$B$40 -> 281.05024 | H14: =Assumptions!$B$39/12+'Market Sizing'!H14*Assumptions!$B$40 -> 282.06627 | I14: =Assumptions!$B$39/12+'Market Sizing'!I14*Assumptions!$B$40 -> 283.15924 | J14: =Assumptions!$B$39/12+'Market Sizing'!J14*Assumptions!$B$40 -> 284.34681 | ... AF14: =Assumptions!$B$39/12+'Market Sizing'!AF14*Assumptions!$B$40 -> 341.20142 | AG14: =Assumptions!$B$39/4+'Market Sizing'!AG14*Assumptions!$B$40 -> 1045.3434 | AH14: =Assumptions!$B$39/4+'Market Sizing'!AH14*Assumptions!$B$40 -> 1076.9377 | AI14: =Assumptions!$B$39/4+'Market Sizing'!AI14*Assumptions!$B$40 -> 1106.7304 | AJ14: =Assumptions!$B$39/4+'Market Sizing'!AJ14*Assumptions!$B$40 -> 1133.3987 | AK14: =Assumptions!$B$39/4+'Market Sizing'!AK14*Assumptions!$B$40 -> 1156.5083 | AL14: =Assumptions!$B$39/4+'Market Sizing'!AL14*Assumptions!$B$40 -> 1175.901 | AM14: =Assumptions!$B$39/4+'Market Sizing'!AM14*Assumptions!$B$40 -> 1191.751 | AN14: =Assumptions!$B$39/4+'Market Sizing'!AN14*Assumptions!$B$40 -> 1204.2927 | ... AR14: =Assumptions!$B$39/4+'Market Sizing'!AR14*Assumptions!$B$40 -> 1232.304
A15: Security / pentest | B15: M VND | C15: =Assumptions!$B$46/12 -> 20.833333 | D15: =Assumptions!$B$46/12 -> 20.833333 | E15: =Assumptions!$B$46/12 -> 20.833333 | F15: =Assumptions!$B$46/12 -> 20.833333 | G15: =Assumptions!$B$46/12 -> 20.833333 | H15: =Assumptions!$B$46/12 -> 20.833333 | I15: =Assumptions!$B$46/12 -> 20.833333 | J15: =Assumptions!$B$46/12 -> 20.833333 | ... AF15: =Assumptions!$B$46/12 -> 20.833333 | AG15: =Assumptions!$B$46/4 -> 62.5 | AH15: =Assumptions!$B$46/4 -> 62.5 | AI15: =Assumptions!$B$46/4 -> 62.5 | AJ15: =Assumptions!$B$46/4 -> 62.5 | AK15: =Assumptions!$B$46/4 -> 62.5 | AL15: =Assumptions!$B$46/4 -> 62.5 | AM15: =Assumptions!$B$46/4 -> 62.5 | AN15: =Assumptions!$B$46/4 -> 62.5 | ... AR15: =Assumptions!$B$46/4 -> 62.5
A16: External affairs | B16: M VND | C16: =Assumptions!$B$41/12 -> 33.333333 | D16: =Assumptions!$B$41/12 -> 33.333333 | E16: =Assumptions!$B$41/12 -> 33.333333 | F16: =Assumptions!$B$41/12 -> 33.333333 | G16: =Assumptions!$B$41/12 -> 33.333333 | H16: =Assumptions!$B$41/12 -> 33.333333 | I16: =Assumptions!$B$41/12 -> 33.333333 | J16: =Assumptions!$B$41/12 -> 33.333333 | ... AF16: =Assumptions!$B$41/12 -> 33.333333 | AG16: =Assumptions!$B$41/4 -> 100 | AH16: =Assumptions!$B$41/4 -> 100 | AI16: =Assumptions!$B$41/4 -> 100 | AJ16: =Assumptions!$B$41/4 -> 100 | AK16: =Assumptions!$B$41/4 -> 100 | AL16: =Assumptions!$B$41/4 -> 100 | AM16: =Assumptions!$B$41/4 -> 100 | AN16: =Assumptions!$B$41/4 -> 100 | ... AR16: =Assumptions!$B$41/4 -> 100
A17: Legal & compliance | B17: M VND | C17: =Assumptions!$B$42/12 -> 20 | D17: =Assumptions!$B$42/12 -> 20 | E17: =Assumptions!$B$42/12 -> 20 | F17: =Assumptions!$B$42/12 -> 20 | G17: =Assumptions!$B$42/12 -> 20 | H17: =Assumptions!$B$42/12 -> 20 | I17: =Assumptions!$B$42/12 -> 20 | J17: =Assumptions!$B$42/12 -> 20 | ... AF17: =Assumptions!$B$42/12 -> 20 | AG17: =Assumptions!$B$42/4 -> 60 | AH17: =Assumptions!$B$42/4 -> 60 | AI17: =Assumptions!$B$42/4 -> 60 | AJ17: =Assumptions!$B$42/4 -> 60 | AK17: =Assumptions!$B$42/4 -> 60 | AL17: =Assumptions!$B$42/4 -> 60 | AM17: =Assumptions!$B$42/4 -> 60 | AN17: =Assumptions!$B$42/4 -> 60 | ... AR17: =Assumptions!$B$42/4 -> 60
A18: Pilot evaluation (Y1 only) | B18: M VND | C18: =Assumptions!$B$43/6 -> 33.333333 | D18: =Assumptions!$B$43/6 -> 33.333333 | E18: =Assumptions!$B$43/6 -> 33.333333 | F18: =Assumptions!$B$43/6 -> 33.333333 | G18: =Assumptions!$B$43/6 -> 33.333333 | H18: =Assumptions!$B$43/6 -> 33.333333 | I18: =0 -> 0 | J18: =0 -> 0 | K18: =0 -> 0 | L18: =0 -> 0 | M18: =0 -> 0 | N18: =0 -> 0 | O18: =0 -> 0 | P18: =0 -> 0 | ... AR18: =0 -> 0
A19: TOTAL OPEX | B19: M VND | C19: =SUM(C10:C18) -> 2953.9805 | D19: =SUM(D10:D18) -> 1802.5867 | E19: =SUM(E10:E18) -> 1803.3685 | F19: =SUM(F10:F18) -> 1804.2127 | G19: =SUM(G10:G18) -> 1805.0836 | H19: =SUM(H10:H18) -> 1806.0996 | I19: =SUM(I10:I18) -> 2554.7492 | J19: =SUM(J10:J18) -> 2123.9368 | ... AR19: =SUM(AR10:AR18) -> 16317.671
A21: TOTAL COSTS (CAPEX + OPEX) | B21: M VND | C21: =C7+C19 -> 3833.9805 | D21: =D7+D19 -> 2682.5867 | E21: =E7+E19 -> 2683.3685 | F21: =F7+F19 -> 2684.2127 | G21: =G7+G19 -> 2685.0836 | H21: =H7+H19 -> 2686.0996 | I21: =I7+I19 -> 2633.9492 | J21: =J7+J19 -> 2203.1368 | ... AR21: =AR7+AR19 -> 16555.271

Sheet P&L
A1: PROFIT & LOSS STATEMENT (M VND)
A3: Item | B3: Unit | C3: Jul 2025 | D3: Aug 2025 | E3: Sep 2025 | F3: Oct 2025 | G3: Nov 2025 | H3: Dec 2025 | I3: Jan 2026 | J3: Feb 2026 | K3: Mar 2026 | L3: Apr 2026 | M3: May 2026 | N3: Jun 2026 | O3: Jul 2026 | P3: Aug 2026 | Q3: Sep 2026 | R3: Oct 2026 | S3: Nov 2026 | T3: Dec 2026 | U3: Jan 2027 | V3: Feb 2027 | W3: Mar 2027 | X3: Apr 2027 | Y3: May 2027 | Z3: Jun 2027 | AA3: Jul 2027 | AB3: Aug 2027 | AC3: Sep 2027 | AD3: Oct 2027 | AE3: Nov 2027 | AF3: Dec 2027 | AG3: Q1 2028 | AH3: Q2 2028 | AI3: Q3 2028 | AJ3: Q4 2028 | AK3: Q1 2029 | AL3: Q2 2029 | AM3: Q3 2029 | AN3: Q4 2029 | AO3: Q1 2030 | AP3: Q2 2030 | AQ3: Q3 2030 | AR3: Q4 2030 | AT3: TOTAL
A4: Revenue | B4: M VND | C4: ='Revenue Schedule'!C16 -> 527.61284 | D4: ='Revenue Schedule'!D16 -> 572.57178 | E4: ='Revenue Schedule'!E16 -> 630.5553 | F4: ='Revenue Schedule'!F16 -> 693.16192 | G4: ='Revenue Schedule'!G16 -> 757.75358 | H4: ='Revenue Schedule'!H16 -> 833.10927 | I4: ='Revenue Schedule'!I16 -> 963.47487 | J4: ='Revenue Schedule'!J16 -> 1056.3034 | ... AR4: ='Revenue Schedule'!AR16 -> 57936.458
A5: Cost of goods sold | B5: M VND | C5: =-'Revenue Schedule'!C20 -> 0 | D5: =-'Revenue Schedule'!D20 -> 0 | E5: =-'Revenue Schedule'!E20 -> 0 | F5: =-'Revenue Schedule'!F20 -> 0 | G5: =-'Revenue Schedule'!G20 -> 0 | H5: =-'Revenue Schedule'!H20 -> 0 | I5: =-'Revenue Schedule'!I20 -> 0 | J5: =-'Revenue Schedule'!J20 -> 0 | ... AR5: =-'Revenue Schedule'!AR20 -> -303.04892
A6: GROSS PROFIT | B6: M VND | C6: =C4+C5 -> 527.61284 | D6: =D4+D5 -> 572.57178 | E6: =E4+E5 -> 630.5553 | F6: =F4+F5 -> 693.16192 | G6: =G4+G5 -> 757.75358 | H6: =H4+H5 -> 833.10927 | I6: =I4+I5 -> 963.47487 | J6: =J4+J5 -> 1056.3034 | ... AR6: =AR4+AR5 -> 57633.409
A8: Operating expenses | B8: M VND | C8: =-'Cost Schedule'!C19 -> -2953.9805 | D8: =-'Cost Schedule'!D19 -> -1802.5867 | E8: =-'Cost Schedule'!E19 -> -1803.3685 | F8: =-'Cost Schedule'!F19 -> -1804.2127 | G8: =-'Cost Schedule'!G19 -> -1805.0836 | H8: =-'Cost Schedule'!H19 -> -1806.0996 | I8: =-'Cost Schedule'!I19 -> -2554.7492 | J8: =-'Cost Schedule'!J19 -> -2123.9368 | ... AR8: =-'Cost Schedule'!AR19 -> -16317.671
A9: EBITDA | B9: M VND | C9: =C6+C8 -> -2426.3677 | D9: =D6+D8 -> -1230.015 | E9: =E6+E8 -> -1172.8132 | F9: =F6+F8 -> -1111.0508 | G9: =G6+G8 -> -1047.33 | H9: =H6+H8 -> -972.99033 | I9: =I6+I8 -> -1591.2744 | J9: =J6+J8 -> -1067.6335 | ... AR9: =AR6+AR8 -> 41315.737
A10: Depreciation & amortization | B10: M VND | C10: =-Assumptions!$B$36/Assumptions!$B$62/12 -> -88 | D10: =-Assumptions!$B$36/Assumptions!$B$62/12 -> -88 | E10: =-Assumptions!$B$36/Assumptions!$B$62/12 -> -88 | F10: =-Assumptions!$B$36/Assumptions!$B$62/12 -> -88 | G10: =-Assumptions!$B$36/Assumptions!$B$62/12 -> -88 | H10: =-Assumptions!$B$36/Assumptions!$B$62/12 -> -88 | I10: =-Assumptions!$B$36/Assumptions!$B$62/12 -> -88 | J10: =-Assumptions!$B$36/Assumptions!$B$62/12 -> -88 | ... AF10: =-Assumptions!$B$36/Assumptions!$B$62/12 -> -88 | AG10: =-Assumptions!$B$36/Assumptions!$B$62/4 -> -264 | AH10: =-Assumptions!$B$36/Assumptions!$B$62/4 -> -264 | AI10: =-Assumptions!$B$36/Assumptions!$B$62/4 -> -264 | AJ10: =-Assumptions!$B$36/Assumptions!$B$62/4 -> -264 | AK10: =-Assumptions!$B$36/Assumptions!$B$62/4 -> -264 | AL10: =-Assumptions!$B$36/Assumptions!$B$62/4 -> -264 | AM10: =-Assumptions!$B$36/Assumptions!$B$62/4 -> -264 | AN10: =-Assumptions!$B$36/Assumptions!$B$62/4 -> -264 | AO10: =0 -> 0 | AP10: =0 -> 0 | AQ10: =0 -> 0 | AR10: =0 -> 0
A11: EBIT | B11: M VND | C11: =C9+C10 -> -2514.3677 | D11: =D9+D10 -> -1318.015 | E11: =E9+E10 -> -1260.8132 | F11: =F9+F10 -> -1199.0508 | G11: =G9+G10 -> -1135.33 | H11: =H9+H10 -> -1060.9903 | I11: =I9+I10 -> -1679.2744 | J11: =J9+J10 -> -1155.6335 | ... AR11: =AR9+AR10 -> 41315.737
A12: Corporate income tax (CIT 20%) | B12: M VND | C12: =IF(C11>0,-C11*Assumptions!$B$60,0) -> 0 | D12: =IF(D11>0,-D11*Assumptions!$B$60,0) -> 0 | E12: =IF(E11>0,-E11*Assumptions!$B$60,0) -> 0 | F12: =IF(F11>0,-F11*Assumptions!$B$60,0) -> 0 | G12: =IF(G11>0,-G11*Assumptions!$B$60,0) -> 0 | H12: =IF(H11>0,-H11*Assumptions!$B$60,0) -> 0 | I12: =IF(I11>0,-I11*Assumptions!$B$60,0) -> 0 | J12: =IF(J11>0,-J11*Assumptions!$B$60,0) -> 0 | ... AR12: =IF(AR11>0,-AR11*Assumptions!$B$60,0) -> -8263.1474
A13: NET INCOME | B13: M VND | C13: =C11+C12 -> -2514.3677 | D13: =D11+D12 -> -1318.015 | E13: =E11+E12 -> -1260.8132 | F13: =F11+F12 -> -1199.0508 | G13: =G11+G12 -> -1135.33 | H13: =H11+H12 -> -1060.9903 | I13: =I11+I12 -> -1679.2744 | J13: =J11+J12 -> -1155.6335 | ... AR13: =AR11+AR12 -> 33052.59
A15: KEY RATIOS
A16: Gross margin | C16: =IF(C4=0,0,C6/C4) -> 1 | D16: =IF(D4=0,0,D6/D4) -> 1 | E16: =IF(E4=0,0,E6/E4) -> 1 | F16: =IF(F4=0,0,F6/F4) -> 1 | G16: =IF(G4=0,0,G6/G4) -> 1 | H16: =IF(H4=0,0,H6/H4) -> 1 | I16: =IF(I4=0,0,I6/I4) -> 1 | J16: =IF(J4=0,0,J6/J4) -> 1 | ... AR16: =IF(AR4=0,0,AR6/AR4) -> 0.99476929
A17: EBITDA margin | C17: =IF(C4=0,0,C9/C4) -> -4.5987655 | D17: =IF(D4=0,0,D9/D4) -> -2.1482284 | E17: =IF(E4=0,0,E9/E4) -> -1.8599689 | F17: =IF(F4=0,0,F9/F4) -> -1.6028733 | G17: =IF(G4=0,0,G9/G4) -> -1.3821512 | H17: =IF(H4=0,0,H9/H4) -> -1.1679024 | I17: =IF(I4=0,0,I9/I4) -> -1.6515993 | J17: =IF(J4=0,0,J9/J4) -> -1.0107262 | ... AR17: =IF(AR4=0,0,AR9/AR4) -> 0.71312156
A18: Net income margin | C18: =IF(C4=0,0,C13/C4) -> -4.7655544 | D18: =IF(D4=0,0,D13/D4) -> -2.3019209 | E18: =IF(E4=0,0,E13/E4) -> -1.9995284 | F18: =IF(F4=0,0,F13/F4) -> -1.7298278 | G18: =IF(G4=0,0,G13/G4) -> -1.4982839 | H18: =IF(H4=0,0,H13/H4) -> -1.2735308 | I18: =IF(I4=0,0,I13/I4) -> -1.7429353 | J18: =IF(J4=0,0,J13/J4) -> -1.0940356 | ... AR18: =IF(AR4=0,0,AR13/AR4) -> 0.57049725

Sheet Cash Flow
A1: CASH FLOW STATEMENT (M VND)
A3: Item | B3: Unit | C3: Jul 2025 | D3: Aug 2025 | E3: Sep 2025 | F3: Oct 2025 | G3: Nov 2025 | H3: Dec 2025 | I3: Jan 2026 | J3: Feb 2026 | K3: Mar 2026 | L3: Apr 2026 | M3: May 2026 | N3: Jun 2026 | O3: Jul 2026 | P3: Aug 2026 | Q3: Sep 2026 | R3: Oct 2026 | S3: Nov 2026 | T3: Dec 2026 | U3: Jan 2027 | V3: Feb 2027 | W3: Mar 2027 | X3: Apr 2027 | Y3: May 2027 | Z3: Jun 2027 | AA3: Jul 2027 | AB3: Aug 2027 | AC3: Sep 2027 | AD3: Oct 2027 | AE3: Nov 2027 | AF3: Dec 2027 | AG3: Q1 2028 | AH3: Q2 2028 | AI3: Q3 2028 | AJ3: Q4 2028 | AK3: Q1 2029 | AL3: Q2 2029 | AM3: Q3 2029 | AN3: Q4 2029 | AO3: Q1 2030 | AP3: Q2 2030 | AQ3: Q3 2030 | AR3: Q4 2030 | AT3: TOTAL
A4: Operating Cash Flow
A5: Net income | C5: ='P&L'!C13 -> -2514.3677 | D5: ='P&L'!D13 -> -1318.015 | E5: ='P&L'!E13 -> -1260.8132 | F5: ='P&L'!F13 -> -1199.0508 | G5: ='P&L'!G13 -> -1135.33 | H5: ='P&L'!H13 -> -1060.9903 | I5: ='P&L'!I13 -> -1679.2744 | J5: ='P&L'!J13 -> -1155.6335 | ... AR5: ='P&L'!AR13 -> 33052.59
A6: Add: Depreciation | C6: =-'P&L'!C10 -> 88 | D6: =-'P&L'!D10 -> 88 | E6: =-'P&L'!E10 -> 88 | F6: =-'P&L'!F10 -> 88 | G6: =-'P&L'!G10 -> 88 | H6: =-'P&L'!H10 -> 88 | I6: =-'P&L'!I10 -> 88 | J6: =-'P&L'!J10 -> 88 | ... AR6: =-'P&L'!AR10 -> 0
A7: Change in working capital | C7: =-'P&L'!C4*Assumptions!$B$63/365 -> -65.048158 | D7: =-('P&L'!D4-'P&L'!C4)*Assumptions!$B$63/365 -> -5.5428834 | E7: =-('P&L'!E4-'P&L'!D4)*Assumptions!$B$63/365 -> -7.1486531 | F7: =-('P&L'!F4-'P&L'!E4)*Assumptions!$B$63/365 -> -7.718624 | G7: =-('P&L'!G4-'P&L'!F4)*Assumptions!$B$63/365 -> -7.9633556 | H7: =-('P&L'!H4-'P&L'!G4)*Assumptions!$B$63/365 -> -9.290427 | I7: =-('P&L'!I4-'P&L'!H4)*Assumptions!$B$63/365 -> -16.072471 | J7: =-('P&L'!J4-'P&L'!I4)*Assumptions!$B$63/365 -> -11.444609 | K7: =-('P&L'!K4-'P&L'!J4)*Assumptions!$B$63/365 -> -12.089469 | ... AR7: =-('P&L'!AR4-'P&L'!AQ4)*Assumptions!$B$63/365 -> -60.480346
A8: OPERATING CASH FLOW | C8: =C5+C6+C7 -> -2491.4159 | D8: =D5+D6+D7 -> -1235.5578 | E8: =E5+E6+E7 -> -1179.9619 | F8: =F5+F6+F7 -> -1118.7694 | G8: =G5+G6+G7 -> -1055.2933 | H8: =H5+H6+H7 -> -982.28076 | I8: =I5+I6+I7 -> -1607.3468 | J8: =J5+J6+J7 -> -1079.0781 | ... AR8: =AR5+AR6+AR7 -> 32992.109
A10: Investing Cash Flow
A11: Capital expenditure | C11: =-'Cost Schedule'!C7 -> -880 | D11: =-'Cost Schedule'!D7 -> -880 | E11: =-'Cost Schedule'!E7 -> -880 | F11: =-'Cost Schedule'!F7 -> -880 | G11: =-'Cost Schedule'!G7 -> -880 | H11: =-'Cost Schedule'!H7 -> -880 | I11: =-'Cost Schedule'!I7 -> -79.2 | J11: =-'Cost Schedule'!J7 -> -79.2 | ... AR11: =-'Cost Schedule'!AR7 -> -237.6
A12: INVESTING CASH FLOW | C12: =C11 -> -880 | D12: =D11 -> -880 | E12: =E11 -> -880 | F12: =F11 -> -880 | G12: =G11 -> -880 | H12: =H11 -> -880 | I12: =I11 -> -79.2 | J12: =J11 -> -79.2 | ... AR12: =AR11 -> -237.6
A14: FREE CASH FLOW | C14: =C8+C12 -> -3371.4159 | D14: =D8+D12 -> -2115.5578 | E14: =E8+E12 -> -2059.9619 | F14: =F8+F12 -> -1998.7694 | G14: =G8+G12 -> -1935.2933 | H14: =H8+H12 -> -1862.2808 | I14: =I8+I12 -> -1686.5468 | J14: =J8+J12 -> -1158.2781 | ... AR14: =AR8+AR12 -> 32754.509
A15: Cumulative cash flow | C15: =C14 -> -3371.4159 | D15: =C15+D14 -> -5486.9737 | E15: =D15+E14 -> -7546.9356 | F15: =E15+F14 -> -9545.705 | G15: =F15+G14 -> -11480.998 | H15: =G15+H14 -> -13343.279 | I15: =H15+I14 -> -15029.826 | J15: =I15+J14 -> -16188.104 | K15: =J15+K14 -> -17250.222 | ... AR15: =AQ15+AR14 -> 372459.68

Sheet DCF & Returns
A1: DCF VALUATION & RETURN METRICS
A3: Annual Free Cash Flow Summary
A4: Year | B4: FCF (M VND)
A5: H2 2025 | B5: =SUM('Cash Flow'!C14:H14) -> -13343.279
A6: 2026 | B6: =SUM('Cash Flow'!I14:T14) -> 15512.11
A7: 2027 | B7: =SUM('Cash Flow'!U14:AF14) -> 49201.635
A8: 2028 | B8: =SUM('Cash Flow'!AG14:AJ14) -> 81985.998
A9: 2029 | B9: =SUM('Cash Flow'!AK14:AN14) -> 112007.26
A10: 2030 | B10: =SUM('Cash Flow'!AO14:AR14) -> 127095.95
A12: Discounted Cash Flow
A13: NPV @ discount rate | B13: =NPV(Assumptions!$B$61,B6:B10)+B5 -> 241386.37
A14: IRR | B14: =IFERROR(IRR(B5:B10),"N/A") -> 2.2298519
A15: Total investment (cumulative losses) | B15: =-MIN(0,'Cash Flow'!C15:'Cash Flow'!AR15) -> 17250.222
A16: ROI (5-year) | B16: =IF(B15=0,0,('Cash Flow'!AR15+B15)/B15) -> 22.591587
A17: Payback period (years) | B17: =IFERROR(MATCH(TRUE,INDEX('Cash Flow'!C15:'Cash Flow'!AR15>0,0),0)/12,"Not reached") -> 1.5
A19: Key Metrics Summary
A20: NPV | B20: =B13 -> 241386.37
A21: IRR | B21: =B14 -> 2.2298519
A22: Discount rate used | B22: =Assumptions!$B$61 -> 0.12
A23: CIT rate applied | B23: =Assumptions!$B$60 -> 0.2

Sheet Sensitivity
A1: SENSITIVITY ANALYSIS
A3: Note: Data tables require manual setup in Excel (What-If Analysis > Data Table).
A4: Below are the parameter ranges and corner-case NPV values for quick reference.
A6: Table 1: Enterprise Ceiling × Cert Fee → NPV Impact
A7: Enterprise ceiling | B7: 500 ent. | C7: 1,000 ent. | D7: 1,500 ent. | E7: 2,000 ent. | F7: 3,000 ent. | G7: 5,000 ent.
A8: Cert fee: 20M VND | B8: 🔴 ~10B/yr cert | C8: 🔴 ~20B/yr cert | D8: 🟡 ~30B/yr cert | E8: 🟡 ~40B/yr cert | F8: 🟢 ~60B/yr cert | G8: 🟢 ~100B/yr cert
A9: Cert fee: 25M VND | B9: 🔴 ~12B/yr cert | C9: 🟡 ~25B/yr cert | D9: 🟡 ~38B/yr cert | E9: 🟡 ~50B/yr cert | F9: 🟢 ~75B/yr cert | G9: 🟢 ~125B/yr cert
A10: Cert fee: 30M VND | B10: 🔴 ~15B/yr cert | C10: 🟡 ~30B/yr cert | D10: 🟡 ~45B/yr cert | E10: 🟢 ~60B/yr cert | F10: 🟢 ~90B/yr cert | G10: 🟢 ~150B/yr cert
A11: Cert fee: 35M VND | B11: 🔴 ~18B/yr cert | C11: 🟡 ~35B/yr cert | D11: 🟢 ~52B/yr cert | E11: 🟢 ~70B/yr cert | F11: 🟢 ~105B/yr cert | G11: 🟢 ~175B/yr cert
A12: Cert fee: 40M VND | B12: 🔴 ~20B/yr cert | C12: 🟡 ~40B/yr cert | D12: 🟢 ~60B/yr cert | E12: 🟢 ~80B/yr cert | F12: 🟢 ~120B/yr cert | G12: 🟢 ~200B/yr cert
A13: Cert fee: 50M VND | B13: 🟡 ~25B/yr cert | C13: 🟡 ~50B/yr cert | D13: 🟢 ~75B/yr cert | E13: 🟢 ~100B/yr cert | F13: 🟢 ~150B/yr cert | G13: 🟢 ~250B/yr cert
A16: Table 2: Market Share × Take Rate → Annual Tx Revenue (2030)
A17: Market share | B17: 0.5% take | C17: 1.0% take | D17: 1.5% take | E17: 2.0% take | F17: 2.5% take | G17: 3.0% take
A18: Market share: 0.5% | B18: 3030 | C18: 6061 | D18: 9091 | E18: 12122 | F18: 15152 | G18: 18183
A19: Market share: 1.0% | B19: 6061 | C19: 12122 | D19: 18183 | E19: 24244 | F19: 30305 | G19: 36366
A20: Market share: 2.0% | B20: 12122 | C20: 24244 | D20: 36366 | E20: 48488 | F20: 60610 | G20: 72732
A21: Market share: 3.0% | B21: 18183 | C21: 36366 | D21: 54549 | E21: 72732 | F21: 90915 | G21: 109098
A22: Market share: 5.0% | B22: 30305 | C22: 60610 | D22: 90915 | E22: 121220 | F22: 151524 | G22: 181829
A23: Market share: 10.0% | B23: 60610 | C23: 121220 | D23: 181829 | E23: 242439 | F23: 303049 | G23: 363659
A26: Scenario Comparison (from Assumptions sheet)
A27: Parameter | B27: Bull | C27: Base | D27: Bear | E27: Failure
A28: Adoption max | B28: 3,000 | C28: 1,500 | D28: 500 | E28: 100
A29: Market share | B29: 5% | C29: 2% | D29: 0.5% | E29: 0%
A30: Cert fee escalation | B30: 10% | C30: 8% | D30: 5% | E30: 0%
A31: Churn rate | B31: 10% | C31: 15% | D31: 25% | E31: 40%
A32: OPEX growth factor | B32: 1.0x | C32: 1.0x | D32: 1.2x | E32: 1.3x
A35: To run scenarios: change values in Assumptions sheet → model recalculates automatically.
