Workbook
Name base_year: Assumptions!$B$6
Name start_month: Assumptions!$B$7
Name TAM_enterprises: Assumptions!$B$11
Name SAM_enterprises: Assumptions!$B$12
Name ecom_market_base: Assumptions!$B$13
Name ecom_growth_rate: Assumptions!$B$14
Name adoption_max: Assumptions!$B$18
Name adoption_midpoint: Assumptions!$B$19
Name adoption_steepness: Assumptions!$B$20
Name pilot_count: Assumptions!$B$21
Name churn_rate: Assumptions!$B$22
Name cert_fee_yr1: Assumptions!$B$26
Name cert_fee_escalation: Assumptions!$B$27
Name tx_take_rate: Assumptions!$B$28
Name platform_market_share: Assumptions!$B$29
Name daas_price: Assumptions!$B$30
Name ad_cpm: Assumptions!$B$31
Name ad_impressions_base: Assumptions!$B$32
Name training_fee: Assumptions!$B$33
Name audit_fee: Assumptions!$B$34
Name training_pct: Assumptions!$B$35
Name capex_maintenance_pct: Assumptions!$B$39
Name opex_marketing: Assumptions!$B$40
Name marketing_growth: Assumptions!$B$41
Name opex_cloud_base: Assumptions!$B$42
Name cloud_per_1M_vcr: Assumptions!$B$43
Name vcr_per_enterprise: Assumptions!$B$44
Name opex_external: Assumptions!$B$45
Name opex_legal: Assumptions!$B$46
Name opex_branding: Assumptions!$B$47
Name opex_security: Assumptions!$B$48
Name opex_pilot_eval: Assumptions!$B$49
Name payment_proc_pct: Assumptions!$B$50
Name opex_support_per_ent: Assumptions!$B$51
Name opex_partner_mgmt: Assumptions!$B$52
Name opex_contingency_pct: Assumptions!$B$53
Name salary_mgmt: Assumptions!$B$57
Name salary_dev: Assumptions!$B$58
Name salary_bizops: Assumptions!$B$59
Name salary_data: Assumptions!$B$60
Name salary_escalation: Assumptions!$B$61
Name bhxh_rate: Assumptions!$B$62
Name recruit_cost_pct: Assumptions!$B$63
Name cit_rate: Assumptions!$B$67
Name discount_rate: Assumptions!$B$68
Name depreciation_years: Assumptions!$B$69
Name ar_days: Assumptions!$B$70
Name ap_days: Assumptions!$B$71
Name stage2_gate: Assumptions!$B$72
Name capex_cloud_setup: 'Đầu tư ban đầu'!$B$4
Name capex_backend: 'Đầu tư ban đầu'!$B$5
Name capex_frontend: 'Đầu tư ban đầu'!$B$6
Name capex_data_platform: 'Đầu tư ban đầu'!$B$7
Name capex_security_setup: 'Đầu tư ban đầu'!$B$8
Name capex_ux_design: 'Đầu tư ban đầu'!$B$9
Name capex_integration: 'Đầu tư ban đầu'!$B$10
Name capex_devops: 'Đầu tư ban đầu'!$B$11
Name capex_testing: 'Đầu tư ban đầu'!$B$12
Name capex_contingency: 'Đầu tư ban đầu'!$B$13
Name capex_total: 'Đầu tư ban đầu'!$B$15

Sheet Hướng dẫn
A1: VISIT VIETNAM — MÔ HÌNH TÀI CHÍNH v4 — HƯỚNG DẪN
A2: v4.0 | 21/03/2026 | Phiên bản tiếng Việt
A4: DANH SÁCH CÁC TRANG
A5: Trang | B5: Mục đích | C5: Ghi chú
A6: Hướng dẫn | B6: Giải thích mô hình, thuật ngữ, công thức, cách sử dụng | C6: Đọc trước
A7: Assumptions | B7: 49 named ranges. MỌI đầu vào ở đây (ô vàng). | C7: Chỉ sửa ô vàng
A8: Đầu tư ban đầu | B8: 10 hạng mục CAPEX → capex_total. Lịch khấu hao. | C8: capex_total dùng khắp nơi
A9: Nhân sự | B9: 4 bộ phận × 42 kỳ. Lương = biên chế × named_salary × tăng × BHXH | C9: Ô vàng = biên chế
A10: Quy mô thị trường | B10: Đường cong S tăng trưởng DN. Year fracs từ base_year. | C10: Không hardcode năm
A11: Doanh thu | B11: 6 nguồn thu. GĐ2 kích hoạt khi đạt ngưỡng stage2_gate. | C11: Named ranges trong formulas
A12: Chi phí | B12: CAPEX (Đầu tư) + OPEX (Nhân sự + 10 danh mục + dự phòng) | C12: Liên kết chéo trang
A13: Kết quả KD | B13: DT → Giá vốn → LN gộp → OPEX → EBITDA → KH → EBIT → Thuế 20% → LN ròng | C13: Thuế TNDN 20%
A14: Dòng tiền | B14: ĐTHĐ + ĐTĐT → DTTD + Lũy kế. Vốn lưu động qua ar_days. | C14: Named ranges
A15: Thẩm định | B15: FCF theo năm, NPV, IRR, ROI. Dùng discount_rate. | C15: Công thức NPV duy nhất
A16: Kịch bản | B16: 5 kịch bản với giải thích chi tiết + yếu tố ảnh hưởng lớn nhất. | C16: Copy vào Assumptions chạy
... A18: Ngân sách 2026 | B18: Ngân sách tháng 1-12/2026. Cùng cấu trúc, NS tăng. | C18: Sẵn sàng duyệt
A20: THUẬT NGỮ
A21: Thuật ngữ | B21: Tên đầy đủ / Ý nghĩa | C21: Trong mô hình này
A22: NPV | B22: Giá trị hiện tại ròng | C22: Tổng dòng tiền tương lai chiết khấu về hiện tại. Dương = tạo giá trị.
A23: IRR | B23: Tỷ suất hoàn vốn nội bộ | C23: Tỷ suất chiết khấu khi NPV = 0. Cao hơn = lợi nhuận tốt hơn.
A24: WACC | B24: Chi phí vốn bình quân gia quyền | C24: Lợi nhuận tối thiểu NĐT kỳ vọng. Dùng làm discount_rate (15% cơ sở).
A25: ROI | B25: Lợi nhuận trên đầu tư | C25: (Dòng tiền lũy kế + Đầu tư) / Đầu tư.
A26: EBITDA | B26: LN trước lãi, thuế, khấu hao | C26: Lợi nhuận hoạt động trước chi phí phi tiền mặt và thuế.
A27: EBIT | B27: LN trước lãi và thuế | C27: =EBITDA - Khấu hao. Lợi nhuận trước thuế.
A28: Thuế TNDN | B28: Thuế thu nhập doanh nghiệp | C28: Thuế suất chuẩn VN = 20%. Chỉ áp dụng khi EBIT > 0.
A29: FCF | B29: Dòng tiền tự do | C29: =ĐTHĐ + ĐTĐT. Tiền thực sự có sẵn sau mọi chi tiêu.
A30: CAPEX | B30: Chi phí đầu tư | C30: Đầu tư 1 lần vào tài sản (nền tảng 5.280Tr). Khấu hao dần.
A31: OPEX | B31: Chi phí hoạt động | C31: Chi phí liên tục: NS, marketing, cloud, pháp lý... Ghi nhận ngay.
A32: COGS | B32: Giá vốn hàng bán | C32: Chi phí trực tiếp gắn với DT: phí thanh toán (2.5% DT giao dịch).
A33: BHXH | B33: Bảo hiểm xã hội | C33: DN đóng ~21.5%: BHXH 17.5% + BHYT 3% + BHTN 1%.
A34: TAM | B34: Tổng thị trường tiềm năng | C34: Tất cả DN du lịch VN (~40.000).
A35: SAM | B35: Thị trường phục vụ được | C35: DN hoạt động số, có thể chứng nhận (~15.000).
A36: GMV | B36: Tổng giá trị giao dịch | C36: Tổng giá trị giao dịch qua nền tảng.
A37: VCR | B37: Bản ghi du khách chứng nhận | C37: Dữ liệu tạo ra/DN. Cơ sở tính giá DaaS.
A38: S-curve | B38: Đường cong tăng trưởng logistic | C38: DN tăng theo mẫu chậm→nhanh→chậm. max/(1+EXP(-k*(t-midpoint)))
A39: Giai đoạn 1 | B39: Nền tảng chứng nhận (2025-2027) | C39: DT từ phí cert, đào tạo, kiểm toán. Không cần khối lượng GD.
A40: Giai đoạn 2 | B40: Nền tảng giao dịch (2028-2030) | C40: DT từ phí GD, DaaS, QC. Yêu cầu ≥300 DN (stage2_gate).
A41: Named Range | B41: Tên được đặt cho ô Excel | C41: VD: cert_fee_yr1 → Assumptions!$B$26. Dùng trong công thức.
A42: Churn | B42: Tỷ lệ rời bỏ | C42: % DN không gia hạn mỗi năm. Giảm net_enterprises.

Sheet Assumptions
A1: VISIT VIETNAM — MÔ HÌNH TÀI CHÍNH v4 — GIẢ ĐỊNH
A2: v4.0 | Ô vàng = giá trị có thể chỉnh | Chữ xanh = placeholder | Named ranges trong mọi công thức
A4: THỜI GIAN
A5: Tham số | B5: Giá trị | C5: Đơn vị | D5: Ghi chú
A6: Năm cơ sở | B6: 2025 | C6: Năm | D6: Năm bắt đầu dự án
A7: Tháng bắt đầu | B7: 7 | C7: Tháng | D7: Tháng 7
A9: DỮ LIỆU THỊ TRƯỜNG
A10: Tham số | B10: Giá trị | C10: Đơn vị | D10: Ghi chú
A11: Tổng doanh nghiệp du lịch VN | B11: 40000 | D11: GSO/VNAT
A12: DN có thể phục vụ | B12: 15000 | D12: Hoạt động số
A13: Thị trường TMĐT du lịch (năm gốc) | B13: 82500 | C13: Tỷ VND | D13: e-Conomy SEA
A14: Tăng trưởng TMĐT du lịch/năm | B14: 0.08 | C14: % | D14: Dữ liệu lịch sử
A16: ĐƯỜNG CONG TĂNG TRƯỞNG (S-CURVE)
A17: Tham số | B17: Giá trị | C17: Đơn vị | D17: Ghi chú
A18: Trần doanh nghiệp (tối đa) | B18: 1200 | D18: Tiệm cận S-curve
A19: Năm tăng trưởng nhanh nhất | B19: 2028 | C19: Năm | D19: Điểm uốn
A20: Hệ số dốc | B20: 0.9 | D20: Cao hơn = dốc hơn
A21: DN ban đầu (thí điểm) | B21: 15 | D21: Đối tác thí điểm
A22: Tỷ lệ không gia hạn/năm | B22: 0.2 | C22: % | D22: Churn chứng nhận
A24: GIÁ DỊCH VỤ
A25: Tham số | B25: Giá trị | C25: Đơn vị | D25: Ghi chú
A26: Phí chứng nhận/DN/năm | B26: 25 | C26: Tr VND | D26: Gói thuê bao năm
A27: Tăng phí chứng nhận/năm | B27: 0.05 | C27: % | D27: Tăng giá
A28: Phí giao dịch (% GMV) | B28: 0.02 | C28: % | D28: Hoa hồng nền tảng
A29: % GMV TMĐT du lịch qua VV | B29: 0.005 | C29: % | D29: Mục tiêu thực tế
A30: Giá DaaS/triệu VCR | B30: 30 | C30: Tr VND | D30: Thuê bao dữ liệu
A31: CPM quảng cáo | B31: 150 | C31: K VND | D31: Benchmark B2B
A32: Lượt hiển thị QC/tháng (K) | B32: 500 | C32: K | D32: Tỷ lệ theo DN
A33: Phí đào tạo/phiên | B33: 15 | C33: Tr VND | D33: Nguồn thu MỚI
A34: Phí kiểm toán chứng nhận | B34: 10 | C34: Tr VND | D34: Nguồn thu MỚI
A35: % DN mua đào tạo | B35: 0.3 | C35: % | D35: Ước tính
A37: THAM SỐ CHI PHÍ
A38: Tham số | B38: Giá trị | C38: Đơn vị | D38: Ghi chú
A39: Bảo trì (% CAPEX/năm) | B39: 0.18 | C39: % | D39: Chuẩn ngành 15-20%
A40: Marketing (cơ sở/năm) | B40: 7000 | C40: Tr VND | D40: Dữ liệu gốc
A41: Tăng trưởng marketing/năm | B41: 0.15 | C41: % | D41: Tăng theo tham vọng
A42: Cloud cơ sở (năm) | B42: 3250 | C42: Tr VND | D42: Dữ liệu gốc
A43: Chi phí cloud/triệu VCR | B43: 8 | C43: Tr VND | D43: Chi phí biến đổi
A44: VCR/DN/tháng | B44: 10000 | C44: bản ghi | D44: Ước tính lưu lượng
A45: Đối ngoại (năm) | B45: 400 | C45: Tr VND | D45: Dữ liệu gốc
...

Sheet Đầu tư ban đầu
A1: ĐẦU TƯ BAN ĐẦU — CHI TIẾT CAPEX (Tr VND)
A3: Hạng mục CAPEX | B3: Số tiền (Tr VND) | C3: Thời điểm | D3: Ghi chú
A4: Hạ tầng Cloud | B4: 800 | C4: H2 2025 | D4: Setup AWS/GCP ban đầu
A5: Phát triển Backend | B5: 1200 | C5: H2 2025 | D5: API, DB, logic lõi
A6: Frontend + mobile | B6: 900 | C6: H2 2025 | D6: Web + ứng dụng di động
A7: Nền tảng dữ liệu | B7: 600 | C7: H2 2025 | D7: Pipeline, phân tích
A8: Hạ tầng bảo mật | B8: 250 | C8: H2 2025 | D8: Pentest, xác thực
A9: Thiết kế UX/UI | B9: 350 | C9: H2 2025 | D9: Design system
A10: Tích hợp bên thứ 3 | B10: 400 | C10: H2 2025 | D10: Cổng TT, API OTA
A11: DevOps & CI/CD | B11: 280 | C11: H2 2025 | D11: Pipeline triển khai
A12: QA & kiểm thử | B12: 200 | C12: H2 2025 | D12: Kiểm thử tự động
A13: Dự phòng CAPEX (10%) | B13: 300 | C13: H2 2025 | D13: Đệm phát sinh
A15: TỔNG ĐẦU TƯ BAN ĐẦU | B15: =SUM(B4:B13)
A17: LỊCH KHẤU HAO
A18: Năm | B18: Khấu hao/năm | C18: Khấu hao lũy kế | D18: Giá trị còn lại
A19: 2025 | B19: =capex_total/depreciation_years | C19: =B19 | D19: =capex_total-C19
A20: 2026 | B20: =capex_total/depreciation_years | C20: =C19+B20 | D20: =capex_total-C20
A21: 2027 | B21: =capex_total/depreciation_years | C21: =C20+B21 | D21: =capex_total-C21
A22: 2028 | B22: =capex_total/depreciation_years | C22: =C21+B22 | D22: =capex_total-C22
A23: 2029 | B23: =capex_total/depreciation_years | C23: =C22+B23 | D23: =capex_total-C23
A24: 2030 | B24: =0 | C24: =C23+B24 | D24: =capex_total-C24

Sheet Nhân sự
A1: KẾ HOẠCH NHÂN SỰ — BIÊN CHẾ & CHI PHÍ
A3: Bộ phận / Hạng mục | B3: ĐVT | C3: Th7 2025 | D3: Th8 2025 | E3: Th9 2025 | F3: Th10 2025 | G3: Th11 2025 | H3: Th12 2025 | I3: Th1 2026 | J3: Th2 2026 | K3: Th3 2026 | L3: Th4 2026 | M3: Th5 2026 | N3: Th6 2026 | O3: Th7 2026 | P3: Th8 2026 | Q3: Th9 2026 | R3: Th10 2026 | S3: Th11 2026 | T3: Th12 2026 | U3: Th1 2027 | V3: Th2 2027 | W3: Th3 2027 | X3: Th4 2027 | Y3: Th5 2027 | Z3: Th6 2027 | AA3: Th7 2027 | AB3: Th8 2027 | AC3: Th9 2027 | AD3: Th10 2027 | AE3: Th11 2027 | AF3: Th12 2027 | AG3: Q1 2028 | AH3: Q2 2028 | AI3: Q3 2028 | AJ3: Q4 2028 | AK3: Q1 2029 | AL3: Q2 2029 | AM3: Q3 2029 | AN3: Q4 2029 | AO3: Q1 2030 | AP3: Q2 2030 | AQ3: Q3 2030 | AR3: Q4 2030
A4: SỐ LƯỢNG NHÂN SỰ
A5: Quản lý | B5: người | C5: 2 | D5: 2 | E5: 2 | F5: 2 | G5: 2 | H5: 2 | I5: 2 | J5: 2 | K5: 2 | L5: 2 | M5: 2 | N5: 2 | O5: 2 | P5: 2 | Q5: 2 | R5: 2 | S5: 2 | T5: 2 | U5: 3 | V5: 3 | W5: 3 | X5: 3 | Y5: 3 | Z5: 3 | AA5: 3 | AB5: 3 | AC5: 3 | AD5: 3 | AE5: 3 | AF5: 3 | AG5: 3 | AH5: 3 | AI5: 3 | AJ5: 3 | AK5: 4 | AL5: 4 | AM5: 4 | AN5: 4 | AO5: 4 | AP5: 4 | AQ5: 4 | AR5: 4
A6: Phát triển | B6: người | C6: 12 | D6: 12 | E6: 12 | F6: 12 | G6: 12 | H6: 12 | I6: 12 | J6: 12 | K6: 12 | L6: 12 | M6: 12 | N6: 12 | O6: 12 | P6: 12 | Q6: 12 | R6: 12 | S6: 12 | T6: 12 | U6: 14 | V6: 14 | W6: 14 | X6: 14 | Y6: 14 | Z6: 14 | AA6: 14 | AB6: 14 | AC6: 14 | AD6: 14 | AE6: 14 | AF6: 14 | AG6: 16 | AH6: 16 | AI6: 16 | AJ6: 16 | AK6: 18 | AL6: 18 | AM6: 18 | AN6: 18 | AO6: 20 | AP6: 20 | AQ6: 20 | AR6: 20
A7: Vận hành KD | B7: người | C7: 2 | D7: 2 | E7: 2 | F7: 2 | G7: 2 | H7: 2 | I7: 6 | J7: 6 | K7: 6 | L7: 6 | M7: 6 | N7: 6 | O7: 6 | P7: 6 | Q7: 6 | R7: 6 | S7: 6 | T7: 6 | U7: 10 | V7: 10 | W7: 10 | X7: 10 | Y7: 10 | Z7: 10 | AA7: 10 | AB7: 10 | AC7: 10 | AD7: 10 | AE7: 10 | AF7: 10 | AG7: 18 | AH7: 18 | AI7: 18 | AJ7: 18 | AK7: 28 | AL7: 28 | AM7: 28 | AN7: 28 | AO7: 35 | AP7: 35 | AQ7: 35 | AR7: 35
A8: Dữ liệu & Phân tích | B8: người | C8: 0 | D8: 0 | E8: 0 | F8: 0 | G8: 0 | H8: 0 | I8: 2 | J8: 2 | K8: 2 | L8: 2 | M8: 2 | N8: 2 | O8: 2 | P8: 2 | Q8: 2 | R8: 2 | S8: 2 | T8: 2 | U8: 3 | V8: 3 | W8: 3 | X8: 3 | Y8: 3 | Z8: 3 | AA8: 3 | AB8: 3 | AC8: 3 | AD8: 3 | AE8: 3 | AF8: 3 | AG8: 4 | AH8: 4 | AI8: 4 | AJ8: 4 | AK8: 5 | AL8: 5 | AM8: 5 | AN8: 5 | AO8: 6 | AP8: 6 | AQ8: 6 | AR8: 6
A9: TỔNG NHÂN SỰ | B9: người | C9: =C5+C6+C7+C8 | D9: =D5+D6+D7+D8 | E9: =E5+E6+E7+E8 | F9: =F5+F6+F7+F8 | G9: =G5+G6+G7+G8 | H9: =H5+H6+H7+H8 | I9: =I5+I6+I7+I8 | J9: =J5+J6+J7+J8 | ... AR9: =AR5+AR6+AR7+AR8
A11: TUYỂN MỚI
A12: Tuyển mới | B12: người | C12: =C9 | D12: =MAX(0,D9-C9) | E12: =MAX(0,E9-D9) | F12: =MAX(0,F9-E9) | G12: =MAX(0,G9-F9) | H12: =MAX(0,H9-G9) | I12: =MAX(0,I9-H9) | J12: =MAX(0,J9-I9) | K12: =MAX(0,K9-J9) | ... AR12: =MAX(0,AR9-AQ9)
A14: CHI PHÍ LƯƠNG (Tr VND)
A15: CP Quản lý | B15: Tr VND | C15: =C5*salary_mgmt*1*(1+salary_escalation)^0*(1+bhxh_rate) | D15: =D5*salary_mgmt*1*(1+salary_escalation)^0*(1+bhxh_rate) | E15: =E5*salary_mgmt*1*(1+salary_escalation)^0*(1+bhxh_rate) | F15: =F5*salary_mgmt*1*(1+salary_escalation)^0*(1+bhxh_rate) | G15: =G5*salary_mgmt*1*(1+salary_escalation)^0*(1+bhxh_rate) | H15: =H5*salary_mgmt*1*(1+salary_escalation)^0*(1+bhxh_rate) | I15: =I5*salary_mgmt*1*(1+salary_escalation)^1*(1+bhxh_rate) | J15: =J5*salary_mgmt*1*(1+salary_escalation)^1*(1+bhxh_rate) | K15: =K5*salary_mgmt*1*(1+salary_escalation)^1*(1+bhxh_rate) | L15: =L5*salary_mgmt*1*(1+salary_escalation)^1*(1+bhxh_rate) | M15: =M5*salary_mgmt*1*(1+salary_escalation)^1*(1+bhxh_rate) | N15: =N5*salary_mgmt*1*(1+salary_escalation)^1*(1+bhxh_rate) | O15: =O5*salary_mgmt*1*(1+salary_escalation)^1*(1+bhxh_rate) | P15: =P5*salary_mgmt*1*(1+salary_escalation)^1*(1+bhxh_rate) | ... T15: =T5*salary_mgmt*1*(1+salary_escalation)^1*(1+bhxh_rate) | U15: =U5*salary_mgmt*1*(1+salary_escalation)^2*(1+bhxh_rate) | V15: =V5*salary_mgmt*1*(1+salary_escalation)^2*(1+bhxh_rate) | W15: =W5*salary_mgmt*1*(1+salary_escalation)^2*(1+bhxh_rate) | X15: =X5*salary_mgmt*1*(1+salary_escalation)^2*(1+bhxh_rate) | Y15: =Y5*salary_mgmt*1*(1+salary_escalation)^2*(1+bhxh_rate) | Z15: =Z5*salary_mgmt*1*(1+salary_escalation)^2*(1+bhxh_rate) | AA15: =AA5*salary_mgmt*1*(1+salary_escalation)^2*(1+bhxh_rate) | AB15: =AB5*salary_mgmt*1*(1+salary_escalation)^2*(1+bhxh_rate) | ... AF15: =AF5*salary_mgmt*1*(1+salary_escalation)^2*(1+bhxh_rate) | AG15: =AG5*salary_mgmt*3*(1+salary_escalation)^3*(1+bhxh_rate) | AH15: =AH5*salary_mgmt*3*(1+salary_escalation)^3*(1+bhxh_rate) | AI15: =AI5*salary_mgmt*3*(1+salary_escalation)^3*(1+bhxh_rate) | AJ15: =AJ5*salary_mgmt*3*(1+salary_escalation)^3*(1+bhxh_rate) | AK15: =AK5*salary_mgmt*3*(1+salary_escalation)^4*(1+bhxh_rate) | AL15: =AL5*salary_mgmt*3*(1+salary_escalation)^4*(1+bhxh_rate) | AM15: =AM5*salary_mgmt*3*(1+salary_escalation)^4*(1+bhxh_rate) | AN15: =AN5*salary_mgmt*3*(1+salary_escalation)^4*(1+bhxh_rate) | AO15: =AO5*salary_mgmt*3*(1+salary_escalation)^5*(1+bhxh_rate) | AP15: =AP5*salary_mgmt*3*(1+salary_escalation)^5*(1+bhxh_rate) | AQ15: =AQ5*salary_mgmt*3*(1+salary_escalation)^5*(1+bhxh_rate) | AR15: =AR5*salary_mgmt*3*(1+salary_escalation)^5*(1+bhxh_rate)
A16: CP Phát triển | B16: Tr VND | C16: =C6*salary_dev*1*(1+salary_escalation)^0*(1+bhxh_rate) | D16: =D6*salary_dev*1*(1+salary_escalation)^0*(1+bhxh_rate) | E16: =E6*salary_dev*1*(1+salary_escalation)^0*(1+bhxh_rate) | F16: =F6*salary_dev*1*(1+salary_escalation)^0*(1+bhxh_rate) | G16: =G6*salary_dev*1*(1+salary_escalation)^0*(1+bhxh_rate) | H16: =H6*salary_dev*1*(1+salary_escalation)^0*(1+bhxh_rate) | I16: =I6*salary_dev*1*(1+salary_escalation)^1*(1+bhxh_rate) | J16: =J6*salary_dev*1*(1+salary_escalation)^1*(1+bhxh_rate) | K16: =K6*salary_dev*1*(1+salary_escalation)^1*(1+bhxh_rate) | L16: =L6*salary_dev*1*(1+salary_escalation)^1*(1+bhxh_rate) | M16: =M6*salary_dev*1*(1+salary_escalation)^1*(1+bhxh_rate) | N16: =N6*salary_dev*1*(1+salary_escalation)^1*(1+bhxh_rate) | O16: =O6*salary_dev*1*(1+salary_escalation)^1*(1+bhxh_rate) | P16: =P6*salary_dev*1*(1+salary_escalation)^1*(1+bhxh_rate) | ... T16: =T6*salary_dev*1*(1+salary_escalation)^1*(1+bhxh_rate) | U16: =U6*salary_dev*1*(1+salary_escalation)^2*(1+bhxh_rate) | V16: =V6*salary_dev*1*(1+salary_escalation)^2*(1+bhxh_rate) | W16: =W6*salary_dev*1*(1+salary_escalation)^2*(1+bhxh_rate) | X16: =X6*salary_dev*1*(1+salary_escalation)^2*(1+bhxh_rate) | Y16: =Y6*salary_dev*1*(1+salary_escalation)^2*(1+bhxh_rate) | Z16: =Z6*salary_dev*1*(1+salary_escalation)^2*(1+bhxh_rate) | AA16: =AA6*salary_dev*1*(1+salary_escalation)^2*(1+bhxh_rate) | AB16: =AB6*salary_dev*1*(1+salary_escalation)^2*(1+bhxh_rate) | ... AF16: =AF6*salary_dev*1*(1+salary_escalation)^2*(1+bhxh_rate) | AG16: =AG6*salary_dev*3*(1+salary_escalation)^3*(1+bhxh_rate) | AH16: =AH6*salary_dev*3*(1+salary_escalation)^3*(1+bhxh_rate) | AI16: =AI6*salary_dev*3*(1+salary_escalation)^3*(1+bhxh_rate) | AJ16: =AJ6*salary_dev*3*(1+salary_escalation)^3*(1+bhxh_rate) | AK16: =AK6*salary_dev*3*(1+salary_escalation)^4*(1+bhxh_rate) | AL16: =AL6*salary_dev*3*(1+salary_escalation)^4*(1+bhxh_rate) | AM16: =AM6*salary_dev*3*(1+salary_escalation)^4*(1+bhxh_rate) | AN16: =AN6*salary_dev*3*(1+salary_escalation)^4*(1+bhxh_rate) | AO16: =AO6*salary_dev*3*(1+salary_escalation)^5*(1+bhxh_rate) | AP16: =AP6*salary_dev*3*(1+salary_escalation)^5*(1+bhxh_rate) | AQ16: =AQ6*salary_dev*3*(1+salary_escalation)^5*(1+bhxh_rate) | AR16: =AR6*salary_dev*3*(1+salary_escalation)^5*(1+bhxh_rate)
A17: CP Vận hành KD | B17: Tr VND | C17: =C7*salary_bizops*1*(1+salary_escalation)^0*(1+bhxh_rate) | D17: =D7*salary_bizops*1*(1+salary_escalation)^0*(1+bhxh_rate) | E17: =E7*salary_bizops*1*(1+salary_escalation)^0*(1+bhxh_rate) | F17: =F7*salary_bizops*1*(1+salary_escalation)^0*(1+bhxh_rate) | G17: =G7*salary_bizops*1*(1+salary_escalation)^0*(1+bhxh_rate) | H17: =H7*salary_bizops*1*(1+salary_escalation)^0*(1+bhxh_rate) | I17: =I7*salary_bizops*1*(1+salary_escalation)^1*(1+bhxh_rate) | J17: =J7*salary_bizops*1*(1+salary_escalation)^1*(1+bhxh_rate) | K17: =K7*salary_bizops*1*(1+salary_escalation)^1*(1+bhxh_rate) | L17: =L7*salary_bizops*1*(1+salary_escalation)^1*(1+bhxh_rate) | M17: =M7*salary_bizops*1*(1+salary_escalation)^1*(1+bhxh_rate) | N17: =N7*salary_bizops*1*(1+salary_escalation)^1*(1+bhxh_rate) | O17: =O7*salary_bizops*1*(1+salary_escalation)^1*(1+bhxh_rate) | P17: =P7*salary_bizops*1*(1+salary_escalation)^1*(1+bhxh_rate) | ... T17: =T7*salary_bizops*1*(1+salary_escalation)^1*(1+bhxh_rate) | U17: =U7*salary_bizops*1*(1+salary_escalation)^2*(1+bhxh_rate) | V17: =V7*salary_bizops*1*(1+salary_escalation)^2*(1+bhxh_rate) | W17: =W7*salary_bizops*1*(1+salary_escalation)^2*(1+bhxh_rate) | X17: =X7*salary_bizops*1*(1+salary_escalation)^2*(1+bhxh_rate) | Y17: =Y7*salary_bizops*1*(1+salary_escalation)^2*(1+bhxh_rate) | Z17: =Z7*salary_bizops*1*(1+salary_escalation)^2*(1+bhxh_rate) | AA17: =AA7*salary_bizops*1*(1+salary_escalation)^2*(1+bhxh_rate) | AB17: =AB7*salary_bizops*1*(1+salary_escalation)^2*(1+bhxh_rate) | ... AF17: =AF7*salary_bizops*1*(1+salary_escalation)^2*(1+bhxh_rate) | AG17: =AG7*salary_bizops*3*(1+salary_escalation)^3*(1+bhxh_rate) | AH17: =AH7*salary_bizops*3*(1+salary_escalation)^3*(1+bhxh_rate) | AI17: =AI7*salary_bizops*3*(1+salary_escalation)^3*(1+bhxh_rate) | AJ17: =AJ7*salary_bizops*3*(1+salary_escalation)^3*(1+bhxh_rate) | AK17: =AK7*salary_bizops*3*(1+salary_escalation)^4*(1+bhxh_rate) | AL17: =AL7*salary_bizops*3*(1+salary_escalation)^4*(1+bhxh_rate) | AM17: =AM7*salary_bizops*3*(1+salary_escalation)^4*(1+bhxh_rate) | AN17: =AN7*salary_bizops*3*(1+salary_escalation)^4*(1+bhxh_rate) | AO17: =AO7*salary_bizops*3*(1+salary_escalation)^5*(1+bhxh_rate) | AP17: =AP7*salary_bizops*3*(1+salary_escalation)^5*(1+bhxh_rate) | AQ17: =AQ7*salary_bizops*3*(1+salary_escalation)^5*(1+bhxh_rate) | AR17: =AR7*salary_bizops*3*(1+salary_escalation)^5*(1+bhxh_rate)
A18: CP Dữ liệu & Phân tích | B18: Tr VND | C18: =C8*salary_data*1*(1+salary_escalation)^0*(1+bhxh_rate) | D18: =D8*salary_data*1*(1+salary_escalation)^0*(1+bhxh_rate) | E18: =E8*salary_data*1*(1+salary_escalation)^0*(1+bhxh_rate) | F18: =F8*salary_data*1*(1+salary_escalation)^0*(1+bhxh_rate) | G18: =G8*salary_data*1*(1+salary_escalation)^0*(1+bhxh_rate) | H18: =H8*salary_data*1*(1+salary_escalation)^0*(1+bhxh_rate) | I18: =I8*salary_data*1*(1+salary_escalation)^1*(1+bhxh_rate) | J18: =J8*salary_data*1*(1+salary_escalation)^1*(1+bhxh_rate) | K18: =K8*salary_data*1*(1+salary_escalation)^1*(1+bhxh_rate) | L18: =L8*salary_data*1*(1+salary_escalation)^1*(1+bhxh_rate) | M18: =M8*salary_data*1*(1+salary_escalation)^1*(1+bhxh_rate) | N18: =N8*salary_data*1*(1+salary_escalation)^1*(1+bhxh_rate) | O18: =O8*salary_data*1*(1+salary_escalation)^1*(1+bhxh_rate) | P18: =P8*salary_data*1*(1+salary_escalation)^1*(1+bhxh_rate) | ... T18: =T8*salary_data*1*(1+salary_escalation)^1*(1+bhxh_rate) | U18: =U8*salary_data*1*(1+salary_escalation)^2*(1+bhxh_rate) | V18: =V8*salary_data*1*(1+salary_escalation)^2*(1+bhxh_rate) | W18: =W8*salary_data*1*(1+salary_escalation)^2*(1+bhxh_rate) | X18: =X8*salary_data*1*(1+salary_escalation)^2*(1+bhxh_rate) | Y18: =Y8*salary_data*1*(1+salary_escalation)^2*(1+bhxh_rate) | Z18: =Z8*salary_data*1*(1+salary_escalation)^2*(1+bhxh_rate) | AA18: =AA8*salary_data*1*(1+salary_escalation)^2*(1+bhxh_rate) | AB18: =AB8*salary_data*1*(1+salary_escalation)^2*(1+bhxh_rate) | ... AF18: =AF8*salary_data*1*(1+salary_escalation)^2*(1+bhxh_rate) | AG18: =AG8*salary_data*3*(1+salary_escalation)^3*(1+bhxh_rate) | AH18: =AH8*salary_data*3*(1+salary_escalation)^3*(1+bhxh_rate) | AI18: =AI8*salary_data*3*(1+salary_escalation)^3*(1+bhxh_rate) | AJ18: =AJ8*salary_data*3*(1+salary_escalation)^3*(1+bhxh_rate) | AK18: =AK8*salary_data*3*(1+salary_escalation)^4*(1+bhxh_rate) | AL18: =AL8*salary_data*3*(1+salary_escalation)^4*(1+bhxh_rate) | AM18: =AM8*salary_data*3*(1+salary_escalation)^4*(1+bhxh_rate) | AN18: =AN8*salary_data*3*(1+salary_escalation)^4*(1+bhxh_rate) | AO18: =AO8*salary_data*3*(1+salary_escalation)^5*(1+bhxh_rate) | AP18: =AP8*salary_data*3*(1+salary_escalation)^5*(1+bhxh_rate) | AQ18: =AQ8*salary_data*3*(1+salary_escalation)^5*(1+bhxh_rate) | AR18: =AR8*salary_data*3*(1+salary_escalation)^5*(1+bhxh_rate)
A19: TỔNG LƯƠNG | B19: Tr VND | C19: =C15+C16+C17+C18 | D19: =D15+D16+D17+D18 | E19: =E15+E16+E17+E18 | F19: =F15+F16+F17+F18 | G19: =G15+G16+G17+G18 | H19: =H15+H16+H17+H18 | I19: =I15+I16+I17+I18 | J19: =J15+J16+J17+J18 | ... AR19: =AR15+AR16+AR17+AR18
A20: Tuyển dụng | B20: Tr VND | C20: =C12*30*12*recruit_cost_pct | D20: =D12*30*12*recruit_cost_pct | E20: =E12*30*12*recruit_cost_pct | F20: =F12*30*12*recruit_cost_pct | G20: =G12*30*12*recruit_cost_pct | H20: =H12*30*12*recruit_cost_pct | I20: =I12*30*12*recruit_cost_pct | J20: =J12*30*12*recruit_cost_pct | ... AR20: =AR12*30*12*recruit_cost_pct
A21: TỔNG CHI PHÍ NHÂN SỰ | B21: Tr VND | C21: =C19+C20 | D21: =D19+D20 | E21: =E19+E20 | F21: =F19+F20 | G21: =G19+G20 | H21: =H19+H20 | I21: =I19+I20 | J21: =J19+J20 | ... AR21: =AR19+AR20

Sheet Quy mô thị trường
A1: QUY MÔ THỊ TRƯỜNG & TĂNG TRƯỞNG
A3: Chỉ số kỳ | B3: idx | C3: 0 | D3: 1 | E3: 2 | F3: 3 | G3: 4 | H3: 5 | I3: 6 | J3: 7 | K3: 8 | L3: 9 | M3: 10 | N3: 11 | O3: 12 | P3: 13 | Q3: 14 | R3: 15 | S3: 16 | T3: 17 | U3: 18 | V3: 19 | W3: 20 | X3: 21 | Y3: 22 | Z3: 23 | AA3: 24 | AB3: 25 | AC3: 26 | AD3: 27 | AE3: 28 | AF3: 29 | AG3: 30 | AH3: 31 | AI3: 32 | AJ3: 33 | AK3: 34 | AL3: 35 | AM3: 36 | AN3: 37 | AO3: 38 | AP3: 39 | AQ3: 40 | AR3: 41
A4: Năm phân số | B4: năm | C4: =base_year+(start_month-1+C3)/12 | D4: =base_year+(start_month-1+D3)/12 | E4: =base_year+(start_month-1+E3)/12 | F4: =base_year+(start_month-1+F3)/12 | G4: =base_year+(start_month-1+G3)/12 | H4: =base_year+(start_month-1+H3)/12 | I4: =base_year+(start_month-1+I3)/12 | J4: =base_year+(start_month-1+J3)/12 | ... AF4: =base_year+(start_month-1+AF3)/12 | AG4: =2028+(1-0.5)/12 | AH4: =2028+(4-0.5)/12 | AI4: =2028+(7-0.5)/12 | AJ4: =2028+(10-0.5)/12 | AK4: =2028+(13-0.5)/12 | AL4: =2028+(16-0.5)/12 | AM4: =2028+(19-0.5)/12 | AN4: =2028+(22-0.5)/12 | AO4: =2028+(25-0.5)/12 | AP4: =2028+(28-0.5)/12 | AQ4: =2028+(31-0.5)/12 | AR4: =2028+(34-0.5)/12
A5: Năm từ gốc | B5: năm | C5: =FLOOR(C4-base_year,1) | D5: =FLOOR(D4-base_year,1) | E5: =FLOOR(E4-base_year,1) | F5: =FLOOR(F4-base_year,1) | G5: =FLOOR(G4-base_year,1) | H5: =FLOOR(H4-base_year,1) | I5: =FLOOR(I4-base_year,1) | J5: =FLOOR(J4-base_year,1) | ... AR5: =FLOOR(AR4-base_year,1)
A6: Ước số kỳ | B6: chia | C6: 12 | D6: 12 | E6: 12 | F6: 12 | G6: 12 | H6: 12 | I6: 12 | J6: 12 | K6: 12 | L6: 12 | M6: 12 | N6: 12 | O6: 12 | P6: 12 | Q6: 12 | R6: 12 | S6: 12 | T6: 12 | U6: 12 | V6: 12 | W6: 12 | X6: 12 | Y6: 12 | Z6: 12 | AA6: 12 | AB6: 12 | AC6: 12 | AD6: 12 | AE6: 12 | AF6: 12 | AG6: 4 | AH6: 4 | AI6: 4 | AJ6: 4 | AK6: 4 | AL6: 4 | AM6: 4 | AN6: 4 | AO6: 4 | AP6: 4 | AQ6: 4 | AR6: 4
A7: Số tháng/kỳ | B7: tháng | C7: 1 | D7: 1 | E7: 1 | F7: 1 | G7: 1 | H7: 1 | I7: 1 | J7: 1 | K7: 1 | L7: 1 | M7: 1 | N7: 1 | O7: 1 | P7: 1 | Q7: 1 | R7: 1 | S7: 1 | T7: 1 | U7: 1 | V7: 1 | W7: 1 | X7: 1 | Y7: 1 | Z7: 1 | AA7: 1 | AB7: 1 | AC7: 1 | AD7: 1 | AE7: 1 | AF7: 1 | AG7: 3 | AH7: 3 | AI7: 3 | AJ7: 3 | AK7: 3 | AL7: 3 | AM7: 3 | AN7: 3 | AO7: 3 | AP7: 3 | AQ7: 3 | AR7: 3
A9: Hạng mục | B9: ĐVT | C9: Th7 2025 | D9: Th8 2025 | E9: Th9 2025 | F9: Th10 2025 | G9: Th11 2025 | H9: Th12 2025 | I9: Th1 2026 | J9: Th2 2026 | K9: Th3 2026 | L9: Th4 2026 | M9: Th5 2026 | N9: Th6 2026 | O9: Th7 2026 | P9: Th8 2026 | Q9: Th9 2026 | R9: Th10 2026 | S9: Th11 2026 | T9: Th12 2026 | U9: Th1 2027 | V9: Th2 2027 | W9: Th3 2027 | X9: Th4 2027 | Y9: Th5 2027 | Z9: Th6 2027 | AA9: Th7 2027 | AB9: Th8 2027 | AC9: Th9 2027 | AD9: Th10 2027 | AE9: Th11 2027 | AF9: Th12 2027 | AG9: Q1 2028 | AH9: Q2 2028 | AI9: Q3 2028 | AJ9: Q4 2028 | AK9: Q1 2029 | AL9: Q2 2029 | AM9: Q3 2029 | AN9: Q4 2029 | AO9: Q1 2030 | AP9: Q2 2030 | AQ9: Q3 2030 | AR9: Q4 2030
A10: TT TMĐT du lịch | B10: Tỷ VND | C10: =ecom_market_base*(1+ecom_growth_rate)^C5/C6 | D10: =ecom_market_base*(1+ecom_growth_rate)^D5/D6 | E10: =ecom_market_base*(1+ecom_growth_rate)^E5/E6 | F10: =ecom_market_base*(1+ecom_growth_rate)^F5/F6 | G10: =ecom_market_base*(1+ecom_growth_rate)^G5/G6 | H10: =ecom_market_base*(1+ecom_growth_rate)^H5/H6 | I10: =ecom_market_base*(1+ecom_growth_rate)^I5/I6 | J10: =ecom_market_base*(1+ecom_growth_rate)^J5/J6 | ... AR10: =ecom_market_base*(1+ecom_growth_rate)^AR5/AR6
A12: TĂNG TRƯỞNG DN (S-CURVE)
A13: DN thô (S-curve) | B13: DN | C13: =MAX(pilot_count,adoption_max/(1+EXP(-adoption_steepness*(C4-adoption_midpoint)))) | D13: =MAX(pilot_count,adoption_max/(1+EXP(-adoption_steepness*(D4-adoption_midpoint)))) | E13: =MAX(pilot_count,adoption_max/(1+EXP(-adoption_steepness*(E4-adoption_midpoint)))) | F13: =MAX(pilot_count,adoption_max/(1+EXP(-adoption_steepness*(F4-adoption_midpoint)))) | G13: =MAX(pilot_count,adoption_max/(1+EXP(-adoption_steepness*(G4-adoption_midpoint)))) | H13: =MAX(pilot_count,adoption_max/(1+EXP(-adoption_steepness*(H4-adoption_midpoint)))) | I13: =MAX(pilot_count,adoption_max/(1+EXP(-adoption_steepness*(I4-adoption_midpoint)))) | J13: =MAX(pilot_count,adoption_max/(1+EXP(-adoption_steepness*(J4-adoption_midpoint)))) | ... AR13: =MAX(pilot_count,adoption_max/(1+EXP(-adoption_steepness*(AR4-adoption_midpoint))))
A14: DN rời bỏ | B14: DN | C14: =0 | D14: =ROUND(D13*churn_rate/D6,0) | E14: =ROUND(E13*churn_rate/E6,0) | F14: =ROUND(F13*churn_rate/F6,0) | G14: =ROUND(G13*churn_rate/G6,0) | H14: =ROUND(H13*churn_rate/H6,0) | I14: =ROUND(I13*churn_rate/I6,0) | J14: =ROUND(J13*churn_rate/J6,0) | K14: =ROUND(K13*churn_rate/K6,0) | ... AR14: =ROUND(AR13*churn_rate/AR6,0)
A15: DN hoạt động ròng | B15: DN | C15: =C13-C14 | D15: =D13-D14 | E15: =E13-E14 | F15: =F13-F14 | G15: =G13-G14 | H15: =H13-H14 | I15: =I13-I14 | J15: =J13-J14 | ... AR15: =AR13-AR14
A16: DN mới/kỳ | B16: DN | C16: =C15 | D16: =MAX(0,D15-C15) | E16: =MAX(0,E15-D15) | F16: =MAX(0,F15-E15) | G16: =MAX(0,G15-F15) | H16: =MAX(0,H15-G15) | I16: =MAX(0,I15-H15) | J16: =MAX(0,J15-I15) | K16: =MAX(0,K15-J15) | ... AR16: =MAX(0,AR15-AQ15)
A17: VCR (triệu bản ghi) | B17: Tr | C17: =C15*vcr_per_enterprise*C7/1000000 | D17: =D15*vcr_per_enterprise*D7/1000000 | E17: =E15*vcr_per_enterprise*E7/1000000 | F17: =F15*vcr_per_enterprise*F7/1000000 | G17: =G15*vcr_per_enterprise*G7/1000000 | H17: =H15*vcr_per_enterprise*H7/1000000 | I17: =I15*vcr_per_enterprise*I7/1000000 | J17: =J15*vcr_per_enterprise*J7/1000000 | ... AR17: =AR15*vcr_per_enterprise*AR7/1000000

Sheet Doanh thu
A1: BẢNG DOANH THU (Tr VND)
A3: Hạng mục | B3: ĐVT | C3: Th7 2025 | D3: Th8 2025 | E3: Th9 2025 | F3: Th10 2025 | G3: Th11 2025 | H3: Th12 2025 | I3: Th1 2026 | J3: Th2 2026 | K3: Th3 2026 | L3: Th4 2026 | M3: Th5 2026 | N3: Th6 2026 | O3: Th7 2026 | P3: Th8 2026 | Q3: Th9 2026 | R3: Th10 2026 | S3: Th11 2026 | T3: Th12 2026 | U3: Th1 2027 | V3: Th2 2027 | W3: Th3 2027 | X3: Th4 2027 | Y3: Th5 2027 | Z3: Th6 2027 | AA3: Th7 2027 | AB3: Th8 2027 | AC3: Th9 2027 | AD3: Th10 2027 | AE3: Th11 2027 | AF3: Th12 2027 | AG3: Q1 2028 | AH3: Q2 2028 | AI3: Q3 2028 | AJ3: Q4 2028 | AK3: Q1 2029 | AL3: Q2 2029 | AM3: Q3 2029 | AN3: Q4 2029 | AO3: Q1 2030 | AP3: Q2 2030 | AQ3: Q3 2030 | AR3: Q4 2030
A4: GIAI ĐOẠN 1
A5: Phí chứng nhận | B5: Tr VND | C5: ='Quy mô thị trường'!C15*cert_fee_yr1*(1+cert_fee_escalation)^'Quy mô thị trường'!C5/'Quy mô thị trường'!C6 | D5: ='Quy mô thị trường'!D15*cert_fee_yr1*(1+cert_fee_escalation)^'Quy mô thị trường'!D5/'Quy mô thị trường'!D6 | E5: ='Quy mô thị trường'!E15*cert_fee_yr1*(1+cert_fee_escalation)^'Quy mô thị trường'!E5/'Quy mô thị trường'!E6 | F5: ='Quy mô thị trường'!F15*cert_fee_yr1*(1+cert_fee_escalation)^'Quy mô thị trường'!F5/'Quy mô thị trường'!F6 | G5: ='Quy mô thị trường'!G15*cert_fee_yr1*(1+cert_fee_escalation)^'Quy mô thị trường'!G5/'Quy mô thị trường'!G6 | H5: ='Quy mô thị trường'!H15*cert_fee_yr1*(1+cert_fee_escalation)^'Quy mô thị trường'!H5/'Quy mô thị trường'!H6 | I5: ='Quy mô thị trường'!I15*cert_fee_yr1*(1+cert_fee_escalation)^'Quy mô thị trường'!I5/'Quy mô thị trường'!I6 | J5: ='Quy mô thị trường'!J15*cert_fee_yr1*(1+cert_fee_escalation)^'Quy mô thị trường'!J5/'Quy mô thị trường'!J6 | ... AR5: ='Quy mô thị trường'!AR15*cert_fee_yr1*(1+cert_fee_escalation)^'Quy mô thị trường'!AR5/'Quy mô thị trường'!AR6
A6: Đào tạo & tư vấn | B6: Tr VND | C6: ='Quy mô thị trường'!C15*training_pct*training_fee/'Quy mô thị trường'!C6 | D6: ='Quy mô thị trường'!D15*training_pct*training_fee/'Quy mô thị trường'!D6 | E6: ='Quy mô thị trường'!E15*training_pct*training_fee/'Quy mô thị trường'!E6 | F6: ='Quy mô thị trường'!F15*training_pct*training_fee/'Quy mô thị trường'!F6 | G6: ='Quy mô thị trường'!G15*training_pct*training_fee/'Quy mô thị trường'!G6 | H6: ='Quy mô thị trường'!H15*training_pct*training_fee/'Quy mô thị trường'!H6 | I6: ='Quy mô thị trường'!I15*training_pct*training_fee/'Quy mô thị trường'!I6 | J6: ='Quy mô thị trường'!J15*training_pct*training_fee/'Quy mô thị trường'!J6 | ... AR6: ='Quy mô thị trường'!AR15*training_pct*training_fee/'Quy mô thị trường'!AR6
A7: Phí kiểm toán | B7: Tr VND | C7: ='Quy mô thị trường'!C15*audit_fee/'Quy mô thị trường'!C6 | D7: ='Quy mô thị trường'!D15*audit_fee/'Quy mô thị trường'!D6 | E7: ='Quy mô thị trường'!E15*audit_fee/'Quy mô thị trường'!E6 | F7: ='Quy mô thị trường'!F15*audit_fee/'Quy mô thị trường'!F6 | G7: ='Quy mô thị trường'!G15*audit_fee/'Quy mô thị trường'!G6 | H7: ='Quy mô thị trường'!H15*audit_fee/'Quy mô thị trường'!H6 | I7: ='Quy mô thị trường'!I15*audit_fee/'Quy mô thị trường'!I6 | J7: ='Quy mô thị trường'!J15*audit_fee/'Quy mô thị trường'!J6 | ... AR7: ='Quy mô thị trường'!AR15*audit_fee/'Quy mô thị trường'!AR6
A8: Tổng GĐ1 | C8: =SUM(C5:C7) | D8: =SUM(D5:D7) | E8: =SUM(E5:E7) | F8: =SUM(F5:F7) | G8: =SUM(G5:G7) | H8: =SUM(H5:H7) | I8: =SUM(I5:I7) | J8: =SUM(J5:J7) | ... AR8: =SUM(AR5:AR7)
A10: GIAI ĐOẠN 2 (có điều kiện)
A11: Phí giao dịch | B11: Tr VND | C11: =IF('Quy mô thị trường'!C15>=stage2_gate,'Quy mô thị trường'!C10*platform_market_share*tx_take_rate*1000,0) | D11: =IF('Quy mô thị trường'!D15>=stage2_gate,'Quy mô thị trường'!D10*platform_market_share*tx_take_rate*1000,0) | E11: =IF('Quy mô thị trường'!E15>=stage2_gate,'Quy mô thị trường'!E10*platform_market_share*tx_take_rate*1000,0) | F11: =IF('Quy mô thị trường'!F15>=stage2_gate,'Quy mô thị trường'!F10*platform_market_share*tx_take_rate*1000,0) | G11: =IF('Quy mô thị trường'!G15>=stage2_gate,'Quy mô thị trường'!G10*platform_market_share*tx_take_rate*1000,0) | H11: =IF('Quy mô thị trường'!H15>=stage2_gate,'Quy mô thị trường'!H10*platform_market_share*tx_take_rate*1000,0) | I11: =IF('Quy mô thị trường'!I15>=stage2_gate,'Quy mô thị trường'!I10*platform_market_share*tx_take_rate*1000,0) | J11: =IF('Quy mô thị trường'!J15>=stage2_gate,'Quy mô thị trường'!J10*platform_market_share*tx_take_rate*1000,0) | ... AR11: =IF('Quy mô thị trường'!AR15>=stage2_gate,'Quy mô thị trường'!AR10*platform_market_share*tx_take_rate*1000,0)
A12: DaaS | B12: Tr VND | C12: =IF('Quy mô thị trường'!C15>=stage2_gate,'Quy mô thị trường'!C17*daas_price,0) | D12: =IF('Quy mô thị trường'!D15>=stage2_gate,'Quy mô thị trường'!D17*daas_price,0) | E12: =IF('Quy mô thị trường'!E15>=stage2_gate,'Quy mô thị trường'!E17*daas_price,0) | F12: =IF('Quy mô thị trường'!F15>=stage2_gate,'Quy mô thị trường'!F17*daas_price,0) | G12: =IF('Quy mô thị trường'!G15>=stage2_gate,'Quy mô thị trường'!G17*daas_price,0) | H12: =IF('Quy mô thị trường'!H15>=stage2_gate,'Quy mô thị trường'!H17*daas_price,0) | I12: =IF('Quy mô thị trường'!I15>=stage2_gate,'Quy mô thị trường'!I17*daas_price,0) | J12: =IF('Quy mô thị trường'!J15>=stage2_gate,'Quy mô thị trường'!J17*daas_price,0) | ... AR12: =IF('Quy mô thị trường'!AR15>=stage2_gate,'Quy mô thị trường'!AR17*daas_price,0)
A13: Quảng cáo | B13: Tr VND | C13: =IF('Quy mô thị trường'!C15>=stage2_gate,ad_impressions_base*'Quy mô thị trường'!C7*'Quy mô thị trường'!C15/1000*ad_cpm/1000,0) | D13: =IF('Quy mô thị trường'!D15>=stage2_gate,ad_impressions_base*'Quy mô thị trường'!D7*'Quy mô thị trường'!D15/1000*ad_cpm/1000,0) | E13: =IF('Quy mô thị trường'!E15>=stage2_gate,ad_impressions_base*'Quy mô thị trường'!E7*'Quy mô thị trường'!E15/1000*ad_cpm/1000,0) | F13: =IF('Quy mô thị trường'!F15>=stage2_gate,ad_impressions_base*'Quy mô thị trường'!F7*'Quy mô thị trường'!F15/1000*ad_cpm/1000,0) | G13: =IF('Quy mô thị trường'!G15>=stage2_gate,ad_impressions_base*'Quy mô thị trường'!G7*'Quy mô thị trường'!G15/1000*ad_cpm/1000,0) | H13: =IF('Quy mô thị trường'!H15>=stage2_gate,ad_impressions_base*'Quy mô thị trường'!H7*'Quy mô thị trường'!H15/1000*ad_cpm/1000,0) | I13: =IF('Quy mô thị trường'!I15>=stage2_gate,ad_impressions_base*'Quy mô thị trường'!I7*'Quy mô thị trường'!I15/1000*ad_cpm/1000,0) | J13: =IF('Quy mô thị trường'!J15>=stage2_gate,ad_impressions_base*'Quy mô thị trường'!J7*'Quy mô thị trường'!J15/1000*ad_cpm/1000,0) | ... AR13: =IF('Quy mô thị trường'!AR15>=stage2_gate,ad_impressions_base*'Quy mô thị trường'!AR7*'Quy mô thị trường'!AR15/1000*ad_cpm/1000,0)
A14: Tổng GĐ2 | C14: =SUM(C11:C13) | D14: =SUM(D11:D13) | E14: =SUM(E11:E13) | F14: =SUM(F11:F13) | G14: =SUM(G11:G13) | H14: =SUM(H11:H13) | I14: =SUM(I11:I13) | J14: =SUM(J11:J13) | ... AR14: =SUM(AR11:AR13)
A16: TỔNG DOANH THU | C16: =C8+C14 | D16: =D8+D14 | E16: =E8+E14 | F16: =F8+F14 | G16: =G8+G14 | H16: =H8+H14 | I16: =I8+I14 | J16: =J8+J14 | ... AR16: =AR8+AR14
A18: GIÁ VỐN
A19: Phí thanh toán | B19: Tr VND | C19: =C11*payment_proc_pct | D19: =D11*payment_proc_pct | E19: =E11*payment_proc_pct | F19: =F11*payment_proc_pct | G19: =G11*payment_proc_pct | H19: =H11*payment_proc_pct | I19: =I11*payment_proc_pct | J19: =J11*payment_proc_pct | ... AR19: =AR11*payment_proc_pct
A20: TỔNG GIÁ VỐN | C20: =C19 | D20: =D19 | E20: =E19 | F20: =F19 | G20: =G19 | H20: =H19 | I20: =I19 | J20: =J19 | ... AR20: =AR19

Sheet Chi phí
A1: BẢNG CHI PHÍ (Tr VND)
A3: Hạng mục | B3: ĐVT | C3: Th7 2025 | D3: Th8 2025 | E3: Th9 2025 | F3: Th10 2025 | G3: Th11 2025 | H3: Th12 2025 | I3: Th1 2026 | J3: Th2 2026 | K3: Th3 2026 | L3: Th4 2026 | M3: Th5 2026 | N3: Th6 2026 | O3: Th7 2026 | P3: Th8 2026 | Q3: Th9 2026 | R3: Th10 2026 | S3: Th11 2026 | T3: Th12 2026 | U3: Th1 2027 | V3: Th2 2027 | W3: Th3 2027 | X3: Th4 2027 | Y3: Th5 2027 | Z3: Th6 2027 | AA3: Th7 2027 | AB3: Th8 2027 | AC3: Th9 2027 | AD3: Th10 2027 | AE3: Th11 2027 | AF3: Th12 2027 | AG3: Q1 2028 | AH3: Q2 2028 | AI3: Q3 2028 | AJ3: Q4 2028 | AK3: Q1 2029 | AL3: Q2 2029 | AM3: Q3 2029 | AN3: Q4 2029 | AO3: Q1 2030 | AP3: Q2 2030 | AQ3: Q3 2030 | AR3: Q4 2030
A4: CAPEX
A5: Phát triển nền tảng | B5: Tr VND | C5: =capex_total/6 | D5: =capex_total/6 | E5: =capex_total/6 | F5: =capex_total/6 | G5: =capex_total/6 | H5: =capex_total/6 | I5: =0 | J5: =0 | K5: =0 | L5: =0 | M5: =0 | N5: =0 | O5: =0 | P5: =0 | ... AR5: =0
A6: Bảo trì | B6: Tr VND | C6: =0 | D6: =0 | E6: =0 | F6: =0 | G6: =0 | H6: =0 | I6: =capex_total*capex_maintenance_pct/'Quy mô thị trường'!I6 | J6: =capex_total*capex_maintenance_pct/'Quy mô thị trường'!J6 | K6: =capex_total*capex_maintenance_pct/'Quy mô thị trường'!K6 | L6: =capex_total*capex_maintenance_pct/'Quy mô thị trường'!L6 | M6: =capex_total*capex_maintenance_pct/'Quy mô thị trường'!M6 | N6: =capex_total*capex_maintenance_pct/'Quy mô thị trường'!N6 | O6: =capex_total*capex_maintenance_pct/'Quy mô thị trường'!O6 | P6: =capex_total*capex_maintenance_pct/'Quy mô thị trường'!P6 | ... AR6: =capex_total*capex_maintenance_pct/'Quy mô thị trường'!AR6
A7: TỔNG CAPEX | C7: =C5+C6 | D7: =D5+D6 | E7: =E5+E6 | F7: =F5+F6 | G7: =G5+G6 | H7: =H5+H6 | I7: =I5+I6 | J7: =J5+J6 | ... AR7: =AR5+AR6
A9: OPEX
A10: Nhân sự (từ Nhân sự) | B10: Tr VND | C10: ='Nhân sự'!C21 | D10: ='Nhân sự'!D21 | E10: ='Nhân sự'!E21 | F10: ='Nhân sự'!F21 | G10: ='Nhân sự'!G21 | H10: ='Nhân sự'!H21 | I10: ='Nhân sự'!I21 | J10: ='Nhân sự'!J21 | ... AR10: ='Nhân sự'!AR21
A11: Marketing | B11: Tr VND | C11: =opex_marketing*(1+marketing_growth)^'Quy mô thị trường'!C5/'Quy mô thị trường'!C6 | D11: =opex_marketing*(1+marketing_growth)^'Quy mô thị trường'!D5/'Quy mô thị trường'!D6 | E11: =opex_marketing*(1+marketing_growth)^'Quy mô thị trường'!E5/'Quy mô thị trường'!E6 | F11: =opex_marketing*(1+marketing_growth)^'Quy mô thị trường'!F5/'Quy mô thị trường'!F6 | G11: =opex_marketing*(1+marketing_growth)^'Quy mô thị trường'!G5/'Quy mô thị trường'!G6 | H11: =opex_marketing*(1+marketing_growth)^'Quy mô thị trường'!H5/'Quy mô thị trường'!H6 | I11: =opex_marketing*(1+marketing_growth)^'Quy mô thị trường'!I5/'Quy mô thị trường'!I6 | J11: =opex_marketing*(1+marketing_growth)^'Quy mô thị trường'!J5/'Quy mô thị trường'!J6 | ... AR11: =opex_marketing*(1+marketing_growth)^'Quy mô thị trường'!AR5/'Quy mô thị trường'!AR6
A12: Thương hiệu & sự kiện | B12: Tr VND | C12: =opex_branding/'Quy mô thị trường'!C6 | D12: =opex_branding/'Quy mô thị trường'!D6 | E12: =opex_branding/'Quy mô thị trường'!E6 | F12: =opex_branding/'Quy mô thị trường'!F6 | G12: =opex_branding/'Quy mô thị trường'!G6 | H12: =opex_branding/'Quy mô thị trường'!H6 | I12: =opex_branding/'Quy mô thị trường'!I6 | J12: =opex_branding/'Quy mô thị trường'!J6 | ... AR12: =opex_branding/'Quy mô thị trường'!AR6
A13: Cloud & hạ tầng | B13: Tr VND | C13: =opex_cloud_base/'Quy mô thị trường'!C6+'Quy mô thị trường'!C17*cloud_per_1M_vcr | D13: =opex_cloud_base/'Quy mô thị trường'!D6+'Quy mô thị trường'!D17*cloud_per_1M_vcr | E13: =opex_cloud_base/'Quy mô thị trường'!E6+'Quy mô thị trường'!E17*cloud_per_1M_vcr | F13: =opex_cloud_base/'Quy mô thị trường'!F6+'Quy mô thị trường'!F17*cloud_per_1M_vcr | G13: =opex_cloud_base/'Quy mô thị trường'!G6+'Quy mô thị trường'!G17*cloud_per_1M_vcr | H13: =opex_cloud_base/'Quy mô thị trường'!H6+'Quy mô thị trường'!H17*cloud_per_1M_vcr | I13: =opex_cloud_base/'Quy mô thị trường'!I6+'Quy mô thị trường'!I17*cloud_per_1M_vcr | J13: =opex_cloud_base/'Quy mô thị trường'!J6+'Quy mô thị trường'!J17*cloud_per_1M_vcr | ... AR13: =opex_cloud_base/'Quy mô thị trường'!AR6+'Quy mô thị trường'!AR17*cloud_per_1M_vcr
A14: Bảo mật | B14: Tr VND | C14: =opex_security/'Quy mô thị trường'!C6 | D14: =opex_security/'Quy mô thị trường'!D6 | E14: =opex_security/'Quy mô thị trường'!E6 | F14: =opex_security/'Quy mô thị trường'!F6 | G14: =opex_security/'Quy mô thị trường'!G6 | H14: =opex_security/'Quy mô thị trường'!H6 | I14: =opex_security/'Quy mô thị trường'!I6 | J14: =opex_security/'Quy mô thị trường'!J6 | ... AR14: =opex_security/'Quy mô thị trường'!AR6
A15: Đối ngoại | B15: Tr VND | C15: =opex_external/'Quy mô thị trường'!C6 | D15: =opex_external/'Quy mô thị trường'!D6 | E15: =opex_external/'Quy mô thị trường'!E6 | F15: =opex_external/'Quy mô thị trường'!F6 | G15: =opex_external/'Quy mô thị trường'!G6 | H15: =opex_external/'Quy mô thị trường'!H6 | I15: =opex_external/'Quy mô thị trường'!I6 | J15: =opex_external/'Quy mô thị trường'!J6 | ... AR15: =opex_external/'Quy mô thị trường'!AR6
A16: Pháp lý | B16: Tr VND | C16: =opex_legal/'Quy mô thị trường'!C6 | D16: =opex_legal/'Quy mô thị trường'!D6 | E16: =opex_legal/'Quy mô thị trường'!E6 | F16: =opex_legal/'Quy mô thị trường'!F6 | G16: =opex_legal/'Quy mô thị trường'!G6 | H16: =opex_legal/'Quy mô thị trường'!H6 | I16: =opex_legal/'Quy mô thị trường'!I6 | J16: =opex_legal/'Quy mô thị trường'!J6 | ... AR16: =opex_legal/'Quy mô thị trường'!AR6
A17: Đánh giá thí điểm (Y1) | B17: Tr VND | C17: =opex_pilot_eval/'Quy mô thị trường'!C6 | D17: =opex_pilot_eval/'Quy mô thị trường'!D6 | E17: =opex_pilot_eval/'Quy mô thị trường'!E6 | F17: =opex_pilot_eval/'Quy mô thị trường'!F6 | G17: =opex_pilot_eval/'Quy mô thị trường'!G6 | H17: =opex_pilot_eval/'Quy mô thị trường'!H6 | I17: =0 | J17: =0 | K17: =0 | L17: =0 | M17: =0 | N17: =0 | O17: =0 | P17: =0 | ... AR17: =0
A18: Quản lý đối tác | B18: Tr VND | C18: =opex_partner_mgmt/'Quy mô thị trường'!C6 | D18: =opex_partner_mgmt/'Quy mô thị trường'!D6 | E18: =opex_partner_mgmt/'Quy mô thị trường'!E6 | F18: =opex_partner_mgmt/'Quy mô thị trường'!F6 | G18: =opex_partner_mgmt/'Quy mô thị trường'!G6 | H18: =opex_partner_mgmt/'Quy mô thị trường'!H6 | I18: =opex_partner_mgmt/'Quy mô thị trường'!I6 | J18: =opex_partner_mgmt/'Quy mô thị trường'!J6 | ... AR18: =opex_partner_mgmt/'Quy mô thị trường'!AR6
A19: Hỗ trợ khách hàng | B19: Tr VND | C19: ='Quy mô thị trường'!C15*opex_support_per_ent/'Quy mô thị trường'!C6 | D19: ='Quy mô thị trường'!D15*opex_support_per_ent/'Quy mô thị trường'!D6 | E19: ='Quy mô thị trường'!E15*opex_support_per_ent/'Quy mô thị trường'!E6 | F19: ='Quy mô thị trường'!F15*opex_support_per_ent/'Quy mô thị trường'!F6 | G19: ='Quy mô thị trường'!G15*opex_support_per_ent/'Quy mô thị trường'!G6 | H19: ='Quy mô thị trường'!H15*opex_support_per_ent/'Quy mô thị trường'!H6 | I19: ='Quy mô thị trường'!I15*opex_support_per_ent/'Quy mô thị trường'!I6 | J19: ='Quy mô thị trường'!J15*opex_support_per_ent/'Quy mô thị trường'!J6 | ... AR19: ='Quy mô thị trường'!AR15*opex_support_per_ent/'Quy mô thị trường'!AR6
A20: OPEX cộng dồn | C20: =SUM(C10:C19) | D20: =SUM(D10:D19) | E20: =SUM(E10:E19) | F20: =SUM(F10:F19) | G20: =SUM(G10:G19) | H20: =SUM(H10:H19) | I20: =SUM(I10:I19) | J20: =SUM(J10:J19) | ... AR20: =SUM(AR10:AR19)
A21: Dự phòng | B21: Tr VND | C21: =C20*opex_contingency_pct | D21: =D20*opex_contingency_pct | E21: =E20*opex_contingency_pct | F21: =F20*opex_contingency_pct | G21: =G20*opex_contingency_pct | H21: =H20*opex_contingency_pct | I21: =I20*opex_contingency_pct | J21: =J20*opex_contingency_pct | ... AR21: =AR20*opex_contingency_pct
A22: TỔNG OPEX | C22: =C20+C21 | D22: =D20+D21 | E22: =E20+E21 | F22: =F20+F21 | G22: =G20+G21 | H22: =H20+H21 | I22: =I20+I21 | J22: =J20+J21 | ... AR22: =AR20+AR21
A24: TỔNG CHI PHÍ | C24: =C7+C22 | D24: =D7+D22 | E24: =E7+E22 | F24: =F7+F22 | G24: =G7+G22 | H24: =H7+H22 | I24: =I7+I22 | J24: =J7+J22 | ... AR24: =AR7+AR22

Sheet Kết quả KD
A1: BÁO CÁO KẾT QUẢ KINH DOANH (Tr VND)
A3: Hạng mục | B3: ĐVT | C3: Th7 2025 | D3: Th8 2025 | E3: Th9 2025 | F3: Th10 2025 | G3: Th11 2025 | H3: Th12 2025 | I3: Th1 2026 | J3: Th2 2026 | K3: Th3 2026 | L3: Th4 2026 | M3: Th5 2026 | N3: Th6 2026 | O3: Th7 2026 | P3: Th8 2026 | Q3: Th9 2026 | R3: Th10 2026 | S3: Th11 2026 | T3: Th12 2026 | U3: Th1 2027 | V3: Th2 2027 | W3: Th3 2027 | X3: Th4 2027 | Y3: Th5 2027 | Z3: Th6 2027 | AA3: Th7 2027 | AB3: Th8 2027 | AC3: Th9 2027 | AD3: Th10 2027 | AE3: Th11 2027 | AF3: Th12 2027 | AG3: Q1 2028 | AH3: Q2 2028 | AI3: Q3 2028 | AJ3: Q4 2028 | AK3: Q1 2029 | AL3: Q2 2029 | AM3: Q3 2029 | AN3: Q4 2029 | AO3: Q1 2030 | AP3: Q2 2030 | AQ3: Q3 2030 | AR3: Q4 2030
A4: Doanh thu | C4: ='Doanh thu'!C16 | D4: ='Doanh thu'!D16 | E4: ='Doanh thu'!E16 | F4: ='Doanh thu'!F16 | G4: ='Doanh thu'!G16 | H4: ='Doanh thu'!H16 | I4: ='Doanh thu'!I16 | J4: ='Doanh thu'!J16 | ... AR4: ='Doanh thu'!AR16
A5: Giá vốn | C5: =-'Doanh thu'!C20 | D5: =-'Doanh thu'!D20 | E5: =-'Doanh thu'!E20 | F5: =-'Doanh thu'!F20 | G5: =-'Doanh thu'!G20 | H5: =-'Doanh thu'!H20 | I5: =-'Doanh thu'!I20 | J5: =-'Doanh thu'!J20 | ... AR5: =-'Doanh thu'!AR20
A6: LỢI NHUẬN GỘP | C6: =C4+C5 | D6: =D4+D5 | E6: =E4+E5 | F6: =F4+F5 | G6: =G4+G5 | H6: =H4+H5 | I6: =I4+I5 | J6: =J4+J5 | ... AR6: =AR4+AR5
A8: Chi phí hoạt động | C8: =-'Chi phí'!C22 | D8: =-'Chi phí'!D22 | E8: =-'Chi phí'!E22 | F8: =-'Chi phí'!F22 | G8: =-'Chi phí'!G22 | H8: =-'Chi phí'!H22 | I8: =-'Chi phí'!I22 | J8: =-'Chi phí'!J22 | ... AR8: =-'Chi phí'!AR22
A9: EBITDA | C9: =C6+C8 | D9: =D6+D8 | E9: =E6+E8 | F9: =F6+F8 | G9: =G6+G8 | H9: =H6+H8 | I9: =I6+I8 | J9: =J6+J8 | ... AR9: =AR6+AR8
A10: Khấu hao | C10: =-capex_total/depreciation_years/'Quy mô thị trường'!C6 | D10: =-capex_total/depreciation_years/'Quy mô thị trường'!D6 | E10: =-capex_total/depreciation_years/'Quy mô thị trường'!E6 | F10: =-capex_total/depreciation_years/'Quy mô thị trường'!F6 | G10: =-capex_total/depreciation_years/'Quy mô thị trường'!G6 | H10: =-capex_total/depreciation_years/'Quy mô thị trường'!H6 | I10: =-capex_total/depreciation_years/'Quy mô thị trường'!I6 | J10: =-capex_total/depreciation_years/'Quy mô thị trường'!J6 | ... AN10: =-capex_total/depreciation_years/'Quy mô thị trường'!AN6 | AO10: =0 | AP10: =0 | AQ10: =0 | AR10: =0
A11: EBIT | C11: =C9+C10 | D11: =D9+D10 | E11: =E9+E10 | F11: =F9+F10 | G11: =G9+G10 | H11: =H9+H10 | I11: =I9+I10 | J11: =J9+J10 | ... AR11: =AR9+AR10
A12: Thuế TNDN (20%) | C12: =IF(C11>0,-C11*cit_rate,0) | D12: =IF(D11>0,-D11*cit_rate,0) | E12: =IF(E11>0,-E11*cit_rate,0) | F12: =IF(F11>0,-F11*cit_rate,0) | G12: =IF(G11>0,-G11*cit_rate,0) | H12: =IF(H11>0,-H11*cit_rate,0) | I12: =IF(I11>0,-I11*cit_rate,0) | J12: =IF(J11>0,-J11*cit_rate,0) | ... AR12: =IF(AR11>0,-AR11*cit_rate,0)
A13: LỢI NHUẬN SAU THUẾ | C13: =C11+C12 | D13: =D11+D12 | E13: =E11+E12 | F13: =F11+F12 | G13: =G11+G12 | H13: =H11+H12 | I13: =I11+I12 | J13: =J11+J12 | ... AR13: =AR11+AR12
A15: BIÊN LỢI NHUẬN
A16: Biên gộp | C16: =IF(C4=0,0,C6/C4) | D16: =IF(D4=0,0,D6/D4) | E16: =IF(E4=0,0,E6/E4) | F16: =IF(F4=0,0,F6/F4) | G16: =IF(G4=0,0,G6/G4) | H16: =IF(H4=0,0,H6/H4) | I16: =IF(I4=0,0,I6/I4) | J16: =IF(J4=0,0,J6/J4) | ... AR16: =IF(AR4=0,0,AR6/AR4)
A17: Biên EBITDA | C17: =IF(C4=0,0,C9/C4) | D17: =IF(D4=0,0,D9/D4) | E17: =IF(E4=0,0,E9/E4) | F17: =IF(F4=0,0,F9/F4) | G17: =IF(G4=0,0,G9/G4) | H17: =IF(H4=0,0,H9/H4) | I17: =IF(I4=0,0,I9/I4) | J17: =IF(J4=0,0,J9/J4) | ... AR17: =IF(AR4=0,0,AR9/AR4)
A18: Biên ròng | C18: =IF(C4=0,0,C13/C4) | D18: =IF(D4=0,0,D13/D4) | E18: =IF(E4=0,0,E13/E4) | F18: =IF(F4=0,0,F13/F4) | G18: =IF(G4=0,0,G13/G4) | H18: =IF(H4=0,0,H13/H4) | I18: =IF(I4=0,0,I13/I4) | J18: =IF(J4=0,0,J13/J4) | ... AR18: =IF(AR4=0,0,AR13/AR4)

Sheet Dòng tiền
A1: BÁO CÁO DÒNG TIỀN (Tr VND)
A3: Hạng mục | B3: ĐVT | C3: Th7 2025 | D3: Th8 2025 | E3: Th9 2025 | F3: Th10 2025 | G3: Th11 2025 | H3: Th12 2025 | I3: Th1 2026 | J3: Th2 2026 | K3: Th3 2026 | L3: Th4 2026 | M3: Th5 2026 | N3: Th6 2026 | O3: Th7 2026 | P3: Th8 2026 | Q3: Th9 2026 | R3: Th10 2026 | S3: Th11 2026 | T3: Th12 2026 | U3: Th1 2027 | V3: Th2 2027 | W3: Th3 2027 | X3: Th4 2027 | Y3: Th5 2027 | Z3: Th6 2027 | AA3: Th7 2027 | AB3: Th8 2027 | AC3: Th9 2027 | AD3: Th10 2027 | AE3: Th11 2027 | AF3: Th12 2027 | AG3: Q1 2028 | AH3: Q2 2028 | AI3: Q3 2028 | AJ3: Q4 2028 | AK3: Q1 2029 | AL3: Q2 2029 | AM3: Q3 2029 | AN3: Q4 2029 | AO3: Q1 2030 | AP3: Q2 2030 | AQ3: Q3 2030 | AR3: Q4 2030
A4: Dòng tiền hoạt động
A5: Lợi nhuận ròng | C5: ='Kết quả KD'!C13 | D5: ='Kết quả KD'!D13 | E5: ='Kết quả KD'!E13 | F5: ='Kết quả KD'!F13 | G5: ='Kết quả KD'!G13 | H5: ='Kết quả KD'!H13 | I5: ='Kết quả KD'!I13 | J5: ='Kết quả KD'!J13 | ... AR5: ='Kết quả KD'!AR13
A6: Cộng: Khấu hao | C6: =-'Kết quả KD'!C10 | D6: =-'Kết quả KD'!D10 | E6: =-'Kết quả KD'!E10 | F6: =-'Kết quả KD'!F10 | G6: =-'Kết quả KD'!G10 | H6: =-'Kết quả KD'!H10 | I6: =-'Kết quả KD'!I10 | J6: =-'Kết quả KD'!J10 | ... AR6: =-'Kết quả KD'!AR10
A7: Thay đổi vốn lưu động | C7: =-'Kết quả KD'!C4*ar_days/365 | D7: =-('Kết quả KD'!D4-'Kết quả KD'!C4)*ar_days/365 | E7: =-('Kết quả KD'!E4-'Kết quả KD'!D4)*ar_days/365 | F7: =-('Kết quả KD'!F4-'Kết quả KD'!E4)*ar_days/365 | G7: =-('Kết quả KD'!G4-'Kết quả KD'!F4)*ar_days/365 | H7: =-('Kết quả KD'!H4-'Kết quả KD'!G4)*ar_days/365 | I7: =-('Kết quả KD'!I4-'Kết quả KD'!H4)*ar_days/365 | J7: =-('Kết quả KD'!J4-'Kết quả KD'!I4)*ar_days/365 | K7: =-('Kết quả KD'!K4-'Kết quả KD'!J4)*ar_days/365 | ... AR7: =-('Kết quả KD'!AR4-'Kết quả KD'!AQ4)*ar_days/365
A8: DÒNG TIỀN HOẠT ĐỘNG | C8: =C5+C6+C7 | D8: =D5+D6+D7 | E8: =E5+E6+E7 | F8: =F5+F6+F7 | G8: =G5+G6+G7 | H8: =H5+H6+H7 | I8: =I5+I6+I7 | J8: =J5+J6+J7 | ... AR8: =AR5+AR6+AR7
A10: Dòng tiền đầu tư
A11: Đầu tư CAPEX | C11: =-'Chi phí'!C7 | D11: =-'Chi phí'!D7 | E11: =-'Chi phí'!E7 | F11: =-'Chi phí'!F7 | G11: =-'Chi phí'!G7 | H11: =-'Chi phí'!H7 | I11: =-'Chi phí'!I7 | J11: =-'Chi phí'!J7 | ... AR11: =-'Chi phí'!AR7
A12: DÒNG TIỀN ĐẦU TƯ | C12: =C11 | D12: =D11 | E12: =E11 | F12: =F11 | G12: =G11 | H12: =H11 | I12: =I11 | J12: =J11 | ... AR12: =AR11
A14: DÒNG TIỀN TỰ DO | C14: =C8+C12 | D14: =D8+D12 | E14: =E8+E12 | F14: =F8+F12 | G14: =G8+G12 | H14: =H8+H12 | I14: =I8+I12 | J14: =J8+J12 | ... AR14: =AR8+AR12
A15: Dòng tiền lũy kế | C15: =C14 | D15: =C15+D14 | E15: =D15+E14 | F15: =E15+F14 | G15: =F15+G14 | H15: =G15+H14 | I15: =H15+I14 | J15: =I15+J14 | K15: =J15+K14 | ... AR15: =AQ15+AR14

Sheet Thẩm định
A1: THẨM ĐỊNH DỰ ÁN & LỢI NHUẬN
A3: Dòng tiền tự do theo năm
A4: Năm | B4: FCF (Tr VND)
A5: H2_2025 | B5: =SUM('Dòng tiền'!C14:H14)
A6: 2026 | B6: =SUM('Dòng tiền'!I14:T14)
A7: 2027 | B7: =SUM('Dòng tiền'!U14:AF14)
A8: 2028 | B8: =SUM('Dòng tiền'!AG14:AJ14)
A9: 2029 | B9: =SUM('Dòng tiền'!AK14:AN14)
A10: 2030 | B10: =SUM('Dòng tiền'!AO14:AR14)
A12: Chỉ số chính
A13: NPV (Giá trị hiện tại ròng) | B13: =NPV(discount_rate,B6:B10)+B5
A14: IRR (Tỷ suất hoàn vốn nội bộ) | B14: =IFERROR(IRR(B5:B10),"N/A")
A15: Đốt tiền tối đa | B15: =-MIN('Dòng tiền'!C15:'Dòng tiền'!AR15)
A16: ROI (Lợi nhuận đầu tư) | B16: =IF(B15=0,0,('Dòng tiền'!AR15+B15)/B15)
A17: Thuế TNDN áp dụng | B17: =cit_rate
A18: Tỷ suất chiết khấu | B18: =discount_rate

Sheet Kịch bản
A1: PHÂN TÍCH KỊCH BẢN
A2: Sao chép giá trị từ cột kịch bản vào trang Assumptions để chạy.
A4: Tham số | B4: XẤU NHẤT | C4: THẬN TRỌNG | D4: CƠ SỞ | E4: LẠC QUAN | F4: TỐT NHẤT
A5: Trần DN (adoption_max) | B5: 200 | C5: 600 | D5: =adoption_max | E5: 2000 | F5: 3500
A6: Hệ số dốc S-curve | B6: 0.5 | C6: 0.7 | D6: =adoption_steepness | E6: 1.2 | F6: 1.5
A7: Tỷ lệ rời bỏ | B7: 0.35 | C7: 0.25 | D7: =churn_rate | E7: 0.15 | F7: 0.1
A8: Thị phần GMV | B8: 0.001 | C8: 0.003 | D8: =platform_market_share | E8: 0.01 | F8: 0.02
A9: Phí chứng nhận (Tr) | B9: 15 | C9: 20 | D9: =cert_fee_yr1 | E9: 30 | F9: 40
A10: Tăng phí/năm | B10: 0 | C10: 0.03 | D10: =cert_fee_escalation | E10: 0.08 | F10: 0.12
A11: Phí giao dịch | B11: 0.01 | C11: 0.015 | D11: =tx_take_rate | E11: 0.025 | F11: 0.03
A12: Marketing cơ sở (Tr) | B12: 8000 | C12: 7500 | D12: =opex_marketing | E12: 6000 | F12: 5000
A13: WACC | B13: 0.2 | C13: 0.18 | D13: =discount_rate | E13: 0.12 | F13: 0.1
A14: Ngưỡng GĐ2 | B14: 500 | C14: 400 | D14: =stage2_gate | E14: 200 | F14: 150
A17: 🔑 YẾU TỐ ẢNH HƯỞNG LỚN NHẤT ĐẾN NPV/IRR
A19: 3 yếu tố ảnh hưởng mạnh nhất đến kết quả mô hình:
A21: 1. TRẦN DOANH NGHIỆP (adoption_max) — YẾU TỐ SỐ 1
A22: Mọi nguồn doanh thu đều phụ thuộc số DN. Cert, đào tạo, kiểm toán — tỷ lệ thuận với DN.
A23: Giai đoạn 2 (phí giao dịch, DaaS, QC) cũng phụ thuộc vượt ngưỡng. Tăng gấp đôi DN ≈ tăng gấp đôi DT.
A24: → Xấu nhất: 200 = dự án không có sức hút. Tốt nhất: 3,500 = trở thành chuẩn ngành.
A26: 2. THỊ PHẦN GMV (platform_market_share) — YẾU TỐ SỐ 2
A27: % GMV TMĐT du lịch VN chạy qua nền tảng VV. Thị trường ~82.500 tỷ, tăng 8%/năm.
A28: Chênh 0.1% = hàng trăm tỷ VND chênh lệch GMV → hàng tỷ phí giao dịch.
A29: → Xấu nhất: 0.1% = ngách. Tốt nhất: 2% = nền tảng thống lĩnh.
A31: 3. TỶ LỆ RỜI BỎ (churn_rate) — YẾU TỐ SỐ 3
A32: % DN không gia hạn chứng nhận mỗi năm. Churn cao = phải liên tục thay thế DN đã mất.
... A61: Kết quả: Sẵn sàng IPO hoặc mục tiêu M&A. Mở rộng Đông Nam Á.

Sheet Ngân sách 2025
A1: NGÂN SÁCH 2025 (Tr VND)
A3: Hạng mục | B3: ĐVT | C3: Th7 | D3: Th8 | E3: Th9 | F3: Th10 | G3: Th11 | H3: Th12 | I3: TỔNG
A4: DOANH THU
A5: Phí chứng nhận | B5: Tr VND | C5: =MAX(pilot_count,adoption_max/(1+EXP(-adoption_steepness*(2025.542-adoption_midpoint))))*cert_fee_yr1*(1+cert_fee_escalation)^0/12 | D5: =MAX(pilot_count,adoption_max/(1+EXP(-adoption_steepness*(2025.625-adoption_midpoint))))*cert_fee_yr1*(1+cert_fee_escalation)^0/12 | E5: =MAX(pilot_count,adoption_max/(1+EXP(-adoption_steepness*(2025.708-adoption_midpoint))))*cert_fee_yr1*(1+cert_fee_escalation)^0/12 | F5: =MAX(pilot_count,adoption_max/(1+EXP(-adoption_steepness*(2025.792-adoption_midpoint))))*cert_fee_yr1*(1+cert_fee_escalation)^0/12 | G5: =MAX(pilot_count,adoption_max/(1+EXP(-adoption_steepness*(2025.875-adoption_midpoint))))*cert_fee_yr1*(1+cert_fee_escalation)^0/12 | H5: =MAX(pilot_count,adoption_max/(1+EXP(-adoption_steepness*(2025.958-adoption_midpoint))))*cert_fee_yr1*(1+cert_fee_escalation)^0/12 | I5: =SUM(C5:H5)
A6: Đào tạo | B6: Tr VND | C6: =MAX(pilot_count,adoption_max/(1+EXP(-adoption_steepness*(2025.542-adoption_midpoint))))*training_pct*training_fee/12 | D6: =MAX(pilot_count,adoption_max/(1+EXP(-adoption_steepness*(2025.625-adoption_midpoint))))*training_pct*training_fee/12 | E6: =MAX(pilot_count,adoption_max/(1+EXP(-adoption_steepness*(2025.708-adoption_midpoint))))*training_pct*training_fee/12 | F6: =MAX(pilot_count,adoption_max/(1+EXP(-adoption_steepness*(2025.792-adoption_midpoint))))*training_pct*training_fee/12 | G6: =MAX(pilot_count,adoption_max/(1+EXP(-adoption_steepness*(2025.875-adoption_midpoint))))*training_pct*training_fee/12 | H6: =MAX(pilot_count,adoption_max/(1+EXP(-adoption_steepness*(2025.958-adoption_midpoint))))*training_pct*training_fee/12 | I6: =SUM(C6:H6)
A7: Kiểm toán | B7: Tr VND | C7: =MAX(pilot_count,adoption_max/(1+EXP(-adoption_steepness*(2025.542-adoption_midpoint))))*audit_fee/12 | D7: =MAX(pilot_count,adoption_max/(1+EXP(-adoption_steepness*(2025.625-adoption_midpoint))))*audit_fee/12 | E7: =MAX(pilot_count,adoption_max/(1+EXP(-adoption_steepness*(2025.708-adoption_midpoint))))*audit_fee/12 | F7: =MAX(pilot_count,adoption_max/(1+EXP(-adoption_steepness*(2025.792-adoption_midpoint))))*audit_fee/12 | G7: =MAX(pilot_count,adoption_max/(1+EXP(-adoption_steepness*(2025.875-adoption_midpoint))))*audit_fee/12 | H7: =MAX(pilot_count,adoption_max/(1+EXP(-adoption_steepness*(2025.958-adoption_midpoint))))*audit_fee/12 | I7: =SUM(C7:H7)
A8: TỔNG DOANH THU | C8: =SUM(C5:C7) | D8: =SUM(D5:D7) | E8: =SUM(E5:E7) | F8: =SUM(F5:F7) | G8: =SUM(G5:G7) | H8: =SUM(H5:H7) | I8: =SUM(C8:H8)
A10: CAPEX
A11: Cloud | B11: Tr VND | C11: =capex_cloud_setup/6 | D11: =capex_cloud_setup/6 | E11: =capex_cloud_setup/6 | F11: =capex_cloud_setup/6 | G11: =capex_cloud_setup/6 | H11: =capex_cloud_setup/6 | I11: =SUM(C11:H11)
A12: Backend | B12: Tr VND | C12: =capex_backend/6 | D12: =capex_backend/6 | E12: =capex_backend/6 | F12: =capex_backend/6 | G12: =capex_backend/6 | H12: =capex_backend/6 | I12: =SUM(C12:H12)
A13: Frontend | B13: Tr VND | C13: =capex_frontend/6 | D13: =capex_frontend/6 | E13: =capex_frontend/6 | F13: =capex_frontend/6 | G13: =capex_frontend/6 | H13: =capex_frontend/6 | I13: =SUM(C13:H13)
A14: Data | B14: Tr VND | C14: =capex_data_platform/6 | D14: =capex_data_platform/6 | E14: =capex_data_platform/6 | F14: =capex_data_platform/6 | G14: =capex_data_platform/6 | H14: =capex_data_platform/6 | I14: =SUM(C14:H14)
A15: Bảo mật | B15: Tr VND | C15: =capex_security_setup/6 | D15: =capex_security_setup/6 | E15: =capex_security_setup/6 | F15: =capex_security_setup/6 | G15: =capex_security_setup/6 | H15: =capex_security_setup/6 | I15: =SUM(C15:H15)
A16: UX/UI | B16: Tr VND | C16: =capex_ux_design/6 | D16: =capex_ux_design/6 | E16: =capex_ux_design/6 | F16: =capex_ux_design/6 | G16: =capex_ux_design/6 | H16: =capex_ux_design/6 | I16: =SUM(C16:H16)
A17: Tích hợp | B17: Tr VND | C17: =capex_integration/6 | D17: =capex_integration/6 | E17: =capex_integration/6 | F17: =capex_integration/6 | G17: =capex_integration/6 | H17: =capex_integration/6 | I17: =SUM(C17:H17)
A18: DevOps | B18: Tr VND | C18: =capex_devops/6 | D18: =capex_devops/6 | E18: =capex_devops/6 | F18: =capex_devops/6 | G18: =capex_devops/6 | H18: =capex_devops/6 | I18: =SUM(C18:H18)
A19: QA | B19: Tr VND | C19: =capex_testing/6 | D19: =capex_testing/6 | E19: =capex_testing/6 | F19: =capex_testing/6 | G19: =capex_testing/6 | H19: =capex_testing/6 | I19: =SUM(C19:H19)
A20: Dự phòng | B20: Tr VND | C20: =capex_contingency/6 | D20: =capex_contingency/6 | E20: =capex_contingency/6 | F20: =capex_contingency/6 | G20: =capex_contingency/6 | H20: =capex_contingency/6 | I20: =SUM(C20:H20)
A21: TỔNG CAPEX | C21: =SUM(C11:C20) | D21: =SUM(D11:D20) | E21: =SUM(E11:E20) | F21: =SUM(F11:F20) | G21: =SUM(G11:G20) | H21: =SUM(H11:H20) | I21: =SUM(C21:H21)
A23: OPEX
A24: NS — QL(2) | B24: Tr VND | C24: =salary_mgmt*2*(1+salary_escalation)^0*(1+bhxh_rate) | D24: =salary_mgmt*2*(1+salary_escalation)^0*(1+bhxh_rate) | E24: =salary_mgmt*2*(1+salary_escalation)^0*(1+bhxh_rate) | F24: =salary_mgmt*2*(1+salary_escalation)^0*(1+bhxh_rate) | G24: =salary_mgmt*2*(1+salary_escalation)^0*(1+bhxh_rate) | H24: =salary_mgmt*2*(1+salary_escalation)^0*(1+bhxh_rate) | I24: =SUM(C24:H24)
A25: NS — PT(12) | B25: Tr VND | C25: =salary_dev*12*(1+salary_escalation)^0*(1+bhxh_rate) | D25: =salary_dev*12*(1+salary_escalation)^0*(1+bhxh_rate) | E25: =salary_dev*12*(1+salary_escalation)^0*(1+bhxh_rate) | F25: =salary_dev*12*(1+salary_escalation)^0*(1+bhxh_rate) | G25: =salary_dev*12*(1+salary_escalation)^0*(1+bhxh_rate) | H25: =salary_dev*12*(1+salary_escalation)^0*(1+bhxh_rate) | I25: =SUM(C25:H25)
A26: NS — VHKD(2) | B26: Tr VND | C26: =salary_bizops*2*(1+salary_escalation)^0*(1+bhxh_rate) | D26: =salary_bizops*2*(1+salary_escalation)^0*(1+bhxh_rate) | E26: =salary_bizops*2*(1+salary_escalation)^0*(1+bhxh_rate) | F26: =salary_bizops*2*(1+salary_escalation)^0*(1+bhxh_rate) | G26: =salary_bizops*2*(1+salary_escalation)^0*(1+bhxh_rate) | H26: =salary_bizops*2*(1+salary_escalation)^0*(1+bhxh_rate) | I26: =SUM(C26:H26)
A27: Tuyển dụng | B27: Tr VND | C27: =16*30*12*recruit_cost_pct | D27: =0 | E27: =0 | F27: =0 | G27: =0 | H27: =0 | I27: =SUM(C27:H27)
A28: Marketing | B28: Tr VND | C28: =opex_marketing*(1+marketing_growth)^0/12 | D28: =opex_marketing*(1+marketing_growth)^0/12 | E28: =opex_marketing*(1+marketing_growth)^0/12 | F28: =opex_marketing*(1+marketing_growth)^0/12 | G28: =opex_marketing*(1+marketing_growth)^0/12 | H28: =opex_marketing*(1+marketing_growth)^0/12 | I28: =SUM(C28:H28)
A29: Thương hiệu | B29: Tr VND | C29: =opex_branding/12 | D29: =opex_branding/12 | E29: =opex_branding/12 | F29: =opex_branding/12 | G29: =opex_branding/12 | H29: =opex_branding/12 | I29: =SUM(C29:H29)
