Workbook

Sheet Annex A
A1: I. CHECK SỔ SÁCH VỚI DANH MỤC KIỂM KÊ
B3: TÀI SẢN | C3: Anex | D3: Theo sổ sách (23.3.2026) | F3: Theo Annex A | H3: Chênh lệch
D4: Số lượng | E4: Giá trị | F4: Số lượng | G4: Giá trị | H4: Số lượng | I4: Giá trị
B5: Tồn kho phim SX (Tk 15666) | C5: A | D5: =COUNTA('TK 15666. Phim SX'!$B$6:$B$13) -> 8 | E5: 36977023489 | G5: =E5 -> 36977023489
B6: Tồn kho CT Phim (Tk 15661) | C6: A | D6: =COUNTA('TK 15661.Bản quyền phim '!$B$6:$B$497)+2 -> 494 | E6: 55564486653 | F6: =COUNTIF('TK 15661.Bản quyền phim '!$AH$6:$AH$497,"OK")+2 -> 456 | G6: =E6 -> 55564486653 | H6: =D6-F6 -> 38 | I6: =SUMIF('TK 15661.Bản quyền phim '!$AH$6:$AH$497, 0, 'TK 15661.Bản quyền phim '!$X$6:$X$497) -> 9.0157619e+08 | J6: Cần kiểm kê bổ sung
B7: Bản quyền phim VOD | C7: A | E7: 0 | F7: =H20 -> 36 | G7: 0 | H7: Đã ghi nhận thẳng vào P&L, không còn số dư trên BCĐKT
B8: Phim Barter | C8: A | E8: 0 | F8: =I20 -> 67 | G8: 0
B9: Show tự sản xuất | C9: A | E9: 0 | F9: =J20 -> 9 | G9: 0
A11: II. CHECK DANH MỤC KIỂM KÊ VỚI SỔ SÁCH
E12: Trong sổ sách | I12: Ngoài sổ sách
B13: Danh sách kiểm kê License | C13: Unit | D13: Number | E13: TK 15661 | F13: TK 242. Bản quyền phim hợp tác | G13: TK 15666. Bản quyền phim tự SX | H13: 242. Bản quyền phim VOD | I13: Phim Barter | J13: Show tự sản xuất | K13: Check | L13: VSTV's note
B14: KK1. Movies | C14: Titles | D14: =COUNTA('KK1. Movies'!A7:A343) -> 337 | E14: =COUNTIF('KK1. Movies'!$AM$7:$AM$343,1) -> 331 | F14: =COUNTIF('242.BQ Phim hợp tác'!$R:$R,1) -> 6 | K14: =SUM(E14:J14)=D14 -> TRUE | L14: Gồm 331 phim trong sheet 15661 và 6 phim trong sheet 242 bản quyền Phim hợp tác
B15: KK2. Series | C15: Titles | D15: =COUNTA('KK2. Series'!A7:A174) -> 168 | E15: =COUNTIF('KK2. Series'!$AR$7:$AR$174,1) -> 72 | G15: =COUNTIF('KK2. Series'!$AQ$7:$AQ$174,1) -> 7 | H15: =COUNTIF('KK2. Series'!$AP$7:$AP$174,1) -> 36 | I15: =COUNTIF('KK2. Series'!$AS$7:$AS$174,1) -> 53 | K15: =SUM(E15:J15)=D15 -> TRUE | L15: Gồm 331 phim trong sheet 15661 và 7 phim trong sheet 15666 Bản quyền phim tự SX
B16: KK3. Kids | C16: Titles | D16: =COUNTA('KK3. Kids'!$A$7:$A$57) -> 51 | E16: =COUNTIF('KK3. Kids'!$AI$7:$AI$57,1) -> 51 | K16: =SUM(E16:J16)=D16 -> TRUE | L16: Thực tế tăng 2 so với Annex A vì lỗi STT ở sheet Kids
B17: KK4. Show | C17: Titles | D17: =COUNTA('KK4. Show'!A7:A15) -> 9 | J17: =COUNTIF('KK4. Show'!$O$6:$O$15,1) -> 9 | K17: =SUM(E17:J17)=D17 -> TRUE | L17: Đây là các show K+ thuê bên thứ 3 hoặc tự sản xuất, không theo dõi tồn kho, đã tính vào chi phí khi phát sóng shows
B18: KK5. Doc | C18: Titles | D18: =COUNTA('KK5. Doc'!A7:A23) -> 17 | E18: =COUNTIF('KK5. Doc'!$X$7:$X$23,1) -> 1 | G18: =COUNTIF('KK5. Doc'!$Y$7:$Y$23,1) -> 1 | I18: =COUNTIF('KK5. Doc'!$Z$7:$Z$23,1) -> 14 | K18: =SUM(E18:J18)=D18 -> FALSE | L18: gồm 14 Docs free của Kênh DW + 3 Docs
B19: KK6. Bổ sung | C19: Titles | D19: =COUNTA('KK6. Bổ sung'!$A$7:$A$44) -> 38 | E19: =COUNTIF('TK 15661.Bản quyền phim '!$AH$5:$AH$1048576,0) -> 38 | K19: =SUM(E19:J19)=D19 -> TRUE
B20: Total | D20: =SUM(D14:D19) -> 620 | E20: =SUM(E14:E19) -> 493 | F20: =SUM(F14:F19) -> 6 | G20: =SUM(G14:G19) -> 8 | H20: =SUM(H14:H19) -> 36 | I20: =SUM(I14:I19) -> 67 | J20: =SUM(J14:J19) -> 9

Sheet KK1. Movies
A1: CÔNG TY: | C1: Công ty TNHH Truyền hình số vệ tinh Việt Nam | AO1: Cộng Hòa Xã Hội Chủ Nghĩa Việt Nam
AO2: Độc Lập - Tự Do - Hạnh Phúc
A3: BÁO CÁO KIỂM KÊ BẢN QUYỀN MOVIES
A4: Thời điểm:….......giờ, ngày…....tháng.........năm 2026
AD5: Lưu trữ | AI5: Ref File Kế toán | AN5: Check | AO5: SỐ LIỆU KIỂM KÊ | AR5: Giải trình chênh lệch | AS5: Đề xuất Phương án xử lý
A6: STT | B6: Content Rating | C6: Clip Code | D6: ENGLISH Title | E6: VIET Title | F6: Main Genre | G6: Provider | H6: Contract number | I6: Year of Production | J6: Origin | K6: Duration (minute) | L6: From (DTH) | M6: To (DTH) | N6: VSTV's 1st airing date | O6: Channel | P6: Exclusive (month) | Q6: Sub-license | R6: OTT rights | S6: Catch-up | T6: SVOD | U6: FVOD | V6: AVOD | W6: TVOD | X6: Internet Streaming | Y6: Internet Downloading | Z6: From (VOD) | AA6: To (VOD) | AB6: Runs No. | AC6: Broadcasted runs | AD6: HD Censorship | AE6: LTO | AF6: Drive ( ổ cứng) | AG6: Note | AI6: Tên trên file Kế toán | AJ6: details kế toán | AK6: Giá trị còn lại (15661) | AL6: Check ref "TK 242.BQ Phim hợp tác" | AM6: Check ref "TK 15661. Bản quyền phim" | AO6: Số lượng | AP6: From (VOD) | AQ6: To (VOD)
A7: =_xlfn.AGGREGATE(3,3,$D$7:D7) -> 1 | B7: 13+ | C7: MOV_DRA730 | D7: SHINING FOR ONE THING | E7: Ngôi Sao Lấp Lánh | F7: Thriller, Mystery, Romance, Fantasy | G7: Skyline Media | H7: 36/2025/HDBQ/VSTV-SM | I7: 2023 | J7: China | K7: 107 | L7: 45674 | M7: 47169 | N7: 45674 | P7: 12 | Q7: No | R7: Yes | S7: Yes | T7: Yes | U7: Yes | V7: Yes | W7: Yes | X7: Yes | Y7: No | Z7: 45674 | AA7: 47169 | AB7: 24 | AC7: 3 | AD7: Yes | AE7: Yes | AG7: Phim còn hạn từ 2026 | AI7: SHINING FOR ONE THING | AJ7: =SUMIF('TK 15661.Bản quyền phim '!F:F,'KK1. Movies'!D7,'TK 15661.Bản quyền phim '!X:X) -> 59932953 | AK7: =SUMIF('TK 15661.Bản quyền phim '!F:F,'KK1. Movies'!AI7,'TK 15661.Bản quyền phim '!X:X) -> 59932953 | AL7: =COUNTIF('242.BQ Phim hợp tác'!$C:$C,'KK1. Movies'!AI7) -> 0 | AM7: =COUNTIF('TK 15661.Bản quyền phim '!F:F,'KK1. Movies'!AI7) -> 1 | AN7: =AL7+AM7 -> 1
A8: =_xlfn.AGGREGATE(3,3,$D$7:D8) -> 2 | B8: 16+ | C8: MOV_ACT_23__2691047 | D8: ROGUE | E8: Biệt đội săn mồi | F8: Action, Adventure | G8: Roses Media | H8: 140/2022/HDBQ/VSTV-RM | I8: 2020 | J8: US | K8: 105 | L8: 45077 | M8: 46172 | N8: 45077 | O8: K+CINE | P8: Exclusive All Pay TV Rights for first 12 months. Non exclusive All VOD during LP | Q8: No | R8: Yes | S8: No | T8: Yes | U8: Yes | V8: Yes | W8: Yes | X8: Yes | Y8: No | Z8: 45077 | AA8: 46172 | AB8: 24 | AC8: 14 | AD8: Yes | AE8: Yes | AG8: Phim còn hạn từ 2026 | AI8: ROGUE HEROS | AJ8: =SUMIF('TK 15661.Bản quyền phim '!F:F,'KK1. Movies'!D8,'TK 15661.Bản quyền phim '!X:X) -> 0 | AK8: =SUMIF('TK 15661.Bản quyền phim '!F:F,'KK1. Movies'!AI8,'TK 15661.Bản quyền phim '!X:X) -> 0 | AL8: =COUNTIF('242.BQ Phim hợp tác'!$C:$C,'KK1. Movies'!AI8) -> 0 | AM8: =COUNTIF('TK 15661.Bản quyền phim '!F:F,'KK1. Movies'!AI8) -> 1 | AN8: =AL8+AM8 -> 1
A9: =_xlfn.AGGREGATE(3,3,$D$7:D9) -> 3 | B9: 16+ | C9: MOV_ACT_22__2687284 | D9: Escape Plan 2: Hades | E9: Kế hoạch đào tẩu 2: Địa ngục | F9: Crime, Thriller | G9: Roses Media | H9: 140/2022/HDBQ/VSTV-RM | I9: 2018 | J9: US | K9: 96 | L9: 44967 | M9: 46062 | N9: 44967 | O9: K+CINE | P9: Exclusive All Pay TV Rights for first 12 months. Non exclusive All VOD during LP | Q9: No | R9: Yes | S9: No | T9: Yes | U9: Yes | V9: Yes | W9: Yes | X9: Yes | Y9: no | Z9: 44967 | AA9: 46062 | AB9: 24 | AC9: 22 | AD9: Yes | AE9: Yes | AG9: Phim còn hạn từ 2026 | AI9: Escape Plan 2: Hades | AJ9: =SUMIF('TK 15661.Bản quyền phim '!F:F,'KK1. Movies'!D9,'TK 15661.Bản quyền phim '!X:X) -> 0 | AK9: =SUMIF('TK 15661.Bản quyền phim '!F:F,'KK1. Movies'!AI9,'TK 15661.Bản quyền phim '!X:X) -> 0 | AL9: =COUNTIF('242.BQ Phim hợp tác'!$C:$C,'KK1. Movies'!AI9) -> 0 | AM9: =COUNTIF('TK 15661.Bản quyền phim '!F:F,'KK1. Movies'!AI9) -> 1 | AN9: =AL9+AM9 -> 1
A10: =_xlfn.AGGREGATE(3,3,$D$7:D10) -> 4 | B10: 16+ | C10: MOV_ACT_23__2693370 | D10: Riam: Fighting Angel | E10: Riam: Nữ quái nổi loạn | F10: Comedy | G10: Roses Media | H10: 140/2022/HDBQ/VSTV-RM | I10: 2020 | J10: Thailand | K10: 108 | L10: 45064 | M10: 46159 | N10: 45064 | O10: K+CINE | P10: Exclusive All Pay TV Rights for first 12 months. Non exclusive All VOD during LP | Q10: No | R10: Yes | S10: No | T10: Yes | U10: Yes | V10: Yes | W10: Yes | X10: Yes | Y10: No | Z10: 45064 | AA10: 46159 | AB10: 24 | AC10: 16 | AD10: Yes | AE10: Yes | AG10: Phim còn hạn từ 2026 | AI10: Riam: Fighting Angel | AJ10: =SUMIF('TK 15661.Bản quyền phim '!F:F,'KK1. Movies'!D10,'TK 15661.Bản quyền phim '!X:X) -> 0 | AK10: =SUMIF('TK 15661.Bản quyền phim '!F:F,'KK1. Movies'!AI10,'TK 15661.Bản quyền phim '!X:X) -> 0 | AL10: =COUNTIF('242.BQ Phim hợp tác'!$C:$C,'KK1. Movies'!AI10) -> 0 | AM10: =COUNTIF('TK 15661.Bản quyền phim '!F:F,'KK1. Movies'!AI10) -> 1 | AN10: =AL10+AM10 -> 1
A11: =_xlfn.AGGREGATE(3,3,$D$7:D11) -> 5 | B11: P | C11: MOV_ANI_23__2697127 | D11: Happy Family | E11: Gia đình là tất cả | F11: Comedy | G11: Roses Media | H11: 140/2022/HDBQ/VSTV-RM | I11: 2017 | J11: Germany | K11: 96 | L11: 45227 | M11: 46322 | N11: 45227 | O11: K+KIDS | Q11: No | R11: Yes | S11: No | T11: Yes | U11: Yes | V11: Yes | W11: Yes | X11: Yes | Y11: No | Z11: 45227 | AA11: 46322 | AB11: 24 | AC11: 16 | AD11: Yes | AE11: Yes | AG11: Phim còn hạn từ 2026 | AI11: Happy Family | AJ11: =SUMIF('TK 15661.Bản quyền phim '!F:F,'KK1. Movies'!D11,'TK 15661.Bản quyền phim '!X:X) -> 0 | AK11: =SUMIF('TK 15661.Bản quyền phim '!F:F,'KK1. Movies'!AI11,'TK 15661.Bản quyền phim '!X:X) -> 0 | AL11: =COUNTIF('242.BQ Phim hợp tác'!$C:$C,'KK1. Movies'!AI11) -> 0 | AM11: =COUNTIF('TK 15661.Bản quyền phim '!F:F,'KK1. Movies'!AI11) -> 1 | AN11: =AL11+AM11 -> 1
A12: =_xlfn.AGGREGATE(3,3,$D$7:D12) -> 6 | B12: 16+ | C12: MOV_DRA739 | D12: MEMOIRS OF A GEISHA | E12: Hồi ức của một Geisha | F12: Drama | G12: SONY | H12: Sony/K+Vietnam PayBasic SVOD Package Agmt D3A FE (Feb-5-24) | I12: 2005 | J12: U.S.A.[excluding Territories & Possessions] | K12: 145 | L12: 45701 | M12: 46430 | Q12: No | R12: Yes | S12: Yes | T12: Yes | U12: No | V12: No | W12: No | X12: Yes | Y12: No | Z12: 45701 | AA12: 46246 | AB12: 7 | AC12: 1 | AD12: Yes | AE12: Yes | AG12: Phim còn hạn từ 2026 | AI12: MEMOIRS OF A GEISHA | AJ12: =SUMIF('TK 15661.Bản quyền phim '!F:F,'KK1. Movies'!D12,'TK 15661.Bản quyền phim '!X:X) -> 46627350 | AK12: =SUMIF('TK 15661.Bản quyền phim '!F:F,'KK1. Movies'!AI12,'TK 15661.Bản quyền phim '!X:X) -> 46627350 | AL12: =COUNTIF('242.BQ Phim hợp tác'!$C:$C,'KK1. Movies'!AI12) -> 0 | AM12: =COUNTIF('TK 15661.Bản quyền phim '!F:F,'KK1. Movies'!AI12) -> 1 | AN12: =AL12+AM12 -> 1
A13: =_xlfn.AGGREGATE(3,3,$D$7:D13) -> 7 | B13: 16+ | C13: MOV_DRA_23__2695077 | D13: Ironbark/ The Courier | E13: Người đưa tin | F13: Crime, Thriller | G13: Roses Media | H13: 140/2022/HDBQ/VSTV-RM | I13: 2021 | J13: US | K13: 112 | L13: 45191 | M13: 46286 | N13: 45191 | O13: K+CINE | P13: Exclusive All Pay TV Rights for first 12 months. Non exclusive All VOD during LP | Q13: No | R13: Yes | S13: No | T13: Yes | U13: Yes | V13: Yes | W13: Yes | X13: Yes | Y13: Yes | Z13: 45191 | AA13: 46286 | AB13: 24 | AC13: 12 | AD13: Yes | AE13: Yes | AG13: Phim còn hạn từ 2026 | AI13: Ironbark/The Courier | AJ13: =SUMIF('TK 15661.Bản quyền phim '!F:F,'KK1. Movies'!D13,'TK 15661.Bản quyền phim '!X:X) -> 0 | AK13: =SUMIF('TK 15661.Bản quyền phim '!F:F,'KK1. Movies'!AI13,'TK 15661.Bản quyền phim '!X:X) -> 0 | AL13: =COUNTIF('242.BQ Phim hợp tác'!$C:$C,'KK1. Movies'!AI13) -> 0 | AM13: =COUNTIF('TK 15661.Bản quyền phim '!F:F,'KK1. Movies'!AI13) -> 1 | AN13: =AL13+AM13 -> 1
A14: =_xlfn.AGGREGATE(3,3,$D$7:D14) -> 8 | B14: 16+ | C14: MOV_ACT_22__2686885 | D14: Hitman's Wife's Bodyguard | E14: Vệ sĩ sát thủ 2: Nhà có nóc | F14: Action, Adventure | G14: Roses Media | H14: 140/2022/HDBQ/VSTV-RM | I14: 2021 | J14: US | K14: 89 | L14: 44951 | M14: 46046 | N14: 44951 | O14: K+CINE | P14: Exclusive All Pay TV Rights for first 12 months. Non exclusive All VOD during LP | Q14: No | R14: Yes | S14: Yes | T14: Yes | U14: Yes | V14: Yes | W14: Yes | X14: Yes | Y14: no | Z14: 44951 | AA14: 46046 | AB14: 24 | AC14: 13 | AD14: Yes | AE14: Yes | AG14: Phim còn hạn từ 2026 | AI14: Hitman's Wife's Bodyguard | AJ14: =SUMIF('TK 15661.Bản quyền phim '!F:F,'KK1. Movies'!D14,'TK 15661.Bản quyền phim '!X:X) -> 0 | AK14: =SUMIF('TK 15661.Bản quyền phim '!F:F,'KK1. Movies'!AI14,'TK 15661.Bản quyền phim '!X:X) -> 0 | AL14: =COUNTIF('242.BQ Phim hợp tác'!$C:$C,'KK1. Movies'!AI14) -> 0 | AM14: =COUNTIF('TK 15661.Bản quyền phim '!F:F,'KK1. Movies'!AI14) -> 1 | AN14: =AL14+AM14 -> 1
A15: =_xlfn.AGGREGATE(3,3,$D$7:D15) -> 9 | B15: 16+ | C15: MOV_HOR_24__2713435 | D15: GUIMOON: THE LIGHTLESS DOOR | E15: CỔNG ĐỊA NGỤC | F15: Horror | G15: CJ HK | H15: 180/2024/HDBQ/VSTV-CJHK | I15: 2021 | J15: Korea | K15: 85 | L15: 45566 | M15: 46660 | N15: 45568 | O15: K+ACTION | P15: 12 | Q15: No | R15: Yes | S15: Yes | T15: Yes | U15: Yes | V15: Yes | W15: Yes | X15: No | Y15: Yes | Z15: 45566 | AA15: 46660 | AB15: Unlimited | AC15: 11 | AD15: Yes | AE15: Yes | AG15: Phim còn hạn từ 2026 | AI15: GUIMOON: THE LIGHTLESS DOOR (CỔNG ĐỊA NGỤC) | AJ15: =SUMIF('TK 15661.Bản quyền phim '!F:F,'KK1. Movies'!D15,'TK 15661.Bản quyền phim '!X:X) -> 0 | AK15: =SUMIF('TK 15661.Bản quyền phim '!F:F,'KK1. Movies'!AI15,'TK 15661.Bản quyền phim '!X:X) -> 28571429 | AL15: =COUNTIF('242.BQ Phim hợp tác'!$C:$C,'KK1. Movies'!AI15) -> 0 | AM15: =COUNTIF('TK 15661.Bản quyền phim '!F:F,'KK1. Movies'!AI15) -> 1 | AN15: =AL15+AM15 -> 1
A16: =_xlfn.AGGREGATE(3,3,$D$7:D16) -> 10 | B16: 16+ | C16: MOV_DRA_23__2696593 | D16: Greta | E16: Góa phụ Greta | F16: Crime, Thriller | G16: Roses Media | H16: 140/2022/HDBQ/VSTV-RM | I16: 2018 | J16: US | K16: 98 | L16: 45217 | M16: 46312 | N16: 45217 | O16: K+CINE | P16: Exclusive All Pay TV Rights for first 12 months. Non exclusive All VOD during LP | Q16: No | R16: Yes | S16: No | T16: Yes | U16: Yes | V16: Yes | W16: Yes | X16: Yes | Y16: No | Z16: 45217 | AA16: 46312 | AB16: 24 | AC16: 18 | AD16: Yes | AE16: Yes | AG16: Phim còn hạn từ 2026 | AH16: MOV_DRA_23__2696593 | AI16: Greta | AJ16: =SUMIF('TK 15661.Bản quyền phim '!F:F,'KK1. Movies'!D16,'TK 15661.Bản quyền phim '!X:X) -> 0 | AK16: =SUMIF('TK 15661.Bản quyền phim '!F:F,'KK1. Movies'!AI16,'TK 15661.Bản quyền phim '!X:X) -> 0 | AL16: =COUNTIF('242.BQ Phim hợp tác'!$C:$C,'KK1. Movies'!AI16) -> 0 | AM16: =COUNTIF('TK 15661.Bản quyền phim '!F:F,'KK1. Movies'!AI16) -> 1 | AN16: =AL16+AM16 -> 1
A17: =_xlfn.AGGREGATE(3,3,$D$7:D17) -> 11 | B17: K | C17: MOV_FAN_22__2686869 | D17: HOUSE WITH A CLOCK IN ITS WALLS | E17: Ngôi nhà có chiếc đồng hồ ma thuật | F17: Comedy | G17: CJ HK | H17: 135/2022/HDBQ/VSTV-CJHK | I17: 2018 | J17: US | K17: 105 | L17: 44952 | M17: 46047 | N17: 44952 | O17: K+CINE | P17: 12 | Q17: No | R17: Yes | S17: Yes | T17: Yes | U17: Yes | V17: Yes | W17: Yes | X17: No | Y17: Yes | Z17: 44952 | AA17: 46047 | AB17: unlimited | AC17: 22 | AD17: Yes | AE17: Yes | AG17: Phim còn hạn từ 2026 | AH17: MOV_FAN_22__2686869 | AI17: HOUSE WITH A CLOCK IN ITS WALLS (Ngôi nhà có chiếc đồng hồ ma thuật) | AJ17: =SUMIF('TK 15661.Bản quyền phim '!F:F,'KK1. Movies'!D17,'TK 15661.Bản quyền phim '!X:X) -> 0 | AK17: =SUMIF('TK 15661.Bản quyền phim '!F:F,'KK1. Movies'!AI17,'TK 15661.Bản quyền phim '!X:X) -> 0 | AL17: =COUNTIF('242.BQ Phim hợp tác'!$C:$C,'KK1. Movies'!AI17) -> 0 | AM17: =COUNTIF('TK 15661.Bản quyền phim '!F:F,'KK1. Movies'!AI17) -> 1 | AN17: =AL17+AM17 -> 1
A18: =_xlfn.AGGREGATE(3,3,$D$7:D18) -> 12 | B18: 16+ | C18: MOV_DRA730 | D18: HUNT, THE | E18: Cuộc săn lùng | F18: action | G18: NBC Universal | H18: 5049540-2/161434-3 | I18: 2019 | J18: US | K18: 90 | L18: 45414 | M18: 46143 | N18: 45442 | O18: K+ACTION | P18: Non exclusive | Q18: No | R18: Yes | S18: Yes | T18: Yes | U18: No | V18: No | W18: No | X18: No | Y18: Yes | Z18: 45414 | AA18: 46143 | AB18: 6 | AC18: 4 | AD18: Yes | AE18: Yes | AG18: Phim còn hạn từ 2026 | AI18: HUNT, THE | AJ18: =SUMIF('TK 15661.Bản quyền phim '!F:F,'KK1. Movies'!D18,'TK 15661.Bản quyền phim '!X:X) -> 0 | AK18: =SUMIF('TK 15661.Bản quyền phim '!F:F,'KK1. Movies'!AI18,'TK 15661.Bản quyền phim '!X:X) -> 0 | AL18: =COUNTIF('242.BQ Phim hợp tác'!$C:$C,'KK1. Movies'!AI18) -> 0 | AM18: =COUNTIF('TK 15661.Bản quyền phim '!F:F,'KK1. Movies'!AI18) -> 1 | AN18: =AL18+AM18 -> 1
A19: =_xlfn.AGGREGATE(3,3,$D$7:D19) -> 13 | B19: 16+ | C19: MOV_CRI_21__2648182 | D19: MOZU | E19: Sát thủ Mozu | F19: Crime, Thriller | G19: TBS | H19: 202104013 | I19: 2015 | J19: Japan | K19: 116 | L19: 44284 | M19: 46109 | N19: 44349 | O19: K+CINE | Q19: No | R19: Yes | S19: Yes | T19: Yes | U19: Yes | V19: Yes | W19: Yes | X19: Yes | Y19: Yes | Z19: 44284 | AA19: 46109 | AB19: 50 | AC19: 34 | AD19: Yes | AE19: Yes | AG19: Phim còn hạn từ 2026 | AH19: MOV_CRI_21__2648182 | AI19: MOZU | AJ19: =SUMIF('TK 15661.Bản quyền phim '!F:F,'KK1. Movies'!D19,'TK 15661.Bản quyền phim '!X:X) -> 0 | AK19: =SUMIF('TK 15661.Bản quyền phim '!F:F,'KK1. Movies'!AI19,'TK 15661.Bản quyền phim '!X:X) -> 0 | AL19: =COUNTIF('242.BQ Phim hợp tác'!$C:$C,'KK1. Movies'!AI19) -> 0 | AM19: =COUNTIF('TK 15661.Bản quyền phim '!F:F,'KK1. Movies'!AI19) -> 1 | AN19: =AL19+AM19 -> 1
A20: =_xlfn.AGGREGATE(3,3,$D$7:D20) -> 14 | B20: 16+ | C20: MOV_ACT556 | D20: Caught In Time | E20: Trừ Gian Diệt Ác | F20: action | G20: Hỏa Thổ | H20: 25A/2024/HDBQ/VSTV-Hoa tho | I20: 2020 | J20: China | K20: 95 | L20: 45443 | M20: 46537 | N20: 45443 | O20: K+CINE | Q20: No | R20: Yes | S20: Yes | T20: Yes | U20: No | V20: Yes | W20: Yes | X20: No | Y20: No | Z20: 45443 | AA20: 46537 | AB20: Unlimited run | AC20: 14 | AD20: Yes | AE20: Yes | AG20: Phim còn hạn từ 2026 | AH20: MOV_ACT556 | AI20: Caught In Time (Trừ Gian Diệt Ác) | AJ20: =SUMIF('TK 15661.Bản quyền phim '!F:F,'KK1. Movies'!D20,'TK 15661.Bản quyền phim '!X:X) -> 0 | AK20: =SUMIF('TK 15661.Bản quyền phim '!F:F,'KK1. Movies'!AI20,'TK 15661.Bản quyền phim '!X:X) -> 33737937 | AL20: =COUNTIF('242.BQ Phim hợp tác'!$C:$C,'KK1. Movies'!AI20) -> 0 | AM20: =COUNTIF('TK 15661.Bản quyền phim '!F:F,'KK1. Movies'!AI20) -> 1 | AN20: =AL20+AM20 -> 1
A21: =_xlfn.AGGREGATE(3,3,$D$7:D21) -> 15 | B21: 16+ | C21: MOV_HOR_24__2713878 | D21: CONTORTED | E21: NHÀ KHO CHẾT CHÓC | F21: Horror | G21: CJ HK | H21: 180/2024/HDBQ/VSTV-CJHK | I21: 2022 | J21: Korea | K21: 90 | L21: 45566 | M21: 46660 | N21: 45589 | O21: K+ACTION | P21: 12 | Q21: No | R21: Yes | S21: Yes | T21: Yes | U21: Yes | V21: Yes | W21: Yes | X21: No | Y21: No | Z21: 45566 | AA21: 46660 | AB21: Unlimited | AC21: 11 | AD21: Yes | AE21: Yes | AG21: Phim còn hạn từ 2026 | AH21: MOV_HOR_24__2713878 | AI21: CONTORTED (NHÀ KHO CHẾT CHÓC) | AJ21: =SUMIF('TK 15661.Bản quyền phim '!F:F,'KK1. Movies'!D21,'TK 15661.Bản quyền phim '!X:X) -> 0 | AK21: =SUMIF('TK 15661.Bản quyền phim '!F:F,'KK1. Movies'!AI21,'TK 15661.Bản quyền phim '!X:X) -> 28571429 | AL21: =COUNTIF('242.BQ Phim hợp tác'!$C:$C,'KK1. Movies'!AI21) -> 0 | AM21: =COUNTIF('TK 15661.Bản quyền phim '!F:F,'KK1. Movies'!AI21) -> 1 | AN21: =AL21+AM21 -> 1
A22: =_xlfn.AGGREGATE(3,3,$D$7:D22) -> 16 | B22: 16+ | C22: MOV_SCI20 | D22: LONG DISTANCE | E22: Tín hiệu vũ trụ | F22: Others | G22: CJ HK | H22: 15/2025/HDBQ/VSTV-CJHK | I22: 2024 | J22: US | K22: 91 | L22: 45722 | M22: 46817 | P22: 12 | Q22: No | R22: Yes | S22: Yes | T22: Yes | U22: Yes | V22: Yes | W22: Yes | X22: Yes | Y22: Yes | Z22: 45722 | AA22: 46817 | AB22: Unlimited | AC22: 8 | AD22: Yes | AE22: Yes | AG22: Phim còn hạn từ 2026 | AI22: LONG DISTANCE | AJ22: =SUMIF('TK 15661.Bản quyền phim '!F:F,'KK1. Movies'!D22,'TK 15661.Bản quyền phim '!X:X) -> 60317460 | AK22: =SUMIF('TK 15661.Bản quyền phim '!F:F,'KK1. Movies'!AI22,'TK 15661.Bản quyền phim '!X:X) -> 60317460 | AL22: =COUNTIF('242.BQ Phim hợp tác'!$C:$C,'KK1. Movies'!AI22) -> 0 | AM22: =COUNTIF('TK 15661.Bản quyền phim '!F:F,'KK1. Movies'!AI22) -> 1 | AN22: =AL22+AM22 -> 1
A23: =_xlfn.AGGREGATE(3,3,$D$7:D23) -> 17 | B23: 16+ | C23: MOV_CRI_22__2686505 | D23: The Night Clerk | E23: Người trực đêm | F23: Crime, Thriller | G23: Skyline Media | H23: 66/2023/HDBQ/VSTV-SM | I23: 2020 | J23: US | K23: 90 | L23: 44937 | M23: 46032 | N23: 44937 | O23: K+CINE | P23: Exclusive All TV Rights the first 12 months of LP Non-exclusive with All Catch-up TV Rights; All VOD Rights during LP | Q23: No | R23: Yes | S23: Yes | T23: Yes | U23: Yes | V23: Yes | W23: Yes | X23: Yes | Y23: Yes | Z23: 44937 | AA23: 46032 | AB23: 24 | AC23: 21 | AD23: Yes | AE23: Yes | AG23: Phim còn hạn từ 2026 | AI23: The Night Clerk | AJ23: =SUMIF('TK 15661.Bản quyền phim '!F:F,'KK1. Movies'!D23,'TK 15661.Bản quyền phim '!X:X) -> 0 | AK23: =SUMIF('TK 15661.Bản quyền phim '!F:F,'KK1. Movies'!AI23,'TK 15661.Bản quyền phim '!X:X) -> 0 | AL23: =COUNTIF('242.BQ Phim hợp tác'!$C:$C,'KK1. Movies'!AI23) -> 0 | AM23: =COUNTIF('TK 15661.Bản quyền phim '!F:F,'KK1. Movies'!AI23) -> 1 | AN23: =AL23+AM23 -> 1
A24: =_xlfn.AGGREGATE(3,3,$D$7:D24) -> 18 | B24: 13+ | C24: MOV_ACT_24__2710733 | D24: Journey to China: The Mystery of the Dragon Seal | E24: Long ẩn cơ mật | F24: Action, Adventure | G24: Rose media | H24: 5/2022/HDBQ/VSTV-RM | I24: 2019 | J24: China | K24: 120 | L24: 45338 | M24: 46433 | N24: 45338 | O24: K+CINE | Q24: No | R24: Yes | S24: Yes | T24: Yes | U24: Yes | V24: Yes | W24: Yes | X24: Yes | Y24: No | Z24: 45338 | AA24: 46433 | AB24: 24 | AC24: 18 | AD24: Yes | AE24: Yes | AG24: Phim còn hạn từ 2026 | AI24: Journey to China: The Mystery of the Dragon Seal | AJ24: =SUMIF('TK 15661.Bản quyền phim '!F:F,'KK1. Movies'!D24,'TK 15661.Bản quyền phim '!X:X) -> 29462698 | AK24: =SUMIF('TK 15661.Bản quyền phim '!F:F,'KK1. Movies'!AI24,'TK 15661.Bản quyền phim '!X:X) -> 29462698 | AL24: =COUNTIF('242.BQ Phim hợp tác'!$C:$C,'KK1. Movies'!AI24) -> 0 | AM24: =COUNTIF('TK 15661.Bản quyền phim '!F:F,'KK1. Movies'!AI24) -> 1 | AN24: =AL24+AM24 -> 1
A25: =_xlfn.AGGREGATE(3,3,$D$7:D25) -> 19 | B25: 16+ | C25: MOV_ACT_22__2686478 | D25: Gringo | E25: Nhọ gặp hên | F25: Action, Adventure | G25: Pro Partner | H25: 56/2023/HDBQ/VSTV-Pro Partner | I25: 2018 | J25: US | K25: 111 | L25: 44930 | M25: 46025 | N25: 44930 | O25: K+CINE | P25: Exclusive All TV Rights the first 9 months of LP Non-exclusive with All Catch-up TV Rights; All VOD Rights during LP | Q25: No | R25: Yes | S25: Yes | T25: Yes | U25: Yes | V25: Yes | W25: Yes | X25: Yes | Y25: Yes | Z25: 44930 | AA25: 46025 | AB25: unlimited | AC25: 27 | AD25: Yes | AE25: Yes | AG25: Phim còn hạn từ 2026 | AI25: Gringo | AJ25: =SUMIF('TK 15661.Bản quyền phim '!F:F,'KK1. Movies'!D25,'TK 15661.Bản quyền phim '!X:X) -> 0 | AK25: =SUMIF('TK 15661.Bản quyền phim '!F:F,'KK1. Movies'!AI25,'TK 15661.Bản quyền phim '!X:X) -> 0 | AL25: =COUNTIF('242.BQ Phim hợp tác'!$C:$C,'KK1. Movies'!AI25) -> 0 | AM25: =COUNTIF('TK 15661.Bản quyền phim '!F:F,'KK1. Movies'!AI25) -> 1 | AN25: =AL25+AM25 -> 1
A26: =_xlfn.AGGREGATE(3,3,$D$7:D26) -> 20 | B26: 16+ | C26: MOV_CRI_23__2694717 | D26: THE GIRL ON THE TRAIN | E26: Cô gái trên tàu | F26: Crime, Thriller | G26: CJ HK | H26: 135/2022/HDBQ/VSTV-CJHK | I26: 2016 | J26: US | K26: 112 | L26: 45275 | M26: 46370 | N26: 45275 | O26: K+CINE | P26: 12 | Q26: No | R26: Yes | S26: Yes | T26: Yes | U26: Yes | V26: Yes | W26: Yes | X26: No | Y26: Yes | Z26: 45275 | AA26: 46370 | AB26: unlimited | AC26: 23 | AD26: Yes | AE26: Yes | AG26: Phim còn hạn từ 2026 | AI26: THE GIRL ON THE TRAIN (Cô gái trên tàu) | AJ26: =SUMIF('TK 15661.Bản quyền phim '!F:F,'KK1. Movies'!D26,'TK 15661.Bản quyền phim '!X:X) -> 0 | AK26: =SUMIF('TK 15661.Bản quyền phim '!F:F,'KK1. Movies'!AI26,'TK 15661.Bản quyền phim '!X:X) -> 0 | AL26: =COUNTIF('242.BQ Phim hợp tác'!$C:$C,'KK1. Movies'!AI26) -> 0 | AM26: =COUNTIF('TK 15661.Bản quyền phim '!F:F,'KK1. Movies'!AI26) -> 1 | AN26: =AL26+AM26 -> 1
A27: =_xlfn.AGGREGATE(3,3,$D$7:D27) -> 21 | B27: 16+ | C27: MOV_ACT_23__2691050 | D27: Triple Threat | E27: Bộ ba vệ sĩ | F27: Crime, Thriller | G27: Roses Media | H27: 140/2022/HDBQ/VSTV-RM | I27: 2019 | J27: US, Thailand, China, France | K27: 96 | L27: 45161 | M27: 46256 | N27: 45161 | O27: K+CINE | P27: Exclusive All Pay TV Rights for first 12 months. Non exclusive All VOD during LP | Q27: No | R27: Yes | S27: No | T27: Yes | U27: Yes | V27: Yes | W27: Yes | X27: Yes | Y27: No | Z27: 45161 | AA27: 46256 | AB27: 24 | AC27: 15 | AD27: Yes | AE27: Yes | AG27: Phim còn hạn từ 2026 | AI27: Triple Threat | AJ27: =SUMIF('TK 15661.Bản quyền phim '!F:F,'KK1. Movies'!D27,'TK 15661.Bản quyền phim '!X:X) -> 0 | AK27: =SUMIF('TK 15661.Bản quyền phim '!F:F,'KK1. Movies'!AI27,'TK 15661.Bản quyền phim '!X:X) -> 0 | AL27: =COUNTIF('242.BQ Phim hợp tác'!$C:$C,'KK1. Movies'!AI27) -> 0 | AM27: =COUNTIF('TK 15661.Bản quyền phim '!F:F,'KK1. Movies'!AI27) -> 1 | AN27: =AL27+AM27 -> 1
A28: =_xlfn.AGGREGATE(3,3,$D$7:D28) -> 22 | B28: 16+ | C28: MOV_THR_24__2712729 | D28: RECALLED | E28: TRIỆU HỒI | F28: Horror | G28: CJ HK | H28: 180/2024/HDBQ/VSTV-CJHK | I28: 2021 | J28: Korea | K28: 99 | L28: 45358 | M28: 46452 | N28: 45358 | O28: K+ACTION | P28: 12 | Q28: No | R28: Yes | S28: Yes | T28: Yes | U28: Yes | V28: Yes | W28: Yes | X28: No | Y28: Yes | Z28: 45358 | AA28: 46452 | AB28: Unlimited | AC28: 18 | AD28: Yes | AE28: Yes | AG28: Phim còn hạn từ 2026 | AI28: RECALLED (TRIỆU HỒI) | AJ28: =SUMIF('TK 15661.Bản quyền phim '!F:F,'KK1. Movies'!D28,'TK 15661.Bản quyền phim '!X:X) -> 0 | AK28: =SUMIF('TK 15661.Bản quyền phim '!F:F,'KK1. Movies'!AI28,'TK 15661.Bản quyền phim '!X:X) -> 19047619 | AL28: =COUNTIF('242.BQ Phim hợp tác'!$C:$C,'KK1. Movies'!AI28) -> 0 | AM28: =COUNTIF('TK 15661.Bản quyền phim '!F:F,'KK1. Movies'!AI28) -> 1 | AN28: =AL28+AM28 -> 1
A29: =_xlfn.AGGREGATE(3,3,$D$7:D29) -> 23 | B29: 13+ | C29: MOV_ADV_23__2694718 | D29: A DOG'S PURPOSE | E29: Mục đích sống của một chú chó | F29: Drama | G29: CJ HK | H29: 135/2022/HDBQ/VSTV-CJHK | I29: 2016 | J29: US | K29: 100 | L29: 45281 | M29: 46376 | N29: 45281 | O29: K+CINE | P29: 12 | Q29: No | R29: Yes | S29: Yes | T29: Yes | U29: Yes | V29: Yes | W29: Yes | X29: No | Y29: Yes | Z29: 45281 | AA29: 46376 | AB29: unlimited | AC29: 16 | AD29: Yes | AE29: Yes | AG29: Phim còn hạn từ 2026 | AI29: A DOG'S PURPOSE (Mục đích sống của một chú chó) | AJ29: =SUMIF('TK 15661.Bản quyền phim '!F:F,'KK1. Movies'!D29,'TK 15661.Bản quyền phim '!X:X) -> 0 | AK29: =SUMIF('TK 15661.Bản quyền phim '!F:F,'KK1. Movies'!AI29,'TK 15661.Bản quyền phim '!X:X) -> 0 | AL29: =COUNTIF('242.BQ Phim hợp tác'!$C:$C,'KK1. Movies'!AI29) -> 0 | AM29: =COUNTIF('TK 15661.Bản quyền phim '!F:F,'KK1. Movies'!AI29) -> 1 | AN29: =AL29+AM29 -> 1
A30: =_xlfn.AGGREGATE(3,3,$D$7:D30) -> 24 | B30: 13+ | C30: MOV_MUS7 | D30: BURLESQUE | E30: Vũ nữ | F30: Drama | G30: SONY PICTURES | H30: Sony/K+Vietnam PayBasic SVOD Package Agmt D2D per JK (19-01-2024) | I30: 2010 | J30: US | K30: 118 | L30: 45505 | M30: 46234 | N30: 45602 | O30: K+CINE | Q30: No | R30: Yes | S30: Yes | T30: Yes | U30: No | V30: No | W30: No | X30: No | Y30: No | Z30: 45505 | AA30: 46234 | AB30: 7 | AC30: 2 | AD30: Yes | AE30: Yes | AG30: Phim còn hạn từ 2026 | AI30: BURLESQUE | AJ30: =SUMIF('TK 15661.Bản quyền phim '!F:F,'KK1. Movies'!D30,'TK 15661.Bản quyền phim '!X:X) -> 0 | AK30: =SUMIF('TK 15661.Bản quyền phim '!F:F,'KK1. Movies'!AI30,'TK 15661.Bản quyền phim '!X:X) -> 0 | AL30: =COUNTIF('242.BQ Phim hợp tác'!$C:$C,'KK1. Movies'!AI30) -> 0 | AM30: =COUNTIF('TK 15661.Bản quyền phim '!F:F,'KK1. Movies'!AI30) -> 1 | AN30: =AL30+AM30 -> 1
A31: =_xlfn.AGGREGATE(3,3,$D$7:D31) -> 25 | B31: 13+ | C31: MOV_ACT_23__2695079 | D31: My Spy | E31: Điệp viên tí hon | F31: Comedy | G31: Roses Media | H31: 140/2022/HDBQ/VSTV-RM | I31: 2020 | J31: US | K31: 99 | L31: 45197 | M31: 46292 | N31: 45197 | O31: K+CINE | P31: Exclusive All Pay TV Rights for first 12 months. Non exclusive All VOD during LP | Q31: No | R31: Yes | S31: No | T31: Yes | U31: Yes | V31: Yes | W31: Yes | X31: Yes | Y31: No | Z31: 45197 | AA31: 46292 | AB31: 24 | AC31: 14 | AD31: Yes | AE31: Yes | AG31: Phim còn hạn từ 2026 | AI31: My Spy | AJ31: =SUMIF('TK 15661.Bản quyền phim '!F:F,'KK1. Movies'!D31,'TK 15661.Bản quyền phim '!X:X) -> 0 | AK31: =SUMIF('TK 15661.Bản quyền phim '!F:F,'KK1. Movies'!AI31,'TK 15661.Bản quyền phim '!X:X) -> 0 | AL31: =COUNTIF('242.BQ Phim hợp tác'!$C:$C,'KK1. Movies'!AI31) -> 0 | AM31: =COUNTIF('TK 15661.Bản quyền phim '!F:F,'KK1. Movies'!AI31) -> 1 | AN31: =AL31+AM31 -> 1
A32: =_xlfn.AGGREGATE(3,3,$D$7:D32) -> 26 | B32: 16+ | C32: MOV_CRI107 | D32: EMILY THE CRIMINAL | E32: Tội phạm Emily | F32: action | G32: NBC Universal | H32: 5049540-2/161434-3 | I32: 2022 | J32: US | K32: 96 | L32: 45554 | M32: 46283 | N32: 45554 | O32: K+ACTION | Q32: No | R32: Yes | S32: Yes | T32: Yes | U32: No | V32: No | W32: No | X32: No | Y32: Yes | Z32: 45554 | AA32: 46283 | AB32: 6 | AC32: 3 | AD32: Yes | AE32: Yes | AG32: Phim còn hạn từ 2026 | AI32: EMILY THE CRIMINAL | AJ32: =SUMIF('TK 15661.Bản quyền phim '!F:F,'KK1. Movies'!D32,'TK 15661.Bản quyền phim '!X:X) -> 0 | AK32: =SUMIF('TK 15661.Bản quyền phim '!F:F,'KK1. Movies'!AI32,'TK 15661.Bản quyền phim '!X:X) -> 0 | AL32: =COUNTIF('242.BQ Phim hợp tác'!$C:$C,'KK1. Movies'!AI32) -> 0 | AM32: =COUNTIF('TK 15661.Bản quyền phim '!F:F,'KK1. Movies'!AI32) -> 1 | AN32: =AL32+AM32 -> 1
A33: =_xlfn.AGGREGATE(3,3,$D$7:D33) -> 27 | B33: 16+ | C33: MOV_COM_24__2710443 | D33: A LONG WAY DOWN | E33: Còn lâu mới chết | F33: Drama | G33: Skyline Media | H33: 28/2024/HDBQ/VSTV-SM | I33: 2014 | J33: UK | K33: 96 | L33: 45385 | M33: 46479 | N33: 45506 | O33: K+CINE | P33: 12 | Q33: No | R33: Yes | S33: Yes | T33: Yes | U33: Yes | V33: Yes | W33: Yes | X33: Yes | Y33: No | Z33: 45385 | AA33: 46479 | AB33: 24 | AC33: 14 | AD33: Yes | AE33: Yes | AG33: Phim còn hạn từ 2026 | AI33: A LONG WAY DOWN | AJ33: =SUMIF('TK 15661.Bản quyền phim '!F:F,'KK1. Movies'!D33,'TK 15661.Bản quyền phim '!X:X) -> 33333492 | AK33: =SUMIF('TK 15661.Bản quyền phim '!F:F,'KK1. Movies'!AI33,'TK 15661.Bản quyền phim '!X:X) -> 33333492 | AL33: =COUNTIF('242.BQ Phim hợp tác'!$C:$C,'KK1. Movies'!AI33) -> 0 | AM33: =COUNTIF('TK 15661.Bản quyền phim '!F:F,'KK1. Movies'!AI33) -> 1 | AN33: =AL33+AM33 -> 1
A34: =_xlfn.AGGREGATE(3,3,$D$7:D34) -> 28 | B34: 16+ | C34: MOV_HOR68 | D34: WITCH, THE | E34: Phù thủy | F34: Horror | G34: NBC Universal | H34: 5049540-2/161434-3 | I34: 2016 | J34: US | K34: 90 | L34: 45596 | M34: 46325 | N34: 45596 | O34: K+ACTION | Q34: No | R34: Yes | S34: Yes | T34: Yes | U34: No | V34: No | W34: No | X34: No | Y34: Yes | Z34: 45596 | AA34: 46325 | AB34: 6 | AC34: 2 | AD34: Yes | AE34: Yes | AG34: Phim còn hạn từ 2026 | AI34: WITCH, THE | AJ34: =SUMIF('TK 15661.Bản quyền phim '!F:F,'KK1. Movies'!D34,'TK 15661.Bản quyền phim '!X:X) -> 0 | AK34: =SUMIF('TK 15661.Bản quyền phim '!F:F,'KK1. Movies'!AI34,'TK 15661.Bản quyền phim '!X:X) -> 0 | AL34: =COUNTIF('242.BQ Phim hợp tác'!$C:$C,'KK1. Movies'!AI34) -> 0 | AM34: =COUNTIF('TK 15661.Bản quyền phim '!F:F,'KK1. Movies'!AI34) -> 1 | AN34: =AL34+AM34 -> 1
A35: =_xlfn.AGGREGATE(3,3,$D$7:D35) -> 29 | B35: 16+ | C35: MOV_ACT584 | D35: AMBULANCE (2022) | E35: Xe cấp cứu | F35: action | G35: NBC Universal | H35: 5049540-2/161434-3 | I35: 2022 | J35: US | K35: 136 | L35: 45513 | M35: 46242 | N35: 45513 | O35: K+CINE | P35: 12 | Q35: No | R35: Yes | S35: Yes | T35: Yes | U35: No | V35: No | W35: No | X35: No | Y35: Yes | Z35: 45513 | AA35: 46242 | AB35: 6 | AC35: 3 | AD35: Yes | AE35: Yes | AG35: Phim còn hạn từ 2026 | AI35: AMBULANCE (2022) | AJ35: =SUMIF('TK 15661.Bản quyền phim '!F:F,'KK1. Movies'!D35,'TK 15661.Bản quyền phim '!X:X) -> 0 | AK35: =SUMIF('TK 15661.Bản quyền phim '!F:F,'KK1. Movies'!AI35,'TK 15661.Bản quyền phim '!X:X) -> 0 | AL35: =COUNTIF('242.BQ Phim hợp tác'!$C:$C,'KK1. Movies'!AI35) -> 0 | AM35: =COUNTIF('TK 15661.Bản quyền phim '!F:F,'KK1. Movies'!AI35) -> 1 | AN35: =AL35+AM35 -> 1
A36: =_xlfn.AGGREGATE(3,3,$D$7:D36) -> 30 | B36: 16+ | C36: MOV_COM_22__2686480 | D36: Best Friend | E36: Láng giềng gần | F36: Drama | G36: Pro Partner | H36: 56/2023/HDBQ/VSTV-Pro Partner | I36: 2020 | J36: Korea | K36: 130 | L36: 44938 | M36: 46033 | N36: 44938 | O36: K+CINE | P36: Exclusive All TV Rights the first 9 months of LP Non-exclusive with All Catch-up TV Rights; All VOD Rights during LP | Q36: No | R36: Yes | S36: Yes | T36: Yes | U36: Yes | V36: Yes | W36: Yes | X36: Yes | Y36: Yes | Z36: 44938 | AA36: 46033 | AB36: unlimited | AC36: 26 | AD36: Yes | AE36: Yes | AG36: Phim còn hạn từ 2026 | AI36: Best Friend | AJ36: =SUMIF('TK 15661.Bản quyền phim '!F:F,'KK1. Movies'!D36,'TK 15661.Bản quyền phim '!X:X) -> 0 | AK36: =SUMIF('TK 15661.Bản quyền phim '!F:F,'KK1. Movies'!AI36,'TK 15661.Bản quyền phim '!X:X) -> 0 | AL36: =COUNTIF('242.BQ Phim hợp tác'!$C:$C,'KK1. Movies'!AI36) -> 0 | AM36: =COUNTIF('TK 15661.Bản quyền phim '!F:F,'KK1. Movies'!AI36) -> 1 | AN36: =AL36+AM36 -> 1
A37: =_xlfn.AGGREGATE(3,3,$D$7:D37) -> 31 | B37: P | C37: MOV_ANI_23__2709986 | D37: AROUND THE WORLD IN 80 DAYS | E37: KHỈ CON LON TON THẾ GIỚI | F37: Comedy | G37: CJ HK | H37: 180/2024/HDBQ/VSTV-CJHK | I37: 2021 | J37: France | K37: 82 | L37: 45304 | M37: 46399 | N37: 45304 | O37: K+KIDS | P37: 12 | Q37: No | R37: Yes | S37: Yes | T37: Yes | U37: Yes | V37: Yes | W37: Yes | X37: No | Y37: Yes | Z37: 45304 | AA37: 46399 | AB37: Unlimited | AC37: 31 | AD37: Yes | AE37: Yes | AG37: Phim còn hạn từ 2026 | AI37: AROUND THE WORLD IN 80 DAYS (KHỈ CON LON TON THẾ GIỚI) | AJ37: =SUMIF('TK 15661.Bản quyền phim '!F:F,'KK1. Movies'!D37,'TK 15661.Bản quyền phim '!X:X) -> 0 | AK37: =SUMIF('TK 15661.Bản quyền phim '!F:F,'KK1. Movies'!AI37,'TK 15661.Bản quyền phim '!X:X) -> 19047619 | AL37: =COUNTIF('242.BQ Phim hợp tác'!$C:$C,'KK1. Movies'!AI37) -> 0 | AM37: =COUNTIF('TK 15661.Bản quyền phim '!F:F,'KK1. Movies'!AI37) -> 1 | AN37: =AL37+AM37 -> 1
A38: =_xlfn.AGGREGATE(3,3,$D$7:D38) -> 32 | B38: 16+ | C38: MOV_DRA_23__2696805 | D38: The Last Princess | E38: Công chúa cuối cùng | F38: Drama | G38: King Content | H38: 52/2023/HDBQ/VSTV-KC | I38: 2016 | J38: Korea | K38: 127 | L38: 45147 | M38: 46242 | N38: 45226 | O38: K+CINE | P38: Exclusive All PayTV rights and Non-Exclusive VOD rights | Q38: Yes | R38: Yes | S38: No | T38: Yes | U38: Yes | V38: Yes | W38: Yes | X38: Yes | Y38: No | Z38: 45147 | AA38: 46242 | AB38: unlimited | AC38: 15 | AD38: Yes | AE38: Yes | AG38: Phim còn hạn từ 2026 | AI38: Last princess | AJ38: =SUMIF('TK 15661.Bản quyền phim '!F:F,'KK1. Movies'!D38,'TK 15661.Bản quyền phim '!X:X) -> 0 | AK38: =SUMIF('TK 15661.Bản quyền phim '!F:F,'KK1. Movies'!AI38,'TK 15661.Bản quyền phim '!X:X) -> 0 | AL38: =COUNTIF('242.BQ Phim hợp tác'!$C:$C,'KK1. Movies'!AI38) -> 0 | AM38: =COUNTIF('TK 15661.Bản quyền phim '!F:F,'KK1. Movies'!AI38) -> 1 | AN38: =AL38+AM38 -> 1
A39: =_xlfn.AGGREGATE(3,3,$D$7:D39) -> 33 | B39: P | C39: MOV_ANI_23__2698580 | D39: Space dogs: Tropical adventure | E39: Biệt đội phi hành cún | F39: Comedy | G39: Roses Media | H39: 82/2023/HDBQ/VSTV-Roses Media | I39: 2020 | J39: Russia | K39: 80 | L39: 45206 | M39: 46301 | N39: 45206 | O39: K+KIDS | P39: Exclusive All Pay TV Rights for first 12 months. Non exclusive All VOD during LP | Q39: No | R39: Yes | S39: Yes | T39: Yes | U39: Yes | V39: Yes | W39: Yes | X39: Yes | Y39: No | Z39: 45206 | AA39: 46301 | AB39: 24 | AC39: 16 | AD39: Yes | AE39: Yes | AG39: Phim còn hạn từ 2026 | AI39: Space Dogs: Return to Earth | AJ39: =SUMIF('TK 15661.Bản quyền phim '!F:F,'KK1. Movies'!D39,'TK 15661.Bản quyền phim '!X:X) -> 0 | AK39: =SUMIF('TK 15661.Bản quyền phim '!F:F,'KK1. Movies'!AI39,'TK 15661.Bản quyền phim '!X:X) -> 0 | AL39: =COUNTIF('242.BQ Phim hợp tác'!$C:$C,'KK1. Movies'!AI39) -> 0 | AM39: =COUNTIF('TK 15661.Bản quyền phim '!F:F,'KK1. Movies'!AI39) -> 1 | AN39: =AL39+AM39 -> 1
A40: =_xlfn.AGGREGATE(3,3,$D$7:D40) -> 34 | B40: 16+ | C40: MOV_ACT_23__2693252 | D40: The Ice Road | E40: Con đường băng | F40: Action, Adventure | G40: Roses Media | H40: 140/2022/HDBQ/VSTV-RM | I40: 2021 | J40: US | K40: 103 | L40: 45133 | M40: 46228 | N40: 45133 | O40: K+CINE | P40: Exclusive All Pay TV Rights for first 12 months. Non exclusive All VOD during LP | Q40: No | R40: Yes | S40: No | T40: Yes | U40: Yes | V40: Yes | W40: Yes | X40: Yes | Y40: No | Z40: 45133 | AA40: 46228 | AB40: 24 | AC40: 15 | AD40: Yes | AE40: Yes | AG40: Phim còn hạn từ 2026 | AI40: The Ice Road | AJ40: =SUMIF('TK 15661.Bản quyền phim '!F:F,'KK1. Movies'!D40,'TK 15661.Bản quyền phim '!X:X) -> 0 | AK40: =SUMIF('TK 15661.Bản quyền phim '!F:F,'KK1. Movies'!AI40,'TK 15661.Bản quyền phim '!X:X) -> 0 | AL40: =COUNTIF('242.BQ Phim hợp tác'!$C:$C,'KK1. Movies'!AI40) -> 0 | AM40: =COUNTIF('TK 15661.Bản quyền phim '!F:F,'KK1. Movies'!AI40) -> 1 | AN40: =AL40+AM40 -> 1
...

Sheet KK6. Bổ sung
A1: CÔNG TY: | B1: Công ty TNHH Truyền hình số vệ tinh Việt Nam | T1: Cộng Hòa Xã Hội Chủ Nghĩa Việt Nam
T2: Độc Lập - Tự Do - Hạnh Phúc
Q4: =COUNTIF(Q7:Q44,1) -> 0 | R4: =COUNTIF(R7:R44,1) -> 38
N5: Ref File Kế toán | S5: Check | T5: SỐ LIỆU KIỂM KÊ | W5: Giải trình chênh lệch | X5: Đề xuất Phương án xử lý
A6: Inventory code | B6: Contract currency | C6: Contractor code | D6: Contractor name | E6: Program name | F6: Nature Programme | G6: No of EPS (Initially) | H6: Starting Date of right | I6: Ending date of right | J6: From (DTH) | K6: To (DTH) | L6: Note | N6: Tên trên file Kế toán | O6: details kế toán | P6: Giá trị còn lại (15661) | Q6: Check ref "TK 242.BQ Phim hợp tác" | R6: Check ref "TK 15661. Bản quyền phim" | T6: Số lượng | U6: From (VOD) | V6: To (VOD)
A7: K+1MOV021273 | B7: VND | C7: S0001502 | D7: Công ty TNHH Đối tác Chuyên nghiệp | E7: THE BREAKUP GURU | F7: Movies International | G7: 1 | H7: 5 | I7: 5 | J7: 44519 | K7: 46160 | L7: Phim còn hạn từ 2026 | N7: SHINING FOR ONE THING | O7: =SUMIF('TK 15661.Bản quyền phim '!F:F,'KK6. Bổ sung'!D7,'TK 15661.Bản quyền phim '!X:X) -> 0 | P7: =SUMIF('TK 15661.Bản quyền phim '!F:F,'KK6. Bổ sung'!N7,'TK 15661.Bản quyền phim '!X:X) -> 59932953 | R7: =COUNTIF('TK 15661.Bản quyền phim '!F:F,'KK6. Bổ sung'!N7) -> 1 | S7: =Q7+R7 -> 1
A8: K+1MOV021274 | B8: VND | C8: S0001502 | D8: Công ty TNHH Đối tác Chuyên nghiệp | E8: FALL IN LOVE LIKE A STAR | F8: Movies International | G8: 1 | H8: 5 | I8: 5 | J8: 44491 | K8: 46133 | L8: Phim còn hạn từ 2026 | N8: ROGUE HEROS | O8: =SUMIF('TK 15661.Bản quyền phim '!F:F,'KK6. Bổ sung'!D8,'TK 15661.Bản quyền phim '!X:X) -> 0 | P8: =SUMIF('TK 15661.Bản quyền phim '!F:F,'KK6. Bổ sung'!N8,'TK 15661.Bản quyền phim '!X:X) -> 0 | R8: =COUNTIF('TK 15661.Bản quyền phim '!F:F,'KK6. Bổ sung'!N8) -> 1 | S8: =Q8+R8 -> 1
A9: K+1MOV021275 | B9: VND | C9: S0001502 | D9: Công ty TNHH Đối tác Chuyên nghiệp | E9: NE ZHA | F9: Movies International | G9: 1 | H9: 5 | I9: 5 | J9: 44533 | K9: 46175 | L9: Phim còn hạn từ 2026 | N9: Escape Plan 2: Hades | O9: =SUMIF('TK 15661.Bản quyền phim '!F:F,'KK6. Bổ sung'!D9,'TK 15661.Bản quyền phim '!X:X) -> 0 | P9: =SUMIF('TK 15661.Bản quyền phim '!F:F,'KK6. Bổ sung'!N9,'TK 15661.Bản quyền phim '!X:X) -> 0 | R9: =COUNTIF('TK 15661.Bản quyền phim '!F:F,'KK6. Bổ sung'!N9) -> 1 | S9: =Q9+R9 -> 1
A10: K+1MOV021276 | B10: VND | C10: S0001502 | D10: Công ty TNHH Đối tác Chuyên nghiệp | E10: SOUL SNATCHER | F10: Movies International | G10: 1 | H10: 5 | I10: 5 | J10: 44517 | K10: 46158 | L10: Phim còn hạn từ 2026 | N10: Riam: Fighting Angel | O10: =SUMIF('TK 15661.Bản quyền phim '!F:F,'KK6. Bổ sung'!D10,'TK 15661.Bản quyền phim '!X:X) -> 0 | P10: =SUMIF('TK 15661.Bản quyền phim '!F:F,'KK6. Bổ sung'!N10,'TK 15661.Bản quyền phim '!X:X) -> 0 | R10: =COUNTIF('TK 15661.Bản quyền phim '!F:F,'KK6. Bổ sung'!N10) -> 1 | S10: =Q10+R10 -> 1
A11: K+1MOV021279 | B11: VND | C11: S0001502 | D11: Công ty TNHH Đối tác Chuyên nghiệp | E11: RAT DISASTER | F11: Movies International | G11: 1 | H11: 5 | I11: 5 | J11: 44538 | K11: 46180 | L11: Phim còn hạn từ 2026 | N11: Happy Family | O11: =SUMIF('TK 15661.Bản quyền phim '!F:F,'KK6. Bổ sung'!D11,'TK 15661.Bản quyền phim '!X:X) -> 0 | P11: =SUMIF('TK 15661.Bản quyền phim '!F:F,'KK6. Bổ sung'!N11,'TK 15661.Bản quyền phim '!X:X) -> 0 | R11: =COUNTIF('TK 15661.Bản quyền phim '!F:F,'KK6. Bổ sung'!N11) -> 1 | S11: =Q11+R11 -> 1
A12: K+1MOV021282 | B12: VND | C12: S0001502 | D12: Công ty TNHH Đối tác Chuyên nghiệp | E12: FEARLESS KUNGFU KING | F12: Movies International | G12: 1 | H12: 5 | I12: 5 | J12: 44531 | K12: 46356 | L12: Phim còn hạn từ 2026 | N12: MEMOIRS OF A GEISHA | O12: =SUMIF('TK 15661.Bản quyền phim '!F:F,'KK6. Bổ sung'!D12,'TK 15661.Bản quyền phim '!X:X) -> 0 | P12: =SUMIF('TK 15661.Bản quyền phim '!F:F,'KK6. Bổ sung'!N12,'TK 15661.Bản quyền phim '!X:X) -> 46627350 | R12: =COUNTIF('TK 15661.Bản quyền phim '!F:F,'KK6. Bổ sung'!N12) -> 1 | S12: =Q12+R12 -> 1
A13: K+1MOV021283 | B13: VND | C13: S0001502 | D13: Công ty TNHH Đối tác Chuyên nghiệp | E13: MATCHLESS MULAN | F13: Movies International | G13: 1 | H13: 5 | I13: 5 | J13: 44489 | K13: 46131 | L13: Phim còn hạn từ 2026 | N13: Ironbark/The Courier | O13: =SUMIF('TK 15661.Bản quyền phim '!F:F,'KK6. Bổ sung'!D13,'TK 15661.Bản quyền phim '!X:X) -> 0 | P13: =SUMIF('TK 15661.Bản quyền phim '!F:F,'KK6. Bổ sung'!N13,'TK 15661.Bản quyền phim '!X:X) -> 0 | R13: =COUNTIF('TK 15661.Bản quyền phim '!F:F,'KK6. Bổ sung'!N13) -> 1 | S13: =Q13+R13 -> 1
A14: K+1MOV021284 | B14: VND | C14: S0001502 | D14: Công ty TNHH Đối tác Chuyên nghiệp | E14: LOVE IN BLOOD | F14: Movies International | G14: 1 | H14: 5 | I14: 5 | J14: 44461 | K14: 46102 | L14: Phim còn hạn từ 2026 | N14: Hitman's Wife's Bodyguard | O14: =SUMIF('TK 15661.Bản quyền phim '!F:F,'KK6. Bổ sung'!D14,'TK 15661.Bản quyền phim '!X:X) -> 0 | P14: =SUMIF('TK 15661.Bản quyền phim '!F:F,'KK6. Bổ sung'!N14,'TK 15661.Bản quyền phim '!X:X) -> 0 | R14: =COUNTIF('TK 15661.Bản quyền phim '!F:F,'KK6. Bổ sung'!N14) -> 1 | S14: =Q14+R14 -> 1
A15: K+1MOV021285 | B15: VND | C15: S0001502 | D15: Công ty TNHH Đối tác Chuyên nghiệp | E15: GOD OF WAR | F15: Movies International | G15: 1 | H15: 5 | I15: 5 | J15: 44475 | K15: 46117 | L15: Phim còn hạn từ 2026 | N15: GUIMOON: THE LIGHTLESS DOOR (CỔNG ĐỊA NGỤC) | O15: =SUMIF('TK 15661.Bản quyền phim '!F:F,'KK6. Bổ sung'!D15,'TK 15661.Bản quyền phim '!X:X) -> 0 | P15: =SUMIF('TK 15661.Bản quyền phim '!F:F,'KK6. Bổ sung'!N15,'TK 15661.Bản quyền phim '!X:X) -> 28571429 | R15: =COUNTIF('TK 15661.Bản quyền phim '!F:F,'KK6. Bổ sung'!N15) -> 1 | S15: =Q15+R15 -> 1
A16: K+1MOV021287 | B16: VND | C16: S0001502 | D16: Công ty TNHH Đối tác Chuyên nghiệp | E16: THE RISE OF HERO | F16: Movies International | G16: 1 | H16: 5 | I16: 5 | J16: 44559 | K16: 46201 | L16: Phim còn hạn từ 2026 | M16: MOV_DRA_23__2696593 | N16: Greta | O16: =SUMIF('TK 15661.Bản quyền phim '!F:F,'KK6. Bổ sung'!D16,'TK 15661.Bản quyền phim '!X:X) -> 0 | P16: =SUMIF('TK 15661.Bản quyền phim '!F:F,'KK6. Bổ sung'!N16,'TK 15661.Bản quyền phim '!X:X) -> 0 | R16: =COUNTIF('TK 15661.Bản quyền phim '!F:F,'KK6. Bổ sung'!N16) -> 1 | S16: =Q16+R16 -> 1
A17: K+1MOV021288 | B17: VND | C17: S0001502 | D17: Công ty TNHH Đối tác Chuyên nghiệp | E17: SWORDSMAN | F17: Movies International | G17: 1 | H17: 5 | I17: 5 | J17: 44503 | K17: 46144 | L17: Phim còn hạn từ 2026 | M17: MOV_FAN_22__2686869 | N17: HOUSE WITH A CLOCK IN ITS WALLS (Ngôi nhà có chiếc đồng hồ ma thuật) | O17: =SUMIF('TK 15661.Bản quyền phim '!F:F,'KK6. Bổ sung'!D17,'TK 15661.Bản quyền phim '!X:X) -> 0 | P17: =SUMIF('TK 15661.Bản quyền phim '!F:F,'KK6. Bổ sung'!N17,'TK 15661.Bản quyền phim '!X:X) -> 0 | R17: =COUNTIF('TK 15661.Bản quyền phim '!F:F,'KK6. Bổ sung'!N17) -> 1 | S17: =Q17+R17 -> 1
A18: K+2SER022116 | B18: USD | C18: S0002262 | D18: IQIYI INTERNATIONAL SINGAPORE PTE. LTD. | E18: Ideal City | F18: Series Asian | G18: 40 | H18: 4 | I18: 160 | J18: 44642 | K18: 46102 | L18: Phim còn hạn từ 2026 | N18: HUNT, THE | O18: =SUMIF('TK 15661.Bản quyền phim '!F:F,'KK6. Bổ sung'!D18,'TK 15661.Bản quyền phim '!X:X) -> 0 | P18: =SUMIF('TK 15661.Bản quyền phim '!F:F,'KK6. Bổ sung'!N18,'TK 15661.Bản quyền phim '!X:X) -> 0 | R18: =COUNTIF('TK 15661.Bản quyền phim '!F:F,'KK6. Bổ sung'!N18) -> 1 | S18: =Q18+R18 -> 1
A19: K+1MOV023009 | B19: VND | C19: S0001804 | D19: CÔNG TY TNHH TRUYỀN THÔNG ROSES | E19: ROGUE | F19: Movies International | G19: 1 | H19: 3 | I19: 3 | J19: 45077 | K19: 46172 | L19: Phim còn hạn từ 2026 | M19: MOV_CRI_21__2648182 | N19: MOZU | O19: =SUMIF('TK 15661.Bản quyền phim '!F:F,'KK6. Bổ sung'!D19,'TK 15661.Bản quyền phim '!X:X) -> 0 | P19: =SUMIF('TK 15661.Bản quyền phim '!F:F,'KK6. Bổ sung'!N19,'TK 15661.Bản quyền phim '!X:X) -> 0 | R19: =COUNTIF('TK 15661.Bản quyền phim '!F:F,'KK6. Bổ sung'!N19) -> 1 | S19: =Q19+R19 -> 1
A20: K+5KID023239 | B20: USD | C20: S0002484 | D20: GULLANE (THOMAS) LIMITED | E20: Thomas & Friends Series 25 Special – Race for the Sodor Cup | F20: KIDS | G20: 1 | H20: 3 | I20: 3 | J20: 45200 | K20: 46295 | L20: Phim còn hạn từ 2026 | M20: MOV_HOR_24__2713878 | N20: CONTORTED (NHÀ KHO CHẾT CHÓC) | O20: =SUMIF('TK 15661.Bản quyền phim '!F:F,'KK6. Bổ sung'!D20,'TK 15661.Bản quyền phim '!X:X) -> 0 | P20: =SUMIF('TK 15661.Bản quyền phim '!F:F,'KK6. Bổ sung'!N20,'TK 15661.Bản quyền phim '!X:X) -> 28571429 | R20: =COUNTIF('TK 15661.Bản quyền phim '!F:F,'KK6. Bổ sung'!N20) -> 1 | S20: =Q20+R20 -> 1
A21: K+1MOV024126 | B21: VND | C21: S0002365 | D21: CÔNG TY CỔ PHẦN TRUYỀN THÔNG HỎA THỔ | E21: The Hot-Blooded (Tử Chiến) | F21: Movies International | G21: 1 | H21: 3 | I21: 3 | J21: 45435 | K21: 46529 | L21: Phim còn hạn từ 2026 | N21: The Night Clerk | O21: =SUMIF('TK 15661.Bản quyền phim '!F:F,'KK6. Bổ sung'!D21,'TK 15661.Bản quyền phim '!X:X) -> 0 | P21: =SUMIF('TK 15661.Bản quyền phim '!F:F,'KK6. Bổ sung'!N21,'TK 15661.Bản quyền phim '!X:X) -> 0 | R21: =COUNTIF('TK 15661.Bản quyền phim '!F:F,'KK6. Bổ sung'!N21) -> 1 | S21: =Q21+R21 -> 1
A22: K+1MOV024132 | B22: VND | C22: S0002365 | D22: CÔNG TY CỔ PHẦN TRUYỀN THÔNG HỎA THỔ | E22: Z Storm (Đội Chống Tham Nhũng) | F22: Movies International | G22: 1 | H22: 3 | I22: 3 | J22: 45506 | K22: 46600 | L22: Phim còn hạn từ 2026 | N22: Journey to China: The Mystery of the Dragon Seal | O22: =SUMIF('TK 15661.Bản quyền phim '!F:F,'KK6. Bổ sung'!D22,'TK 15661.Bản quyền phim '!X:X) -> 0 | P22: =SUMIF('TK 15661.Bản quyền phim '!F:F,'KK6. Bổ sung'!N22,'TK 15661.Bản quyền phim '!X:X) -> 29462698 | R22: =COUNTIF('TK 15661.Bản quyền phim '!F:F,'KK6. Bổ sung'!N22) -> 1 | S22: =Q22+R22 -> 1
A23: K+1MOV024133 | B23: VND | C23: S0002365 | D23: CÔNG TY CỔ PHẦN TRUYỀN THÔNG HỎA THỔ | E23: Raging Fire (Cuồng Phong Nộ Hỏa) | F23: Movies International | G23: 1 | H23: 3 | I23: 3 | J23: 45520 | K23: 46614 | L23: Phim còn hạn từ 2026 | N23: Gringo | O23: =SUMIF('TK 15661.Bản quyền phim '!F:F,'KK6. Bổ sung'!D23,'TK 15661.Bản quyền phim '!X:X) -> 0 | P23: =SUMIF('TK 15661.Bản quyền phim '!F:F,'KK6. Bổ sung'!N23,'TK 15661.Bản quyền phim '!X:X) -> 0 | R23: =COUNTIF('TK 15661.Bản quyền phim '!F:F,'KK6. Bổ sung'!N23) -> 1 | S23: =Q23+R23 -> 1
A24: K+1MOV024134 | B24: VND | C24: S0002365 | D24: CÔNG TY CỔ PHẦN TRUYỀN THÔNG HỎA THỔ | E24: Ip Man 3 (Diệp Vấn 3) | F24: Movies International | G24: 1 | H24: 3 | I24: 3 | J24: 45548 | K24: 46642 | L24: Phim còn hạn từ 2026 | N24: THE GIRL ON THE TRAIN (Cô gái trên tàu) | O24: =SUMIF('TK 15661.Bản quyền phim '!F:F,'KK6. Bổ sung'!D24,'TK 15661.Bản quyền phim '!X:X) -> 0 | P24: =SUMIF('TK 15661.Bản quyền phim '!F:F,'KK6. Bổ sung'!N24,'TK 15661.Bản quyền phim '!X:X) -> 0 | R24: =COUNTIF('TK 15661.Bản quyền phim '!F:F,'KK6. Bổ sung'!N24) -> 1 | S24: =Q24+R24 -> 1
A25: K+1MOV024135 | B25: USD | C25: S0002438 | D25: Paramount Pictures International Limited | E25: CRAWL | F25: Movies International | G25: 1 | H25: 2 | I25: 2 | J25: 45609 | K25: 46154 | L25: Phim còn hạn từ 2026 | N25: Triple Threat | O25: =SUMIF('TK 15661.Bản quyền phim '!F:F,'KK6. Bổ sung'!D25,'TK 15661.Bản quyền phim '!X:X) -> 0 | P25: =SUMIF('TK 15661.Bản quyền phim '!F:F,'KK6. Bổ sung'!N25,'TK 15661.Bản quyền phim '!X:X) -> 0 | R25: =COUNTIF('TK 15661.Bản quyền phim '!F:F,'KK6. Bổ sung'!N25) -> 1 | S25: =Q25+R25 -> 1
A26: K+2MOV024138 | B26: USD | C26: S0002438 | D26: Paramount Pictures International Limited | E26: GHOST IN THE SHELL (2017) | F26: Movies International | G26: 1 | H26: 2 | I26: 2 | J26: 45609 | K26: 46154 | L26: Phim còn hạn từ 2026 | N26: RECALLED (TRIỆU HỒI) | O26: =SUMIF('TK 15661.Bản quyền phim '!F:F,'KK6. Bổ sung'!D26,'TK 15661.Bản quyền phim '!X:X) -> 0 | P26: =SUMIF('TK 15661.Bản quyền phim '!F:F,'KK6. Bổ sung'!N26,'TK 15661.Bản quyền phim '!X:X) -> 19047619 | R26: =COUNTIF('TK 15661.Bản quyền phim '!F:F,'KK6. Bổ sung'!N26) -> 1 | S26: =Q26+R26 -> 1
A27: K+1MOV024140 | B27: USD | C27: S0002438 | D27: Paramount Pictures International Limited | E27: JACK RYAN: SHADOW RECRUIT | F27: Movies International | G27: 1 | H27: 2 | I27: 2 | J27: 45569 | K27: 46115 | L27: Phim còn hạn từ 2026 | N27: A DOG'S PURPOSE (Mục đích sống của một chú chó) | O27: =SUMIF('TK 15661.Bản quyền phim '!F:F,'KK6. Bổ sung'!D27,'TK 15661.Bản quyền phim '!X:X) -> 0 | P27: =SUMIF('TK 15661.Bản quyền phim '!F:F,'KK6. Bổ sung'!N27,'TK 15661.Bản quyền phim '!X:X) -> 0 | R27: =COUNTIF('TK 15661.Bản quyền phim '!F:F,'KK6. Bổ sung'!N27) -> 1 | S27: =Q27+R27 -> 1
A28: K+1MOV024141 | B28: USD | C28: S0002438 | D28: Paramount Pictures International Limited | E28: MISSION: IMPOSSIBLE | F28: Movies International | G28: 1 | H28: 2 | I28: 2 | J28: 45597 | K28: 46142 | L28: Phim còn hạn từ 2026 | N28: BURLESQUE | O28: =SUMIF('TK 15661.Bản quyền phim '!F:F,'KK6. Bổ sung'!D28,'TK 15661.Bản quyền phim '!X:X) -> 0 | P28: =SUMIF('TK 15661.Bản quyền phim '!F:F,'KK6. Bổ sung'!N28,'TK 15661.Bản quyền phim '!X:X) -> 0 | R28: =COUNTIF('TK 15661.Bản quyền phim '!F:F,'KK6. Bổ sung'!N28) -> 1 | S28: =Q28+R28 -> 1
A29: K+1MOV024142 | B29: USD | C29: S0002438 | D29: Paramount Pictures International Limited | E29: MISSION: IMPOSSIBLE - GHOST PROTOCOL | F29: Movies International | G29: 1 | H29: 2 | I29: 2 | J29: 45597 | K29: 46142 | L29: Phim còn hạn từ 2026 | N29: My Spy | O29: =SUMIF('TK 15661.Bản quyền phim '!F:F,'KK6. Bổ sung'!D29,'TK 15661.Bản quyền phim '!X:X) -> 0 | P29: =SUMIF('TK 15661.Bản quyền phim '!F:F,'KK6. Bổ sung'!N29,'TK 15661.Bản quyền phim '!X:X) -> 0 | R29: =COUNTIF('TK 15661.Bản quyền phim '!F:F,'KK6. Bổ sung'!N29) -> 1 | S29: =Q29+R29 -> 1
A30: K+1MOV024143 | B30: USD | C30: S0002438 | D30: Paramount Pictures International Limited | E30: MISSION: IMPOSSIBLE - ROGUE NATION | F30: Movies International | G30: 1 | H30: 2 | I30: 2 | J30: 45597 | K30: 46142 | L30: Phim còn hạn từ 2026 | N30: EMILY THE CRIMINAL | O30: =SUMIF('TK 15661.Bản quyền phim '!F:F,'KK6. Bổ sung'!D30,'TK 15661.Bản quyền phim '!X:X) -> 0 | P30: =SUMIF('TK 15661.Bản quyền phim '!F:F,'KK6. Bổ sung'!N30,'TK 15661.Bản quyền phim '!X:X) -> 0 | R30: =COUNTIF('TK 15661.Bản quyền phim '!F:F,'KK6. Bổ sung'!N30) -> 1 | S30: =Q30+R30 -> 1
A31: K+1MOV024144 | B31: USD | C31: S0002438 | D31: Paramount Pictures International Limited | E31: MISSION: IMPOSSIBLE II | F31: Movies International | G31: 1 | H31: 2 | I31: 2 | J31: 45597 | K31: 46142 | L31: Phim còn hạn từ 2026 | N31: A LONG WAY DOWN | O31: =SUMIF('TK 15661.Bản quyền phim '!F:F,'KK6. Bổ sung'!D31,'TK 15661.Bản quyền phim '!X:X) -> 0 | P31: =SUMIF('TK 15661.Bản quyền phim '!F:F,'KK6. Bổ sung'!N31,'TK 15661.Bản quyền phim '!X:X) -> 33333492 | R31: =COUNTIF('TK 15661.Bản quyền phim '!F:F,'KK6. Bổ sung'!N31) -> 1 | S31: =Q31+R31 -> 1
A32: K+1MOV024145 | B32: USD | C32: S0002438 | D32: Paramount Pictures International Limited | E32: MISSION: IMPOSSIBLE III | F32: Movies International | G32: 1 | H32: 2 | I32: 2 | J32: 45597 | K32: 46142 | L32: Phim còn hạn từ 2026 | N32: WITCH, THE | O32: =SUMIF('TK 15661.Bản quyền phim '!F:F,'KK6. Bổ sung'!D32,'TK 15661.Bản quyền phim '!X:X) -> 0 | P32: =SUMIF('TK 15661.Bản quyền phim '!F:F,'KK6. Bổ sung'!N32,'TK 15661.Bản quyền phim '!X:X) -> 0 | R32: =COUNTIF('TK 15661.Bản quyền phim '!F:F,'KK6. Bổ sung'!N32) -> 1 | S32: =Q32+R32 -> 1
... A41: K+1MOV025037 | B41: VND | C41: S0001883 | D41: Công Ty TNHH HÌNH ẢNH CON CHIM NHẠI | E41: Anti -piracy-contract 8 movies Mockingbird 2025 | F41: Movies International | G41: 1 | H41: 1 | I41: 1 | J41: 45688 | K41: 46052 | L41: Phim còn hạn từ 2026 | N41: LITTLE WOMEN (2019) | O41: =SUMIF('TK 15661.Bản quyền phim '!F:F,'KK6. Bổ sung'!D41,'TK 15661.Bản quyền phim '!X:X) -> 0 | P41: =SUMIF('TK 15661.Bản quyền phim '!F:F,'KK6. Bổ sung'!N41,'TK 15661.Bản quyền phim '!X:X) -> 46627350 | R41: =COUNTIF('TK 15661.Bản quyền phim '!F:F,'KK6. Bổ sung'!N41) -> 1 | S41: =Q41+R41 -> 1
A42: K+1MOV025053 | B42: VND | C42: S0001328 | D42: Công ty TNHH Skyline Media | E42: ARTICLE 20 | F42: Movies International | G42: 1 | H42: 3 | I42: 3 | J42: 45807 | K42: 46902 | L42: Phim còn hạn từ 2026 | M42: MOV_ACT587 | N42: RIDE ALONG | O42: =SUMIF('TK 15661.Bản quyền phim '!F:F,'KK6. Bổ sung'!D42,'TK 15661.Bản quyền phim '!X:X) -> 0 | P42: =SUMIF('TK 15661.Bản quyền phim '!F:F,'KK6. Bổ sung'!N42,'TK 15661.Bản quyền phim '!X:X) -> 0 | R42: =COUNTIF('TK 15661.Bản quyền phim '!F:F,'KK6. Bổ sung'!N42) -> 1 | S42: =Q42+R42 -> 1
A43: K+1DOC025186 | B43: USD | C43: S0001082 | D43: FCCE BV | E43: End Of Year Special 2025 | F43: Doc-Art | G43: 1 | H43: 1 | I43: 1 | J43: 45806 | K43: 46170 | L43: Phim còn hạn từ 2026 | M43: MOV_ROM_23__2697130 | N43: Time Freak | O43: =SUMIF('TK 15661.Bản quyền phim '!F:F,'KK6. Bổ sung'!D43,'TK 15661.Bản quyền phim '!X:X) -> 0 | P43: =SUMIF('TK 15661.Bản quyền phim '!F:F,'KK6. Bổ sung'!N43,'TK 15661.Bản quyền phim '!X:X) -> 0 | R43: =COUNTIF('TK 15661.Bản quyền phim '!F:F,'KK6. Bổ sung'!N43) -> 1 | S43: =Q43+R43 -> 1
A44: K+2SER025189 | B44: USD | C44: S0002419 | D44: PCCW Vuclip (Singapore) Pte. Ltd. | E44: Love's ambition (Hãy để tôi tỏa sáng) | F44: Series Asian | G44: 32 | H44: 5 | I44: 160 | J44: 45926 | K44: 47751 | L44: Phim còn hạn từ 2026 | M44: MOV_ACT_24__2715853 | N44: Cloudy Mountain (Chiều Sâu Vô Hạn) | O44: =SUMIF('TK 15661.Bản quyền phim '!F:F,'KK6. Bổ sung'!D44,'TK 15661.Bản quyền phim '!X:X) -> 0 | P44: =SUMIF('TK 15661.Bản quyền phim '!F:F,'KK6. Bổ sung'!N44,'TK 15661.Bản quyền phim '!X:X) -> 33737937 | R44: =COUNTIF('TK 15661.Bản quyền phim '!F:F,'KK6. Bổ sung'!N44) -> 1 | S44: =Q44+R44 -> 1

Sheet KK2. Series
A1: CÔNG TY: | B1: Công ty TNHH Truyền hình số vệ tinh Việt Nam | AO1: Cộng Hòa Xã Hội Chủ Nghĩa Việt Nam | AU1: Cộng Hòa Xã Hội Chủ Nghĩa Việt Nam
AO2: Độc Lập - Tự Do - Hạnh Phúc | AU2: Độc Lập - Tự Do - Hạnh Phúc
A3: BÁO CÁO KIỂM KÊ BẢN QUYỀN SERIES
A4: Thời điểm:….......giờ, ngày…....tháng.........năm 2026 | AT4: Check
A5: No. | B5: Clip code | C5: ENGLISH Title | D5: VIET Title | E5: Provider | F5: Contract number | G5: Origin | H5: Year of production | I5: No. of eps | J5: Duration (minute) | K5: Duration ( Hour) | L5: No. of eps (after Cut) | M5: Genre | N5: Main Genre | O5: From (DTH) | P5: To (DTH) | Q5: VSTV's 1st airing date | R5: Channel | S5: Exclusive (month) | T5: Sub-license | U5: OTT rights | V5: Catch-up | W5: SVOD | X5: FVOD | Y5: AVOD | Z5: TVOD | AA5: Internet Streaming | AB5: Internet Downloading | AC5: From (VOD) | AD5: To (VOD) | AE5: Runs No. | AF5: Broadcasted runs | AG5: Last broadcast date | AH5: Remain Run | AI5: HD Censorship | AJ5: LTO | AK5: Day And Date | AL5: Note | AM5: Tên trên file Kế toán | AN5: details kế toán | AO5: Giá trị còn lại (15661) | AP5: Check ref "242. BQ Phim VOD" | AQ5: Check ref "TK 15666. Phim SX" | AR5: Check ref "TK 15661. Bản quyền phim" | AS5: Phim Barter | AU5: SỐ LIỆU KIỂM KÊ | AX5: Giải trình chênh lệch | AY5: Đề xuất Phương án xử lý
AP6: =COUNTIF(AP7:AP174,1) -> 36 | AQ6: =COUNTIF(AQ7:AQ174,1) -> 7 | AR6: =COUNTIF(AR7:AR174,1) -> 72 | AU6: Số lượng | AV6: From (VOD) | AW6: To (VOD)
A7: 1 | B7: Voice: EP01 – SER_DRA_2656765 EP02 – SER_DRA_2656766 EP03 – SER_DRA_2656767 EP04 – SER_DRA_2656768 EP05 – SER_DRA_2656769 EP06 – SER_DRA_2656770 EP07 – SER_DRA_2656771 EP08 – SER_DRA_2656772 EP09 – SER_DRA_2656773 EP10 – SER_DRA_2656774 EP11 – SER_DRA_2656775 EP12 – SER_DRA_2656776 EP13 – SER_DRA_2656777 EP14 – SER_DRA_2656778 EP15 – SER_DRA_2656779 EP16 – SER_DRA_2656780 EP17 – SER_DRA_2656781 EP18 – SER_DRA_2656782 EP19 – SER_DRA_2656783 EP20 – SER_DRA_2656784 EP21 – SER_DRA_2656785 EP22 – SER_DRA_2656786 EP23 – SER_DRA_2656787 EP24 – SER_DRA_2656788 EP25 – SER_DRA_2656789 EP26 – SER_DRA_2656790 EP27 – SER_DRA_2656791 EP28 – SER_DRA_2656792 EP29 – SER_DRA_2656793 EP30 – SER_DRA_2656794 EP31 – SER_DRA_2656795 EP32 – SER_DRA_2656796 EP33 – SER_DRA_2656797 EP34 – SER_DRA_2656798 EP35 – SER_DRA_2656799 EP36 – SER_DRA_2656800 EP37 – SER_DRA_2656801 EP38 – SER_DRA_2656802 EP39 – SER_DRA_2656803 EP40 – SER_DRA_2656804 Sub: SER_DRA_21_2652587 LOVE IS TRUE, EP40 (VOD) SER_DRA_21_2652586 LOVE IS TRUE, EP39 (VOD) SER_DRA_21_2652585 LOVE IS TRUE, EP38 (VOD) SER_DRA_21_2652584 LOVE IS TRUE, EP37 (VOD) SER_DRA_21_2652581 LOVE IS TRUE, EP34 (VOD) SER_DRA_21_2652583 LOVE IS TRUE, EP36 (VOD) SER_DRA_21_2652582 LOVE IS TRUE, EP35 (VOD) SER_DRA_21_2652580 LOVE IS TRUE, EP33 (VOD) SER_DRA_21_2652579 LOVE IS TRUE, EP32 (VOD) SER_DRA_21_2652578 LOVE IS TRUE, EP31 (VOD) SER_DRA_21_2652577 LOVE IS TRUE, EP30 (VOD) SER_DRA_21_2652576 LOVE IS TRUE, EP29 (VOD) SER_DRA_21_2652575 LOVE IS TRUE, EP28 (VOD) SER_DRA_21_2652574 LOVE IS TRUE, EP27 (VOD) SER_DRA_21_2652572 LOVE IS TRUE, EP25 (VOD) SER_DRA_21_2652573 LOVE IS TRUE, EP26 (VOD) SER_DRA_21_2652571 LOVE IS TRUE, EP24 (VOD) SER_DRA_21_2652569 LOVE IS TRUE, EP22 (VOD) SER_DRA_21_2652570 LOVE IS TRUE, EP23 (VOD) SER_DRA_21_2652568 LOVE IS TRUE, EP21 (VOD) SER_DRA_21_2652567 LOVE IS TRUE, EP20 (VOD) SER_DRA_21_2652565 LOVE IS TRUE, EP18 (VOD) SER_DRA_21_2652566 LOVE IS TRUE, EP19 (VOD) SER_DRA_21_2652564 LOVE IS TRUE, EP17 (VOD) SER_DRA_21_2652563 LOVE IS TRUE, EP16 (VOD) SER_DRA_21_2652562 LOVE IS TRUE, EP15 (VOD) SER_DRA_21_2652561 LOVE IS TRUE, EP14 (VOD) SER_DRA_21_2652560 LOVE IS TRUE, EP13 (VOD) SER_DRA_21_2652558 LOVE IS TRUE, EP11 (VOD) SER_DRA_21_2652559 LOVE IS TRUE, EP12 (VOD) SER_DRA_21_2652557 LOVE IS TRUE, EP10 (VOD) SER_DRA_21_2652555 LOVE IS TRUE, EP08 (VOD) SER_DRA_21_2652556 LOVE IS TRUE, EP09 (VOD) SER_DRA_21_2652554 LOVE IS TRUE, EP07 (VOD) SER_DRA_21_2652553 LOVE IS TRUE, EP06 (VOD) SER_DRA_21_2652551 LOVE IS TRUE, EP04 (VOD) SER_DRA_21_2652552 LOVE IS TRUE, EP05 (VOD) SER_DRA_21_2652550 LOVE IS TRUE, EP03 (VOD) SER_DRA_21_2652549 LOVE IS TRUE, EP02 (VOD) SER_DRA__2652548 LOVE IS TRUE, EP01 (VOD) | C7: LOVE IS TRUE | D7: THẬT LÒNG YÊU EM | E7: Hangzhou IX Media | F7: IX Media/Love is True | G7: China | H7: 2021 | I7: 40 | J7: 45 | K7: =(I7*J7)/60 -> 30 | L7: =I7 -> 40 | M7: Drama, Romance | N7: Romance | O7: 44394 | P7: 46219 | Q7: 44595 | R7: K+LIFE | S7: Exclusive All TV Rights and All VOD Rights during LP | T7: Yes | U7: Yes | V7: Yes | W7: Yes | X7: Yes | Y7: Yes | Z7: Yes | AA7: No | AB7: No | AC7: 44394 | AD7: 46219 | AE7: Unlimited | AF7: 3 | AG7: 44600 | AH7: Unlimited | AI7: Yes | AJ7: Yes | AL7: Phim còn hạn từ 2026 | AM7: LOVE IS TRUE | AO7: =SUMIF('TK 15661.Bản quyền phim '!F:F,'KK2. Series'!C7,'TK 15661.Bản quyền phim '!K:K) -> 2767800000 | AP7: =COUNTIF('242.BQ Phim VOD'!$C$5:$C$8,'KK2. Series'!AM7) -> 0 | AQ7: =COUNTIF('TK 15666. Phim SX'!$C$6:$C$13,'KK2. Series'!AM7) -> 0 | AR7: =COUNTIF('TK 15661.Bản quyền phim '!F:F,'KK2. Series'!AM7) -> 1 | AT7: =SUM(AP7:AS7) -> 1
